Workbook

Sheet Raw Data (KG)
B1: Trash | C1: Yellow Skip | D1: Paper (LG7/SSID) | E1: Paper (corrugated containers+office paper+ newspapers) | F1: Metal (Aluminium) | G1: Metal Skip (Metal) | H1: Plastic (waste plastic bottles + plastic bag) | I1: Expanded Polystyrene | J1: CD @0.154kg | K1: Glass | L1: Clothes | M1: Fluorescent Tube @ 0.3kg | N1: Lamp @ 0.07kg | O1: Rechargeable Battery | P1: Toner | Q1: Ink Cartridge (expressed in PIECES) | R1: Electronic Ballast (2x32W) @0.34kg | S1: Electronic Ballast (2x36W) @0.13 | T1: Electronic Ballast (1x36W) @0.15 | U1: Electrical Appliance | V1: Wood | W1: Food Waste (Contractor) | X1: Animal Bedding | Y1: Landscape | Z1: Tetra Packs | AA1: Monthly Total of Waste to Landfill | AB1: Waste to Landfill 12 month rolling sum | AC1: Waste to Landfill 12 month rolling average | AD1: Monthly Total of Recycling | AE1: Recycling 12 month rolling sum | AF1: Recycling 12 month rolling average | AH1: Total Waste Generate | AI1: Total Waste (12month rolling sum)
A2: 41456 | B2: 282100 | D2: 2000 | E2: =5120 | F2: 108 | H2: 240 | J2: 3.25 | M2: 217 | N2: 23 | O2: - | P2: =0.67*172 | Q2: 0 | AA2: =SUM(B2:C2) | AD2: =SUM(D2:Z2)
A3: 41487 | B3: 282100 | D3: 2000 | E3: =4100 | F3: 300 | H3: 250 | J3: 1.16 | M3: 203 | N3: 22 | O3: - | P3: =0.67*177 | Q3: 0 | AA3: =SUM(B3:C3) | AD3: =SUM(D3:Z3)
A4: 41518 | B4: 273000 | D4: 2000 | E4: =4900 | F4: 320 | H4: 310 | J4: 0.696 | M4: 223 | N4: 24 | O4: - | P4: =0.67*134 | Q4: 58 | AA4: =SUM(B4:C4) | AD4: =SUM(D4:Z4)
A5: 41548 | B5: 282100 | D5: 2000 | E5: =4700 | F5: 150 | H5: 440 | J5: 0.155 | M5: 400 | N5: 200 | O5: - | P5: =0.67*221 | Q5: 0 | AA5: =SUM(B5:C5) | AD5: =SUM(D5:Z5)
A6: 41579 | B6: 273000 | D6: 2000 | E6: =4450 | F6: 11 | H6: 570 | J6: 2.413 | M6: 800 | N6: 400 | O6: - | P6: =0.67*142 | Q6: 8 | AA6: =SUM(B6:C6) | AD6: =SUM(D6:Z6)
A7: 41609 | B7: 282100 | D7: 2000 | E7: =4150 | F7: 90 | H7: 600 | J7: 1.748 | M7: 600 | N7: 400 | O7: =0.05*68 | P7: =0.67*112 | Q7: 46 | AA7: =SUM(B7:C7) | AD7: =SUM(D7:Z7)
A8: 41640 | B8: 282100 | D8: 2000 | E8: =4360 | F8: 70 | H8: 520 | J8: 1.779 | M8: 600 | N8: 200 | O8: - | P8: =0.67*95 | Q8: 0 | AA8: =SUM(B8:C8) | AD8: =SUM(D8:Z8)
A9: 41671 | B9: 254800 | D9: 2000 | E9: =4400 | F9: 200 | H9: 410 | J9: 3.604 | M9: 800 | N9: 200 | O9: - | P9: =0.67*154 | Q9: 0 | AA9: =SUM(B9:C9) | AD9: =SUM(D9:Z9)
A10: 41699 | B10: 282100 | D10: 2000 | E10: =4800 | F10: 150 | H10: 390 | J10: 0.263 | M10: 800 | N10: 400 | O10: - | P10: =0.67*170 | Q10: 0 | AA10: =SUM(B10:C10) | AD10: =SUM(D10:Z10)
A11: 41730 | B11: 273000 | D11: 2000 | E11: =4620 | F11: 110 | H11: 510 | J11: 8.399 | M11: 800 | N11: 400 | O11: - | P11: =0.67*174 | Q11: 0 | AA11: =SUM(B11:C11) | AD11: =SUM(D11:Z11)
A12: 41760 | B12: 282100 | D12: 2000 | E12: =4900 | F12: 350 | H12: 470 | J12: 22.335 | M12: 800 | N12: 400 | O12: - | P12: =0.67*120 | Q12: 30 | AA12: =SUM(B12:C12) | AD12: =SUM(D12:Z12)
A13: 41791 | B13: 273000 | D13: 2000 | E13: =4700 | F13: 450 | H13: 400 | J13: 14.836 | M13: 800 | N13: 400 | O13: - | P13: =0.67*112 | Q13: 0 | AA13: =SUM(B13:C13) | AB13: =SUM(AA2:AA13) | AC13: =AB13/12 | AD13: =SUM(D13:Z13) | AE13: =SUM(AD2:AD13) | AF13: =AE13/12 | AH13: =AB13+AE13
A14: 41821 | B14: 282100 | D14: 2000 | E14: =4520 | F14: 150 | H14: 370 | J14: 27.087 | M14: 1000 | N14: 600 | O14: - | P14: =0.67*114 | Q14: 0 | AA14: =SUM(B14:C14) | AB14: =SUM(AA3:AA14) | AC14: =AB14/12 | AD14: =SUM(D14:Z14) | AE14: =SUM(AD3:AD14) | AF14: =AE14/12
A15: 41852 | B15: 282100 | D15: 2000 | E15: =4610 | F15: 140 | H15: 400 | J15: 16.097 | K15: 626 | M15: 800 | N15: 400 | O15: - | P15: =0.67*86 | Q15: 0 | AA15: =SUM(B15:C15) | AB15: =SUM(AA4:AA15) | AC15: =AB15/12 | AD15: =SUM(D15:Z15) | AE15: =SUM(AD4:AD15) | AF15: =AE15/12
A16: 41883 | B16: 273000 | D16: 2000 | E16: =4500 | F16: 350 | H16: 390 | J16: 4.022 | K16: 827 | M16: 800 | N16: 400 | O16: - | P16: =0.67*139 | Q16: 0 | AA16: =SUM(B16:C16) | AB16: =SUM(AA5:AA16) | AC16: =AB16/12 | AD16: =SUM(D16:Z16) | AE16: =SUM(AD5:AD16) | AF16: =AE16/12
A17: 41913 | B17: 282100 | D17: 2000 | E17: =4100 | F17: 90 | H17: 420 | J17: 0.526 | K17: 728 | L17: 0 | M17: 800 | N17: 400 | O17: - | P17: =0.67*100 | Q17: 25 | AA17: =SUM(B17:C17) | AB17: =SUM(AA6:AA17) | AC17: =AB17/12 | AD17: =SUM(D17:Z17) | AE17: =SUM(AD6:AD17) | AF17: =AE17/12
A18: 41944 | B18: 273000 | D18: 2000 | E18: =4900 | F18: 110 | H18: 390 | J18: 2.475 | K18: 1653 | L18: 0 | M18: 800 | N18: 400 | O18: - | P18: =0.67*100 | Q18: 0 | AA18: =SUM(B18:C18) | AB18: =SUM(AA7:AA18) | AC18: =AB18/12 | AD18: =SUM(D18:Z18) | AE18: =SUM(AD7:AD18) | AF18: =AE18/12
A19: 41974 | B19: 282100 | D19: 2000 | E19: =4750 | F19: 100 | H19: 420 | J19: 2.521 | K19: 875 | L19: 160 | M19: 1000 | N19: 400 | O19: =0.05*117 | P19: =0.67*93 | Q19: 0 | AA19: =SUM(B19:C19) | AB19: =SUM(AA8:AA19) | AC19: =AB19/12 | AD19: =SUM(D19:Z19) | AE19: =SUM(AD8:AD19) | AF19: =AE19/12
A20: 42005 | B20: 282100 | D20: 2000 | E20: =4640 | F20: 370 | H20: 390 | J20: 4.687 | K20: 870 | L20: 70 | M20: 800 | N20: 400 | O20: - | P20: =0.67*146 | Q20: 0 | AA20: =SUM(B20:C20) | AB20: =SUM(AA9:AA20) | AC20: =AB20/12 | AD20: =SUM(D20:Z20) | AE20: =SUM(AD9:AD20) | AF20: =AE20/12
A21: 42036 | B21: 254800 | D21: 2000 | E21: =4540 | F21: 110 | H21: 380 | J21: 14.617 | K21: 856 | L21: 0 | M21: 800 | N21: 400 | O21: - | P21: =0.67*97 | Q21: 21 | AA21: =SUM(B21:C21) | AB21: =SUM(AA10:AA21) | AC21: =AB21/12 | AD21: =SUM(D21:Z21) | AE21: =SUM(AD10:AD21) | AF21: =AE21/12
A22: 42064 | B22: 282100 | D22: 2000 | E22: =4140 | F22: 140 | H22: 410 | J22: 4.378 | K22: 1953 | L22: 0 | M22: 800 | N22: 400 | O22: - | P22: =0.67*127 | Q22: 0 | AA22: =SUM(B22:C22) | AB22: =SUM(AA11:AA22) | AC22: =AB22/12 | AD22: =SUM(D22:Z22) | AE22: =SUM(AD11:AD22) | AF22: =AE22/12
A23: 42095 | B23: 273000 | D23: 2000 | E23: =4040 | F23: 110 | H23: 500 | J23: 0.65 | K23: 1067 | L23: 240 | M23: 1000 | N23: 400 | O23: - | P23: =0.67*88 | Q23: 0 | AA23: =SUM(B23:C23) | AB23: =SUM(AA12:AA23) | AC23: =AB23/12 | AD23: =SUM(D23:Z23) | AE23: =SUM(AD12:AD23) | AF23: =AE23/12
A24: 42125 | B24: 282100 | D24: 2000 | E24: =4090 | F24: 550 | H24: 460 | J24: 3.357 | K24: 1074 | L24: 400 | M24: 800 | N24: 400 | O24: - | P24: =0.67*115 | Q24: 0 | AA24: =SUM(B24:C24) | AB24: =SUM(AA13:AA24) | AC24: =AB24/12 | AD24: =SUM(D24:Z24) | AE24: =SUM(AD13:AD24) | AF24: =AE24/12
A25: 42156 | B25: 273000 | D25: 2000 | E25: =4000 | F25: 150 | H25: 410 | J25: 1.764 | K25: 1038 | L25: 270 | M25: 800 | N25: 400 | O25: - | P25: =0.67*138 | Q25: 0 | AA25: =SUM(B25:C25) | AB25: =SUM(AA14:AA25) | AC25: =AB25/12 | AD25: =SUM(D25:Z25) | AE25: =SUM(AD14:AD25) | AF25: =AE25/12 | AH25: =AB25+AE25 | AI25: =AE25/AB25
A26: 42186 | B26: 231390 | D26: 2000 | E26: =4150 | F26: 110 | H26: 510 | J26: 0.062 | K26: 957 | L26: 0 | M26: 1000 | N26: 600 | O26: - | P26: =0.67*155 | Q26: 0 | AA26: =SUM(B26:C26) | AB26: =SUM(AA15:AA26) | AC26: =AB26/12 | AD26: =SUM(D26:Z26) | AE26: =SUM(AD15:AD26) | AF26: =AE26/12
A27: 42217 | B27: 281540 | D27: 2000 | E27: =4020 | F27: 130 | H27: 480 | J27: 5.006 | K27: 827 | L27: 270 | M27: 800 | N27: 400 | O27: - | P27: =0.67*105 | Q27: 0 | AA27: =SUM(B27:C27) | AB27: =SUM(AA16:AA27) | AC27: =AB27/12 | AD27: =SUM(D27:Z27) | AE27: =SUM(AD16:AD27) | AF27: =AE27/12
A28: 42248 | B28: 272880 | D28: 2000 | E28: =3810 | F28: 100 | H28: 390 | J28: 1.578 | K28: 1956 | L28: 120 | M28: 1000 | N28: 400 | O28: - | P28: =0.67*128 | Q28: 0 | AA28: =SUM(B28:C28) | AB28: =SUM(AA17:AA28) | AC28: =AB28/12 | AD28: =SUM(D28:Z28) | AE28: =SUM(AD17:AD28) | AF28: =AE28/12
A29: 42278 | B29: 281000 | D29: 2000 | E29: =3970 | F29: 90 | H29: 480 | J29: 2.042 | K29: 3297 | L29: 160 | M29: 800 | N29: 200 | O29: - | P29: =0.67*103 | Q29: 0 | AA29: =SUM(B29:C29) | AB29: =SUM(AA18:AA29) | AC29: =AB29/12 | AD29: =SUM(D29:Z29) | AE29: =SUM(AD18:AD29) | AF29: =AE29/12
A30: 42309 | B30: 274290 | D30: 2000 | E30: =3890 | F30: 100 | H30: 450 | J30: 0.062 | K30: 1785 | L30: 50 | M30: 800 | N30: 600 | O30: - | P30: =0.67*143 | Q30: 0 | AA30: =SUM(B30:C30) | AB30: =SUM(AA19:AA30) | AC30: =AB30/12 | AD30: =SUM(D30:Z30) | AE30: =SUM(AD19:AD30) | AF30: =AE30/12
A31: 42339 | B31: 267880 | D31: 2000 | E31: =3810 | F31: 250 | H31: 370 | J31: 3.224 | K31: 1400 | L31: 250 | M31: 1200 | N31: 1200 | O31: =0.05*97 | P31: =0.67*130 | Q31: 0 | AA31: =SUM(B31:C31) | AB31: =SUM(AA20:AA31) | AC31: =AB31/12 | AD31: =SUM(D31:Z31) | AE31: =SUM(AD20:AD31) | AF31: =AE31/12
A32: 42370 | B32: 269800 | D32: =2000+177.808333 | E32: =4230 | F32: 300 | H32: 460 | J32: 0.17 | K32: 1647 | L32: 100 | M32: 1200 | N32: 400 | O32: - | P32: =0.67*77 | Q32: 20 | AA32: =SUM(B32:C32) | AB32: =SUM(AA21:AA32) | AC32: =AB32/12 | AD32: =SUM(D32:Z32) | AE32: =SUM(AD21:AD32) | AF32: =AE32/12
A33: 42401 | B33: 240500 | D33: =2000+177.808333 | E33: =4070 | F33: 250 | H33: 490 | J33: 0.108 | K33: 3015 | L33: 160 | M33: 600 | N33: 200 | O33: - | P33: =0.67*57 | Q33: 0 | AA33: =SUM(B33:C33) | AB33: =SUM(AA22:AA33) | AC33: =AB33/12 | AD33: =SUM(D33:Z33) | AE33: =SUM(AD22:AD33) | AF33: =AE33/12
A34: 42430 | B34: 263290 | D34: =2000+177.808333 | E34: =4120 | F34: 170 | H34: 500 | J34: 1.436 | K34: 1168 | L34: 30 | M34: 1200 | N34: 400 | O34: - | P34: =0.67*130 | Q34: 0 | AA34: =SUM(B34:C34) | AB34: =SUM(AA23:AA34) | AC34: =AB34/12 | AD34: =SUM(D34:Z34) | AE34: =SUM(AD23:AD34) | AF34: =AE34/12
A35: 42461 | B35: 260100 | D35: =2000+177.808333 | E35: =4050 | F35: 140 | H35: 410 | J35: 1.764 | K35: 1397 | L35: 100 | M35: 600 | N35: 400 | O35: - | P35: =0.67*81 | Q35: 0 | AA35: =SUM(B35:C35) | AB35: =SUM(AA24:AA35) | AC35: =AB35/12 | AD35: =SUM(D35:Z35) | AE35: =SUM(AD24:AD35) | AF35: =AE35/12
A36: 42491 | B36: 279280 | D36: =2000+177.808333 | E36: =4080 | F36: 110 | H36: 500 | J36: 0 | K36: 1824 | L36: 150 | M36: 1000 | N36: 400 | O36: - | P36: =0.67*52 | Q36: 9 | AA36: =SUM(B36:C36) | AB36: =SUM(AA25:AA36) | AC36: =AB36/12 | AD36: =SUM(D36:Z36) | AE36: =SUM(AD25:AD36) | AF36: =AE36/12
A37: 42522 | B37: 265300 | D37: =2000+177.808333 | E37: =4120 | F37: 270 | H37: 490 | J37: 0 | K37: 1672 | L37: 340 | M37: 800 | N37: 400 | O37: - | P37: 0 | Q37: 0 | X37: 0 | AA37: =SUM(B37:C37) | AB37: =SUM(AA26:AA37) | AC37: =AB37/12 | AD37: =SUM(D37:Z37) | AE37: =SUM(AD26:AD37) | AF37: =AE37/12 | AH37: =AB37+AE37
A38: 42552 | B38: 230700 | D38: =2480+177.808333 | E38: 2980 | F38: 260 | H38: 510 | J38: 0 | K38: 2495 | L38: 0 | M38: 1000 | N38: 600 | O38: - | P38: 0 | Q38: 0 | AA38: =SUM(B38:C38) | AB38: =SUM(AA27:AA38) | AC38: =AB38/12 | AD38: =SUM(D38:Z38) | AE38: =SUM(AD27:AD38) | AF38: =AE38/12
A39: 42583 | B39: 249380 | D39: =2580+177.808333 | E39: =7160 | F39: 400 | H39: 577.5 | J39: 0 | K39: 1142 | L39: 200 | M39: 2400 | N39: 200 | O39: - | P39: 0 | Q39: 0 | AA39: =SUM(B39:C39) | AB39: =SUM(AA28:AA39) | AC39: =AB39/12 | AD39: =SUM(D39:Z39) | AE39: =SUM(AD28:AD39) | AF39: =AE39/12
A40: 42614 | B40: 261650 | D40: =2830+177.808333 | E40: 7820 | F40: 250 | H40: 1119.8 | J40: 0 | K40: 2204 | L40: 220 | M40: 1800 | N40: 400 | O40: - | P40: =0.67*253 | Q40: 0 | X40: 0 | AA40: =SUM(B40:C40) | AB40: =SUM(AA29:AA40) | AC40: =AB40/12 | AD40: =SUM(D40:Z40) | AE40: =SUM(AD29:AD40) | AF40: =AE40/12
...

Sheet Raw Food Data (KG)
A1: Date | B1: LG1 Canteen and China Garden | C1: LG7 Canteens | D1: McDonald's | E1: LG7 Canteen + McDonald's | F1: LG7 Fusion | G1: Courtyard (Lift 25) | H1: UC Bistro (Tower C) | I1: LSK Campus | J1: Seafront Cafeteria (now collected at UG6 starting July 23) | K1: UG Halls | L1: UG Halls + Seafront Cafeteria | M1: Conference Lodge | N1: Staff Quarters | O1: Junior Staff Quarters | P1: Staff Quarters (All) | Q1: Total (kg) | R1: Yearly Total (kg)
A2: 42644 | B2: 4750 | C2: 11825 | E2: =(C2+D2) | G2: 2000 | H2: 1050 | I2: 250 | J2: 1075 | L2: =J2+K2 | M2: 850 | P2: =N2+O2 | Q2: =B2+SUM(E2:I2)+SUM(L2:M2)+P2
A3: 42675 | B3: 4350 | C3: 9850 | E3: =(C3+D3) | G3: 2375 | H3: 875 | I3: 100 | J3: 775 | L3: =J3+K3 | M3: 925 | P3: =N3+O3 | Q3: =B3+SUM(E3:I3)+SUM(L3:M3)+P3
A4: 42705 | B4: 4600 | C4: 7300 | E4: =(C4+D4) | G4: 1650 | H4: 900 | I4: 975 | J4: 625 | L4: =J4+K4 | M4: 850 | P4: =N4+O4 | Q4: =B4+SUM(E4:I4)+SUM(L4:M4)+P4
A5: 42736 | B5: 4025 | C5: 5700 | E5: =(C5+D5) | G5: 1325 | H5: 825 | I5: 875 | J5: 100 | L5: =J5+K5 | M5: 900 | P5: =N5+O5 | Q5: =B5+SUM(E5:I5)+SUM(L5:M5)+P5
A6: 42767 | B6: 5175 | C6: 7725 | E6: =(C6+D6) | G6: 2125 | H6: 875 | I6: 1925 | J6: 750 | L6: =J6+K6 | M6: 250 | P6: =N6+O6 | Q6: =B6+SUM(E6:I6)+SUM(L6:M6)+P6
A7: 42795 | B7: 5850 | C7: 8200 | E7: =(C7+D7) | G7: 2500 | H7: 825 | I7: 3350 | J7: 825 | L7: =J7+K7 | M7: 100 | O7: 325 | P7: =N7+O7 | Q7: =B7+SUM(E7:I7)+SUM(L7:M7)+P7
A8: 42826 | B8: 4750 | C8: 6475 | E8: =(C8+D8) | G8: 1850 | H8: 1200 | I8: 2625 | J8: 975 | L8: =J8+K8 | M8: 25 | O8: 950 | P8: =N8+O8 | Q8: =B8+SUM(E8:I8)+SUM(L8:M8)+P8
A9: 42856 | B9: 7225 | C9: 6250 | E9: =(C9+D9) | G9: 1575 | H9: 850 | I9: 2675 | J9: 750 | L9: =J9+K9 | M9: 175 | O9: 775 | P9: =N9+O9 | Q9: =B9+SUM(E9:I9)+SUM(L9:M9)+P9
A10: 42887 | B10: 8300 | C10: 6200 | E10: =(C10+D10) | G10: 1375 | H10: 925 | I10: 2250 | J10: 300 | L10: =J10+K10 | M10: 950 | O10: 725 | P10: =N10+O10 | Q10: =B10+SUM(E10:I10)+SUM(L10:M10)+P10
A11: 42917 | B11: 0 | C11: 6425 | E11: =(C11+D11) | G11: 1625 | H11: 0 | I11: 2500 | J11: 200 | L11: =J11+K11 | M11: 1750 | O11: 775 | P11: =N11+O11 | Q11: =B11+SUM(E11:I11)+SUM(L11:M11)+P11
A12: 42948 | B12: 0 | C12: 7525 | E12: =(C12+D12) | G12: 1950 | H12: 0 | I12: 2600 | J12: 25 | L12: =J12+K12 | M12: 2450 | O12: 975 | P12: =N12+O12 | Q12: =B12+SUM(E12:I12)+SUM(L12:M12)+P12
A13: 42979 | B13: 0 | C13: 12775 | E13: =(C13+D13) | G13: 3975 | H13: 0 | I13: 3650 | J13: 950 | L13: =J13+K13 | M13: 2825 | O13: 875 | P13: =N13+O13 | Q13: =B13+SUM(E13:I13)+SUM(L13:M13)+P13
A14: 43009 | B14: 0 | C14: 13875 | E14: =(C14+D14) | G14: 3825 | H14: 0 | I14: 3000 | J14: 675 | L14: =J14+K14 | M14: 3025 | O14: 775 | P14: =N14+O14 | Q14: =B14+SUM(E14:I14)+SUM(L14:M14)+P14
A15: 43040 | B15: 0 | C15: 16550 | E15: =(C15+D15) | G15: 4600 | H15: 675 | I15: 3300 | J15: 875 | L15: =J15+K15 | M15: 3900 | O15: 200 | P15: =N15+O15 | Q15: =B15+SUM(E15:I15)+SUM(L15:M15)+P15
A16: 43070 | B16: 0 | C16: 17675 | E16: =(C16+D16) | G16: 3400 | H16: 675 | I16: 2500 | J16: 675 | L16: =J16+K16 | M16: 4525 | O16: 750 | P16: =N16+O16 | Q16: =B16+SUM(E16:I16)+SUM(L16:M16)+P16
A17: 43101 | B17: 2825 | C17: 15750 | E17: =(C17+D17) | G17: 1975 | H17: 1200 | I17: 2075 | J17: 875 | L17: =J17+K17 | M17: 2450 | O17: 825 | P17: =N17+O17 | Q17: =B17+SUM(E17:I17)+SUM(L17:M17)+P17
A18: 43132 | B18: 6300 | C18: 7950 | E18: =(C18+D18) | G18: 1900 | H18: 625 | I18: 1700 | J18: 525 | L18: =J18+K18 | M18: 2125 | O18: 700 | P18: =N18+O18 | Q18: =B18+SUM(E18:I18)+SUM(L18:M18)+P18
... A23: 43282 | B23: 6675 | C23: 11525 | E23: =(C23+D23) | G23: 0 | H23: 825 | I23: 100 | J23: 800 | L23: =J23+K23 | M23: 4900 | O23: 850 | P23: =N23+O23 | Q23: =B23+SUM(E23:I23)+SUM(L23:M23)+P23
A24: 43313 | B24: 4449 | C24: 8041.3 | E24: =(C24+D24) | F24: 106 | G24: 0 | H24: 402.3 | I24: 596.5 | J24: 1049.5 | K24: 79.5 | L24: =J24+K24 | M24: 698 | N24: 410 | O24: 801.8 | P24: =N24+O24 | Q24: =B24+SUM(E24:I24)+SUM(L24:M24)+P24
A25: 43344 | B25: 4678 | C25: 7819.5 | E25: =(C25+D25) | F25: 92 | G25: 0 | H25: 623 | I25: 1688.05 | J25: 542 | K25: 427 | L25: =J25+K25 | M25: 1428.5 | N25: 464 | O25: 432 | P25: =N25+O25 | Q25: =B25+SUM(E25:I25)+SUM(L25:M25)+P25
A26: 43374 | B26: 7165.5 | C26: 10113 | E26: =(C26+D26) | F26: 147.5 | G26: 61.5 | H26: 993.5 | I26: 3076.5 | J26: 518.5 | K26: 866.5 | L26: =J26+K26 | M26: 1943 | N26: 771 | O26: 401.5 | P26: =N26+O26 | Q26: =B26+SUM(E26:I26)+SUM(L26:M26)+P26
A27: 43405 | B27: 9863.5 | C27: 10139 | E27: =(C27+D27) | F27: 311 | G27: 757 | H27: 737 | I27: 3278 | J27: 148 | K27: 744 | L27: =J27+K27 | M27: 1859 | N27: 701 | O27: 355 | P27: =N27+O27 | Q27: =B27+SUM(E27:I27)+SUM(L27:M27)+P27
A28: 43435 | B28: 6931 | C28: 7915 | E28: =(C28+D28) | F28: 328.5 | G28: 877 | H28: 794.5 | I28: 2441 | J28: 384.5 | K28: 628.5 | L28: =J28+K28 | M28: 2771 | N28: 873 | O28: 590.5 | P28: =N28+O28 | Q28: =B28+SUM(E28:I28)+SUM(L28:M28)+P28
A29: 43466 | B29: 6138 | C29: 6203 | E29: =(C29+D29) | F29: 519 | G29: 642 | H29: 702 | I29: 2362.5 | J29: 538.5 | K29: 464 | L29: =J29+K29 | M29: 2805 | N29: 722.5 | O29: 661 | P29: =N29+O29 | Q29: =B29+SUM(E29:I29)+SUM(L29:M29)+P29
A30: 43497 | B30: 8182.5 | C30: 7480 | E30: =(C30+D30) | F30: 436 | G30: 550 | H30: 788 | I30: 2829 | J30: 573 | K30: 391 | L30: =J30+K30 | M30: 2159.5 | N30: 572.5 | O30: 623 | P30: =N30+O30 | Q30: =B30+SUM(E30:I30)+SUM(L30:M30)+P30
A31: 43525 | B31: 10408 | C31: 8673.5 | E31: =(C31+D31) | F31: 810 | G31: 797.5 | H31: 818.5 | I31: 3365.5 | J31: 1174 | K31: 720.5 | L31: =J31+K31 | M31: 2328.5 | N31: 1050 | O31: 784.5 | P31: =N31+O31 | Q31: =B31+SUM(E31:I31)+SUM(L31:M31)+P31
A32: 43556 | B32: 9209.5 | C32: 11363 | E32: =(C32+D32) | F32: 329 | G32: 864 | H32: 815.5 | I32: 3463 | J32: 1044.5 | K32: 470.5 | L32: =J32+K32 | M32: 2543 | N32: 1346.5 | O32: 1086 | P32: =N32+O32 | Q32: =B32+SUM(E32:I32)+SUM(L32:M32)+P32
A33: 43586 | B33: 11016.5 | C33: 9187 | E33: =(C33+D33) | F33: 0 | G33: 552.5 | H33: 919 | I33: 3833 | J33: 1153.5 | K33: 177 | L33: =J33+K33 | M33: 2498 | N33: 1177 | O33: 1150.5 | P33: =N33+O33 | Q33: =B33+SUM(E33:I33)+SUM(L33:M33)+P33
A34: 43617 | B34: 10993.5 | C34: 2631 | E34: =(C34+D34) | F34: 155.5 | G34: 1099 | H34: 0 | I34: 3305.5 | J34: 650 | K34: 201.5 | L34: =J34+K34 | M34: 2776.5 | N34: 522.5 | O34: 827.5 | P34: =N34+O34 | Q34: =B34+SUM(E34:I34)+SUM(L34:M34)+P34
A35: 43647 | B35: 10186 | C35: 1470.5 | E35: =(C35+D35) | F35: 0 | G35: 1016 | H35: 44.5 | I35: 3162 | J35: 854 | K35: 26 | L35: =J35+K35 | M35: 2117 | N35: 0 | O35: 690 | P35: =N35+O35 | Q35: =B35+SUM(E35:I35)+SUM(L35:M35)+P35
... A61: 44440 | B61: 10427 | C61: 12690 | E61: =(C61+D61) | F61: 4807 | G61: 996 | H61: 912 | I61: 640 | J61: 1146 | K61: 121 | L61: =J61+K61 | M61: 1101 | N61: 1239 | O61: 1297 | P61: =N61+O61 | Q61: =B61+SUM(E61:I61)+SUM(L61:M61)+P61
A62: 44470 | B62: 13958 | C62: 13721 | D62: 708 | E62: =(C62+D62) | F62: 5212 | G62: 1328 | H62: 1773 | I62: 1648 | J62: 1407 | K62: 976 | L62: =J62+K62 | M62: 1707 | N62: 1651 | O62: 1311 | P62: =N62+O62 | Q62: =B62+SUM(E62:I62)+SUM(L62:M62)+P62
A63: 44501 | B63: 10607 | C63: 14354 | D63: 1740 | E63: =(C63+D63) | F63: 4468 | G63: 1566 | H63: 1457 | I63: 1563 | J63: 1156 | K63: 842 | L63: =J63+K63 | M63: 1660 | N63: 1535 | O63: 1717 | P63: =N63+O63 | Q63: =B63+SUM(E63:I63)+SUM(L63:M63)+P63
A64: 44531 | B64: 12824 | C64: 10146 | D64: 1844 | E64: =(C64+D64) | F64: 5198 | G64: 1227 | H64: 1641 | I64: 1634 | J64: 1187 | K64: 660 | L64: =J64+K64 | M64: 1949 | N64: 1298 | O64: 1730 | P64: =N64+O64 | Q64: =B64+SUM(E64:I64)+SUM(L64:M64)+P64
A65: 44562 | B65: 8566 | C65: 8810 | D65: 1919 | E65: =(C65+D65) | F65: 4794 | G65: 929 | H65: 1354 | I65: 874 | J65: 1034 | K65: 686 | L65: =J65+K65 | M65: 1449 | N65: 1243 | O65: 1413 | P65: =N65+O65 | Q65: =B65+SUM(E65:I65)+SUM(L65:M65)+P65
A66: 44593 | B66: 6686 | C66: 8256 | D66: 1206 | E66: =(C66+D66) | F66: 3189 | G66: 778 | H66: 751 | I66: 430 | J66: 952 | K66: 541 | L66: =J66+K66 | M66: 614 | N66: 715 | O66: 829 | P66: =N66+O66 | Q66: =B66+SUM(E66:I66)+SUM(L66:M66)+P66
A67: 44621 | B67: 4351 | C67: 5420 | D67: 1022 | E67: =(C67+D67) | F67: 5829 | G67: 774 | H67: 809 | I67: 579 | J67: 848 | K67: 492 | L67: =J67+K67 | M67: 436 | N67: 719 | O67: 812 | P67: =N67+O67 | Q67: =B67+SUM(E67:I67)+SUM(L67:M67)+P67
A68: 44652 | B68: 6373.3 | C68: 5682 | D68: 1561 | E68: =(C68+D68) | F68: 4437.3 | G68: 965 | H68: 890 | I68: 224 | J68: 1273 | K68: 684 | L68: =J68+K68 | M68: 220 | N68: 1151 | O68: 1126 | P68: =N68+O68 | Q68: =B68+SUM(E68:I68)+SUM(L68:M68)+P68
A69: 44682 | B69: 6973 | C69: 7170 | D69: 1769 | E69: =(C69+D69) | F69: 4356 | G69: 1248 | H69: 1170 | I69: 476 | J69: 1026 | K69: 645 | L69: =J69+K69 | M69: 381 | N69: 1186 | O69: 1062 | P69: =N69+O69 | Q69: =B69+SUM(E69:I69)+SUM(L69:M69)+P69
...
