Workbook

Sheet Table of Contents
A1: Annual Report | C1: Monthly Data | E1: Yearly Data
A2: Energy | C2: Renewable | E2: Renewable
A3: Water | C3: Electricity (Overview) | E3: Electricity (Overview)
A4: Waste | C4: Electricity (Reformatted) | E4: Electricity (Reformatted)
C5: Towngas (TGU) | E5: Towngas (TGU)
A6: Half-Year Report | C6: Potable Water (Overview) | E6: Fuel
A7: Water | C7: Potable Water (Meters) | E7: Scope 1 GHG (mtCO2)
A8: Waste | C8: Seawater (m3) | E8: Scope 2 GHG (mtCO2)
C9: Category Water Data | E9: Scope 3 GHG (mtCO2)
A10: Raw Data | C10: Monthly Waste by Location (kg) | E10: GHG (mtCO2)
A11: Waste | C11: Category Waste Data | E11: Potable Water (Overview)
A12: Food Waste | C12: Recycling (kg) | E12: Potable Water (Meters)
C13: Paper Distribution (kg) | E13: Seawater (m3)
A14: Smart Waste Bin | E14: Recycling (kg)
A15: Staff Quarters | E15: Food Waste (kg)
A16: Canteen | E16: Paper Distribution (kg)
E17: Paper Distribution (match monthly) (kg)
A18: Other
A19: Emission Factor (Keep Updated)
A20: Emission Factor (Original)
A22: Daily Data
A23: Food Waste

Sheet Annual Report (Energy)
A1: Date | B1: Liquid Fuels/Diesel | C1: Towngas | D1: Electricity | E1: Energy (kWh) | F1: Energy per Capita | G1: Energy per GFA | J1: Date | K1: Electricity Consumption | L1: Renewable Generation (kWh) | M1: Emission Factor (kg/ KWh) | N1: Renewable Generation (CO2 tonnes) | R1: Date | S1: Main Acad. Building & Others | T1: Cheng Yu Tung Building | U1: Main Chiller Plant | V1: LSK Chiller Plant | W1: LSK Building | X1: IAS Building | Y1: Conference Lodge | Z1: Staff Quarter Common Area | AA1: Student Housing | AB1: Staff Quarters & Commercial Outlets | AD1: Year | AE1: Total S1&2 | AF1: Total S3 | AG1: Emissions per Capita | AH1: Emissions per GFA | AJ1: Academic Year | AK1: Actual (including renewables) | AL1: Actual | AM1: Projected | AN1: 2028 | AO1: 2035 | AP1: 2045 | AQ1: 2050
A2: 2014/15 | B2: 280000 | C2: ='Yearly Towngas (TGU)'!I6 | D2: 93067207 | E2: =SUM(B2:D2) | F2: =E2/'Yearly GHG (mCO2)'!G6 | G2: =E2/'Yearly GHG (mCO2)'!H6 | J2: 2014/15 | K2: 93067207 | L2: 0 | N2: 0 | R2: 2023/24 kWh | S2: 51334417 | T2: 4746630 | U2: 17653437 | V2: 1497696 | W2: 2713600 | X2: 588506 | Y2: 1478893 | Z2: 909181 | AA2: 6604565 | AB2: 9182416 | AD2: 2014/15 | AE2: ='Yearly GHG (mCO2)'!E6 | AF2: ='Yearly GHG (mCO2)'!D6 | AG2: ='Yearly GHG (mCO2)'!I6 | AH2: ='Yearly GHG (mCO2)'!J6 | AJ2: 2014 | AK2: 61233 | AL2: 61233 | AN2: =AK2 | AS2: Reduction
A3: 2015/16 | B3: 370000 | C3: ='Yearly Towngas (TGU)'!I7 | D3: 95800070 | E3: =SUM(B3:D3) | F3: =E3/'Yearly GHG (mCO2)'!G7 | G3: =E3/'Yearly GHG (mCO2)'!H7 | J3: 2015/16 | K3: 95800070 | L3: 0 | N3: 0 | R3: 2023/24 % | S3: 0.5308 | T3: 0.0491 | U3: 0.1825 | V3: 0.0155 | W3: 0.0281 | X3: 0.0061 | Y3: 0.0153 | Z3: 0.0094 | AA3: 0.0683 | AB3: 0.0949 | AD3: 2015/16 | AE3: ='Yearly GHG (mCO2)'!E7 | AF3: ='Yearly GHG (mCO2)'!D7 | AG3: ='Yearly GHG (mCO2)'!I7 | AH3: ='Yearly GHG (mCO2)'!J7 | AJ3: 2015 | AK3: 53624 | AL3: 53624 | AN3: =AN2+AT8 | AS3: 0 | AT3: =AK2
A4: 2016/17 | B4: 201980.5 | C4: ='Yearly Towngas (TGU)'!I8 | D4: 94486358 | E4: =SUM(B4:D4) | F4: =E4/'Yearly GHG (mCO2)'!G8 | G4: =E4/'Yearly GHG (mCO2)'!H8 | J4: 2016/17 | K4: 94486358 | L4: 0 | N4: 0 | AD4: 2016/17 | AE4: ='Yearly GHG (mCO2)'!E8 | AF4: ='Yearly GHG (mCO2)'!D8 | AG4: ='Yearly GHG (mCO2)'!I8 | AH4: ='Yearly GHG (mCO2)'!J8 | AJ4: 2016 | AK4: 52656 | AL4: 52656 | AN4: =AN3+AT8 | AS4: 0.4 | AT4: =0.6*AK2
A5: 2017/18 | B5: 221452.21 | C5: ='Yearly Towngas (TGU)'!I9 | D5: 92966450 | E5: =SUM(B5:D5) | F5: =E5/'Yearly GHG (mCO2)'!G9 | G5: =E5/'Yearly GHG (mCO2)'!H9 | J5: 2017/18 | K5: 92966450 | L5: 0 | N5: 0 | AD5: 2017/18 | AE5: ='Yearly GHG (mCO2)'!E9 | AF5: ='Yearly GHG (mCO2)'!D9 | AG5: ='Yearly GHG (mCO2)'!I9 | AH5: ='Yearly GHG (mCO2)'!J9 | AJ5: 2017 | AK5: 48813 | AL5: 48813 | AN5: =AN4+AT8 | AS5: 0.5 | AT5: =0.5*AK2
A6: 2018/19 | B6: 205172.45 | C6: ='Yearly Towngas (TGU)'!I10 | D6: 90186094 | E6: =SUM(B6:D6) | F6: =E6/'Yearly GHG (mCO2)'!G10 | G6: =E6/'Yearly GHG (mCO2)'!H10 | J6: 2018/19 | K6: 90186094 | L6: 0 | N6: 0 | AD6: 2018/19 | AE6: ='Yearly GHG (mCO2)'!E10 | AF6: ='Yearly GHG (mCO2)'!D10 | AG6: ='Yearly GHG (mCO2)'!I10 | AH6: ='Yearly GHG (mCO2)'!J10 | AJ6: 2018 | AK6: 47482 | AL6: 47482 | AN6: =AN5+AT8
A7: 2019/20 | B7: 181092.19 | C7: ='Yearly Towngas (TGU)'!I11 | D7: 87353244 | E7: =SUM(B7:D7) | F7: =E7/'Yearly GHG (mCO2)'!G11 | G7: =E7/'Yearly GHG (mCO2)'!H11 | J7: 2019/20 | K7: 87353244 | L7: 2920 | M7: 0.51 | N7: =(L7*M7)/1000 | P7: =L7/K7 | AD7: 2019/20 | AE7: ='Yearly GHG (mCO2)'!E11 | AF7: ='Yearly GHG (mCO2)'!D11 | AG7: ='Yearly GHG (mCO2)'!I11 | AH7: ='Yearly GHG (mCO2)'!J11 | AJ7: 2019 | AK7: =44850-N7 | AL7: =44850 | AN7: =AN6+AT8 | AS7: Slopes
A8: 2020/21 | B8: 224833.4 | C8: ='Yearly Towngas (TGU)'!I12 | D8: 88318175 | E8: =SUM(B8:D8) | F8: =E8/'Yearly GHG (mCO2)'!G12 | G8: =E8/'Yearly GHG (mCO2)'!H12 | J8: 2020/21 | K8: 88318175 | L8: 391443 | M8: 0.37 | N8: =(L8*M8)/1000 | P8: =L8/K8 | AD8: 2020/21 | AE8: ='Yearly GHG (mCO2)'!E12 | AF8: ='Yearly GHG (mCO2)'!D12 | AG8: ='Yearly GHG (mCO2)'!I12 | AH8: ='Yearly GHG (mCO2)'!J12 | AJ8: 2020 | AK8: =33904-N8 | AL8: =33904 | AN8: =AN7+AT8 | AS8: 2028 Slope | AT8: =(AN16-AN2)/14
A9: 2021/22 | B9: 234812 | C9: ='Yearly Towngas (TGU)'!I13 | D9: 89692408 | E9: =SUM(B9:D9) | F9: =E9/'Yearly GHG (mCO2)'!G13 | G9: =E9/'Yearly GHG (mCO2)'!H13 | J9: 2021/22 | K9: 89692408 | L9: 1912724 | M9: 0.39 | N9: =(L9*M9)/1000 | P9: =L9/K9 | AD9: 2021/22 | AE9: ='Yearly GHG (mCO2)'!E13 | AF9: ='Yearly GHG (mCO2)'!D13 | AG9: ='Yearly GHG (mCO2)'!I13 | AH9: ='Yearly GHG (mCO2)'!J13 | AJ9: 2021 | AK9: =36252-N9 | AL9: =36252 | AN9: =AN8+AT8 | AS9: 2035 Slope | AT9: =(AO23-AO16)/(22-15)
A10: 2022/23 | B10: 292973.43 | C10: ='Yearly Towngas (TGU)'!I14 | D10: 93932338 | E10: =SUM(B10:D10) | F10: =E10/'Yearly GHG (mCO2)'!G14 | G10: =E10/'Yearly GHG (mCO2)'!H14 | J10: 2022/23 | K10: 93932338 | L10: 2319773 | M10: 0.39 | N10: =(L10*M10)/1000 | O10: =(L10-L9)/L9 | P10: =L10/K10 | AD10: 2022/23 | AE10: ='Yearly GHG (mCO2)'!E14 | AF10: ='Yearly GHG (mCO2)'!D14 | AG10: ='Yearly GHG (mCO2)'!I14 | AH10: ='Yearly GHG (mCO2)'!J14 | AJ10: 2022 | AK10: =38014-N10 | AL10: =38014 | AN10: =AN9+AT8 | AS10: 2045 Slope | AT10: =(AP33-AP23)/(32-22)
A11: 2023/24 | B11: 243473.34 | C11: ='Yearly Towngas (TGU)'!I15 | D11: 96709341 | E11: =SUM(B11:D11) | F11: =E11/'Yearly GHG (mCO2)'!G15 | G11: =E11/'Yearly GHG (mCO2)'!H15 | J11: 2023/24 | K11: 96709341 | L11: 2334777 | M11: 0.39 | N11: =(L11*M11)/1000 | AD11: 2023/24 | AE11: ='Yearly GHG (mCO2)'!E15 | AF11: ='Yearly GHG (mCO2)'!D15 | AG11: ='Yearly GHG (mCO2)'!I15 | AH11: ='Yearly GHG (mCO2)'!J15 | AJ11: 2023 | AK11: =AL11-N11 | AL11: 40466 | AM11: 38236.386 | AN11: =AN10+AT8 | AS11: 2050 Slope | AT11: =(AQ38-AQ23)/(37-22)
A12: 2024/25 | B12: ='Yearly Fuel'!K16 | C12: ='Yearly Towngas (TGU)'!I16 | D12: ='Yearly Electricity Reformatted'!Q13 | E12: =SUM(B12:D12) | F12: =E12/'Yearly GHG (mCO2)'!G16 | G12: =E12/'Yearly GHG (mCO2)'!H16 | J12: 2024/25 | K12: ='Yearly Electricity Reformatted'!Q13 | L12: ='Yearly Renewable'!F11 | M12: 0.39 | N12: =(L12*M12)/1000 | AD12: 2024/25 | AE12: ='Yearly GHG (mCO2)'!E16 | AF12: ='Yearly GHG (mCO2)'!D16 | AG12: ='Yearly GHG (mCO2)'!I16 | AH12: ='Yearly GHG (mCO2)'!J16 | AJ12: 2024 | AL12: 41443 | AM12: 37131.515 | AN12: =AN11+AT8
A13: 2025/26 | B13: ='Yearly Fuel'!K17 | C13: ='Yearly Towngas (TGU)'!I17 | D13: ='Yearly Electricity Reformatted'!Q14 | E13: =SUM(B13:D13) | F13: =E13/'Yearly GHG (mCO2)'!G17 | G13: =E13/'Yearly GHG (mCO2)'!H17 | AE13: =AE12/AE2-1 | AF13: =AF12/AF2-1 | AG13: =AG12/AG2-1 | AH13: =AH12/AH2-1 | AJ13: 2025 | AM13: 37121.752 | AN13: =AN12+AT8 | AS13: 2022 | AT13: =(AK2-AK10)/AK2
AE14: =AE12/AE11-1 | AF14: =AF12/AF11-1 | AG14: =AG12/AG11-1 | AH14: =AH12/AH11-1 | AJ14: 2026 | AM14: 43405.672 | AN14: =AN13+AT8 | AS14: 2021 | AT14: =(AK9-AK2)/AK2
AJ15: 2027 | AM15: 41891.025 | AN15: =AN14+AT8 | AS15: 2023 | AT15: =(AL11-AK2)/AK2
AJ16: 2028 | AM16: 47439.701 | AN16: =AT4 | AO16: =AN16 | AS16: 2024 | AT16: =(AL12-AK2)/AK2
AJ17: 2029 | AM17: 45117.055 | AO17: =AO16+AT9
AJ18: 2030 | AM18: 49445.731 | AO18: =AO17+AT9 | AT18: =(AL10-AL2)/AL2*100
AJ19: 2031 | AM19: 47614.408 | AO19: =AO18+AT9 | AT19: =(AL11-AL2)/AL2*100
AJ20: 2032 | AM20: 44815.761 | AO20: =AO19+AT9
AJ21: 2033 | AM21: 42948.438 | AO21: =AO20+AT9
AJ22: 2034 | AM22: 41741.114 | AO22: =AO21+AT9
AJ23: 2035 | AM23: 39843.791 | AO23: =AT5 | AP23: =AO23 | AQ23: =AP23
AJ24: 2036 | AM24: 39066.468 | AP24: =AP23+AT10 | AQ24: =AQ23+AT11
AJ25: 2037 | AM25: 37113.144 | AP25: =AP24+AT10 | AQ25: =AQ24+AT11
AJ26: 2038 | AM26: 35699.821 | AP26: =AP25+AT10 | AQ26: =AQ25+AT11
AJ27: 2039 | AM27: 33716.497 | AP27: =AP26+AT10 | AQ27: =AQ26+AT11
AJ28: 2040 | AM28: 32613.174 | AP28: =AP27+AT10 | AQ28: =AQ27+AT11
AJ29: 2041 | AM29: 30574.851 | AP29: =AP28+AT10 | AQ29: =AQ28+AT11
AJ30: 2042 | AM30: 31114.851 | AP30: =AP29+AT10 | AQ30: =AQ29+AT11
AJ31: 2043 | AM31: 29040.527 | AP31: =AP30+AT10 | AQ31: =AQ30+AT11
AJ32: 2044 | AM32: 27434.204 | AP32: =AP31+AT10 | AQ32: =AQ31+AT11
AJ33: 2045 | AM33: 25323.881 | AP33: 0 | AQ33: =AQ32+AT11
AJ34: 2046 | AM34: 25983.881 | AQ34: =AQ33+AT11
AJ35: 2047 | AM35: 23818.557 | AQ35: =AQ34+AT11
AJ36: 2048 | AM36: 24214.557 | AQ36: =AQ35+AT11
AJ37: 2049 | AM37: 22013.234 | AQ37: =AQ36+AT11
AJ38: 2050 | AQ38: 0

Sheet Monthly Renewable
A1: Period | B1: LPT Bill | C1: SSQ Bill | D1: JSQ Bill | E1: VC & Guest Lodge | F1: Total | G1: 12-Month Rolling Sum
A2: 43891 | B2: 552 | F2: 552 | G2: =SUM(F2:F13)
A3: 43922 | B3: 832 | F3: 832 | G3: =SUM(F3:F14)
A4: 43952 | B4: 756 | F4: 756 | G4: =SUM(F4:F15)
A5: 43983 | B5: 780 | F5: 780 | G5: =SUM(F5:F16)
A6: 44013 | B6: 954 | F6: 954 | G6: =SUM(F6:F17)
A7: 44044 | B7: 1462 | F7: 1462 | G7: =SUM(F7:F18)
A8: 44075 | B8: 1419 | F8: 1419 | G8: =SUM(F8:F19)
A9: 44105 | B9: 1699 | F9: 1699 | G9: =SUM(F9:F20)
A10: 44136 | B10: 1498 | F10: 1498 | G10: =SUM(F10:F21)
A11: 44166 | B11: 7001 | F11: 7001 | G11: =SUM(F11:F22)
A12: 44197 | B12: 8076 | F12: 8076 | G12: =SUM(F12:F23)
A13: 44228 | B13: 23018 | F13: 23018 | G13: =SUM(F13:F24)
... A17: 44348 | B17: 110958 | F17: 110958 | G17: =SUM(F17:F28)
A18: 44378 | B18: 160133 | C18: 0 | F18: 160133 | G18: =SUM(F18:F29)
A19: 44409 | B19: 147598 | C19: 8279 | D19: 3427 | F19: 159304 | G19: =SUM(F19:F30)
A20: 44440 | B20: 180730 | C20: 23799 | D20: 11349 | F20: 215878 | G20: =SUM(F20:F31)
A21: 44470 | B21: 122185 | C21: 9107 | D21: 7922 | F21: 139214 | G21: =SUM(F21:F32)
A22: 44501 | B22: 144397 | C22: 13911 | D22: 11770 | F22: 170078 | G22: =SUM(F22:F33)
A23: 44531 | B23: 117181 | C23: 6562 | D23: 5230 | F23: 128973 | G23: =SUM(F23:F34)
A24: 44562 | B24: 94201 | C24: 4908 | D24: 4004 | F24: 103113 | G24: =SUM(F24:F35)
A25: 44594 | B25: 107196 | C25: 4891 | D25: 4180 | F25: 116267 | G25: =SUM(F25:F36)
A26: 44626 | B26: 145751 | C26: 7025 | D26: 6137 | F26: 158916 | G26: =SUM(F26:F37)
A27: 44652 | B27: 201510 | C27: 8833 | D27: 7666 | F27: 218009 | G27: =SUM(F27:F38)
A28: 44682 | B28: 144961 | C28: 6611 | D28: 5788 | F28: 157360 | G28: =SUM(F28:F39)
A29: 44713 | B29: 171373 | C29: 7469 | D29: 6637 | F29: 185479 | G29: =SUM(F29:F40)
A30: 44743 | B30: 230422 | C30: 9293 | D30: 8264 | F30: 247979 | G30: =SUM(F30:F41)
... A37: 44958 | B37: 166577 | C37: 6916 | D37: 8582 | F37: 182075 | G37: =SUM(F37:F48)
A38: 44986 | B38: 166701 | C38: 6502 | D38: 8075 | E38: 2742 | F38: 184020 | G38: =SUM(F38:F49)
A39: 45017 | B39: 117085 | C39: 4635 | D39: 5779 | E39: 781 | F39: 128280 | G39: =SUM(F39:F50)
A40: 45047 | B40: 177122 | C40: 6807 | D40: 8365 | E40: 1158 | F40: 193452 | G40: =SUM(F40:F51)
A41: 45078 | B41: 224897 | C41: 7772 | D41: 9772 | E41: 1352 | F41: 243793 | G41: =SUM(F41:F52)
A42: 45108 | B42: 255467 | C42: 9081 | D42: 12814 | E42: 1557 | F42: 278919 | G42: =SUM(F42:F53)
A43: 45139 | B43: 260667 | C43: 8733 | D43: 14748 | E43: 1494 | F43: 285642 | G43: =SUM(F43:F54)
A44: 45170 | B44: 193050 | C44: 6417 | D44: 10761 | E44: 1102 | F44: 211330 | G44: =SUM(F44:F55)
A45: 45200 | B45: 187049 | C45: 6214 | D45: 10597 | E45: 997 | F45: 204857 | G45: =SUM(F45:F56)
A46: 45231 | B46: 199647 | C46: 6841 | D46: 11363 | E46: 1007 | F46: 218858 | G46: =SUM(F46:F57)
A47: 45262 | B47: 129813 | C47: 4941 | D47: 7827 | E47: 697 | F47: 143278 | G47: =SUM(F47:F58)
A48: 45292 | B48: 174410 | C48: 6432 | D48: 9963 | E48: 893 | F48: 191698 | G48: =SUM(F48:F59)
A49: 45323 | B49: 121311 | C49: 4299 | D49: 6964 | E49: 663 | F49: 133237 | G49: =SUM(F49:F60)
...

Sheet Yearly Renewable
A1: Date | B1: LPT Bill | C1: SSQ Bill | D1: JSQ Bill | E1: VC & Guest Lodge | F1: Renewable energy generation | G1: % of total electricity
A2: 2015/16 | F2: 0
A3: 2016/17 | F3: 0
A4: 2017/18 | F4: 0
A5: 2018/19 | F5: 0
A6: 2019/20 | B6: =SUM('Monthly Renewable'!B2:B5) | C6: =SUM('Monthly Renewable'!C2:C5) | D6: =SUM('Monthly Renewable'!D2:D5) | E6: =SUM('Monthly Renewable'!E2:E5) | F6: =SUM('Monthly Renewable'!B2:B5) | G6: =F6/'Yearly Electricity (Overview)'!C7
A7: 2020/21 | B7: =SUM('Monthly Renewable'!B6:B17) | C7: =SUM('Monthly Renewable'!C6:C17) | D7: =SUM('Monthly Renewable'!D6:D17) | E7: =SUM('Monthly Renewable'!E6:E17) | F7: =SUM('Monthly Renewable'!B6:B17) | G7: =F7/'Yearly Electricity (Overview)'!C8
A8: 2021/22 | B8: =SUM('Monthly Renewable'!B18:B29) | C8: =SUM('Monthly Renewable'!C18:C29) | D8: =SUM('Monthly Renewable'!D18:D29) | E8: =SUM('Monthly Renewable'!E18:E29) | F8: =SUM('Monthly Renewable'!F18:F29) | G8: =F8/'Yearly Electricity (Overview)'!C9
A9: 2022/23 | B9: =SUM('Monthly Renewable'!B30:B41) | C9: =SUM('Monthly Renewable'!C30:C41) | D9: =SUM('Monthly Renewable'!D30:D41) | E9: =SUM('Monthly Renewable'!E30:E41) | F9: =SUM('Monthly Renewable'!F30:F41) | G9: =F9/'Yearly Electricity (Overview)'!C10
A10: 2023/24 | B10: =SUM('Monthly Renewable'!B42:B53) | C10: =SUM('Monthly Renewable'!C42:C53) | D10: =SUM('Monthly Renewable'!D42:D53) | E10: =SUM('Monthly Renewable'!E42:E53) | F10: =SUM('Monthly Renewable'!F42:F53) | G10: =F10/'Yearly Electricity (Overview)'!C11
A11: 2024/25 | B11: =SUM('Monthly Renewable'!B54:B65) | C11: =SUM('Monthly Renewable'!C54:C65) | D11: =SUM('Monthly Renewable'!D54:D65) | E11: =SUM('Monthly Renewable'!E54:E65) | F11: =SUM('Monthly Renewable'!F54:F65) | G11: =F11/'Yearly Electricity (Overview)'!C12
A12: 2025/26 | B12: =SUM('Monthly Renewable'!B66:B77) | C12: =SUM('Monthly Renewable'!C66:C77) | D12: =SUM('Monthly Renewable'!D66:D77) | E12: =SUM('Monthly Renewable'!E66:E77) | F12: =SUM('Monthly Renewable'!F66:F77) | G12: =F12/'Yearly Electricity (Overview)'!C13

Sheet Monthly Electricity (Overview)
A1: Period | B1: CLP Total | C1: Main Academic Buildings & Other Public Facilities | D1: EC | E1: CYT | F1: Shaw Auditorium | G1: APCF (R/F Zone L) | H1: New Data Centre (2/F Zone L) | I1: Main Chiller Plant | J1: LSKBB | K1: IAS | L1: Conference Lodge | M1: LSK Hostel | N1: LSK Chiller Plant | O1: WWT | P1: Water Sport Centre | Q1: SISC | R1: HPC6 | S1: RB2 | T1: IB | U1: SRD (UG10-13) | V1: TA-B | W1: GGT | X1: Student Housing UG1-UG9, PG1-PG2 | Y1: Staff Quarters & Commercial Outlets | Z1: Commercial Outlets | AA1: Staff Quarters | AB1: Combined Chiller Plants | AD1: TKO JC Hall | AE1: EC 3/F Data Centre (Elect) | AF1: EC 3/F Data Centre (Chiller kWhe) | AG1: SRD (Chiller kWhe) | AH1: IB (Chiller kWhe) | AI1: BMW EV Charger kWh (LG7 & WWT) | AJ1: Corner Stone EV Charger kWh | AK1: On-Campus Buildings 12-Month Rolling Sum | AL1: Total + TKOJCH | AM1: On-Campus Buildings Monthly Total | AN1: Monthly Total + TKOJCH
A2: 41640 | B2: 5938547 | C2: 3924710 | D2: 190811 | E2: 41274 | F2: 0 | G2: 0 | H2: 0 | I2: 500427 | J2: 205345 | K2: 44678 | L2: 0 | M2: 0 | N2: 48446 | O2: 59654 | P2: 0 | Q2: 0 | W2: 0 | X2: 361571 | Y2: 561631 | Z2: 229909 | AA2: 331722 | AB2: 548873 | AD2: 0 | AE2: 0 | AF2: 0 | AG2: 0 | AH2: 0 | AM2: =SUM(C2:Y2) | AN2: =AM2+AD2
A3: 41671 | B3: 5888877 | C3: 3565612 | D3: 252064 | E3: 28315 | F3: 0 | G3: 0 | H3: 0 | I3: 502155 | J3: 290449 | K3: 56447 | L3: 0 | M3: 0 | N3: 47613 | O3: 47313 | P3: 0 | Q3: 0 | W3: 0 | X3: 504993 | Y3: 593916 | Z3: 220164 | AA3: 373752 | AB3: 549768 | AD3: 0 | AE3: 0 | AF3: 0 | AG3: 0 | AH3: 0 | AM3: =SUM(C3:Y3) | AN3: =AM3+AD3
A4: 41699 | B4: 6018786 | C4: 3680694 | D4: 185065 | E4: 40257 | F4: 0 | G4: 0 | H4: 0 | I4: 754593 | J4: 182485 | K4: 34491 | L4: 0 | M4: 0 | N4: 46854 | O4: 43566 | P4: 0 | Q4: 0 | W4: 0 | X4: 511265 | Y4: 539516 | Z4: 247766 | AA4: 291750 | AB4: 801447 | AD4: 0 | AE4: 0 | AF4: 0 | AG4: 0 | AH4: 0 | AM4: =SUM(C4:Y4) | AN4: =AM4+AD4
A5: 41730 | B5: 7488350 | C5: 4459315 | D5: 203049 | E5: 56946 | F5: 0 | G5: 0 | H5: 0 | I5: 1100944 | J5: 213938 | K5: 46284 | L5: 0 | M5: 0 | N5: 141417 | O5: 73814 | P5: 0 | Q5: 0 | W5: 0 | X5: 612777 | Y5: 579866 | Z5: 295835 | AA5: 284031 | AB5: 1242361 | AD5: 0 | AE5: 0 | AF5: 0 | AG5: 0 | AH5: 0 | AM5: =SUM(C5:Y5) | AN5: =AM5+AD5
A6: 41760 | B6: 7986119 | C6: 3816523 | D6: 345876 | E6: 89452 | F6: 0 | G6: 0 | H6: 0 | I6: 1749797 | J6: 224043 | K6: 103456 | L6: 0 | M6: 0 | N6: 170062 | O6: 82044 | P6: 0 | Q6: 0 | W6: 0 | X6: 692230 | Y6: 712636 | Z6: 281303 | AA6: 431333 | AB6: 1919859 | AD6: 0 | AE6: 0 | AF6: 0 | AG6: 0 | AH6: 0 | AM6: =SUM(C6:Y6) | AN6: =AM6+AD6
A7: 41791 | B7: 8876152 | C7: 4173507 | D7: 250379 | E7: 92936 | F7: 0 | G7: 0 | H7: 0 | I7: 2204099 | J7: 250703 | K7: 71494 | L7: 0 | M7: 0 | N7: 273139 | O7: 97780 | P7: 0 | Q7: 0 | W7: 0 | X7: 574711 | Y7: 887404 | Z7: 266840 | AA7: 620564 | AB7: 2477238 | AD7: 0 | AE7: 0 | AF7: 0 | AG7: 0 | AH7: 0 | AM7: =SUM(C7:Y7) | AN7: =AM7+AD7
A8: 41821 | B8: 9340526 | C8: 4361073 | D8: 221804 | E8: 97729 | F8: 0 | G8: 0 | H8: 0 | I8: 2443732 | J8: 225313 | K8: 48903 | L8: 0 | M8: 0 | N8: 246402 | O8: 109439 | P8: 0 | Q8: 0 | W8: 0 | X8: 687729 | Y8: 898402 | Z8: 274134 | AA8: 624268 | AB8: 2690134 | AD8: 0 | AE8: 0 | AF8: 0 | AG8: 0 | AH8: 0 | AM8: =SUM(C8:Y8) | AN8: =AM8+AD8 | AO8: New building: after 2014
A9: 41852 | B9: 8583907 | C9: 3673176 | D9: 228122 | E9: 146934 | F9: 0 | G9: 0 | H9: 0 | I9: 2460070 | J9: 232978 | K9: 53454 | L9: 0 | M9: 0 | N9: 275655 | O9: 99316 | P9: 0 | Q9: 0 | W9: 0 | X9: 624042 | Y9: 790160 | Z9: 264880 | AA9: 525280 | AB9: 2735725 | AD9: 0 | AE9: 0 | AF9: 0 | AG9: 0 | AH9: 0 | AM9: =SUM(C9:Y9) | AN9: =AM9+AD9 | AO9: Old building: before 2014
A10: 41883 | B10: 10023872 | C10: 4469625 | D10: 276014 | E10: 132812 | F10: 0 | G10: 0 | H10: 0 | I10: 2515785 | J10: 269881 | K10: 79871 | L10: 0 | M10: 0 | N10: 307475 | O10: 89352 | P10: 0 | Q10: 0 | W10: 0 | X10: 956639 | Y10: 926418 | Z10: 311968 | AA10: 614450 | AB10: 2823260 | AD10: 0 | AE10: 0 | AF10: 0 | AG10: 0 | AH10: 0 | AM10: =SUM(C10:Y10) | AN10: =AM10+AD10
A11: 41913 | B11: 8035429 | C11: 4049333 | D11: 203926 | E11: 145929 | F11: 0 | G11: 0 | H11: 0 | I11: 1763222 | J11: 248622 | K11: 39903 | L11: 0 | M11: 0 | N11: 153059 | O11: 89097 | P11: 0 | Q11: 0 | W11: 0 | X11: 708839 | Y11: 633499 | Z11: 297097 | AA11: 336402 | AB11: 1916281 | AD11: 0 | AE11: 0 | AF11: 0 | AG11: 0 | AH11: 0 | AM11: =SUM(C11:Y11) | AN11: =AM11+AD11
A12: 41944 | B12: 6858052 | C12: 3872340 | D12: 214292 | E12: 95091 | F12: 0 | G12: 0 | H12: 0 | I12: 1119362 | J12: 267023 | K12: 50426 | L12: 0 | M12: 0 | N12: 153510 | O12: 76299 | P12: 0 | Q12: 0 | W12: 0 | X12: 532301 | Y12: 477408 | Z12: 276436 | AA12: 200972 | AB12: 1272872 | AD12: 0 | AE12: 0 | AF12: 0 | AG12: 0 | AH12: 0 | AM12: =SUM(C12:Y12) | AN12: =AM12+AD12
A13: 41974 | B13: 6405579 | C13: 3982954 | D13: 253212 | E13: 117318 | F13: 0 | G13: 0 | H13: 0 | I13: 548769 | J13: 246466 | K13: 71670 | L13: 0 | M13: 0 | N13: 67209 | O13: 55450 | P13: 0 | Q13: 0 | W13: 0 | X13: 483170 | Y13: 579361 | Z13: 281511 | AA13: 297850 | AB13: 615978 | AD13: 0 | AE13: 0 | AF13: 0 | AG13: 0 | AH13: 0 | AM13: =SUM(C13:Y13) | AN13: =AM13+AD13
A14: 42005 | B14: 6037637 | C14: 3908677 | D14: 195665 | E14: 99565 | F14: 0 | G14: 0 | H14: 0 | I14: 544141 | J14: 233787 | K14: 42271 | L14: 0 | M14: 0 | N14: 40400 | O14: 48517 | P14: 0 | Q14: 0 | W14: 0 | X14: 377084 | Y14: 547530 | Z14: 262207 | AA14: 285323 | AB14: 584541 | AD14: 0 | AE14: 0 | AF14: 0 | AG14: 0 | AH14: 0 | AM14: =SUM(C14:Y14) | AN14: =AM14+AD14
A15: 42036 | B15: 5695515 | C15: 3489436 | D15: 224244 | E15: 114195 | F15: 0 | G15: 0 | H15: 0 | I15: 515349 | J15: 235819 | K15: 56423 | L15: 0 | M15: 0 | N15: 52158 | O15: 49783 | P15: 0 | Q15: 0 | W15: 0 | X15: 470725 | Y15: 487383 | Z15: 247789 | AA15: 239594 | AB15: 567507 | AD15: 0 | AE15: 0 | AF15: 0 | AG15: 0 | AH15: 0 | AM15: =SUM(C15:Y15) | AN15: =AM15+AD15
A16: 42064 | B16: 6808373 | C16: 4118527 | D16: 218508 | E16: 125033 | F16: 0 | G16: 0 | H16: 0 | I16: 822631 | J16: 265435 | K16: 53193 | L16: 0 | M16: 0 | N16: 66141 | O16: 74567 | P16: 0 | Q16: 0 | W16: 0 | X16: 503575 | Y16: 560763 | Z16: 302505 | AA16: 258258 | AB16: 888772 | AD16: 0 | AE16: 0 | AF16: 0 | AG16: 0 | AH16: 0 | AM16: =SUM(C16:Y16) | AN16: =AM16+AD16
A17: 42095 | B17: 7375395 | C17: 4123782 | D17: 205482 | E17: 172615 | F17: 0 | G17: 0 | H17: 0 | I17: 1230463 | J17: 237697 | K17: 54391 | L17: 0 | M17: 0 | N17: 110064 | O17: 97242 | P17: 0 | Q17: 0 | W17: 0 | X17: 593115 | Y17: 550544 | Z17: 303017 | AA17: 247527 | AB17: 1340527 | AD17: 0 | AE17: 0 | AF17: 0 | AG17: 0 | AH17: 0 | AM17: =SUM(C17:Y17) | AN17: =AM17+AD17
A18: 42125 | B18: 8190535 | C18: 3697825 | D18: 220809 | E18: 203655 | F18: 0 | G18: 0 | H18: 0 | I18: 2094261 | J18: 212132 | K18: 49088 | L18: 0 | M18: 0 | N18: 186711 | O18: 72445 | P18: 0 | Q18: 0 | W18: 0 | X18: 777496 | Y18: 676113 | Z18: 293556 | AA18: 382557 | AB18: 2280972 | AD18: 0 | AE18: 0 | AF18: 0 | AG18: 0 | AH18: 0 | AM18: =SUM(C18:Y18) | AN18: =AM18+AD18
A19: 42156 | B19: 9712387 | C19: 4414578 | D19: 239524 | E19: 194738 | F19: 0 | G19: 0 | H19: 0 | I19: 2544609 | J19: 280980 | K19: 129946 | L19: 0 | M19: 0 | N19: 255852 | O19: 111119 | P19: 0 | Q19: 0 | W19: 0 | X19: 589036 | Y19: 952005 | Z19: 302993 | AA19: 649012 | AB19: 2800461 | AD19: 0 | AE19: 0 | AF19: 0 | AG19: 0 | AH19: 0 | AK19: =SUM(B8:B19) | AL19: =AK19 | AM19: =SUM(C19:Y19) | AN19: =AM19+AD19
A20: 42186 | B20: 8834027 | C20: 3840527 | D20: 216309 | E20: 224950 | F20: 0 | G20: 0 | H20: 0 | I20: 2507656 | J20: 217810 | K20: 77610 | L20: 25769 | M20: 0 | N20: 212246 | O20: 90399 | P20: 0 | Q20: 0 | W20: 0 | X20: 636984 | Y20: 783767 | Z20: 277550 | AA20: 506217 | AB20: 2719902 | AD20: 0 | AE20: 0 | AF20: 0 | AG20: 0 | AH20: 0 | AK20: =SUM(B9:B20) | AM20: =SUM(C20:Y20) | AN20: =AM20+AD20
A21: 42217 | B21: 8681882 | C21: 3336768 | D21: 260880 | E21: 198008 | F21: 0 | G21: 0 | H21: 0 | I21: 2564183 | J21: 268478 | K21: 71460 | L21: 134760 | M21: 0 | N21: 252328 | O21: 107250 | P21: 0 | Q21: 0 | W21: 0 | X21: 680006 | Y21: 807761 | Z21: 278196 | AA21: 529565 | AB21: 2816511 | AD21: 0 | AE21: 0 | AF21: 0 | AG21: 0 | AH21: 0 | AK21: =SUM(B10:B21) | AM21: =SUM(C21:Y21) | AN21: =AM21+AD21
A22: 42248 | B22: 9954396 | C22: 4633259 | D22: 234187 | E22: 228598 | F22: 0 | G22: 0 | H22: 0 | I22: 2359914 | J22: 263450 | K22: 56020 | L22: 135352 | M22: 0 | N22: 222957 | O22: 84622 | P22: 0 | Q22: 0 | W22: 0 | X22: 887878 | Y22: 848159 | Z22: 338617 | AA22: 509542 | AB22: 2582871 | AD22: 0 | AE22: 0 | AF22: 0 | AG22: 0 | AH22: 0 | AK22: =SUM(B11:B22) | AM22: =SUM(C22:Y22) | AN22: =AM22+AD22
A23: 42278 | B23: 8352722 | C23: 4009560 | D23: 212948 | E23: 252642 | F23: 0 | G23: 0 | H23: 0 | I23: 1873529 | J23: 247453 | K23: 52867 | L23: 131511 | M23: 0 | N23: 179183 | O23: 77686 | P23: 0 | Q23: 0 | W23: 0 | X23: 705699 | Y23: 609644 | Z23: 309456 | AA23: 300188 | AB23: 2052712 | AD23: 0 | AE23: 0 | AF23: 0 | AG23: 0 | AH23: 0 | AK23: =SUM(B12:B23) | AM23: =SUM(C23:Y23) | AN23: =AM23+AD23
A24: 42309 | B24: 8050995 | C24: 4200888 | D24: 229804 | E24: 304409 | F24: 0 | G24: 0 | H24: 0 | I24: 1464223 | J24: 278579 | K24: 45990 | L24: 146949 | M24: 0 | N24: 173483 | O24: 65641 | P24: 0 | Q24: 0 | W24: 0 | X24: 587552 | Y24: 553477 | Z24: 318937 | AA24: 234540 | AB24: 1637706 | AD24: 0 | AE24: 0 | AF24: 0 | AG24: 0 | AH24: 0 | AK24: =SUM(B13:B24) | AM24: =SUM(C24:Y24) | AN24: =AM24+AD24
A25: 42339 | B25: 6493453 | C25: 3614603 | D25: 290741 | E25: 333130 | F25: 0 | G25: 0 | H25: 0 | I25: 690904 | J25: 285264 | K25: 65483 | L25: 103943 | M25: 0 | N25: 90243 | O25: 79484 | P25: 0 | Q25: 0 | W25: 0 | X25: 453971 | Y25: 485687 | Z25: 282739 | AA25: 202948 | AB25: 781147 | AD25: 0 | AE25: 0 | AF25: 0 | AG25: 0 | AH25: 0 | AK25: =SUM(B14:B25) | AM25: =SUM(C25:Y25) | AN25: =AM25+AD25
A26: 42370 | B26: 6245223 | C26: 3831763 | D26: 139048 | E26: 277210 | F26: 0 | G26: 0 | H26: 0 | I26: 516685 | J26: 242251 | K26: 42075 | L26: 122690 | M26: 0 | N26: 50559 | O26: 78005 | P26: 0 | Q26: 0 | W26: 0 | X26: 377458 | Y26: 567479 | Z26: 259474 | AA26: 308005 | AB26: 567244 | AD26: 0 | AE26: 0 | AF26: 0 | AG26: 0 | AH26: 0 | AK26: =SUM(B15:B26) | AM26: =SUM(C26:Y26) | AN26: =AM26+AD26
A27: 42401 | B27: 6466884 | C27: 3779412 | D27: 298078 | E27: 343984 | F27: 0 | G27: 0 | H27: 0 | I27: 406263 | J27: 294647 | K27: 45944 | L27: 117026 | M27: 0 | N27: 48852 | O27: 37408 | P27: 0 | Q27: 0 | W27: 0 | X27: 487805 | Y27: 607465 | Z27: 272882 | AA27: 334583 | AB27: 455115 | AD27: 0 | AE27: 0 | AF27: 0 | AG27: 0 | AH27: 0 | AK27: =SUM(B16:B27) | AM27: =SUM(C27:Y27) | AN27: =AM27+AD27
A28: 42430 | B28: 6613470 | C28: 3972874 | D28: 204423 | E28: 276509 | F28: 0 | G28: 0 | H28: 0 | I28: 553500 | J28: 237417 | K28: 58069 | L28: 81220 | M28: 0 | N28: 57570 | O28: 60129 | P28: 0 | Q28: 0 | W28: 0 | X28: 547267 | Y28: 564492 | Z28: 289377 | AA28: 275115 | AB28: 611070 | AD28: 0 | AE28: 0 | AF28: 0 | AG28: 0 | AH28: 0 | AK28: =SUM(B17:B28) | AM28: =SUM(C28:Y28) | AN28: =AM28+AD28
A29: 42461 | B29: 7584721 | C29: 4018970 | D29: 215813 | E29: 296537 | F29: 0 | G29: 0 | H29: 0 | I29: 1283919 | J29: 271059 | K29: 49082 | L29: 118821 | M29: 0 | N29: 135895 | O29: 63059 | P29: 0 | Q29: 0 | W29: 0 | X29: 558826 | Y29: 572740 | Z29: 308674 | AA29: 264066 | AB29: 1419814 | AD29: 0 | AE29: 0 | AF29: 0 | AG29: 0 | AH29: 0 | AK29: =SUM(B18:B29) | AM29: =SUM(C29:Y29) | AN29: =AM29+AD29
A30: 42491 | B30: 8730352 | C30: 3773707 | D30: 263078 | E30: 405553 | F30: 0 | G30: 0 | H30: 0 | I30: 1964154 | J30: 277527 | K30: 71026 | L30: 204440 | M30: 0 | N30: 241532 | O30: 102506 | P30: 0 | Q30: 0 | W30: 0 | X30: 728971 | Y30: 697858 | Z30: 320173 | AA30: 377685 | AB30: 2205686 | AD30: 0 | AE30: 0 | AF30: 0 | AG30: 0 | AH30: 0 | AK30: =SUM(B19:B30) | AM30: =SUM(C30:Y30) | AN30: =AM30+AD30
A31: 42522 | B31: 9791945 | C31: 4046518 | D31: 274465 | E31: 503779 | F31: 0 | G31: 0 | H31: 0 | I31: 2672172 | J31: 247180 | K31: 48151 | L31: 162606 | M31: 0 | N31: 204368 | O31: 87014 | P31: 0 | Q31: 0 | W31: 0 | X31: 649314 | Y31: 896378 | Z31: 301989 | AA31: 594389 | AB31: 2876540 | AD31: 0 | AE31: 0 | AF31: 0 | AG31: 0 | AH31: 0 | AK31: =SUM(B20:B31) | AL31: =AK31 | AM31: =SUM(C31:Y31) | AN31: =AM31+AD31
A32: 42552 | B32: 9168714 | C32: 3655670 | D32: 171816 | E32: 346896 | F32: 0 | G32: 0 | H32: 0 | I32: 2679758 | J32: 241218 | K32: 56433 | L32: 183048 | M32: 0 | N32: 231512 | O32: 89776 | P32: 0 | Q32: 0 | W32: 0 | X32: 701641 | Y32: 810946 | Z32: 285596 | AA32: 525350 | AB32: 2911270 | AD32: 0 | AE32: 0 | AF32: 0 | AG32: 0 | AH32: 0 | AK32: =SUM(B21:B32) | AM32: =SUM(C32:Y32) | AN32: =AM32+AD32
A33: 42583 | B33: 9494610 | C33: 3873088 | D33: 267163 | E33: 515939 | F33: 0 | G33: 0 | H33: 0 | I33: 2450437 | J33: 296189 | K33: 70401 | L33: 187636 | M33: 0 | N33: 253271 | O33: 98211 | P33: 0 | Q33: 0 | W33: 0 | X33: 706214 | Y33: 776061 | Z33: 313559 | AA33: 462502 | AB33: 2703708 | AD33: 0 | AE33: 0 | AF33: 0 | AG33: 0 | AH33: 0 | AK33: =SUM(B22:B33) | AM33: =SUM(C33:Y33) | AN33: =AM33+AD33
A34: 42614 | B34: 9481784 | C34: 4228883 | D34: 247221 | E34: 400844 | F34: 0 | G34: 0 | H34: 0 | I34: 2315953 | J34: 260266 | K34: 58317 | L34: 155062 | M34: 0 | N34: 205585 | O34: 86794 | P34: 0 | Q34: 0 | W34: 0 | X34: 809354 | Y34: 713505 | Z34: 333329 | AA34: 380176 | AB34: 2521538 | AD34: 0 | AE34: 0 | AF34: 0 | AG34: 0 | AH34: 0 | AK34: =SUM(B23:B34) | AM34: =SUM(C34:Y34) | AN34: =AM34+AD34
A35: 42644 | B35: 8039061 | C35: 3320287 | D35: 244358 | E35: 301842 | F35: 0 | G35: 0 | H35: 0 | I35: 2065366 | J35: 252484 | K35: 59236 | L35: 143725 | M35: 0 | N35: 191013 | O35: 67897 | P35: 0 | Q35: 0 | W35: 0 | X35: 828064 | Y35: 564789 | Z35: 295061 | AA35: 269728 | AB35: 2256379 | AD35: 0 | AE35: 0 | AF35: 0 | AG35: 0 | AH35: 0 | AK35: =SUM(B24:B35) | AM35: =SUM(C35:Y35) | AN35: =AM35+AD35
A36: 42675 | B36: 8258064 | C36: 4405647 | D36: 269652 | E36: 561953 | F36: 0 | G36: 0 | H36: 0 | I36: 1190430 | J36: 309914 | K36: 74983 | L36: 137244 | M36: 0 | N36: 161352 | O36: 68587 | P36: 0 | Q36: 0 | W36: 0 | X36: 531267 | Y36: 547035 | Z36: 351124 | AA36: 195911 | AB36: 1351782 | AD36: 0 | AE36: 0 | AF36: 0 | AG36: 0 | AH36: 0 | AK36: =SUM(B25:B36) | AM36: =SUM(C36:Y36) | AN36: =AM36+AD36
A37: 42705 | B37: 6468025 | C37: 3593398 | D37: 239740 | E37: 398980 | F37: 0 | G37: 0 | H37: 0 | I37: 761395 | J37: 261691 | K37: 59003 | L37: 108647 | M37: 0 | N37: 86111 | O37: 51534 | P37: 0 | Q37: 0 | W37: 0 | X37: 463216 | Y37: 444310 | Z37: 303998 | AA37: 140312 | AB37: 847506 | AD37: 0 | AE37: 0 | AF37: 0 | AG37: 0 | AH37: 0 | AK37: =SUM(B26:B37) | AM37: =SUM(C37:Y37) | AN37: =AM37+AD37
A38: 42736 | B38: 5525573 | C38: 3099589 | D38: 214435 | E38: 370050 | F38: 0 | G38: 0 | H38: 0 | I38: 618875 | J38: 233523 | K38: 46449 | L38: 99324 | M38: 0 | N38: 55694 | O38: 41576 | P38: 0 | Q38: 0 | W38: 0 | X38: 337896 | Y38: 408162 | Z38: 243772 | AA38: 164390 | AB38: 674569 | AD38: 0 | AE38: 0 | AF38: 0 | AG38: 0 | AH38: 0 | AK38: =SUM(B27:B38) | AM38: =SUM(C38:Y38) | AN38: =AM38+AD38
A39: 42767 | B39: 6826525 | C39: 4036987 | D39: 254971 | E39: 430923 | F39: 0 | G39: 0 | H39: 0 | I39: 526051 | J39: 277051 | K39: 57162 | L39: 104695 | M39: 0 | N39: 58566 | O39: 46491 | P39: 0 | Q39: 0 | W39: 0 | X39: 498147 | Y39: 535481 | Z39: 308838 | AA39: 226643 | AB39: 584617 | AD39: 0 | AE39: 0 | AF39: 0 | AG39: 0 | AH39: 0 | AK39: =SUM(B28:B39) | AM39: =SUM(C39:Y39) | AN39: =AM39+AD39
A40: 42795 | B40: 6883831 | C40: 3870515 | D40: 248895 | E40: 445814 | F40: 0 | G40: 0 | H40: 0 | I40: 740508 | J40: 295298 | K40: 58107 | L40: 92166 | M40: 0 | N40: 72031 | O40: 46835 | P40: 0 | Q40: 0 | W40: 0 | X40: 500980 | Y40: 512682 | Z40: 317794 | AA40: 194888 | AB40: 812539 | AD40: 0 | AE40: 0 | AF40: 0 | AG40: 0 | AH40: 0 | AK40: =SUM(B29:B40) | AM40: =SUM(C40:Y40) | AN40: =AM40+AD40
...

Sheet Yearly Electricity (Overview)
A1: Date | B1: CLP + TKO | C1: CLP Total | D1: Main Academic Buildings & Other Public Facilities | E1: EC | F1: CYT | G1: Shaw Auditorium | H1: APCF (R/F Zone L) | I1: New Data Centre (2/F Zone L) | J1: Main Chiller Plant | K1: LSKBB | L1: IAS | M1: Conference Lodge | N1: LSK Hostel | O1: LSK Chiller Plant | P1: WWT | Q1: Water Sport Centre | R1: SISC | S1: HPC6 | T1: RB2 | U1: IB | V1: SRD (UG10-13) | W1: TA-B | X1: GGT | Y1: Student Housing | Z1: Staff Quarters & Commercial Outlets | AA1: Commercial Outlets | AB1: Staff Quarters | AC1: Combined Chiller Plants | AE1: TKO JC Hall | AF1: EC 3/F Data Centre (Elect) | AG1: EC 3/F Data Centre (Chiller kWhe) | AH1: SRD (Chiller kWhe) | AI1: IB (Chiller kWhe) | AJ1: BMW EV Charger kWh (LG7 & WWT) | AK1: Corner Stone EV Charger kWh
A2: 2014/15 | B2: =C2+AE2 | C2: =SUM('Monthly Electricity (Overview)'!B8:B19) | D2: =SUM('Monthly Electricity (Overview)'!C8:C19) | E2: =SUM('Monthly Electricity (Overview)'!D8:D19) | F2: =SUM('Monthly Electricity (Overview)'!E8:E19) | G2: =SUM('Monthly Electricity (Overview)'!F8:F19) | H2: =SUM('Monthly Electricity (Overview)'!G8:G19) | I2: =SUM('Monthly Electricity (Overview)'!H8:H19) | J2: =SUM('Monthly Electricity (Overview)'!I8:I19) | ... L2: =SUM('Monthly Electricity (Overview)'!K8:K19) | N2: =SUM('Monthly Electricity (Overview)'!M8:M19) | O2: =SUM('Monthly Electricity (Overview)'!N8:N19) | P2: =SUM('Monthly Electricity (Overview)'!O8:O19) | Y2: =SUM('Monthly Electricity (Overview)'!X8:X19) | Z2: =SUM('Monthly Electricity (Overview)'!Y8:Y19) | AA2: =SUM('Monthly Electricity (Overview)'!Z8:Z19) | AB2: =SUM('Monthly Electricity (Overview)'!AA8:AA19) | AC2: =SUM('Monthly Electricity (Overview)'!AB8:AB19)
A3: 2015/16 | B3: =C3+AE3 | C3: =SUM('Monthly Electricity (Overview)'!B20:B31) | D3: =SUM('Monthly Electricity (Overview)'!C20:C31) | E3: =SUM('Monthly Electricity (Overview)'!D20:D31) | F3: =SUM('Monthly Electricity (Overview)'!E20:E31) | G3: =SUM('Monthly Electricity (Overview)'!F20:F31) | H3: =SUM('Monthly Electricity (Overview)'!G20:G31) | I3: =SUM('Monthly Electricity (Overview)'!H20:H31) | J3: =SUM('Monthly Electricity (Overview)'!I20:I31) | ... P3: =SUM('Monthly Electricity (Overview)'!O20:O31) | Y3: =SUM('Monthly Electricity (Overview)'!X20:X31) | Z3: =SUM('Monthly Electricity (Overview)'!Y20:Y31) | AA3: =SUM('Monthly Electricity (Overview)'!Z20:Z31) | AB3: =SUM('Monthly Electricity (Overview)'!AA20:AA31) | AC3: =SUM('Monthly Electricity (Overview)'!AB20:AB31)
A4: 2016/17 | B4: =C4+AE4 | C4: =SUM('Monthly Electricity (Overview)'!B32:B43) | D4: =SUM('Monthly Electricity (Overview)'!C32:C43) | E4: =SUM('Monthly Electricity (Overview)'!D32:D43) | F4: =SUM('Monthly Electricity (Overview)'!E32:E43) | G4: =SUM('Monthly Electricity (Overview)'!F32:F43) | H4: =SUM('Monthly Electricity (Overview)'!G32:G43) | I4: =SUM('Monthly Electricity (Overview)'!H32:H43) | J4: =SUM('Monthly Electricity (Overview)'!I32:I43) | ... P4: =SUM('Monthly Electricity (Overview)'!O32:O43) | Y4: =SUM('Monthly Electricity (Overview)'!X32:X43) | Z4: =SUM('Monthly Electricity (Overview)'!Y32:Y43) | AA4: =SUM('Monthly Electricity (Overview)'!Z32:Z43) | AB4: =SUM('Monthly Electricity (Overview)'!AA32:AA43) | AC4: =SUM('Monthly Electricity (Overview)'!AB32:AB43)
A5: 2017/18 | B5: =C5+AE5 | C5: =SUM('Monthly Electricity (Overview)'!B44:B55) | D5: =SUM('Monthly Electricity (Overview)'!C44:C55) | E5: =SUM('Monthly Electricity (Overview)'!D44:D55) | F5: =SUM('Monthly Electricity (Overview)'!E44:E55) | G5: =SUM('Monthly Electricity (Overview)'!F44:F55) | H5: =SUM('Monthly Electricity (Overview)'!G44:G55) | I5: =SUM('Monthly Electricity (Overview)'!H44:H55) | J5: =SUM('Monthly Electricity (Overview)'!I44:I55) | ... P5: =SUM('Monthly Electricity (Overview)'!O44:O55) | R5: =SUM('Monthly Electricity (Overview)'!Q44:Q55) | Y5: =SUM('Monthly Electricity (Overview)'!X44:X55) | Z5: =SUM('Monthly Electricity (Overview)'!Y44:Y55) | AA5: =SUM('Monthly Electricity (Overview)'!Z44:Z55) | AB5: =SUM('Monthly Electricity (Overview)'!AA44:AA55) | AC5: =SUM('Monthly Electricity (Overview)'!AB44:AB55) | AE5: =SUM('Monthly Electricity (Overview)'!AD44:AD55)
A6: 2018/19 | B6: =C6+AE6 | C6: =SUM('Monthly Electricity (Overview)'!B56:B67) | D6: =SUM('Monthly Electricity (Overview)'!C56:C67) | E6: =SUM('Monthly Electricity (Overview)'!D56:D67) | F6: =SUM('Monthly Electricity (Overview)'!E56:E67) | G6: =SUM('Monthly Electricity (Overview)'!F56:F67) | H6: =SUM('Monthly Electricity (Overview)'!G56:G67) | I6: =SUM('Monthly Electricity (Overview)'!H56:H67) | J6: =SUM('Monthly Electricity (Overview)'!I56:I67) | ... P6: =SUM('Monthly Electricity (Overview)'!O56:O67) | R6: =SUM('Monthly Electricity (Overview)'!Q56:Q67) | Y6: =SUM('Monthly Electricity (Overview)'!X56:X67) | Z6: =SUM('Monthly Electricity (Overview)'!Y56:Y67) | AA6: =SUM('Monthly Electricity (Overview)'!Z56:Z67) | AB6: =SUM('Monthly Electricity (Overview)'!AA56:AA67) | AC6: =SUM('Monthly Electricity (Overview)'!AB56:AB67) | AE6: =SUM('Monthly Electricity (Overview)'!AD56:AD67)
A7: 2019/20 | B7: =C7+AE7 | C7: =SUM('Monthly Electricity (Overview)'!B68:B79) | D7: =SUM('Monthly Electricity (Overview)'!C68:C79) | E7: =SUM('Monthly Electricity (Overview)'!D68:D79) | F7: =SUM('Monthly Electricity (Overview)'!E68:E79) | G7: =SUM('Monthly Electricity (Overview)'!F68:F79) | H7: =SUM('Monthly Electricity (Overview)'!G68:G79) | I7: =SUM('Monthly Electricity (Overview)'!H68:H79) | J7: =SUM('Monthly Electricity (Overview)'!I68:I79) | ... P7: =SUM('Monthly Electricity (Overview)'!O68:O79) | R7: =SUM('Monthly Electricity (Overview)'!Q68:Q79) | Y7: =SUM('Monthly Electricity (Overview)'!X68:X79) | Z7: =SUM('Monthly Electricity (Overview)'!Y68:Y79) | AA7: =SUM('Monthly Electricity (Overview)'!Z68:Z79) | AB7: =SUM('Monthly Electricity (Overview)'!AA68:AA79) | AC7: =SUM('Monthly Electricity (Overview)'!AB68:AB79) | AE7: =SUM('Monthly Electricity (Overview)'!AD68:AD79)
A8: 2020/21 | B8: =C8+AE8 | C8: =SUM('Monthly Electricity (Overview)'!B80:B91) | D8: =SUM('Monthly Electricity (Overview)'!C80:C91) | E8: =SUM('Monthly Electricity (Overview)'!D80:D91) | F8: =SUM('Monthly Electricity (Overview)'!E80:E91) | G8: =SUM('Monthly Electricity (Overview)'!F80:F91) | H8: =SUM('Monthly Electricity (Overview)'!G80:G91) | I8: =SUM('Monthly Electricity (Overview)'!H80:H91) | J8: =SUM('Monthly Electricity (Overview)'!I80:I91) | ... R8: =SUM('Monthly Electricity (Overview)'!Q80:Q91) | X8: =SUM('Monthly Electricity (Overview)'!W80:W91) | Y8: =SUM('Monthly Electricity (Overview)'!X80:X91) | Z8: =SUM('Monthly Electricity (Overview)'!Y80:Y91) | AA8: =SUM('Monthly Electricity (Overview)'!Z80:Z91) | AB8: =SUM('Monthly Electricity (Overview)'!AA80:AA91) | AC8: =SUM('Monthly Electricity (Overview)'!AB80:AB91) | AE8: =SUM('Monthly Electricity (Overview)'!AD80:AD91)
A9: 2021/22 | B9: =C9+AE9 | C9: =SUM('Monthly Electricity (Overview)'!B92:B103) | D9: =SUM('Monthly Electricity (Overview)'!C92:C103) | E9: =SUM('Monthly Electricity (Overview)'!D92:D103) | F9: =SUM('Monthly Electricity (Overview)'!E92:E103) | G9: =SUM('Monthly Electricity (Overview)'!F92:F103) | H9: =SUM('Monthly Electricity (Overview)'!G92:G103) | I9: =SUM('Monthly Electricity (Overview)'!H92:H103) | J9: =SUM('Monthly Electricity (Overview)'!I92:I103) | ... R9: =SUM('Monthly Electricity (Overview)'!Q92:Q103) | X9: =SUM('Monthly Electricity (Overview)'!W92:W103) | Y9: =SUM('Monthly Electricity (Overview)'!X92:X103) | Z9: =SUM('Monthly Electricity (Overview)'!Y92:Y103) | AA9: =SUM('Monthly Electricity (Overview)'!Z92:Z103) | AB9: =SUM('Monthly Electricity (Overview)'!AA92:AA103) | AC9: =SUM('Monthly Electricity (Overview)'!AB92:AB103) | AE9: =SUM('Monthly Electricity (Overview)'!AD92:AD103)
A10: 2022/23 | B10: =C10+AE10 | C10: =SUM('Monthly Electricity (Overview)'!B104:B115) | D10: =SUM('Monthly Electricity (Overview)'!C104:C115) | E10: =SUM('Monthly Electricity (Overview)'!D104:D115) | F10: =SUM('Monthly Electricity (Overview)'!E104:E115) | G10: =SUM('Monthly Electricity (Overview)'!F104:F115) | H10: =SUM('Monthly Electricity (Overview)'!G104:G115) | I10: =SUM('Monthly Electricity (Overview)'!H104:H115) | J10: =SUM('Monthly Electricity (Overview)'!I104:I115) | ... R10: =SUM('Monthly Electricity (Overview)'!Q104:Q115) | W10: =SUM('Monthly Electricity (Overview)'!V104:V115) | X10: =SUM('Monthly Electricity (Overview)'!W104:W115) | Y10: =SUM('Monthly Electricity (Overview)'!X104:X115) | Z10: =SUM('Monthly Electricity (Overview)'!Y104:Y115) | AA10: =SUM('Monthly Electricity (Overview)'!Z104:Z115) | AB10: =SUM('Monthly Electricity (Overview)'!AA104:AA115) | AC10: =SUM('Monthly Electricity (Overview)'!AB104:AB115) | AE10: =SUM('Monthly Electricity (Overview)'!AD104:AD115)
A11: 2023/24 | B11: =C11+AE11 | C11: =SUM('Monthly Electricity (Overview)'!B116:B127) | D11: =SUM('Monthly Electricity (Overview)'!C116:C127) | E11: =SUM('Monthly Electricity (Overview)'!D116:D127) | F11: =SUM('Monthly Electricity (Overview)'!E116:E127) | G11: =SUM('Monthly Electricity (Overview)'!F116:F127) | H11: =SUM('Monthly Electricity (Overview)'!G116:G127) | I11: =SUM('Monthly Electricity (Overview)'!H116:H127) | J11: =SUM('Monthly Electricity (Overview)'!I116:I127) | ... R11: =SUM('Monthly Electricity (Overview)'!Q116:Q127) | T11: =SUM('Monthly Electricity (Overview)'!S116:S127) | V11: =SUM('Monthly Electricity (Overview)'!U116:U127) | W11: =SUM('Monthly Electricity (Overview)'!V116:V127) | X11: =SUM('Monthly Electricity (Overview)'!W116:W127) | Y11: =SUM('Monthly Electricity (Overview)'!X116:X127) | Z11: =SUM('Monthly Electricity (Overview)'!Y116:Y127) | AA11: =SUM('Monthly Electricity (Overview)'!Z116:Z127) | AB11: =SUM('Monthly Electricity (Overview)'!AA116:AA127) | AC11: =SUM('Monthly Electricity (Overview)'!AB116:AB127) | AE11: =SUM('Monthly Electricity (Overview)'!AD116:AD127) | AJ11: =SUM('Monthly Electricity (Overview)'!AI116:AI127) | AK11: =SUM('Monthly Electricity (Overview)'!AJ116:AJ127)
A12: 2024/25 | B12: =C12+AE12 | C12: =SUM('Monthly Electricity (Overview)'!B128:B139) | D12: =SUM('Monthly Electricity (Overview)'!C128:C139) | E12: =SUM('Monthly Electricity (Overview)'!D128:D139) | F12: =SUM('Monthly Electricity (Overview)'!E128:E139) | G12: =SUM('Monthly Electricity (Overview)'!F128:F139) | H12: =SUM('Monthly Electricity (Overview)'!G128:G139) | I12: =SUM('Monthly Electricity (Overview)'!H128:H139) | J12: =SUM('Monthly Electricity (Overview)'!I128:I139) | ... R12: =SUM('Monthly Electricity (Overview)'!Q128:Q139) | T12: =SUM('Monthly Electricity (Overview)'!S128:S139) | U12: =SUM('Monthly Electricity (Overview)'!T128:T139) | V12: =SUM('Monthly Electricity (Overview)'!U128:U139) | W12: =SUM('Monthly Electricity (Overview)'!V128:V139) | X12: =SUM('Monthly Electricity (Overview)'!W128:W139) | Y12: =SUM('Monthly Electricity (Overview)'!X128:X139) | Z12: =SUM('Monthly Electricity (Overview)'!Y128:Y139) | AA12: =SUM('Monthly Electricity (Overview)'!Z128:Z139) | ... AC12: =SUM('Monthly Electricity (Overview)'!AB128:AB139) | AE12: =SUM('Monthly Electricity (Overview)'!AD128:AD139) | AF12: =SUM('Monthly Electricity (Overview)'!AE128:AE139) | AG12: =SUM('Monthly Electricity (Overview)'!AF128:AF139) | AJ12: =SUM('Monthly Electricity (Overview)'!AI128:AI139) | AK12: =SUM('Monthly Electricity (Overview)'!AJ128:AJ139)
A13: 2025/26 | B13: =C13+AE13 | C13: =SUM('Monthly Electricity (Overview)'!B140:B151) | D13: =SUM('Monthly Electricity (Overview)'!C140:C151) | E13: =SUM('Monthly Electricity (Overview)'!D140:D151) | F13: =SUM('Monthly Electricity (Overview)'!E140:E151) | G13: =SUM('Monthly Electricity (Overview)'!F140:F151) | H13: =SUM('Monthly Electricity (Overview)'!G140:G151) | I13: =SUM('Monthly Electricity (Overview)'!H140:H151) | J13: =SUM('Monthly Electricity (Overview)'!I140:I151) | ... AC13: =SUM('Monthly Electricity (Overview)'!AB140:AB151) | AE13: =SUM('Monthly Electricity (Overview)'!AD140:AD151) | AF13: =SUM('Monthly Electricity (Overview)'!AE140:AE151) | AG13: =SUM('Monthly Electricity (Overview)'!AF140:AF151) | AH13: =SUM('Monthly Electricity (Overview)'!AG140:AG151) | AI13: =SUM('Monthly Electricity (Overview)'!AH140:AH151) | AJ13: =SUM('Monthly Electricity (Overview)'!AI140:AI151) | AK13: =SUM('Monthly Electricity (Overview)'!AJ140:AJ151)

Sheet Monthly Electricity Reformatted
A1: Period | B1: Main Academic Buildings and Others | C1: Main Chiller Plant | D1: LSK Chiller Plant | E1: Cheng Yu Tung Building | F1: LSK Building | G1: IAS Building | H1: HPC 6 | I1: Research Building 2 | J1: Innovation Building | K1: Conference Lodge | L1: Staff Quarter Common Area | M1: Student Housing | N1: Staff Quarters | O1: Commercial Outlets | P1: Staff Quarters & Commercial Outlet | Q1: Whole Campus (including staff quarter common area) | R1: Whole Campus (excluding staff quarter common area)
A2: 44013 | B2: =SUM('Monthly Electricity (Overview)'!C80:D80)+SUM('Monthly Electricity (Overview)'!F80:H80)+SUM('Monthly Electricity (Overview)'!O80:Q80) | C2: ='Monthly Electricity (Overview)'!I80 | D2: ='Monthly Electricity (Overview)'!N80 | E2: ='Monthly Electricity (Overview)'!E80 | F2: ='Monthly Electricity (Overview)'!J80 | G2: ='Monthly Electricity (Overview)'!K80 | K2: ='Monthly Electricity (Overview)'!L80 | L2: 99693 | M2: =SUM('Monthly Electricity (Overview)'!U80:X80)+'Monthly Electricity (Overview)'!AD80 | N2: ='Monthly Electricity (Overview)'!AA80 | O2: ='Monthly Electricity (Overview)'!Z80 | P2: ='Monthly Electricity (Overview)'!Y80 | Q2: =SUM(B2:P2)-P2 | R2: =SUM(B2:O2)-L2
A3: 44044 | B3: =SUM('Monthly Electricity (Overview)'!C81:D81)+SUM('Monthly Electricity (Overview)'!F81:H81)+SUM('Monthly Electricity (Overview)'!O81:Q81) | C3: ='Monthly Electricity (Overview)'!I81 | D3: ='Monthly Electricity (Overview)'!N81 | E3: ='Monthly Electricity (Overview)'!E81 | F3: ='Monthly Electricity (Overview)'!J81 | G3: ='Monthly Electricity (Overview)'!K81 | K3: ='Monthly Electricity (Overview)'!L81 | L3: 111077 | M3: =SUM('Monthly Electricity (Overview)'!U81:X81)+'Monthly Electricity (Overview)'!AD81 | N3: ='Monthly Electricity (Overview)'!AA81 | O3: ='Monthly Electricity (Overview)'!Z81 | P3: ='Monthly Electricity (Overview)'!Y81 | Q3: =SUM(B3:P3)-P3 | R3: =SUM(B3:O3)-L3
A4: 44075 | B4: =SUM('Monthly Electricity (Overview)'!C82:D82)+SUM('Monthly Electricity (Overview)'!F82:H82)+SUM('Monthly Electricity (Overview)'!O82:Q82) | C4: ='Monthly Electricity (Overview)'!I82 | D4: ='Monthly Electricity (Overview)'!N82 | E4: ='Monthly Electricity (Overview)'!E82 | F4: ='Monthly Electricity (Overview)'!J82 | G4: ='Monthly Electricity (Overview)'!K82 | K4: ='Monthly Electricity (Overview)'!L82 | L4: 124553 | M4: =SUM('Monthly Electricity (Overview)'!U82:X82)+'Monthly Electricity (Overview)'!AD82 | N4: ='Monthly Electricity (Overview)'!AA82 | O4: ='Monthly Electricity (Overview)'!Z82 | P4: ='Monthly Electricity (Overview)'!Y82 | Q4: =SUM(B4:P4)-P4 | R4: =SUM(B4:O4)-L4
A5: 44105 | B5: =SUM('Monthly Electricity (Overview)'!C83:D83)+SUM('Monthly Electricity (Overview)'!F83:H83)+SUM('Monthly Electricity (Overview)'!O83:Q83) | C5: ='Monthly Electricity (Overview)'!I83 | D5: ='Monthly Electricity (Overview)'!N83 | E5: ='Monthly Electricity (Overview)'!E83 | F5: ='Monthly Electricity (Overview)'!J83 | G5: ='Monthly Electricity (Overview)'!K83 | K5: ='Monthly Electricity (Overview)'!L83 | L5: 81463 | M5: =SUM('Monthly Electricity (Overview)'!U83:X83)+'Monthly Electricity (Overview)'!AD83 | N5: ='Monthly Electricity (Overview)'!AA83 | O5: ='Monthly Electricity (Overview)'!Z83 | P5: ='Monthly Electricity (Overview)'!Y83 | Q5: =SUM(B5:P5)-P5 | R5: =SUM(B5:O5)-L5
A6: 44136 | B6: =SUM('Monthly Electricity (Overview)'!C84:D84)+SUM('Monthly Electricity (Overview)'!F84:H84)+SUM('Monthly Electricity (Overview)'!O84:Q84) | C6: ='Monthly Electricity (Overview)'!I84 | D6: ='Monthly Electricity (Overview)'!N84 | E6: ='Monthly Electricity (Overview)'!E84 | F6: ='Monthly Electricity (Overview)'!J84 | G6: ='Monthly Electricity (Overview)'!K84 | K6: ='Monthly Electricity (Overview)'!L84 | L6: 59032 | M6: =SUM('Monthly Electricity (Overview)'!U84:X84)+'Monthly Electricity (Overview)'!AD84 | N6: ='Monthly Electricity (Overview)'!AA84 | O6: ='Monthly Electricity (Overview)'!Z84 | P6: ='Monthly Electricity (Overview)'!Y84 | Q6: =SUM(B6:P6)-P6 | R6: =SUM(B6:O6)-L6
A7: 44166 | B7: =SUM('Monthly Electricity (Overview)'!C85:D85)+SUM('Monthly Electricity (Overview)'!F85:H85)+SUM('Monthly Electricity (Overview)'!O85:Q85) | C7: ='Monthly Electricity (Overview)'!I85 | D7: ='Monthly Electricity (Overview)'!N85 | E7: ='Monthly Electricity (Overview)'!E85 | F7: ='Monthly Electricity (Overview)'!J85 | G7: ='Monthly Electricity (Overview)'!K85 | K7: ='Monthly Electricity (Overview)'!L85 | L7: 53030 | M7: =SUM('Monthly Electricity (Overview)'!U85:X85)+'Monthly Electricity (Overview)'!AD85 | N7: ='Monthly Electricity (Overview)'!AA85 | O7: ='Monthly Electricity (Overview)'!Z85 | P7: ='Monthly Electricity (Overview)'!Y85 | Q7: =SUM(B7:P7)-P7 | R7: =SUM(B7:O7)-L7
A8: 44197 | B8: =SUM('Monthly Electricity (Overview)'!C86:D86)+SUM('Monthly Electricity (Overview)'!F86:H86)+SUM('Monthly Electricity (Overview)'!O86:Q86) | C8: ='Monthly Electricity (Overview)'!I86 | D8: ='Monthly Electricity (Overview)'!N86 | E8: ='Monthly Electricity (Overview)'!E86 | F8: ='Monthly Electricity (Overview)'!J86 | G8: ='Monthly Electricity (Overview)'!K86 | K8: ='Monthly Electricity (Overview)'!L86 | L8: 48369 | M8: =SUM('Monthly Electricity (Overview)'!U86:X86)+'Monthly Electricity (Overview)'!AD86 | N8: ='Monthly Electricity (Overview)'!AA86 | O8: ='Monthly Electricity (Overview)'!Z86 | P8: ='Monthly Electricity (Overview)'!Y86 | Q8: =SUM(B8:P8)-P8 | R8: =SUM(B8:O8)-L8
A9: 44228 | B9: =SUM('Monthly Electricity (Overview)'!C87:D87)+SUM('Monthly Electricity (Overview)'!F87:H87)+SUM('Monthly Electricity (Overview)'!O87:Q87) | C9: ='Monthly Electricity (Overview)'!I87 | D9: ='Monthly Electricity (Overview)'!N87 | E9: ='Monthly Electricity (Overview)'!E87 | F9: ='Monthly Electricity (Overview)'!J87 | G9: ='Monthly Electricity (Overview)'!K87 | K9: ='Monthly Electricity (Overview)'!L87 | L9: 45841 | M9: =SUM('Monthly Electricity (Overview)'!U87:X87)+'Monthly Electricity (Overview)'!AD87 | N9: ='Monthly Electricity (Overview)'!AA87 | O9: ='Monthly Electricity (Overview)'!Z87 | P9: ='Monthly Electricity (Overview)'!Y87 | Q9: =SUM(B9:P9)-P9 | R9: =SUM(B9:O9)-L9
A10: 44256 | B10: =SUM('Monthly Electricity (Overview)'!C88:D88)+SUM('Monthly Electricity (Overview)'!F88:H88)+SUM('Monthly Electricity (Overview)'!O88:Q88) | C10: ='Monthly Electricity (Overview)'!I88 | D10: ='Monthly Electricity (Overview)'!N88 | E10: ='Monthly Electricity (Overview)'!E88 | F10: ='Monthly Electricity (Overview)'!J88 | G10: ='Monthly Electricity (Overview)'!K88 | K10: ='Monthly Electricity (Overview)'!L88 | L10: 55029 | M10: =SUM('Monthly Electricity (Overview)'!U88:X88)+'Monthly Electricity (Overview)'!AD88 | N10: ='Monthly Electricity (Overview)'!AA88 | O10: ='Monthly Electricity (Overview)'!Z88 | P10: ='Monthly Electricity (Overview)'!Y88 | Q10: =SUM(B10:P10)-P10 | R10: =SUM(B10:O10)-L10
A11: 44287 | B11: =SUM('Monthly Electricity (Overview)'!C89:D89)+SUM('Monthly Electricity (Overview)'!F89:H89)+SUM('Monthly Electricity (Overview)'!O89:Q89) | C11: ='Monthly Electricity (Overview)'!I89 | D11: ='Monthly Electricity (Overview)'!N89 | E11: ='Monthly Electricity (Overview)'!E89 | F11: ='Monthly Electricity (Overview)'!J89 | G11: ='Monthly Electricity (Overview)'!K89 | K11: ='Monthly Electricity (Overview)'!L89 | L11: 62537 | M11: =SUM('Monthly Electricity (Overview)'!U89:X89)+'Monthly Electricity (Overview)'!AD89 | N11: ='Monthly Electricity (Overview)'!AA89 | O11: ='Monthly Electricity (Overview)'!Z89 | P11: ='Monthly Electricity (Overview)'!Y89 | Q11: =SUM(B11:P11)-P11 | R11: =SUM(B11:O11)-L11
A12: 44317 | B12: =SUM('Monthly Electricity (Overview)'!C90:D90)+SUM('Monthly Electricity (Overview)'!F90:H90)+SUM('Monthly Electricity (Overview)'!O90:Q90) | C12: ='Monthly Electricity (Overview)'!I90 | D12: ='Monthly Electricity (Overview)'!N90 | E12: ='Monthly Electricity (Overview)'!E90 | F12: ='Monthly Electricity (Overview)'!J90 | G12: ='Monthly Electricity (Overview)'!K90 | K12: ='Monthly Electricity (Overview)'!L90 | L12: 84771 | M12: =SUM('Monthly Electricity (Overview)'!U90:X90)+'Monthly Electricity (Overview)'!AD90 | N12: ='Monthly Electricity (Overview)'!AA90 | O12: ='Monthly Electricity (Overview)'!Z90 | P12: ='Monthly Electricity (Overview)'!Y90 | Q12: =SUM(B12:P12)-P12 | R12: =SUM(B12:O12)-L12
A13: 44348 | B13: =SUM('Monthly Electricity (Overview)'!C91:D91)+SUM('Monthly Electricity (Overview)'!F91:H91)+SUM('Monthly Electricity (Overview)'!O91:Q91) | C13: ='Monthly Electricity (Overview)'!I91 | D13: ='Monthly Electricity (Overview)'!N91 | E13: ='Monthly Electricity (Overview)'!E91 | F13: ='Monthly Electricity (Overview)'!J91 | G13: ='Monthly Electricity (Overview)'!K91 | K13: ='Monthly Electricity (Overview)'!L91 | L13: 90161 | M13: =SUM('Monthly Electricity (Overview)'!U91:X91)+'Monthly Electricity (Overview)'!AD91 | N13: ='Monthly Electricity (Overview)'!AA91 | O13: ='Monthly Electricity (Overview)'!Z91 | P13: ='Monthly Electricity (Overview)'!Y91 | Q13: =SUM(B13:P13)-P13 | R13: =SUM(B13:O13)-L13
... A44: 45292 | B44: =SUM('Monthly Electricity (Overview)'!C122:D122)+SUM('Monthly Electricity (Overview)'!F122:H122)+SUM('Monthly Electricity (Overview)'!O122:Q122) | C44: ='Monthly Electricity (Overview)'!I122 | D44: ='Monthly Electricity (Overview)'!N122 | E44: ='Monthly Electricity (Overview)'!E122 | F44: ='Monthly Electricity (Overview)'!J122 | G44: ='Monthly Electricity (Overview)'!K122 | K44: ='Monthly Electricity (Overview)'!L122 | L44: 50823 | M44: =SUM('Monthly Electricity (Overview)'!U122:X122)+'Monthly Electricity (Overview)'!AD122 | N44: ='Monthly Electricity (Overview)'!AA122 | O44: ='Monthly Electricity (Overview)'!Z122 | P44: ='Monthly Electricity (Overview)'!Y122 | Q44: =SUM(B44:P44)-P44 | R44: =SUM(B44:O44)-L44
A45: 45323 | B45: =SUM('Monthly Electricity (Overview)'!C123:D123)+SUM('Monthly Electricity (Overview)'!F123:H123)+SUM('Monthly Electricity (Overview)'!O123:Q123) | C45: ='Monthly Electricity (Overview)'!I123 | D45: ='Monthly Electricity (Overview)'!N123 | E45: ='Monthly Electricity (Overview)'!E123 | F45: ='Monthly Electricity (Overview)'!J123 | G45: ='Monthly Electricity (Overview)'!K123 | I45: ='Monthly Electricity (Overview)'!S123 | K45: ='Monthly Electricity (Overview)'!L123 | L45: 54165 | M45: =SUM('Monthly Electricity (Overview)'!U123:X123)+'Monthly Electricity (Overview)'!AD123 | N45: ='Monthly Electricity (Overview)'!AA123 | O45: ='Monthly Electricity (Overview)'!Z123 | P45: ='Monthly Electricity (Overview)'!Y123 | Q45: =SUM(B45:P45)-P45 | R45: =SUM(B45:O45)-L45
A46: 45352 | B46: =SUM('Monthly Electricity (Overview)'!C124:D124)+SUM('Monthly Electricity (Overview)'!F124:H124)+SUM('Monthly Electricity (Overview)'!O124:Q124) | C46: ='Monthly Electricity (Overview)'!I124 | D46: ='Monthly Electricity (Overview)'!N124 | E46: ='Monthly Electricity (Overview)'!E124 | F46: ='Monthly Electricity (Overview)'!J124 | G46: ='Monthly Electricity (Overview)'!K124 | I46: ='Monthly Electricity (Overview)'!S124 | K46: ='Monthly Electricity (Overview)'!L124 | L46: 46664 | M46: =SUM('Monthly Electricity (Overview)'!U124:X124)+'Monthly Electricity (Overview)'!AD124 | N46: ='Monthly Electricity (Overview)'!AA124 | O46: ='Monthly Electricity (Overview)'!Z124 | P46: ='Monthly Electricity (Overview)'!Y124 | Q46: =SUM(B46:P46)-P46 | R46: =SUM(B46:O46)-L46
A47: 45383 | B47: =SUM('Monthly Electricity (Overview)'!C125:D125)+SUM('Monthly Electricity (Overview)'!F125:H125)+SUM('Monthly Electricity (Overview)'!O125:Q125) | C47: ='Monthly Electricity (Overview)'!I125 | D47: ='Monthly Electricity (Overview)'!N125 | E47: ='Monthly Electricity (Overview)'!E125 | F47: ='Monthly Electricity (Overview)'!J125 | G47: ='Monthly Electricity (Overview)'!K125 | I47: ='Monthly Electricity (Overview)'!S125 | K47: ='Monthly Electricity (Overview)'!L125 | L47: 76596 | M47: =SUM('Monthly Electricity (Overview)'!U125:X125)+'Monthly Electricity (Overview)'!AD125 | N47: ='Monthly Electricity (Overview)'!AA125 | O47: ='Monthly Electricity (Overview)'!Z125 | P47: ='Monthly Electricity (Overview)'!Y125 | Q47: =SUM(B47:P47)-P47 | R47: =SUM(B47:O47)-L47
A48: 45413 | B48: =SUM('Monthly Electricity (Overview)'!C126:D126)+SUM('Monthly Electricity (Overview)'!F126:H126)+SUM('Monthly Electricity (Overview)'!O126:Q126) | C48: ='Monthly Electricity (Overview)'!I126 | D48: ='Monthly Electricity (Overview)'!N126 | E48: ='Monthly Electricity (Overview)'!E126 | F48: ='Monthly Electricity (Overview)'!J126 | G48: ='Monthly Electricity (Overview)'!K126 | I48: ='Monthly Electricity (Overview)'!S126 | K48: ='Monthly Electricity (Overview)'!L126 | L48: 69174 | M48: =SUM('Monthly Electricity (Overview)'!U126:X126)+'Monthly Electricity (Overview)'!AD126 | N48: ='Monthly Electricity (Overview)'!AA126 | O48: ='Monthly Electricity (Overview)'!Z126 | P48: ='Monthly Electricity (Overview)'!Y126 | Q48: =SUM(B48:P48)-P48 | R48: =SUM(B48:O48)-L48
A49: 45444 | B49: =SUM('Monthly Electricity (Overview)'!C127:D127)+SUM('Monthly Electricity (Overview)'!F127:H127)+SUM('Monthly Electricity (Overview)'!O127:Q127) | C49: ='Monthly Electricity (Overview)'!I127 | D49: ='Monthly Electricity (Overview)'!N127 | E49: ='Monthly Electricity (Overview)'!E127 | F49: ='Monthly Electricity (Overview)'!J127 | G49: ='Monthly Electricity (Overview)'!K127 | I49: ='Monthly Electricity (Overview)'!S127 | K49: ='Monthly Electricity (Overview)'!L127 | L49: 89300 | M49: =SUM('Monthly Electricity (Overview)'!U127:X127)+'Monthly Electricity (Overview)'!AD127 | N49: ='Monthly Electricity (Overview)'!AA127 | O49: ='Monthly Electricity (Overview)'!Z127 | P49: ='Monthly Electricity (Overview)'!Y127 | Q49: =SUM(B49:P49)-P49 | R49: =SUM(B49:O49)-L49
A50: 45474 | B50: =SUM('Monthly Electricity (Overview)'!C128:D128)+SUM('Monthly Electricity (Overview)'!F128:H128)+SUM('Monthly Electricity (Overview)'!O128:Q128) | C50: ='Monthly Electricity (Overview)'!I128 | D50: ='Monthly Electricity (Overview)'!N128 | E50: ='Monthly Electricity (Overview)'!E128 | F50: ='Monthly Electricity (Overview)'!J128 | G50: ='Monthly Electricity (Overview)'!K128 | I50: ='Monthly Electricity (Overview)'!S128 | J50: ='Monthly Electricity (Overview)'!T128 | K50: ='Monthly Electricity (Overview)'!L128 | L50: 96675 | M50: =SUM('Monthly Electricity (Overview)'!U128:X128)+'Monthly Electricity (Overview)'!AD128 | N50: ='Monthly Electricity (Overview)'!AA128 | O50: ='Monthly Electricity (Overview)'!Z128 | P50: ='Monthly Electricity (Overview)'!Y128 | Q50: =SUM(B50:P50)-P50 | R50: =SUM(B50:O50)-L50
A51: 45505 | B51: =SUM('Monthly Electricity (Overview)'!C129:D129)+SUM('Monthly Electricity (Overview)'!F129:H129)+SUM('Monthly Electricity (Overview)'!O129:Q129) | C51: ='Monthly Electricity (Overview)'!I129 | D51: ='Monthly Electricity (Overview)'!N129 | E51: ='Monthly Electricity (Overview)'!E129 | F51: ='Monthly Electricity (Overview)'!J129 | G51: ='Monthly Electricity (Overview)'!K129 | I51: ='Monthly Electricity (Overview)'!S129 | J51: ='Monthly Electricity (Overview)'!T129 | K51: ='Monthly Electricity (Overview)'!L129 | L51: 102262 | M51: =SUM('Monthly Electricity (Overview)'!U129:X129)+'Monthly Electricity (Overview)'!AD129 | N51: ='Monthly Electricity (Overview)'!AA129 | O51: ='Monthly Electricity (Overview)'!Z129 | P51: ='Monthly Electricity (Overview)'!Y129 | Q51: =SUM(B51:P51)-P51 | R51: =SUM(B51:O51)-L51
A52: 45536 | B52: =SUM('Monthly Electricity (Overview)'!C130:D130)+SUM('Monthly Electricity (Overview)'!F130:H130)+SUM('Monthly Electricity (Overview)'!O130:Q130) | C52: ='Monthly Electricity (Overview)'!I130 | D52: ='Monthly Electricity (Overview)'!N130 | E52: ='Monthly Electricity (Overview)'!E130 | F52: ='Monthly Electricity (Overview)'!J130 | G52: ='Monthly Electricity (Overview)'!K130 | I52: ='Monthly Electricity (Overview)'!S130 | J52: ='Monthly Electricity (Overview)'!T130 | K52: ='Monthly Electricity (Overview)'!L130 | L52: 94188 | M52: =SUM('Monthly Electricity (Overview)'!U130:X130)+'Monthly Electricity (Overview)'!AD130 | N52: ='Monthly Electricity (Overview)'!AA130 | O52: ='Monthly Electricity (Overview)'!Z130 | P52: ='Monthly Electricity (Overview)'!Y130 | Q52: =SUM(B52:P52)-P52 | R52: =SUM(B52:O52)-L52
A53: 45566 | B53: =SUM('Monthly Electricity (Overview)'!C131:D131)+SUM('Monthly Electricity (Overview)'!F131:H131)+SUM('Monthly Electricity (Overview)'!O131:Q131) | C53: ='Monthly Electricity (Overview)'!I131 | D53: ='Monthly Electricity (Overview)'!N131 | E53: ='Monthly Electricity (Overview)'!E131 | F53: ='Monthly Electricity (Overview)'!J131 | G53: ='Monthly Electricity (Overview)'!K131 | I53: ='Monthly Electricity (Overview)'!S131 | J53: ='Monthly Electricity (Overview)'!T131 | K53: ='Monthly Electricity (Overview)'!L131 | L53: 74174 | M53: =SUM('Monthly Electricity (Overview)'!U131:X131)+'Monthly Electricity (Overview)'!AD131 | N53: ='Monthly Electricity (Overview)'!AA131 | O53: ='Monthly Electricity (Overview)'!Z131 | P53: ='Monthly Electricity (Overview)'!Y131 | Q53: =SUM(B53:P53)-P53 | R53: =SUM(B53:O53)-L53
