Workbook
Name Category: #REF!
Name dd: #REF!
Name GHGItems: #REF!
Name GHGItems: #REF!
Name New: #REF!
Name New: #REF!
Name newyear: #REF!
Name newyear: #REF!
Name Reduction: #REF!
Name Reduction: #REF!
Name s: #REF!
Name Y: #REF!
Name Y: #REF!
Name Year: #REF!

Sheet CLP Tariff
B1: Total (Group A) (kWh) | C1: LPT Total (excluding Gp B) (kWh) | D1: LPT Group B (kWh) | E1: FiT Renewable Energy Generation (kWh) | K1: No. of days. | L1: Billing Days
B2: Whole Campus | C2: Teaching Buildings, Public Facilities & Student Hostels | D2: Staff Quarters & Commercial Outlets | E2: LPT Bill | F2: SSQ Bill | G2: JSQ Bill | H2: VC & Guest Lodge | I2: Solar kWhTotal | J2: % of Solar kWh / Whole Campus kWh | N2: Period | O2: 12-month Rolling Sum in Electricity Consumption (kWh) | P2: 12-month Rolling Sum in Renewable Energy Generation (kWh) | Q2: 12-month Rolling Sum of Net Electricity Consumption (kWh) | R2: 12-month Rolling Saving Performance | S2: 12-month Rolling Net Saving Performance
A3: 41456 | B3: =SUM(C3:D3) -> 8917775 | C3: 8036102 | D3: 881673 | K3: 32 | N3: 41456
A4: 41487 | B4: =SUM(C4:D4) -> 8906248 | C4: 8026656 | D4: 879592 | K4: 31 | N4: 41487
A5: 41518 | B5: =SUM(C5:D5) -> 8919899 | C5: 8108930 | D5: 810969 | K5: 31 | N5: 41518
A6: 41548 | B6: =SUM(C6:D6) -> 7600046 | C6: 6953433 | D6: 646613 | K6: 30 | N6: 41548
A7: 41579 | B7: =SUM(C7:D7) -> 6995914 | C7: 6475053 | D7: 520861 | K7: 30 | N7: 41579
A8: 41609 | B8: =SUM(C8:D8) -> 6133318 | C8: 5561498 | D8: 571820 | K8: 31 | N8: 41609
A9: 41640 | B9: =SUM(C9:D9) -> 5938547 | C9: 5376916 | D9: 561631 | K9: 31 | L9: =SUM(K9:K20) -> 365 | O9: =SUM(B9:B20) -> 91444196 | V9: Jul-Sep 2014 | W9: =SUM(B15:B17) -> 27948305
A10: 41671 | B10: =SUM(C10:D10) -> 5888877 | C10: 5294961 | D10: 593916 | K10: 29 | O10: =SUM(B10:B21) -> 91543286 | V10: Jul-Sep 2015 | W10: =SUM(B27:B29) -> 27470305
A11: 41699 | B11: =SUM(C11:D11) -> 6018786 | C11: 5479270 | D11: 539516 | K11: 28 | O11: =SUM(B11:B22) -> 91349924 | V11: Jul-Sep 2016 | W11: =SUM(B39:B41) -> 28145108
A12: 41730 | B12: =SUM(C12:D12) -> 7488350 | C12: 6908484 | D12: 579866 | K12: 33 | O12: =SUM(B12:B23) -> 92139511 | V12: Jul-Sep 2017 | W12: =SUM(B51:B53) -> 27598323
A13: 41760 | B13: =SUM(C13:D13) -> 7986119 | C13: 7273483 | D13: 712636 | K13: 30 | O13: =SUM(B13:B24) -> 92026556 | V13: Jul-Sep 2018 | W13: =SUM(B63:B65) -> 26978153
A14: 41791 | B14: =SUM(C14:D14) -> 8876152 | C14: 7988748 | D14: 887404 | K14: 31 | O14: =SUM(B14:B25) -> 92230972 | V14: Jul-Sep 2019 | W14: =SUM(B75:B77) -> 27880497
A15: 41821 | B15: =SUM(C15:D15) -> 9340526 | C15: 8442124 | D15: 898402 | K15: 31 | N15: Jul 14 - Jun 15 | O15: =SUM(B15:B26) -> 93067207 | Q15: 93067207 | R15: Base Year | V15: Jul-Sep 2020 | W15: =SUM(B87:B89) -> 26237832
A16: 41852 | B16: =SUM(C16:D16) -> 8583907 | C16: 7793747 | D16: 790160 | K16: 29 | O16: =SUM(B16:B27) -> 92560708 | Q16: 92560708 | R16: =(O16-$O$15)/$O$15 -> -0.0054422929 | V16: Jul-Sep 2021 | W16: =SUM(B99:B101) -> 27528189
A17: 41883 | B17: =SUM(C17:D17) -> 10023872 | C17: 9097454 | D17: 926418 | K17: 32 | O17: =SUM(B17:B28) -> 92658683 | Q17: 92658683 | R17: =(O17-$O$15)/$O$15 -> -0.004389559
A18: 41913 | B18: =SUM(C18:D18) -> 8035429 | C18: 7401930 | D18: 633499 | K18: 30 | O18: =SUM(B18:B29) -> 92589207 | Q18: 92589207 | R18: =(O18-$O$15)/$O$15 -> -0.0051360733
A19: 41944 | B19: =SUM(C19:D19) -> 6858052 | C19: 6380644 | D19: 477408 | K19: 29 | O19: =SUM(B19:B30) -> 92906500 | Q19: 92906500 | R19: =(O19-$O$15)/$O$15 -> -0.0017267844
A20: 41974 | B20: =SUM(C20:D20) -> 6405579 | C20: 5826218 | D20: 579361 | K20: 32 | O20: =SUM(B20:B31) -> 94099443 | Q20: 94099443 | R20: =(O20-$O$15)/$O$15 -> 0.011091297
A21: 42005 | B21: =SUM(C21:D21) -> 6037637 | C21: 5490107 | D21: 547530 | K21: 31 | L21: =SUM(K21:K32) -> 365 | O21: =SUM(B21:B32) -> 94187317 | Q21: 94187317 | R21: =(O21-$O$15)/$O$15 -> 0.012035496
A22: 42036 | B22: =SUM(C22:D22) -> 5695515 | C22: 5208132 | D22: 487383 | K22: 28 | O22: =SUM(B22:B33) -> 94394903 | Q22: 94394903 | R22: =(O22-$O$15)/$O$15 -> 0.014265992
A23: 42064 | B23: =SUM(C23:D23) -> 6808373 | C23: 6247610 | D23: 560763 | K23: 31 | O23: =SUM(B23:B34) -> 95166272 | Q23: 95166272 | R23: =(O23-$O$15)/$O$15 -> 0.022554292
A24: 42095 | B24: =SUM(C24:D24) -> 7375395 | C24: 6824851 | D24: 550544 | K24: 31 | O24: =SUM(B24:B35) -> 94971369 | Q24: 94971369 | R24: =(O24-$O$15)/$O$15 -> 0.020460075
A25: 42125 | B25: =SUM(C25:D25) -> 8190535 | C25: 7514422 | D25: 676113 | K25: 29 | O25: =SUM(B25:B36) -> 95180695 | Q25: 95180695 | R25: =(O25-$O$15)/$O$15 -> 0.022709266
A26: 42156 | B26: =SUM(C26:D26) -> 9712387 | C26: 8760382 | D26: 952005 | K26: 32 | O26: =SUM(B26:B37) -> 95720512 | Q26: 95720512 | R26: =(O26-$O$15)/$O$15 -> 0.028509559
A27: 42186 | B27: =SUM(C27:D27) -> 8834027 | C27: 8050260 | D27: 783767 | K27: 30 | N27: Jul 15 - Jun 16 | O27: =SUM(B27:B38) -> 95800070 | Q27: 95800070 | R27: =(O27-$O$15)/$O$15 -> 0.029364403
A28: 42217 | B28: =SUM(C28:D28) -> 8681882 | C28: 7874121 | D28: 807761 | K28: 29 | O28: =SUM(B28:B39) -> 96134757 | Q28: 96134757 | R28: =(O28-$O$15)/$O$15 -> 0.032960589
A29: 42248 | B29: =SUM(C29:D29) -> 9954396 | C29: 9106237 | D29: 848159 | K29: 33 | O29: =SUM(B29:B40) -> 96947485 | Q29: 96947485 | R29: =(O29-$O$15)/$O$15 -> 0.041693289
A30: 42278 | B30: =SUM(C30:D30) -> 8352722 | C30: 7743078 | D30: 609644 | K30: 30 | O30: =SUM(B30:B41) -> 96474873 | Q30: 96474873 | R30: =(O30-$O$15)/$O$15 -> 0.03661511
A31: 42309 | B31: =SUM(C31:D31) -> 8050995 | C31: 7497518 | D31: 553477 | K31: 31 | O31: =SUM(B31:B42) -> 96161212 | Q31: 96161212 | R31: =(O31-$O$15)/$O$15 -> 0.033244846
A32: 42339 | B32: =SUM(C32:D32) -> 6493453 | C32: 6007766 | D32: 485687 | K32: 30 | O32: =SUM(B32:B43) -> 96368281 | Q32: 96368281 | R32: =(O32-$O$15)/$O$15 -> 0.035469787
A33: 42370 | B33: =SUM(C33:D33) -> 6245223 | C33: 5677744 | D33: 567479 | K33: 30 | L33: =SUM(K33:K44) -> 366 | O33: =SUM(B33:B44) -> 96342853 | Q33: 96342853 | R33: =(O33-$O$15)/$O$15 -> 0.035196565
A34: 42401 | B34: =SUM(C34:D34) -> 6466884 | C34: 5859419 | D34: 607465 | K34: 31 | O34: =SUM(B34:B45) -> 95623203 | Q34: 95623203 | R34: =(O34-$O$15)/$O$15 -> 0.027463981
A35: 42430 | B35: =SUM(C35:D35) -> 6613470 | C35: 6048978 | D35: 564492 | K35: 30 | O35: =SUM(B35:B46) -> 95982844 | Q35: 95982844 | R35: =(O35-$O$15)/$O$15 -> 0.031328296
A36: 42461 | B36: =SUM(C36:D36) -> 7584721 | C36: 7011981 | D36: 572740 | K36: 30 | O36: =SUM(B36:B47) -> 96253205 | Q36: 96253205 | R36: =(O36-$O$15)/$O$15 -> 0.034233304
A37: 42491 | B37: =SUM(C37:D37) -> 8730352 | C37: 8032494 | D37: 697858 | K37: 31 | O37: =SUM(B37:B48) -> 95356819 | Q37: 95356819 | R37: =(O37-$O$15)/$O$15 -> 0.024601705
A38: 42522 | B38: =SUM(C38:D38) -> 9791945 | C38: 8895567 | D38: 896378 | K38: 31 | O38: =SUM(B38:B49) -> 94764032 | Q38: 94764032 | R38: =(O38-$O$15)/$O$15 -> 0.018232254
A39: 42552 | B39: =SUM(C39:D39) -> 9168714 | C39: 8357768 | D39: 810946 | K39: 29 | N39: Jul 16 - Jun 17 | O39: =SUM(B39:B50) -> 94486358 | Q39: 94486358 | R39: =(O39-$O$15)/$O$15 -> 0.015248669
A40: 42583 | B40: =SUM(C40:D40) -> 9494610 | C40: 8718549 | D40: 776061 | K40: 32 | O40: =SUM(B40:B51) -> 93560730 | Q40: 93560730 | R40: =(O40-$O$15)/$O$15 -> 0.0053028668
...

Sheet Breakdown
A1: HKUST Electricity Consumption (kWh)
A2: # Remark : The electricity consumption by category should not be double counted.
A3: Period | B3: CLP Total | C3: Main Academic Buildings & Other Public Facilities | D3: EC (ALL) | E3: CYT | F3: Shaw Auditorium | G3: APCF (R/F Zone L) | H3: New Data Centre (2/F Zone L) | I3: Main Chiller Plant | J3: LSKBB | K3: IAS | L3: Conference Lodge | M3: LSK Hostel | N3: LSK Chiller Plant | O3: WWT | P3: Water Sport Centre | Q3: SISC | R3: HPC5 | S3: RB2 | T3: IB | U3: SRD (UG10-13) | V3: TA-B | W3: GGT | X3: Student Housing UG1-UG9, PG1-PG2 | Y3: Staff Quarters & Commercial Outlets | Z3: Commercial Outlets | AA3: Staff Quarters | AB3: Combined Chiller Plants | AD3: TKO JC Hall | AE3: EC 3/F Data Centre (Elect) | AF3: SRD (Chiller kWhe) | AG3: IB (Chiller kWhe) | AH3: BMW EV Charger kWh (LG7 & WWT) | AI3: Corner Stone EV Charger kWh | AJ3: TEST BUILDING 1 | AL3: TEST BUILDING 2
A4: 41640 | B4: ='CLP Tariff'!B9 -> 5938547 | C4: =B4-SUM(D4:Y4) -> 3924710 | D4: 190811 | E4: 41274 | F4: 0 | G4: 0 | H4: 0 | I4: 500427 | J4: 205345 | K4: 44678 | L4: 0 | M4: 0 | N4: 48446 | O4: 59654 | P4: 0 | Q4: 0 | T4: 0 | U4: 0 | W4: 0 | X4: 361571 | Y4: ='CLP Tariff'!D9 -> 561631 | Z4: ='Commercial & Quarter'!K72 -> 229909 | AA4: =Y4-Z4 -> 331722 | AB4: =I4+N4 -> 548873 | AD4: 0 | AE4: 0 | AF4: 0 | AG4: 0
A5: 41671 | B5: ='CLP Tariff'!B10 -> 5888877 | C5: =B5-SUM(D5:Y5) -> 3565612 | D5: 252064 | E5: 28315 | F5: 0 | G5: 0 | H5: 0 | I5: 502155 | J5: 290449 | K5: 56447 | L5: 0 | M5: 0 | N5: 47613 | O5: 47313 | P5: 0 | Q5: 0 | T5: 0 | U5: 0 | W5: 0 | X5: 504993 | Y5: ='CLP Tariff'!D10 -> 593916 | Z5: ='Commercial & Quarter'!L72 -> 220164 | AA5: =Y5-Z5 -> 373752 | AB5: =I5+N5 -> 549768 | AD5: 0 | AE5: 0 | AF5: 0 | AG5: 0
A6: 41699 | B6: ='CLP Tariff'!B11 -> 6018786 | C6: =B6-SUM(D6:Y6) -> 3680694 | D6: 185065 | E6: 40257 | F6: 0 | G6: 0 | H6: 0 | I6: 754593 | J6: 182485 | K6: 34491 | L6: 0 | M6: 0 | N6: 46854 | O6: 43566 | P6: 0 | Q6: 0 | T6: 0 | U6: 0 | W6: 0 | X6: 511265 | Y6: ='CLP Tariff'!D11 -> 539516 | Z6: ='Commercial & Quarter'!M72 -> 247766 | AA6: =Y6-Z6 -> 291750 | AB6: =I6+N6 -> 801447 | AD6: 0 | AE6: 0 | AF6: 0 | AG6: 0
A7: 41730 | B7: ='CLP Tariff'!B12 -> 7488350 | C7: =B7-SUM(D7:Y7) -> 4459315 | D7: 203049 | E7: 56946 | F7: 0 | G7: 0 | H7: 0 | I7: 1100944 | J7: 213938 | K7: 46284 | L7: 0 | M7: 0 | N7: 141417 | O7: 73814 | P7: 0 | Q7: 0 | T7: 0 | U7: 0 | W7: 0 | X7: 612777 | Y7: ='CLP Tariff'!D12 -> 579866 | Z7: ='Commercial & Quarter'!N72 -> 295835 | AA7: =Y7-Z7 -> 284031 | AB7: =I7+N7 -> 1242361 | AD7: 0 | AE7: 0 | AF7: 0 | AG7: 0
A8: 41760 | B8: ='CLP Tariff'!B13 -> 7986119 | C8: =B8-SUM(D8:Y8) -> 3816523 | D8: 345876 | E8: 89452 | F8: 0 | G8: 0 | H8: 0 | I8: 1749797 | J8: 224043 | K8: 103456 | L8: 0 | M8: 0 | N8: 170062 | O8: 82044 | P8: 0 | Q8: 0 | T8: 0 | U8: 0 | W8: 0 | X8: 692230 | Y8: ='CLP Tariff'!D13 -> 712636 | Z8: ='Commercial & Quarter'!O72 -> 281303 | AA8: =Y8-Z8 -> 431333 | AB8: =I8+N8 -> 1919859 | AD8: 0 | AE8: 0 | AF8: 0 | AG8: 0
A9: 41791 | B9: ='CLP Tariff'!B14 -> 8876152 | C9: =B9-SUM(D9:Y9) -> 4173507 | D9: 250379 | E9: 92936 | F9: 0 | G9: 0 | H9: 0 | I9: 2204099 | J9: 250703 | K9: 71494 | L9: 0 | M9: 0 | N9: 273139 | O9: 97780 | P9: 0 | Q9: 0 | T9: 0 | U9: 0 | W9: 0 | X9: 574711 | Y9: ='CLP Tariff'!D14 -> 887404 | Z9: ='Commercial & Quarter'!P72 -> 266840 | AA9: =Y9-Z9 -> 620564 | AB9: =I9+N9 -> 2477238 | AD9: 0 | AE9: 0 | AF9: 0 | AG9: 0
A10: 41821 | B10: ='CLP Tariff'!B15 -> 9340526 | C10: =B10-SUM(D10:Y10) -> 4361073 | D10: 221804 | E10: 97729 | F10: 0 | G10: 0 | H10: 0 | I10: 2443732 | J10: 225313 | K10: 48903 | L10: 0 | M10: 0 | N10: 246402 | O10: 109439 | P10: 0 | Q10: 0 | T10: 0 | U10: 0 | W10: 0 | X10: 687729 | Y10: ='CLP Tariff'!D15 -> 898402 | Z10: ='Commercial & Quarter'!Q72 -> 274134 | AA10: =Y10-Z10 -> 624268 | AB10: =I10+N10 -> 2690134 | AD10: 0 | AE10: 0 | AF10: 0 | AG10: 0
A11: 41852 | B11: ='CLP Tariff'!B16 -> 8583907 | C11: =B11-SUM(D11:Y11) -> 3673176 | D11: 228122 | E11: 146934 | F11: 0 | G11: 0 | H11: 0 | I11: 2460070 | J11: 232978 | K11: 53454 | L11: 0 | M11: 0 | N11: 275655 | O11: 99316 | P11: 0 | Q11: 0 | T11: 0 | U11: 0 | W11: 0 | X11: 624042 | Y11: ='CLP Tariff'!D16 -> 790160 | Z11: ='Commercial & Quarter'!R72 -> 264880 | AA11: =Y11-Z11 -> 525280 | AB11: =I11+N11 -> 2735725 | AD11: 0 | AE11: 0 | AF11: 0 | AG11: 0
A12: 41883 | B12: ='CLP Tariff'!B17 -> 10023872 | C12: =B12-SUM(D12:Y12) -> 4469625 | D12: 276014 | E12: 132812 | F12: 0 | G12: 0 | H12: 0 | I12: 2515785 | J12: 269881 | K12: 79871 | L12: 0 | M12: 0 | N12: 307475 | O12: 89352 | P12: 0 | Q12: 0 | T12: 0 | U12: 0 | W12: 0 | X12: 956639 | Y12: ='CLP Tariff'!D17 -> 926418 | Z12: ='Commercial & Quarter'!S72 -> 311968 | AA12: =Y12-Z12 -> 614450 | AB12: =I12+N12 -> 2823260 | AD12: 0 | AE12: 0 | AF12: 0 | AG12: 0
A13: 41913 | B13: ='CLP Tariff'!B18 -> 8035429 | C13: =B13-SUM(D13:Y13) -> 4049333 | D13: 203926 | E13: 145929 | F13: 0 | G13: 0 | H13: 0 | I13: 1763222 | J13: 248622 | K13: 39903 | L13: 0 | M13: 0 | N13: 153059 | O13: 89097 | P13: 0 | Q13: 0 | T13: 0 | U13: 0 | W13: 0 | X13: 708839 | Y13: ='CLP Tariff'!D18 -> 633499 | Z13: ='Commercial & Quarter'!T72 -> 297097 | AA13: =Y13-Z13 -> 336402 | AB13: =I13+N13 -> 1916281 | AD13: 0 | AE13: 0 | AF13: 0 | AG13: 0
A14: 41944 | B14: ='CLP Tariff'!B19 -> 6858052 | C14: =B14-SUM(D14:Y14) -> 3872340 | D14: 214292 | E14: 95091 | F14: 0 | G14: 0 | H14: 0 | I14: 1119362 | J14: 267023 | K14: 50426 | L14: 0 | M14: 0 | N14: 153510 | O14: 76299 | P14: 0 | Q14: 0 | T14: 0 | U14: 0 | W14: 0 | X14: 532301 | Y14: ='CLP Tariff'!D19 -> 477408 | Z14: ='Commercial & Quarter'!U72 -> 276436 | AA14: =Y14-Z14 -> 200972 | AB14: =I14+N14 -> 1272872 | AD14: 0 | AE14: 0 | AF14: 0 | AG14: 0
A15: 41974 | B15: ='CLP Tariff'!B20 -> 6405579 | C15: =B15-SUM(D15:Y15) -> 3982954 | D15: 253212 | E15: 117318 | F15: 0 | G15: 0 | H15: 0 | I15: 548769 | J15: 246466 | K15: 71670 | L15: 0 | M15: 0 | N15: 67209 | O15: 55450 | P15: 0 | Q15: 0 | T15: 0 | U15: 0 | W15: 0 | X15: 483170 | Y15: ='CLP Tariff'!D20 -> 579361 | Z15: ='Commercial & Quarter'!V72 -> 281511 | AA15: =Y15-Z15 -> 297850 | AB15: =I15+N15 -> 615978 | AD15: 0 | AE15: 0 | AF15: 0 | AG15: 0
A16: 42005 | B16: ='CLP Tariff'!B21 -> 6037637 | C16: =B16-SUM(D16:Y16) -> 3908677 | D16: 195665 | E16: 99565 | F16: 0 | G16: 0 | H16: 0 | I16: 544141 | J16: 233787 | K16: 42271 | L16: 0 | M16: 0 | N16: 40400 | O16: 48517 | P16: 0 | Q16: 0 | T16: 0 | U16: 0 | W16: 0 | X16: 377084 | Y16: ='CLP Tariff'!D21 -> 547530 | Z16: ='Commercial & Quarter'!W72 -> 262207 | AA16: =Y16-Z16 -> 285323 | AB16: =I16+N16 -> 584541 | AD16: 0 | AE16: 0 | AF16: 0 | AG16: 0
A17: 42036 | B17: ='CLP Tariff'!B22 -> 5695515 | C17: =B17-SUM(D17:Y17) -> 3489436 | D17: 224244 | E17: 114195 | F17: 0 | G17: 0 | H17: 0 | I17: 515349 | J17: 235819 | K17: 56423 | L17: 0 | M17: 0 | N17: 52158 | O17: 49783 | P17: 0 | Q17: 0 | T17: 0 | U17: 0 | W17: 0 | X17: 470725 | Y17: ='CLP Tariff'!D22 -> 487383 | Z17: ='Commercial & Quarter'!X72 -> 247789 | AA17: =Y17-Z17 -> 239594 | AB17: =I17+N17 -> 567507 | AD17: 0 | AE17: 0 | AF17: 0 | AG17: 0
A18: 42064 | B18: ='CLP Tariff'!B23 -> 6808373 | C18: =B18-SUM(D18:Y18) -> 4118527 | D18: 218508 | E18: 125033 | F18: 0 | G18: 0 | H18: 0 | I18: 822631 | J18: 265435 | K18: 53193 | L18: 0 | M18: 0 | N18: 66141 | O18: 74567 | P18: 0 | Q18: 0 | T18: 0 | U18: 0 | W18: 0 | X18: 503575 | Y18: ='CLP Tariff'!D23 -> 560763 | Z18: ='Commercial & Quarter'!Y72 -> 302505 | AA18: =Y18-Z18 -> 258258 | AB18: =I18+N18 -> 888772 | AD18: 0 | AE18: 0 | AF18: 0 | AG18: 0
A19: 42095 | B19: ='CLP Tariff'!B24 -> 7375395 | C19: =B19-SUM(D19:Y19) -> 4123782 | D19: 205482 | E19: 172615 | F19: 0 | G19: 0 | H19: 0 | I19: 1230463 | J19: 237697 | K19: 54391 | L19: 0 | M19: 0 | N19: 110064 | O19: 97242 | P19: 0 | Q19: 0 | T19: 0 | U19: 0 | W19: 0 | X19: 593115 | Y19: ='CLP Tariff'!D24 -> 550544 | Z19: ='Commercial & Quarter'!Z72 -> 303017 | AA19: =Y19-Z19 -> 247527 | AB19: =I19+N19 -> 1340527 | AD19: 0 | AE19: 0 | AF19: 0 | AG19: 0
A20: 42125 | B20: ='CLP Tariff'!B25 -> 8190535 | C20: =B20-SUM(D20:Y20) -> 3697825 | D20: 220809 | E20: 203655 | F20: 0 | G20: 0 | H20: 0 | I20: 2094261 | J20: 212132 | K20: 49088 | L20: 0 | M20: 0 | N20: 186711 | O20: 72445 | P20: 0 | Q20: 0 | T20: 0 | U20: 0 | W20: 0 | X20: 777496 | Y20: ='CLP Tariff'!D25 -> 676113 | Z20: ='Commercial & Quarter'!AA72 -> 293556 | AA20: =Y20-Z20 -> 382557 | AB20: =I20+N20 -> 2280972 | AD20: 0 | AE20: 0 | AF20: 0 | AG20: 0
A21: 42156 | B21: ='CLP Tariff'!B26 -> 9712387 | C21: =B21-SUM(D21:Y21) -> 4414578 | D21: 239524 | E21: 194738 | F21: 0 | G21: 0 | H21: 0 | I21: 2544609 | J21: 280980 | K21: 129946 | L21: 0 | M21: 0 | N21: 255852 | O21: 111119 | P21: 0 | Q21: 0 | T21: 0 | U21: 0 | W21: 0 | X21: 589036 | Y21: ='CLP Tariff'!D26 -> 952005 | Z21: ='Commercial & Quarter'!AB72 -> 302993 | AA21: =Y21-Z21 -> 649012 | AB21: =I21+N21 -> 2800461 | AD21: 0 | AE21: 0 | AF21: 0 | AG21: 0
A22: 42186 | B22: ='CLP Tariff'!B27 -> 8834027 | C22: =B22-SUM(D22:Y22) -> 3840527 | D22: 216309 | E22: 224950 | F22: 0 | G22: 0 | H22: 0 | I22: 2507656 | J22: 217810 | K22: 77610 | L22: 25769 | M22: 0 | N22: 212246 | O22: 90399 | P22: 0 | Q22: 0 | T22: 0 | U22: 0 | W22: 0 | X22: 636984 | Y22: ='CLP Tariff'!D27 -> 783767 | Z22: ='Commercial & Quarter'!AC72 -> 277550 | AA22: =Y22-Z22 -> 506217 | AB22: =I22+N22 -> 2719902 | AD22: 0 | AE22: 0 | AF22: 0 | AG22: 0
A23: 42217 | B23: ='CLP Tariff'!B28 -> 8681882 | C23: =B23-SUM(D23:Y23) -> 3336768 | D23: 260880 | E23: 198008 | F23: 0 | G23: 0 | H23: 0 | I23: 2564183 | J23: 268478 | K23: 71460 | L23: 134760 | M23: 0 | N23: 252328 | O23: 107250 | P23: 0 | Q23: 0 | T23: 0 | U23: 0 | W23: 0 | X23: 680006 | Y23: ='CLP Tariff'!D28 -> 807761 | Z23: ='Commercial & Quarter'!AD72 -> 278196 | AA23: =Y23-Z23 -> 529565 | AB23: =I23+N23 -> 2816511 | AD23: 0 | AE23: 0 | AF23: 0 | AG23: 0
A24: 42248 | B24: ='CLP Tariff'!B29 -> 9954396 | C24: =B24-SUM(D24:Y24) -> 4633259 | D24: 234187 | E24: 228598 | F24: 0 | G24: 0 | H24: 0 | I24: 2359914 | J24: 263450 | K24: 56020 | L24: 135352 | M24: 0 | N24: 222957 | O24: 84622 | P24: 0 | Q24: 0 | T24: 0 | U24: 0 | W24: 0 | X24: 887878 | Y24: ='CLP Tariff'!D29 -> 848159 | Z24: ='Commercial & Quarter'!AE72 -> 338617 | AA24: =Y24-Z24 -> 509542 | AB24: =I24+N24 -> 2582871 | AD24: 0 | AE24: 0 | AF24: 0 | AG24: 0
A25: 42278 | B25: ='CLP Tariff'!B30 -> 8352722 | C25: =B25-SUM(D25:Y25) -> 4009560 | D25: 212948 | E25: 252642 | F25: 0 | G25: 0 | H25: 0 | I25: 1873529 | J25: 247453 | K25: 52867 | L25: 131511 | M25: 0 | N25: 179183 | O25: 77686 | P25: 0 | Q25: 0 | T25: 0 | U25: 0 | W25: 0 | X25: 705699 | Y25: ='CLP Tariff'!D30 -> 609644 | Z25: ='Commercial & Quarter'!AF72 -> 309456 | AA25: =Y25-Z25 -> 300188 | AB25: =I25+N25 -> 2052712 | AD25: 0 | AE25: 0 | AF25: 0 | AG25: 0
A26: 42309 | B26: ='CLP Tariff'!B31 -> 8050995 | C26: =B26-SUM(D26:Y26) -> 4200888 | D26: 229804 | E26: 304409 | F26: 0 | G26: 0 | H26: 0 | I26: 1464223 | J26: 278579 | K26: 45990 | L26: 146949 | M26: 0 | N26: 173483 | O26: 65641 | P26: 0 | Q26: 0 | T26: 0 | U26: 0 | W26: 0 | X26: 587552 | Y26: ='CLP Tariff'!D31 -> 553477 | Z26: ='Commercial & Quarter'!AG72 -> 318937 | AA26: =Y26-Z26 -> 234540 | AB26: =I26+N26 -> 1637706 | AD26: 0 | AE26: 0 | AF26: 0 | AG26: 0
A27: 42339 | B27: ='CLP Tariff'!B32 -> 6493453 | C27: =B27-SUM(D27:Y27) -> 3614603 | D27: 290741 | E27: 333130 | F27: 0 | G27: 0 | H27: 0 | I27: 690904 | J27: 285264 | K27: 65483 | L27: 103943 | M27: 0 | N27: 90243 | O27: 79484 | P27: 0 | Q27: 0 | T27: 0 | U27: 0 | W27: 0 | X27: 453971 | Y27: ='CLP Tariff'!D32 -> 485687 | Z27: ='Commercial & Quarter'!AH72 -> 282739 | AA27: =Y27-Z27 -> 202948 | AB27: =I27+N27 -> 781147 | AD27: 0 | AE27: 0 | AF27: 0 | AG27: 0
A28: 42370 | B28: ='CLP Tariff'!B33 -> 6245223 | C28: =B28-SUM(D28:Y28) -> 3831763 | D28: 139048 | E28: 277210 | F28: 0 | G28: 0 | H28: 0 | I28: 516685 | J28: 242251 | K28: 42075 | L28: 122690 | M28: 0 | N28: 50559 | O28: 78005 | P28: 0 | Q28: 0 | T28: 0 | U28: 0 | W28: 0 | X28: 377458 | Y28: ='CLP Tariff'!D33 -> 567479 | Z28: ='Commercial & Quarter'!AI72 -> 259474 | AA28: =Y28-Z28 -> 308005 | AB28: =I28+N28 -> 567244 | AD28: 0 | AE28: 0 | AF28: 0 | AG28: 0
A29: 42401 | B29: ='CLP Tariff'!B34 -> 6466884 | C29: =B29-SUM(D29:Y29) -> 3779412 | D29: 298078 | E29: 343984 | F29: 0 | G29: 0 | H29: 0 | I29: 406263 | J29: 294647 | K29: 45944 | L29: 117026 | M29: 0 | N29: 48852 | O29: 37408 | P29: 0 | Q29: 0 | T29: 0 | U29: 0 | W29: 0 | X29: 487805 | Y29: ='CLP Tariff'!D34 -> 607465 | Z29: ='Commercial & Quarter'!AJ72 -> 272882 | AA29: =Y29-Z29 -> 334583 | AB29: =I29+N29 -> 455115 | AD29: 0 | AE29: 0 | AF29: 0 | AG29: 0
A30: 42430 | B30: ='CLP Tariff'!B35 -> 6613470 | C30: =B30-SUM(D30:Y30) -> 3972874 | D30: 204423 | E30: 276509 | F30: 0 | G30: 0 | H30: 0 | I30: 553500 | J30: 237417 | K30: 58069 | L30: 81220 | M30: 0 | N30: 57570 | O30: 60129 | P30: 0 | Q30: 0 | T30: 0 | U30: 0 | W30: 0 | X30: 547267 | Y30: ='CLP Tariff'!D35 -> 564492 | Z30: ='Commercial & Quarter'!AK72 -> 289377 | AA30: =Y30-Z30 -> 275115 | AB30: =I30+N30 -> 611070 | AD30: 0 | AE30: 0 | AF30: 0 | AG30: 0
A31: 42461 | B31: ='CLP Tariff'!B36 -> 7584721 | C31: =B31-SUM(D31:Y31) -> 4018970 | D31: 215813 | E31: 296537 | F31: 0 | G31: 0 | H31: 0 | I31: 1283919 | J31: 271059 | K31: 49082 | L31: 118821 | M31: 0 | N31: 135895 | O31: 63059 | P31: 0 | Q31: 0 | T31: 0 | U31: 0 | W31: 0 | X31: 558826 | Y31: ='CLP Tariff'!D36 -> 572740 | Z31: ='Commercial & Quarter'!AL72 -> 308674 | AA31: =Y31-Z31 -> 264066 | AB31: =I31+N31 -> 1419814 | AD31: 0 | AE31: 0 | AF31: 0 | AG31: 0
A32: 42491 | B32: ='CLP Tariff'!B37 -> 8730352 | C32: =B32-SUM(D32:Y32) -> 3773707 | D32: 263078 | E32: 405553 | F32: 0 | G32: 0 | H32: 0 | I32: 1964154 | J32: 277527 | K32: 71026 | L32: 204440 | M32: 0 | N32: 241532 | O32: 102506 | P32: 0 | Q32: 0 | T32: 0 | U32: 0 | W32: 0 | X32: 728971 | Y32: ='CLP Tariff'!D37 -> 697858 | Z32: ='Commercial & Quarter'!AM72 -> 320173 | AA32: =Y32-Z32 -> 377685 | AB32: =I32+N32 -> 2205686 | AD32: 0 | AE32: 0 | AF32: 0 | AG32: 0
A33: 42522 | B33: ='CLP Tariff'!B38 -> 9791945 | C33: =B33-SUM(D33:Y33) -> 4046518 | D33: 274465 | E33: 503779 | F33: 0 | G33: 0 | H33: 0 | I33: 2672172 | J33: 247180 | K33: 48151 | L33: 162606 | M33: 0 | N33: 204368 | O33: 87014 | P33: 0 | Q33: 0 | T33: 0 | U33: 0 | W33: 0 | X33: 649314 | Y33: ='CLP Tariff'!D38 -> 896378 | Z33: ='Commercial & Quarter'!AN72 -> 301989 | AA33: =Y33-Z33 -> 594389 | AB33: =I33+N33 -> 2876540 | AD33: 0 | AE33: 0 | AF33: 0 | AG33: 0
A34: 42552 | B34: ='CLP Tariff'!B39 -> 9168714 | C34: =B34-SUM(D34:Y34) -> 3655670 | D34: 171816 | E34: 346896 | F34: 0 | G34: 0 | H34: 0 | I34: 2679758 | J34: 241218 | K34: 56433 | L34: 183048 | M34: 0 | N34: 231512 | O34: 89776 | P34: 0 | Q34: 0 | T34: 0 | U34: 0 | W34: 0 | X34: 701641 | Y34: ='CLP Tariff'!D39 -> 810946 | Z34: ='Commercial & Quarter'!AO72 -> 285596 | AA34: =Y34-Z34 -> 525350 | AB34: =I34+N34 -> 2911270 | AD34: 0 | AE34: 0 | AF34: 0 | AG34: 0
A35: 42583 | B35: ='CLP Tariff'!B40 -> 9494610 | C35: =B35-SUM(D35:Y35) -> 3873088 | D35: 267163 | E35: 515939 | F35: 0 | G35: 0 | H35: 0 | I35: 2450437 | J35: 296189 | K35: 70401 | L35: 187636 | M35: 0 | N35: 253271 | O35: 98211 | P35: 0 | Q35: 0 | T35: 0 | U35: 0 | W35: 0 | X35: 706214 | Y35: ='CLP Tariff'!D40 -> 776061 | Z35: ='Commercial & Quarter'!AP72 -> 313559 | AA35: =Y35-Z35 -> 462502 | AB35: =I35+N35 -> 2703708 | AD35: 0 | AE35: 0 | AF35: 0 | AG35: 0
A36: 42614 | B36: ='CLP Tariff'!B41 -> 9481784 | C36: =B36-SUM(D36:Y36) -> 4228883 | D36: 247221 | E36: 400844 | F36: 0 | G36: 0 | H36: 0 | I36: 2315953 | J36: 260266 | K36: 58317 | L36: 155062 | M36: 0 | N36: 205585 | O36: 86794 | P36: 0 | Q36: 0 | T36: 0 | U36: 0 | W36: 0 | X36: 809354 | Y36: ='CLP Tariff'!D41 -> 713505 | Z36: ='Commercial & Quarter'!AQ72 -> 333329 | AA36: =Y36-Z36 -> 380176 | AB36: =I36+N36 -> 2521538 | AD36: 0 | AE36: 0 | AF36: 0 | AG36: 0
A37: 42644 | B37: ='CLP Tariff'!B42 -> 8039061 | C37: =B37-SUM(D37:Y37) -> 3320287 | D37: 244358 | E37: 301842 | F37: 0 | G37: 0 | H37: 0 | I37: 2065366 | J37: 252484 | K37: 59236 | L37: 143725 | M37: 0 | N37: 191013 | O37: 67897 | P37: 0 | Q37: 0 | T37: 0 | U37: 0 | W37: 0 | X37: 828064 | Y37: ='CLP Tariff'!D42 -> 564789 | Z37: ='Commercial & Quarter'!AR72 -> 295061 | AA37: =Y37-Z37 -> 269728 | AB37: =I37+N37 -> 2256379 | AD37: 0 | AE37: 0 | AF37: 0 | AG37: 0
A38: 42675 | B38: ='CLP Tariff'!B43 -> 8258064 | C38: =B38-SUM(D38:Y38) -> 4405647 | D38: 269652 | E38: 561953 | F38: 0 | G38: 0 | H38: 0 | I38: 1190430 | J38: 309914 | K38: 74983 | L38: 137244 | M38: 0 | N38: 161352 | O38: 68587 | P38: 0 | Q38: 0 | T38: 0 | U38: 0 | W38: 0 | X38: 531267 | Y38: ='CLP Tariff'!D43 -> 547035 | Z38: ='Commercial & Quarter'!AS72 -> 351124 | AA38: =Y38-Z38 -> 195911 | AB38: =I38+N38 -> 1351782 | AD38: 0 | AE38: 0 | AF38: 0 | AG38: 0
A39: 42705 | B39: ='CLP Tariff'!B44 -> 6468025 | C39: =B39-SUM(D39:Y39) -> 3593398 | D39: 239740 | E39: 398980 | F39: 0 | G39: 0 | H39: 0 | I39: 761395 | J39: 261691 | K39: 59003 | L39: 108647 | M39: 0 | N39: 86111 | O39: 51534 | P39: 0 | Q39: 0 | T39: 0 | U39: 0 | W39: 0 | X39: 463216 | Y39: ='CLP Tariff'!D44 -> 444310 | Z39: ='Commercial & Quarter'!AT72 -> 303998 | AA39: =Y39-Z39 -> 140312 | AB39: =I39+N39 -> 847506 | AD39: 0 | AE39: 0 | AF39: 0 | AG39: 0
A40: 42736 | B40: ='CLP Tariff'!B45 -> 5525573 | C40: =B40-SUM(D40:Y40) -> 3099589 | D40: 214435 | E40: 370050 | F40: 0 | G40: 0 | H40: 0 | I40: 618875 | J40: 233523 | K40: 46449 | L40: 99324 | M40: 0 | N40: 55694 | O40: 41576 | P40: 0 | Q40: 0 | T40: 0 | U40: 0 | W40: 0 | X40: 337896 | Y40: ='CLP Tariff'!D45 -> 408162 | Z40: ='Commercial & Quarter'!AU72 -> 243772 | AA40: =Y40-Z40 -> 164390 | AB40: =I40+N40 -> 674569 | AD40: 0 | AE40: 0 | AF40: 0 | AG40: 0
...

Sheet Commercial & Quarter
B1: Summary of Commercial Outlets Meters
FR2: Reading | FS2: Reading | FT2: Reading | FU2: Reading | FV2: Reading
A3: CLP Deduction meter no. | B3: Meter number | C3: Old meter number | D3: Company | E3: 2013/7 | F3: 2013/8 | G3: 2013/9 | H3: 2013/10 | I3: 2013/11 | J3: 2013/12 | K3: 2014/1 | L3: 2014/2 | M3: 2014/3 | N3: 2014/4 | O3: 2014/5 | P3: 2014/6 | Q3: 2014/07 | R3: 2014/08 | S3: 2014/09 | T3: 2014/10 | U3: 2014/11 | V3: 2014/12 | W3: 2015/01 | X3: 2015/02 | Y3: 2015/03 | Z3: 2015/04 | AA3: 2015/05 | AB3: 2015/06 | AC3: 2015/07 | AD3: 2015/08 | AE3: 2015/09 | AF3: 2015/10 | AG3: 2015/11 | AH3: 2015/12 | AI3: 2016/01 | AJ3: 2016/02 | AK3: 2016/03 | AL3: 2016/04 | AM3: 2016/05 | AN3: 2016/06 | AO3: 2016/07 | AP3: 2016/08 | AQ3: 2016/09 | AR3: 2016/10 | AS3: 2016/11 | AT3: 2016/12 | AU3: 2017/01 | AV3: 2017/02 | AW3: 2017/03 | AX3: 2017/04 | AY3: 2017/05 | AZ3: 2017/06 | BA3: 2017/07 | BB3: 2017/08 | BC3: 2017/09 | BD3: 2017/10 | BE3: 2017/11 | BF3: 2017/12 | BG3: 2018/1 | BH3: 2018/2 | BI3: 2018/3 | BJ3: 2018/4 | BK3: 2018/5 | BL3: 2018/6 | BM3: 2018/7 | BN3: 2018/8 | BO3: 2018/9 | BP3: 2018/10 | BQ3: 2018/11 | BR3: 2018/12 | BS3: 2019/1 | BT3: 2019/2 | BU3: 2019/3 | BV3: 2019/4 | BW3: 2019/5 | BX3: 2019/6 | BY3: 2019/7 | BZ3: 2019/8 | CA3: 2019/9 | CB3: 2019/10 | CC3: 2019/11 | CD3: 2019/12 | CE3: 2020/01 | CF3: 2020/02 | CG3: 2020/03 | CH3: 2020/04 | CI3: 2020/05 | CJ3: 2020/06 | CK3: 2020/07 | CL3: 2020/08 | CM3: 2020/09 | CN3: 2020/10 | CO3: 2020/11 | CP3: 2020/12 | CQ3: 2021/01 | CR3: 2021/02 | CS3: 2021/03 | CT3: 2021/04 | CU3: 2021/05 | CV3: 2021/06 | CW3: 2021/07 | CX3: 2021/08 | CY3: 2021/09 | CZ3: 2021/10 | DA3: 2021/11 | DB3: 2021/12 | DC3: 44562 | DD3: 44593 | DE3: 44621 | DF3: 44652 | DG3: 44682 | DH3: 44713 | DI3: 44743 | DJ3: 44774 | DK3: 44805 | DL3: 44835 | DM3: 44866 | DN3: 44896 | DO3: 44927 | DP3: 44958 | DQ3: 44986 | DR3: 45017 | DS3: 45047 | DT3: 45078 | DU3: 45108 | DV3: 45139 | DW3: 45170 | DX3: 45200 | DY3: 45231 | DZ3: 45261 | EA3: 45292 | EB3: 45323 | EC3: 45352 | ED3: 45383 | EE3: 45413 | EF3: 45444 | EG3: 45474 | EH3: 45505 | EI3: 45536 | EJ3: 45566 | EK3: 45597 | EL3: 45627 | EM3: 45658 | EN3: 45689 | EO3: 45717 | EP3: 45748 | EQ3: 45778 | ER3: 45809 | ES3: 45839 | ET3: 45870 | EU3: 45901 | EV3: 45931 | EW3: 45962 | EX3: 45992 | EY3: 46023 | EZ3: 46054 | FA3: 46082 | FB3: 46113 | FC3: Company | FE3: 45383 | FF3: 45352 | FG3: 45323 | FH3: 45292 | FI3: 45261 | FJ3: 45231 | FK3: 45200 | FL3: 45170 | FM3: 45139 | FN3: 45108 | FO3: 45078 | FP3: 45047 | FQ3: 45017 | FR3: 44986 | FS3: 44958 | FT3: 44927 | FU3: 44896 | FV3: 44866
B4: 1052830 | D4: Seafront Snake Shop (UG6 G/F Kitchen) | E4: 5080 | F4: 5330 | G4: 7990 | H4: 7890 | I4: 8680 | J4: 6700 | K4: 5370 | L4: 7320 | M4: 7990 | N4: 8430 | O4: 8150 | P4: 5000 | Q4: 5370 | R4: 5160 | S4: 8050 | T4: 7900 | U4: 8170 | V4: 7180 | W4: 5780 | X4: 6260 | Y4: 8600 | Z4: 7850 | AA4: 7830 | AB4: 5420 | AC4: 4770 | AD4: 5020 | AE4: 7520 | AF4: 8290 | AG4: 8770 | AH4: 6690 | AI4: 5710 | AJ4: 6670 | AK4: 7600 | AL4: 8300 | AM4: 8090 | AN4: 4970 | AO4: 4710 | AP4: 4790 | AQ4: 7220 | AR4: 7030 | AS4: 9150 | AT4: 6480 | AU4: 4580 | AV4: 7640 | AW4: 8480 | AX4: 6580 | AY4: 7670 | AZ4: 5210 | BA4: 4690 | BB4: 5460 | BC4: 7510 | BD4: 7580 | BE4: 8230 | BF4: 6290 | BG4: 5230 | BH4: 5250 | BI4: 7450 | BJ4: 7700 | BK4: 7640 | BL4: 4460 | BM4: 3700 | BN4: 0 | BO4: 0 | BP4: 0 | BQ4: 0 | BR4: 0 | BS4: 0 | BT4: 0 | BU4: 0 | BV4: 0 | BW4: 0 | BX4: 0 | BY4: 0 | BZ4: 0 | CA4: 0 | CB4: 0 | CC4: 0 | CD4: 0 | CE4: 0 | CF4: 0 | CG4: 0 | CH4: 0 | CI4: 0 | CJ4: 0 | CK4: 0 | CL4: 0 | CM4: 0 | CN4: 0 | CO4: 0 | CP4: 0 | CQ4: 0 | CR4: 0 | CS4: 0 | CT4: 0 | CU4: 0 | CV4: 0 | CW4: 0 | CX4: 0 | CY4: 0 | CZ4: 0 | DA4: 0 | DB4: 0 | DC4: 0 | DD4: 0 | DE4: 0 | DF4: - | DG4: - | DH4: - | DI4: - | DJ4: - | DK4: - | DL4: - | DM4: - | DN4: - | DO4: - | DP4: - | DQ4: - | DR4: - | DS4: - | DT4: - | DU4: - | DV4: - | DW4: - | DX4: - | DY4: - | DZ4: - | EA4: - | EB4: - | EC4: - | ED4: - | EE4: - | EF4: - | EG4: - | FC4: Seafront Snake Shop (UG6 G/F Kitchen) | FE4: - | FF4: - | FG4: - | FH4: - | FI4: - | FJ4: - | FK4: - | FL4: - | FM4: - | FN4: - | FO4: - | FP4: - | FQ4: - | FR4: - | FS4: - | FT4: - | FU4: - | FV4: -
B5: 3151919 | D5: CARRIES TECHNOLOGY LIMITED | E5: 2270 | F5: 2112 | G5: 2115 | H5: 2018 | I5: 1905 | J5: 1817 | K5: 1810 | L5: 1643 | M5: 1646 | N5: 1990 | O5: 1727 | P5: 1593 | Q5: 1682 | R5: 1770 | S5: 2048 | T5: 1798 | U5: 1587 | V5: 1672 | W5: 1679 | X5: 1524 | Y5: 1728 | Z5: 1774 | AA5: 1695 | AB5: 1890 | AC5: 1760 | AD5: 1700 | AE5: 1914 | AF5: 1730 | AG5: 1649 | AH5: 1534 | AI5: 1598 | AJ5: 1648 | AK5: 1569 | AL5: 1580 | AM5: 1671 | AN5: 1737 | AO5: 1633 | AP5: 1778 | AQ5: 1760 | AR5: 1638 | AS5: 1881 | AT5: 1695 | AU5: 1284 | AV5: 1449 | AW5: 1451 | AX5: 1570 | AY5: 1783 | AZ5: 1809 | BA5: 1323 | BB5: 1235 | BC5: 1325 | BD5: 733 | BE5: 0 | BF5: 9 | BG5: 0 | BH5: 0 | BI5: 0 | BJ5: 0 | BK5: 0 | BL5: 0 | BM5: 0 | BN5: 0 | BO5: 0 | BP5: 0 | BQ5: 0 | BR5: 0 | BS5: 0 | BT5: 0 | BU5: 0 | BV5: 0 | BW5: 0 | BX5: 0 | BY5: 0 | BZ5: 0 | CA5: 0 | CB5: 0 | CC5: 0 | CD5: 0 | CE5: 0 | CF5: 0 | CG5: 0 | CH5: 0 | CI5: 0 | CJ5: 0 | CK5: 0 | CL5: 0 | CM5: 0 | CN5: 0 | CO5: 0 | CP5: 0 | CQ5: 0 | CR5: 0 | CS5: 0 | CT5: 0 | CU5: 0 | CV5: 0 | CW5: 0 | CX5: 0 | CY5: 0 | CZ5: 0 | DA5: 0 | DB5: 0 | DC5: 0 | DD5: 0 | DE5: 0 | DF5: - | DG5: - | DH5: - | DI5: - | DJ5: - | DK5: - | DL5: - | DM5: - | DN5: - | DO5: - | DP5: - | DQ5: - | DR5: - | DS5: - | DT5: - | DU5: - | DV5: - | DW5: - | DX5: - | DY5: - | DZ5: - | EA5: - | EB5: - | EC5: - | ED5: - | EE5: - | EF5: - | EG5: - | FC5: CARRIES TECHNOLOGY LIMITED | FE5: - | FF5: - | FG5: - | FH5: - | FI5: - | FJ5: - | FK5: - | FL5: - | FM5: - | FN5: - | FO5: - | FP5: - | FQ5: - | FR5: - | FS5: - | FT5: - | FU5: - | FV5: -
B6: 3575460 | D6: LG7 Hair Salon (R001) | E6: 1706 | F6: 1706 | G6: 1713 | H6: 1803 | I6: 1913 | J6: 1865 | K6: 1965 | L6: 1560 | M6: 1847 | N6: 2024 | O6: 1935 | P6: 1791 | Q6: 1768 | R6: 1675 | S6: 1847 | T6: 1753 | U6: 1838 | V6: 1996 | W6: 1839 | X6: 1798 | Y6: 2096 | Z6: 1972 | AA6: 1878 | AB6: 1904 | AC6: 1622 | AD6: 1620 | AE6: 1977 | AF6: 1847 | AG6: 2059 | AH6: 1724 | AI6: 1737 | AJ6: 1786 | AK6: 1927 | AL6: 2011 | AM6: 2049 | AN6: 1882 | AO6: 1589 | AP6: 1767 | AQ6: 1781 | AR6: 1568 | AS6: 1977 | AT6: 1707 | AU6: 1581 | AV6: 1774 | AW6: 2085 | AX6: 1425 | AY6: 50 | AZ6: 0 | BA6: 0 | BB6: 0 | BC6: 0 | BD6: 0 | BE6: 0 | BF6: 0 | BG6: 0 | BH6: 0 | BI6: 0 | BJ6: 0 | BK6: 0 | BL6: 0 | BM6: 0 | BN6: 0 | BO6: 0 | BP6: 0 | BQ6: 0 | BR6: 0 | BS6: 0 | BT6: 0 | BU6: 0 | BV6: 0 | BW6: 0 | BX6: 0 | BY6: 0 | BZ6: 0 | CA6: 0 | CB6: 0 | CC6: 0 | CD6: 0 | CE6: 0 | CF6: 0 | CG6: 0 | CH6: 0 | CI6: 0 | CJ6: 0 | CK6: 0 | CL6: 0 | CM6: 0 | CN6: 0 | CO6: 0 | CP6: 0 | CQ6: 0 | CR6: 0 | CS6: 0 | CT6: 0 | CU6: 0 | CV6: 0 | CW6: 0 | CX6: 0 | CY6: 0 | CZ6: 0 | DA6: 0 | DB6: 0 | DC6: 0 | DD6: 0 | DE6: 0 | DF6: - | DG6: - | DH6: - | DI6: - | DJ6: - | DK6: - | DL6: - | DM6: - | DN6: - | DO6: - | DP6: - | DQ6: - | DR6: - | DS6: - | DT6: - | DU6: - | DV6: - | DW6: - | DX6: - | DY6: - | DZ6: - | EA6: - | EB6: - | EC6: - | ED6: - | EE6: - | EF6: - | EG6: - | FC6: LG7 Hair Salon (R001) | FE6: - | FF6: - | FG6: - | FH6: - | FI6: - | FJ6: - | FK6: - | FL6: - | FM6: - | FN6: - | FO6: - | FP6: - | FQ6: - | FR6: - | FS6: - | FT6: - | FU6: - | FV6: -
B7: 3598064 | D7: CLP POWER HONG KONG LIMITED | E7: 0 | F7: 0 | G7: 0 | H7: 0 | I7: 0 | J7: 0 | K7: 0 | L7: 0 | M7: 0 | N7: 0 | O7: 0 | P7: 0 | Q7: 0 | R7: 0 | S7: 0 | T7: 0 | U7: 0 | V7: 0 | W7: 0 | X7: 0 | Y7: 0 | Z7: 0 | AA7: 0 | AB7: 0 | AC7: 0 | AD7: 0 | AE7: 0 | AF7: 0 | AG7: 0 | AH7: 0 | AI7: 0 | AJ7: 0 | AK7: 0 | AL7: 0 | AM7: 0 | AN7: 0 | AO7: 0 | AP7: 0 | AQ7: 0 | AR7: 0 | AS7: 0 | AT7: 0 | AU7: 0 | AV7: 0 | AW7: 0 | AX7: 0 | AY7: 0 | AZ7: 0 | BA7: 0 | BB7: 0 | BC7: 0 | BD7: 0 | BE7: 0 | BF7: 0 | BG7: 0 | BH7: 0 | BI7: 0 | BJ7: 0 | BK7: 0 | BL7: 0 | BM7: 0 | BN7: 0 | BO7: 0 | BP7: 0 | BQ7: 0 | BR7: 0 | BS7: 0 | BT7: 0 | BU7: 0 | BV7: 0 | BW7: 0 | BX7: 0 | BY7: 0 | BZ7: 0 | CA7: 0 | CB7: 0 | CC7: 0 | CD7: 0 | CE7: 0 | CF7: 0 | CG7: 0 | CH7: 0 | CI7: 0 | CJ7: 0 | CK7: 0 | CL7: 0 | CM7: 0 | CN7: 0 | CO7: 0 | CP7: 0 | CQ7: 0 | CR7: 0 | CS7: 0 | CT7: 0 | CU7: 0 | CV7: 0 | CW7: 0 | CX7: 0 | CY7: 0 | CZ7: 0 | DA7: 0 | DB7: 0 | DC7: 0 | DD7: 0 | DE7: 0 | DF7: - | DG7: - | DH7: - | DI7: - | DJ7: - | DK7: - | DL7: - | DM7: - | DN7: - | DO7: - | DP7: - | DQ7: - | DR7: - | DS7: - | DT7: - | DU7: - | DV7: - | DW7: - | DX7: - | DY7: - | DZ7: - | EA7: - | EB7: - | EC7: - | ED7: - | EE7: - | EF7: - | EG7: - | FC7: CLP POWER HONG KONG LIMITED | FE7: - | FF7: - | FG7: - | FH7: - | FI7: - | FJ7: - | FK7: - | FL7: - | FM7: - | FN7: - | FO7: - | FP7: - | FQ7: - | FR7: - | FS7: - | FT7: - | FU7: - | FV7: -
B8: 5643252 | D8: HONG KONG CABLE TELEVISION LIMITED | E8: 158 | F8: 152 | G8: 153 | H8: 148 | I8: 147 | J8: 151 | K8: 159 | L8: 142 | M8: 136 | N8: 162 | O8: 147 | P8: 152 | Q8: 152 | R8: 143 | S8: 157 | T8: 145 | U8: 141 | V8: 154 | W8: 150 | X8: 135 | Y8: 149 | Z8: 147 | AA8: 139 | AB8: 153 | AC8: 144 | AD8: 139 | AE8: 157 | AF8: 144 | AG8: 148 | AH8: 143 | AI8: 142 | AJ8: 148 | AK8: 143 | AL8: 144 | AM8: 149 | AN8: 149 | AO8: 140 | AP8: 155 | AQ8: 4 | AR8: 0 | AS8: 0 | AT8: 0 | AU8: 0 | AV8: 0 | AW8: 0 | AX8: 0 | AY8: 0 | AZ8: 0 | BA8: 0 | BB8: 0 | BC8: 0 | BD8: 0 | BE8: 0 | BF8: 0 | BG8: 0 | BH8: 0 | BI8: 0 | BJ8: 0 | BK8: 0 | BL8: 0 | BM8: 0 | BN8: 0 | BO8: 0 | BP8: 0 | BQ8: 0 | BR8: 0 | BS8: 0 | BT8: 0 | BU8: 0 | BV8: 0 | BW8: 0 | BX8: 0 | BY8: 0 | BZ8: 0 | CA8: 0 | CB8: 0 | CC8: 0 | CD8: 0 | CE8: 0 | CF8: 0 | CG8: 0 | CH8: 0 | CI8: 0 | CJ8: 0 | CK8: 0 | CL8: 0 | CM8: 0 | CN8: 0 | CO8: 0 | CP8: 0 | CQ8: 0 | CR8: 0 | CS8: 0 | CT8: 0 | CU8: 0 | CV8: 0 | CW8: 0 | CX8: 0 | CY8: 0 | CZ8: 0 | DA8: 0 | DB8: 0 | DC8: 0 | DD8: 0 | DE8: 0 | DF8: - | DG8: - | DH8: - | DI8: - | DJ8: - | DK8: - | DL8: - | DM8: - | DN8: - | DO8: - | DP8: - | DQ8: - | DR8: - | DS8: - | DT8: - | DU8: - | DV8: - | DW8: - | DX8: - | DY8: - | DZ8: - | EA8: - | EB8: - | EC8: - | ED8: - | EE8: - | EF8: - | EG8: - | FC8: HONG KONG CABLE TELEVISION LIMITED | FE8: - | FF8: - | FG8: - | FH8: - | FI8: - | FJ8: - | FK8: - | FL8: - | FM8: - | FN8: - | FO8: - | FP8: - | FQ8: - | FR8: - | FS8: - | FT8: - | FU8: - | FV8: -
B9: 9093561 | D9: LG7 Gold Rice Bowl | E9: 25670 | F9: 26775 | G9: 29064 | H9: 28645 | I9: 28773 | J9: 26735 | K9: 22754 | L9: 22440 | M9: 25876 | N9: 29005 | O9: 27403 | P9: 22733 | Q9: 25401 | R9: 25640 | S9: 29369 | T9: 27584 | U9: 25681 | V9: 25745 | W9: 21333 | X9: 20380 | Y9: 27859 | Z9: 27441 | AA9: 26387 | AB9: 26469 | AC9: 23790 | AD9: 25727 | AE9: 30899 | AF9: 28204 | AG9: 29000 | AH9: 25759 | AI9: 20248 | AJ9: 22066 | AK9: 25219 | AL9: 27139 | AM9: 27758 | AN9: 24324 | AO9: 22687 | AP9: 27034 | AQ9: 30308 | AR9: 26713 | AS9: 31878 | AT9: 25565 | AU9: 17713 | AV9: 25615 | AW9: 29080 | AX9: 26006 | AY9: 32381 | AZ9: 28089 | BA9: 30318 | BB9: 33524 | BC9: 34142 | BD9: 32722 | BE9: 33310 | BF9: 27600 | BG9: 24827 | BH9: 22685 | BI9: 29264 | BJ9: 31121 | BK9: 30337 | BL9: 26229 | BM9: 27092 | BN9: 28718 | BO9: 28046 | BP9: 31729 | BQ9: 30820 | BR9: 24169 | BS9: 25817 | BT9: 20322 | BU9: 23839 | BV9: 24265 | BW9: 22207 | BX9: 2054 | BY9: 0 | BZ9: 0 | CA9: 0 | CB9: 0 | CC9: 0 | CD9: 0 | CE9: 0 | CF9: 0 | CG9: 0 | CH9: 0 | CI9: 0 | CJ9: 0 | CK9: 0 | CL9: 0 | CM9: 0 | CN9: 0 | CO9: 0 | CP9: 0 | CQ9: 0 | CR9: 0 | CS9: 0 | CT9: 0 | CU9: 0 | CV9: 0 | CW9: 0 | CX9: 0 | CY9: 0 | CZ9: 0 | DA9: 0 | DB9: 0 | DC9: 0 | DD9: 0 | DE9: 0 | DF9: - | DG9: - | DH9: - | DI9: - | DJ9: - | DK9: - | DL9: - | DM9: - | DN9: - | DO9: - | DP9: - | DQ9: - | DR9: - | DS9: - | DT9: - | DU9: - | DV9: - | DW9: - | DX9: - | DY9: - | DZ9: - | EA9: - | EB9: - | EC9: - | ED9: - | EE9: - | EF9: - | EG9: - | FC9: LG7 Gold Rice Bowl | FE9: - | FF9: - | FG9: - | FH9: - | FI9: - | FJ9: - | FK9: - | FL9: - | FM9: - | FN9: - | FO9: - | FP9: - | FQ9: - | FR9: - | FS9: - | FT9: - | FU9: - | FV9: -
B10: 9097369 | D10: LG7 Gold Rice Bowl | E10: 3881 | F10: 3762 | G10: 4655 | H10: 4585 | I10: 4379 | J10: 3453 | K10: 2932 | L10: 3270 | M10: 3909 | N10: 4460 | O10: 4419 | P10: 3074 | Q10: 3577 | R10: 3968 | S10: 5201 | T10: 4911 | U10: 4972 | V10: 4784 | W10: 3739 | X10: 3794 | Y10: 5330 | Z10: 5145 | AA10: 5033 | AB10: 4515 | AC10: 4177 | AD10: 4596 | AE10: 5800 | AF10: 5422 | AG10: 5234 | AH10: 4178 | AI10: 3531 | AJ10: 3893 | AK10: 4432 | AL10: 4606 | AM10: 4654 | AN10: 4027 | AO10: 3746 | AP10: 4470 | AQ10: 5277 | AR10: 4599 | AS10: 5602 | AT10: 4586 | AU10: 3212 | AV10: 4229 | AW10: 4700 | AX10: 4410 | AY10: 4994 | AZ10: 4306 | BA10: 4919 | BB10: 5415 | BC10: 6720 | BD10: 6492 | BE10: 6708 | BF10: 5142 | BG10: 4515 | BH10: 4118 | BI10: 5493 | BJ10: 5916 | BK10: 5882 | BL10: 4656 | BM10: 4831 | BN10: 5353 | BO10: 5489 | BP10: 6348 | BQ10: 6353 | BR10: 4919 | BS10: 4419 | BT10: 4029 | BU10: 5245 | BV10: 5599 | BW10: 5450 | BX10: 124 | BY10: 0 | BZ10: 0 | CA10: 0 | CB10: 0 | CC10: 0 | CD10: 0 | CE10: 0 | CF10: 0 | CG10: 0 | CH10: 0 | CI10: 0 | CJ10: 0 | CK10: 0 | CL10: 0 | CM10: 0 | CN10: 0 | CO10: 0 | CP10: 0 | CQ10: 0 | CR10: 0 | CS10: 0 | CT10: 0 | CU10: 0 | CV10: 0 | CW10: 0 | CX10: 0 | CY10: 0 | CZ10: 0 | DA10: 0 | DB10: 0 | DC10: 0 | DD10: 0 | DE10: 0 | DF10: - | DG10: - | DH10: - | DI10: - | DJ10: - | DK10: - | DL10: - | DM10: - | DN10: - | DO10: - | DP10: - | DQ10: - | DR10: - | DS10: - | DT10: - | DU10: - | DV10: - | DW10: - | DX10: - | DY10: - | DZ10: - | EA10: - | EB10: - | EC10: - | ED10: - | EE10: - | EF10: - | EG10: - | FC10: LG7 Gold Rice Bowl | FE10: - | FF10: - | FG10: - | FH10: - | FI10: - | FJ10: - | FK10: - | FL10: - | FM10: - | FN10: - | FO10: - | FP10: - | FQ10: - | FR10: - | FS10: - | FT10: - | FU10: - | FV10: -
B11: 9094041 | D11: LG7 Malino | E11: 13583 | F11: 13745 | G11: 14542 | H11: 14065 | I11: 13858 | J11: 12940 | K11: 12056 | L11: 12020 | M11: 14257 | N11: 13444 | O11: 14180 | P11: 13089 | Q11: 12781 | R11: 12232 | S11: 13563 | T11: 12620 | U11: 12621 | V11: 12165 | W11: 12048 | X11: 11473 | Y11: 14357 | Z11: 12485 | AA11: 12128 | AB11: 12336 | AC11: 11491 | AD11: 11302 | AE11: 13756 | AF11: 13654 | AG11: 16256 | AH11: 13405 | AI11: 10489 | AJ11: 12421 | AK11: 13456 | AL11: 14924 | AM11: 14169 | AN11: 13839 | AO11: 13377 | AP11: 13636 | AQ11: 15451 | AR11: 13140 | AS11: 16478 | AT11: 12577 | AU11: 11780 | AV11: 14075 | AW11: 15334 | AX11: 12382 | AY11: 14886 | AZ11: 14026 | BA11: 12275 | BB11: 14989 | BC11: 15219 | BD11: 14170 | BE11: 15841 | BF11: 12774 | BG11: 13908 | BH11: 11487 | BI11: 13615 | BJ11: 13370 | BK11: 13650 | BL11: 10244 | BM11: 10888 | BN11: 11997 | BO11: 12507 | BP11: 14968 | BQ11: 15247 | BR11: 11326 | BS11: 13449 | BT11: 11917 | BU11: 13404 | BV11: 12623 | BW11: 5248 | BX11: 241 | BY11: 0 | BZ11: 0 | CA11: 0 | CB11: 0 | CC11: 0 | CD11: 0 | CE11: 0 | CF11: 0 | CG11: 0 | CH11: 0 | CI11: 0 | CJ11: 0 | CK11: 0 | CL11: 0 | CM11: 0 | CN11: 0 | CO11: 0 | CP11: 0 | CQ11: 0 | CR11: 0 | CS11: 0 | CT11: 0 | CU11: 0 | CV11: 0 | CW11: 0 | CX11: 0 | CY11: 0 | CZ11: 0 | DA11: 0 | DB11: 0 | DC11: 0 | DD11: 0 | DE11: 0 | DF11: - | DG11: - | DH11: - | DI11: - | DJ11: - | DK11: - | DL11: - | DM11: - | DN11: - | DO11: - | DP11: - | DQ11: - | DR11: - | DS11: - | DT11: - | DU11: - | DV11: - | DW11: - | DX11: - | DY11: - | DZ11: - | EA11: - | EB11: - | EC11: - | ED11: - | EE11: - | EF11: - | EG11: - | FC11: LG7 Malino | FE11: - | FF11: - | FG11: - | FH11: - | FI11: - | FJ11: - | FK11: - | FL11: - | FM11: - | FN11: - | FO11: - | FP11: - | FQ11: - | FR11: - | FS11: - | FT11: - | FU11: - | FV11: -
B12: 9094509 | D12: LG7 Asia Pacific | E12: 38273 | F12: 35530 | G12: 38396 | H12: 38094 | I12: 39017 | J12: 35469 | K12: 33170 | L12: 29053 | M12: 34127 | N12: 37650 | O12: 36319 | P12: 34063 | Q12: 34234 | R12: 32634 | S12: 37810 | T12: 35621 | U12: 31388 | V12: 33642 | W12: 31027 | X12: 26193 | Y12: 34229 | Z12: 34667 | AA12: 33702 | AB12: 34705 | AC12: 30974 | AD12: 30174 | AE12: 36551 | AF12: 33113 | AG12: 34270 | AH12: 31967 | AI12: 29821 | AJ12: 28958 | AK12: 34071 | AL12: 35786 | AM12: 36564 | AN12: 34061 | AO12: 32426 | AP12: 34088 | AQ12: 34752 | AR12: 30962 | AS12: 36290 | AT12: 31493 | AU12: 26421 | AV12: 29897 | AW12: 32560 | AX12: 28559 | AY12: 31721 | AZ12: 31603 | BA12: 29134 | BB12: 34268 | BC12: 34365 | BD12: 34148 | BE12: 34158 | BF12: 30665 | BG12: 32483 | BH12: 27458 | BI12: 31655 | BJ12: 33780 | BK12: 32679 | BL12: 27976 | BM12: 29578 | BN12: 30451 | BO12: 28675 | BP12: 33594 | BQ12: 31977 | BR12: 27715 | BS12: 29749 | BT12: 25712 | BU12: 29818 | BV12: 32474 | BW12: 30135 | BX12: 2665 | BY12: 0 | BZ12: 0 | CA12: 0 | CB12: 0 | CC12: 0 | CD12: 0 | CE12: 0 | CF12: 0 | CG12: 0 | CH12: 0 | CI12: 0 | CJ12: 0 | CK12: 0 | CL12: 0 | CM12: 0 | CN12: 0 | CO12: 0 | CP12: 0 | CQ12: 0 | CR12: 0 | CS12: 0 | CT12: 0 | CU12: 0 | CV12: 0 | CW12: 0 | CX12: 0 | CY12: 0 | CZ12: 0 | DA12: 0 | DB12: 0 | DC12: 0 | DD12: 0 | DE12: 0 | DF12: - | DG12: - | DH12: - | DI12: - | DJ12: - | DK12: - | DL12: - | DM12: - | DN12: - | DO12: - | DP12: - | DQ12: - | DR12: - | DS12: - | DT12: - | DU12: - | DV12: - | DW12: - | DX12: - | DY12: - | DZ12: - | EA12: - | EB12: - | EC12: - | ED12: - | EE12: - | EF12: - | EG12: - | FC12: LG7 Asia Pacific | FE12: - | FF12: - | FG12: - | FH12: - | FI12: - | FJ12: - | FK12: - | FL12: - | FM12: - | FN12: - | FO12: - | FP12: - | FQ12: - | FR12: - | FS12: - | FT12: - | FU12: - | FV12: -
B13: 9097356 | D13: LG7 Asia Pacific | E13: 3987 | F13: 3764 | G13: 4060 | H13: 3990 | I13: 4015 | J13: 3891 | K13: 3772 | L13: 3162 | M13: 3627 | N13: 4172 | O13: 3854 | P13: 3643 | Q13: 3716 | R13: 3487 | S13: 4044 | T13: 3825 | U13: 3795 | V13: 3967 | W13: 3798 | X13: 3030 | Y13: 4008 | Z13: 3983 | AA13: 3734 | AB13: 3828 | AC13: 3506 | AD13: 3618 | AE13: 4133 | AF13: 3698 | AG13: 3857 | AH13: 3633 | AI13: 3426 | AJ13: 3357 | AK13: 3684 | AL13: 3716 | AM13: 3869 | AN13: 3623 | AO13: 3356 | AP13: 3659 | AQ13: 3931 | AR13: 3477 | AS13: 4102 | AT13: 3562 | AU13: 3083 | AV13: 3525 | AW13: 3810 | AX13: 3198 | AY13: 3359 | AZ13: 2753 | BA13: 2552 | BB13: 3077 | BC13: 3415 | BD13: 3512 | BE13: 3540 | BF13: 3125 | BG13: 3090 | BH13: 2680 | BI13: 3208 | BJ13: 3390 | BK13: 3123 | BL13: 2782 | BM13: 2959 | BN13: 3060 | BO13: 2832 | BP13: 3221 | BQ13: 3208 | BR13: 2746 | BS13: 2876 | BT13: 2573 | BU13: 2984 | BV13: 3117 | BW13: 1947 | BX13: 161 | BY13: 0 | BZ13: 0 | CA13: 0 | CB13: 0 | CC13: 0 | CD13: 0 | CE13: 0 | CF13: 0 | CG13: 0 | CH13: 0 | CI13: 0 | CJ13: 0 | CK13: 0 | CL13: 0 | CM13: 0 | CN13: 0 | CO13: 0 | CP13: 0 | CQ13: 0 | CR13: 0 | CS13: 0 | CT13: 0 | CU13: 0 | CV13: 0 | CW13: 0 | CX13: 0 | CY13: 0 | CZ13: 0 | DA13: 0 | DB13: 0 | DC13: 0 | DD13: 0 | DE13: 0 | DF13: - | DG13: - | DH13: - | DI13: - | DJ13: - | DK13: - | DL13: - | DM13: - | DN13: - | DO13: - | DP13: - | DQ13: - | DR13: - | DS13: - | DT13: - | DU13: - | DV13: - | DW13: - | DX13: - | DY13: - | DZ13: - | EA13: - | EB13: - | EC13: - | ED13: - | EE13: - | EF13: - | EG13: - | FC13: LG7 Asia Pacific | FE13: - | FF13: - | FG13: - | FH13: - | FI13: - | FJ13: - | FK13: - | FL13: - | FM13: - | FN13: - | FO13: - | FP13: - | FQ13: - | FR13: - | FS13: - | FT13: - | FU13: - | FV13: -
B14: 7629952 | C14: 3006113 | D14: SNACK KITCHEN G/F,M-RISE P/GRADUATE HOST, HK U OF SCI & TECHNY | E14: 2879 | F14: 2805 | G14: 2783 | H14: 2171 | I14: 1338 | J14: 930 | K14: 1015 | L14: 971 | M14: 871 | N14: 1345 | O14: 2001 | P14: 3063 | Q14: 3262 | R14: 2956 | S14: 3055 | T14: 2045 | U14: 1288 | V14: 1055 | W14: 1060 | X14: 924 | Y14: 1099 | Z14: 1497 | AA14: 2676 | AB14: 3498 | AC14: 3141 | AD14: 3102 | AE14: 3386 | AF14: 2224 | AG14: 1552 | AH14: 1104 | AI14: 1025 | AJ14: 1019 | AK14: 1055 | AL14: 1469 | AM14: 2258 | AN14: 3073 | AO14: 3046 | AP14: 3299 | AQ14: 2934 | AR14: 2387 | AS14: 1680 | AT14: 1283 | AU14: 1087 | AV14: 1263 | AW14: 1257 | AX14: 1556 | AY14: 2252 | AZ14: 2913 | BA14: 2677 | BB14: 3236 | BC14: 2860 | BD14: 2366 | BE14: 1171 | BF14: 968 | BG14: 1036 | BH14: 893 | BI14: 792 | BJ14: 1094 | BK14: 2133 | BL14: 2340 | BM14: 2567 | BN14: 2501 | BO14: 2123 | BP14: 1239 | BQ14: 740 | BR14: 596 | BS14: 638 | BT14: 623 | BU14: 643 | BV14: 1205 | BW14: 1565 | BX14: 2005 | BY14: 2227 | BZ14: 2162 | CA14: 1945 | CB14: 1596 | CC14: 668 | CD14: 569 | CE14: 564 | CF14: 519 | CG14: 620 | CH14: 666 | CI14: 1217 | CJ14: 1711 | CK14: 1779 | CL14: 1551 | CM14: 1731 | CN14: 1087 | CO14: 711 | CP14: 593 | CQ14: 549 | CR14: 562 | CS14: 423 | CT14: 634 | CU14: 1271 | CV14: 1265 | CW14: 1496 | CX14: 1477 | CY14: =1085+377 -> 1462 | CZ14: 838 | DA14: 274 | DB14: 208 | DC14: 207 | DD14: 409 | DE14: 219 | DF14: 437 | DG14: 946 | DH14: 1358 | DI14: 1355 | DJ14: 1540 | DK14: 1387 | DL14: 860 | DM14: 616 | DN14: =FU14-FV14 -> 181 | DO14: =FT14-FU14 -> 207 | DP14: =FS14-FT14 -> 157 | DQ14: =FR14-FS14 -> 233 | DR14: =FQ14-FR14 -> 434 | DS14: =FP14-FQ14 -> 820 | DT14: =FO14-FP14 -> 1262 | DU14: =FN14-FO14 -> 1229 | DV14: =FM14-FN14 -> 1483 | DW14: =FL14-FM14 -> 1370 | DX14: =FK14-FL14 -> 1116 | DY14: =FJ14-FK14 -> 508 | DZ14: =FI14-FJ14 -> 197 | EA14: =FH14-FI14 -> 272 | EB14: =FG14-FH14 -> 227 | EC14: =FF14-FG14 -> 458 | ED14: =FE14-FF14 -> 1106 | EX14: 261 | EY14: 244 | EZ14: 233 | FA14: 455 | FB14: 737 | FC14: SNACK KITCHEN G/F,M-RISE P/GRADUATE HOST, HK U OF SCI & TECHNY | FE14: 23011 | FF14: 21905 | FG14: 21447 | FH14: 21220 | FI14: 20948 | FJ14: 20751 | FK14: 20243 | FL14: 19127 | FM14: 17757 | FN14: 16274 | FO14: 15045 | FP14: 13783 | FQ14: 12963 | FR14: 12529 | FS14: 12296 | FT14: 12139 | FU14: 11932 | FV14: 11751
B15: 7631007 | C15: 3054632 | D15: Commercial Press | E15: 4028 | F15: 4110 | G15: 4400 | H15: 3898 | I15: 4044 | J15: 3645 | K15: 3935 | L15: 3690 | M15: 3617 | N15: 303 | O15: 0 | P15: 0 | Q15: 0 | R15: 0 | S15: 0 | T15: 50 | U15: 297 | V15: 1066 | W15: 2058 | X15: 1744 | Y15: 2226 | Z15: 1886 | AA15: 1831 | AB15: 2037 | AC15: 1955 | AD15: 1993 | AE15: 2265 | AF15: 1925 | AG15: 2076 | AH15: 1904 | AI15: 1897 | AJ15: 1832 | AK15: 1813 | AL15: 1974 | AM15: 1894 | AN15: 2057 | AO15: 1937 | AP15: 2137 | AQ15: 2334 | AR15: 1802 | AS15: 2172 | AT15: 1866 | AU15: 1688 | AV15: 1988 | AW15: 1992 | AX15: 1582 | AY15: 1888 | AZ15: 2016 | BA15: 1718 | BB15: 2100 | BC15: 2061 | BD15: 1777 | BE15: 1941 | BF15: 1649 | BG15: 1934 | BH15: 1753 | BI15: 1901 | BJ15: 1681 | BK15: 1789 | BL15: 1771 | BM15: 1839 | BN15: 1966 | BO15: 1837 | BP15: 1863 | BQ15: 1880 | BR15: 1679 | BS15: 1976 | BT15: 1684 | BU15: 1791 | BV15: 1700 | BW15: 1814 | BX15: 1795 | BY15: 1968 | BZ15: 1919 | CA15: 1883 | CB15: 1681 | CC15: 1370 | CD15: 1739 | CE15: 1488 | CF15: 1572 | CG15: 1809 | CH15: 1592 | CI15: 1653 | CJ15: 1712 | CK15: 1658 | CL15: 1597 | CM15: 1938 | CN15: 1465 | CO15: 1777 | CP15: 1674 | CQ15: 1628 | CR15: 1432 | CS15: 1807 | CT15: 1562 | CU15: 1648 | CV15: 1522 | CW15: 1639 | CX15: 1650 | CY15: =843+1058 -> 1901 | CZ15: 1414 | DA15: 1739 | DB15: 1618 | DC15: 1620 | DD15: 1492 | DE15: 1442 | DF15: 1315 | DG15: 1424 | DH15: 1526 | DI15: 1413 | DJ15: 1575 | DK15: 1750 | DL15: 1504 | DM15: 1325 | DN15: =FU15-FV15 -> 2909 | DO15: =FT15-FU15 -> 1288 | DP15: =FS15-FT15 -> 1315 | DQ15: =FR15-FS15 -> 2058 | DR15: =FQ15-FR15 -> 1948 | DS15: =FP15-FQ15 -> 2964 | DT15: =FO15-FP15 -> 256 | DU15: Removed | DV15: Removed | DW15: Removed | DX15: Removed | DY15: Removed | DZ15: Removed | EA15: Removed | EB15: Removed | EC15: Removed | ED15: Removed | EE15: Removed | EF15: Removed | EG15: Removed | EH15: Removed | EI15: Removed | EJ15: Removed | EK15: Removed | EL15: Removed | EM15: Removed | EN15: Removed | EO15: Removed | EP15: Removed | EQ15: Removed | ER15: Removed | ES15: Removed | ET15: Removed | EU15: Removed | EV15: Removed | EW15: Removed | EX15: Removed | EY15: Removed | EZ15: Removed | FA15: Removed | FB15: Removed | FC15: Commercial Press | FE15: Removed | FF15: Removed | FG15: Removed | FH15: Removed | FI15: Removed | FJ15: Removed | FK15: Removed | FL15: Removed | FM15: Removed | FN15: Removed | FO15: 34965 | FP15: 34709 | FQ15: 31745 | FR15: 29797 | FS15: 27739 | FT15: 26424 | FU15: 25136 | FV15: 22227
B16: 7631011 | C16: 3058702 | D16: Bank Of China | E16: 3268 | F16: 3217 | G16: 3031 | H16: 2884 | I16: 2963 | J16: 2750 | K16: 3017 | L16: 2845 | M16: 2904 | N16: 3164 | O16: 2868 | P16: 2929 | Q16: 3060 | R16: 2947 | S16: 3060 | T16: 2807 | U16: 2839 | V16: 2880 | W16: 3002 | X16: 2606 | Y16: 2920 | Z16: 2820 | AA16: 2704 | AB16: 2994 | AC16: 2875 | AD16: 2913 | AE16: 3069 | AF16: 2791 | AG16: 2832 | AH16: 2880 | AI16: 2920 | AJ16: 2828 | AK16: 2804 | AL16: 2846 | AM16: 2887 | AN16: 2958 | AO16: 2738 | AP16: 2993 | AQ16: 3133 | AR16: 2580 | AS16: 3115 | AT16: 2736 | AU16: 2613 | AV16: 3136 | AW16: 3112 | AX16: 2519 | AY16: 2784 | AZ16: 3169 | BA16: 2782 | BB16: 3172 | BC16: 3072 | BD16: 2810 | BE16: 3081 | BF16: 2823 | BG16: 3220 | BH16: 3076 | BI16: 3250 | BJ16: 3225 | BK16: 3280 | BL16: 3107 | BM16: 3198 | BN16: 3398 | BO16: 3068 | BP16: 3156 | BQ16: 3241 | BR16: 2723 | BS16: 3238 | BT16: 2765 | BU16: 2971 | BV16: 3026 | BW16: 2906 | BX16: 2778 | BY16: 2964 | BZ16: 3076 | CA16: 2935 | CB16: 2541 | CC16: 1874 | CD16: 2287 | CE16: 2289 | CF16: 1050 | CG16: 974 | CH16: 1097 | CI16: 2367 | CJ16: 2897 | CK16: 2678 | CL16: 1710 | CM16: 2946 | CN16: 2419 | CO16: 2662 | CP16: 2659 | CQ16: 2653 | CR16: 2383 | CS16: 2807 | CT16: 2477 | CU16: 2885 | CV16: 2586 | CW16: 2883 | CX16: 2783 | CY16: =1711+1190 -> 2901 | CZ16: 2590 | DA16: 2840 | DB16: 2708 | DC16: 2607 | DD16: 2380 | DE16: 1481 | DF16: 1980 | DG16: 2600 | DH16: 2715 | DI16: 2495 | DJ16: 2674 | DK16: 2620 | DL16: 2498 | DM16: 2654 | DN16: =FU16-FV16 -> 2522 | DO16: =FT16-FU16 -> 2289 | DP16: =FS16-FT16 -> 2420 | DQ16: =FR16-FS16 -> 2484 | DR16: =FQ16-FR16 -> 2283 | DS16: =FP16-FQ16 -> 2550 | DT16: =FO16-FP16 -> 2614 | DU16: =FN16-FO16 -> 2330 | DV16: =FM16-FN16 -> 2796 | DW16: =FL16-FM16 -> 2490 | DX16: =FK16-FL16 -> 2452 | DY16: =FJ16-FK16 -> 2726 | DZ16: =FI16-FJ16 -> 2358 | EA16: =FH16-FI16 -> 2628 | EB16: =FG16-FH16 -> 2452 | EC16: =FF16-FG16 -> 2338 | ED16: =FE16-FF16 -> 2540 | EE16: 2419 | EF16: 2353 | EG16: 856 | EH16: 2660 | EI16: 2431 | EJ16: 2410 | EK16: 2418 | EL16: 2336 | EM16: 2263 | EN16: 2263 | EO16: 2287 | EP16: 2479 | EQ16: 2344 | ER16: 2468 | ES16: 2092 | ET16: 2382 | EU16: 2441 | EV16: 2361 | EW16: 2488 | EX16: 2635 | EY16: 2562 | EZ16: 2210 | FA16: 2514 | FB16: 2414 | FC16: Bank Of China | FE16: 78837 | FF16: 76297 | FG16: 73959 | FH16: 71507 | FI16: 68879 | FJ16: 66521 | FK16: 63795 | FL16: 61343 | FM16: 58853 | FN16: 56057 | FO16: 53727 | FP16: 51113 | FQ16: 48563 | FR16: 46280 | FS16: 43796 | FT16: 41376 | FU16: 39087 | FV16: 36565
B17: 7631012 | C17: 3058782 | D17: Hang Seng Bank | E17: 3151 | F17: 3349 | G17: 3217 | H17: 3105 | I17: 3233 | J17: 2918 | K17: 3062 | L17: 2817 | M17: 2837 | N17: 3057 | O17: 2934 | P17: 3023 | Q17: 3066 | R17: 3083 | S17: 3273 | T17: 3021 | U17: 2930 | V17: 2956 | W17: 2981 | X17: 2365 | Y17: 2301 | Z17: 2255 | AA17: 2176 | AB17: 2483 | AC17: 2357 | AD17: 2361 | AE17: 2507 | AF17: 2257 | AG17: 2251 | AH17: 2260 | AI17: 2284 | AJ17: 2163 | AK17: 2228 | AL17: 2327 | AM17: 2296 | AN17: 2441 | AO17: 2214 | AP17: 2339 | AQ17: 2359 | AR17: 1991 | AS17: 2462 | AT17: 2120 | AU17: 1873 | AV17: 2203 | AW17: 2292 | AX17: 1903 | AY17: 2141 | AZ17: 2351 | BA17: 2085 | BB17: 2421 | BC17: 2288 | BD17: 2173 | BE17: 2886 | BF17: 1227 | BG17: 2108 | BH17: 1941 | BI17: 2099 | BJ17: 2091 | BK17: 2238 | BL17: 2076 | BM17: 2105 | BN17: 2446 | BO17: 2183 | BP17: 2127 | BQ17: 2236 | BR17: 1971 | BS17: 2227 | BT17: 1920 | BU17: 2014 | BV17: 2071 | BW17: 1978 | BX17: 1917 | BY17: 2092 | BZ17: 2285 | CA17: 2190 | CB17: 2103 | CC17: 1773 | CD17: 2017 | CE17: 1981 | CF17: 1852 | CG17: 2099 | CH17: 1979 | CI17: 1989 | CJ17: 2183 | CK17: 2333 | CL17: 1303 | CM17: 2352 | CN17: 2112 | CO17: 2348 | CP17: 2251 | CQ17: 2180 | CR17: 1961 | CS17: 2334 | CT17: 2157 | CU17: 3779 | CV17: 924 | CW17: 2374 | CX17: 2162 | CY17: =1317+915 -> 2232 | CZ17: 1917 | DA17: 2132 | DB17: 2030 | DC17: 2051 | DD17: 1348 | DE17: 1107 | DF17: 1483 | DG17: 2195 | DH17: 2392 | DI17: 2225 | DJ17: 2367 | DK17: 2267 | DL17: 2138 | DM17: 2353 | DN17: =FU17-FV17 -> 2201 | DO17: =FT17-FU17 -> 2074 | DP17: =FS17-FT17 -> 2009 | DQ17: =FR17-FS17 -> 2105 | DR17: =FQ17-FR17 -> 1960 | DS17: =FP17-FQ17 -> 2256 | DT17: =FO17-FP17 -> 2237 | DU17: =FN17-FO17 -> 2105 | DV17: =FM17-FN17 -> 2534 | DW17: =FL17-FM17 -> 2173 | DX17: =FK17-FL17 -> 2180 | DY17: =FJ17-FK17 -> 2289 | DZ17: =FI17-FJ17 -> 1946 | EA17: =FH17-FI17 -> 2068 | EB17: =FG17-FH17 -> 1937 | EC17: =FF17-FG17 -> 1831 | ED17: =FE17-FF17 -> 2151 | EE17: 2076 | EF17: 2074 | EG17: 2227 | EH17: 2294 | EI17: 2131 | EJ17: 2061 | EK17: 2043 | EL17: 1926 | EM17: 1833 | EN17: 1833 | EO17: 1866 | EP17: 2126 | EQ17: 2095 | ER17: 2156 | ES17: 2092 | ET17: 2130 | EU17: 2170 | EV17: 2039 | EW17: 1944 | EX17: 1986 | EY17: 1996 | EZ17: 1727 | FA17: 2050 | FB17: 1966 | FC17: Hang Seng Bank | FE17: 65390 | FF17: 63239 | FG17: 61408 | FH17: 59471 | FI17: 57403 | FJ17: 55457 | FK17: 53168 | FL17: 50988 | FM17: 48815 | FN17: 46281 | FO17: 44176 | FP17: 41939 | FQ17: 39683 | FR17: 37723 | FS17: 35618 | FT17: 33609 | FU17: 31535 | FV17: 29334
B18: 7631033 | C18: 3152185 | D18: CHINA MOBILE HONG KONG COMPANY LIMI | E18: 1572 | F18: 1352 | G18: 1353 | H18: 1303 | I18: 1300 | J18: 1363 | K18: 1355 | L18: 1272 | M18: 1236 | N18: 1465 | O18: 1384 | P18: 1465 | Q18: 1483 | R18: 1371 | S18: 1519 | T18: 1406 | U18: 1342 | V18: 1466 | W18: 1417 | X18: 1294 | Y18: 1437 | Z18: 1454 | AA18: 1373 | AB18: 1534 | AC18: 1416 | AD18: 1371 | AE18: 1592 | AF18: 1422 | AG18: 1456 | AH18: 1390 | AI18: 1385 | AJ18: 1428 | AK18: 1387 | AL18: 1392 | AM18: 1450 | AN18: 1446 | AO18: 1364 | AP18: 1500 | AQ18: 1388 | AR18: 1161 | AS18: 1852 | AT18: 742 | AU18: 1150 | AV18: 1426 | AW18: 1379 | AX18: 1251 | AY18: 1300 | AZ18: 1214 | BA18: 1116 | BB18: 1439 | BC18: 1341 | BD18: 1320 | BE18: 1259 | BF18: 1158 | BG18: 1254 | BH18: 1652 | BI18: 677 | BJ18: 1293 | BK18: 1269 | BL18: 1198 | BM18: 1297 | BN18: 1303 | BO18: 1247 | BP18: 1377 | BQ18: 1357 | BR18: 1208 | BS18: 1397 | BT18: 1250 | BU18: 1269 | BV18: 1390 | BW18: 1315 | BX18: 1241 | BY18: 1377 | BZ18: 1326 | CA18: 1378 | CB18: 1341 | CC18: 1310 | CD18: 1333 | CE18: 1320 | CF18: 1168 | CG18: 1235 | CH18: 1201 | CI18: 1218 | CJ18: 1306 | CK18: 1231 | CL18: 1506 | CM18: 2344 | CN18: 2118 | CO18: 2188 | CP18: 2071 | CQ18: 2099 | CR18: 1984 | CS18: 2324 | CT18: 2153 | CU18: 2357 | CV18: 2106 | CW18: 2284 | CX18: 2269 | CY18: 602 | CZ18: 2044 | DA18: 2287 | DB18: 2090 | DC18: 1970 | DD18: 2093 | DE18: 2034 | DF18: 2103 | DG18: 2179 | DH18: 2181 | DI18: 2040 | DJ18: 2286 | DK18: 2275 | DL18: 2053 | DM18: 2429 | DN18: =FU18-FV18 -> 2308 | DO18: =FT18-FU18 -> 2320 | DP18: =FS18-FT18 -> 2286 | DQ18: =FR18-FS18 -> 2415 | DR18: =FQ18-FR18 -> 2368 | DS18: =FP18-FQ18 -> 2594 | DT18: =FO18-FP18 -> 2442 | DU18: =FN18-FO18 -> 2215 | DV18: =FM18-FN18 -> 2636 | DW18: =FL18-FM18 -> 2506 | DX18: =FK18-FL18 -> 2581 | DY18: =FJ18-FK18 -> 2604 | DZ18: =FI18-FJ18 -> 2359 | EA18: =FH18-FI18 -> 2529 | EB18: =FG18-FH18 -> 2451 | EC18: =FF18-FG18 -> 2350 | ED18: =FE18-FF18 -> 2775 | EE18: 2541 | EF18: 2354 | EG18: 2585 | EH18: 2507 | EI18: 2643 | EJ18: 2576 | EK18: 2564 | EL18: 2537 | EM18: 2273 | EN18: 2273 | EO18: 2801 | EP18: 3271 | EQ18: 2997 | ER18: 2997 | ES18: 2920 | ET18: 3081 | EU18: 3577 | EV18: 3348 | EW18: 3166 | EX18: 3566 | EY18: 3380 | EZ18: 3186 | FA18: 3665 | FB18: 3647 | FC18: CHINA MOBILE HONG KONG COMPANY LIMI | FE18: 73486 | FF18: 70711 | FG18: 68361 | FH18: 65910 | FI18: 63381 | FJ18: 61022 | FK18: 58418 | FL18: 55837 | FM18: 53331 | FN18: 50695 | FO18: 48480 | FP18: 46038 | FQ18: 43444 | FR18: 41076 | FS18: 38661 | FT18: 36375 | FU18: 34055 | FV18: 31747
B19: 7631015 | C19: 3156551 | D19: SMARTONE MOBILE COMMUNICATIONS LIMI | E19: 3607 | F19: 3511 | G19: 3475 | H19: 3298 | I19: 3221 | J19: 3124 | K19: 3162 | L19: 2913 | M19: 2930 | N19: 3505 | O19: 3352 | P19: 3663 | Q19: 3656 | R19: 3320 | S19: 3614 | T19: 3330 | U19: 3139 | V19: 3363 | W19: 3307 | X19: 3181 | Y19: 3610 | Z19: 3886 | AA19: 3790 | AB19: 4301 | AC19: 3945 | AD19: 3775 | AE19: 4209 | AF19: 3830 | AG19: 3897 | AH19: 3609 | AI19: 3543 | AJ19: 3642 | AK19: 3586 | AL19: 3764 | AM19: 3984 | AN19: 5037 | AO19: 5340 | AP19: 5707 | AQ19: 5469 | AR19: 4927 | AS19: 5529 | AT19: 4754 | AU19: 4146 | AV19: 4931 | AW19: 4835 | AX19: 4713 | AY19: 5492 | AZ19: 5693 | BA19: 5021 | BB19: 5885 | BC19: 5317 | BD19: 5377 | BE19: 5023 | BF19: 4319 | BG19: 4705 | BH19: 4284 | BI19: 4635 | BJ19: 5413 | BK19: 5554 | BL19: 5205 | BM19: 5583 | BN19: 5479 | BO19: 3424 | BP19: 2989 | BQ19: 2809 | BR19: 2520 | BS19: 2938 | BT19: 2556 | BU19: 2600 | BV19: 2901 | BW19: 3201 | BX19: 3614 | BY19: 3764 | BZ19: 3669 | CA19: 3655 | CB19: 3178 | CC19: 2821 | CD19: 2901 | CE19: 2874 | CF19: 2699 | CG19: 2897 | CH19: 2800 | CI19: 2830 | CJ19: 3051 | CK19: 2865 | CL19: 2762 | CM19: 3212 | CN19: 2891 | CO19: 2967 | CP19: 2840 | CQ19: 2845 | CR19: 2666 | CS19: 3046 | CT19: 2879 | CU19: 3121 | CV19: 2783 | CW19: 3016 | CX19: 3009 | CY19: =1843+1138 -> 2981 | CZ19: 2743 | DA19: 3061 | DB19: 2796 | DC19: 2789 | DD19: 2985 | DE19: 2976 | DF19: 2981 | DG19: 3121 | DH19: 3165 | DI19: 3630 | DJ19: 4075 | DK19: 3632 | DL19: 3380 | DM19: 3639 | DN19: =FU19-FV19 -> 3256 | DO19: =FT19-FU19 -> 3637 | DP19: =FS19-FT19 -> 3611 | DQ19: =FR19-FS19 -> 3806 | DR19: =FQ19-FR19 -> 3561 | DS19: =FP19-FQ19 -> 3661 | DT19: =FO19-FP19 -> 3487 | DU19: =FN19-FO19 -> 3397 | DV19: =FM19-FN19 -> 3881 | DW19: =FL19-FM19 -> 3479 | DX19: =FK19-FL19 -> 3513 | DY19: =FJ19-FK19 -> 3616 | DZ19: =FI19-FJ19 -> 5272 | EA19: =FH19-FI19 -> 5781 | EB19: =FG19-FH19 -> 5331 | EC19: =FF19-FG19 -> 4906 | ED19: =FE19-FF19 -> 6062 | EE19: 5483 | EF19: 5522 | EG19: 6302 | EH19: 6087 | EI19: 6039 | EJ19: 5786 | EK19: 5658 | EL19: 5689 | EM19: 5316 | EN19: 5633 | EO19: 5209 | EP19: 6192 | EQ19: 6192 | ER19: 5854 | ES19: 5829 | ET19: 5831 | EU19: 6160 | EV19: 5392 | EW19: 4859 | EX19: 5282 | EY19: 5067 | EZ19: 4689 | FA19: 5442 | FB19: 5401 | FC19: SMARTONE MOBILE COMMUNICATIONS LIMI | FE19: 117085 | FF19: 111023 | FG19: 106117 | FH19: 100786 | FI19: 95005 | FJ19: 89733 | FK19: 86117 | FL19: 82604 | FM19: 79125 | FN19: 75244 | FO19: 71847 | FP19: 68360 | FQ19: 64699 | FR19: 61138 | FS19: 57332 | FT19: 53721 | FU19: 50084 | FV19: 46828
