Workbook

Sheet Table of Contents
A1: Annual Report | C1: Monthly Data | E1: Yearly Data
A2: Energy | C2: Renewable | E2: Renewable
A3: Water | C3: Electricity (Overview) | E3: Electricity (Overview)
A4: Waste | C4: Electricity (Reformatted) | E4: Electricity (Reformatted)
C5: Towngas (TGU) | E5: Towngas (TGU)
A6: Half-Year Report | C6: Potable Water (Overview) | E6: Fuel
A7: Water | C7: Potable Water (Meters) | E7: Scope 1 GHG (mtCO2)
A8: Waste | C8: Seawater (m3) | E8: Scope 2 GHG (mtCO2)
C9: Category Water Data | E9: Scope 3 GHG (mtCO2)
A10: Raw Data | C10: Monthly Waste by Location (kg) | E10: GHG (mtCO2)
A11: Waste | C11: Category Waste Data | E11: Potable Water (Overview)
A12: Food Waste | C12: Recycling (kg) | E12: Potable Water (Meters)
C13: Paper Distribution (kg) | E13: Seawater (m3)
A14: Smart Waste Bin | E14: Recycling (kg)
A15: Staff Quarters | E15: Food Waste (kg)
A16: Canteen | E16: Paper Distribution (kg)
E17: Paper Distribution (match monthly) (kg)
A18: Other
A19: Emission Factor (Keep Updated)
A20: Emission Factor (Original)
A22: Daily Data
A23: Food Waste

Sheet Annual Report (Energy)
A1: Date | B1: Liquid Fuels/Diesel | C1: Towngas | D1: Electricity | E1: Energy (kWh) | F1: Energy per Capita | G1: Energy per GFA | J1: Date | K1: Electricity Consumption | L1: Renewable Generation (kWh) | M1: Emission Factor (kg/ KWh) | N1: Renewable Generation (CO2 tonnes) | R1: Date | S1: Main Acad. Building & Others | T1: Cheng Yu Tung Building | U1: Main Chiller Plant | V1: LSK Chiller Plant | W1: LSK Building | X1: IAS Building | Y1: Conference Lodge | Z1: Staff Quarter Common Area | AA1: Student Housing | AB1: Staff Quarters & Commercial Outlets | AD1: Year | AE1: Total S1&2 | AF1: Total S3 | AG1: Emissions per Capita | AH1: Emissions per GFA | AJ1: Academic Year | AK1: Actual (including renewables) | AL1: Actual | AM1: Projected | AN1: 2028 | AO1: 2035 | AP1: 2045 | AQ1: 2050
A2: 2014/15 | B2: 280000 | C2: ='Yearly Towngas (TGU)'!I6 -> 5874308 | D2: 93067207 | E2: =SUM(B2:D2) -> 99221515 | F2: =E2/'Yearly GHG (mCO2)'!G6 -> 6072.3081 | G2: =E2/'Yearly GHG (mCO2)'!H6 -> 209.52229 | J2: 2014/15 | K2: 93067207 | L2: 0 | N2: 0 | R2: 2023/24 kWh | S2: 51334417 | T2: 4746630 | U2: 17653437 | V2: 1497696 | W2: 2713600 | X2: 588506 | Y2: 1478893 | Z2: 909181 | AA2: 6604565 | AB2: 9182416 | AD2: 2014/15 | AE2: ='Yearly GHG (mCO2)'!E6 -> 61233.387 | AF2: ='Yearly GHG (mCO2)'!D6 -> 795.24599 | AG2: ='Yearly GHG (mCO2)'!I6 -> 3.7474533 | AH2: ='Yearly GHG (mCO2)'!J6 -> 1.2930421 | AJ2: 2014 | AK2: 61233 | AL2: 61233 | AN2: =AK2 -> 61233 | AS2: Reduction
A3: 2015/16 | B3: 370000 | C3: ='Yearly Towngas (TGU)'!I7 -> 7232698 | D3: 95800070 | E3: =SUM(B3:D3) -> 103402768 | F3: =E3/'Yearly GHG (mCO2)'!G7 -> 6221.2122 | G3: =E3/'Yearly GHG (mCO2)'!H7 -> 215.38048 | J3: 2015/16 | K3: 95800070 | L3: 0 | N3: 0 | R3: 2023/24 % | S3: 0.5308 | T3: 0.0491 | U3: 0.1825 | V3: 0.0155 | W3: 0.0281 | X3: 0.0061 | Y3: 0.0153 | Z3: 0.0094 | AA3: 0.0683 | AB3: 0.0949 | AD3: 2015/16 | AE3: ='Yearly GHG (mCO2)'!E7 -> 53623.842 | AF3: ='Yearly GHG (mCO2)'!D7 -> 865.87691 | AG3: ='Yearly GHG (mCO2)'!I7 -> 3.2262705 | AH3: ='Yearly GHG (mCO2)'!J7 -> 1.1169458 | AJ3: 2015 | AK3: 53624 | AL3: 53624 | AN3: =AN2+AT8 -> 59483.486 | AS3: 0 | AT3: =AK2 -> 61233
A4: 2016/17 | B4: 201980.5 | C4: ='Yearly Towngas (TGU)'!I8 -> 6584444 | D4: 94486358 | E4: =SUM(B4:D4) -> 1.0127278e+08 | F4: =E4/'Yearly GHG (mCO2)'!G8 -> 5854.0873 | G4: =E4/'Yearly GHG (mCO2)'!H8 -> 199.35587 | J4: 2016/17 | K4: 94486358 | L4: 0 | N4: 0 | AD4: 2016/17 | AE4: ='Yearly GHG (mCO2)'!E8 -> 52655.5 | AF4: ='Yearly GHG (mCO2)'!D8 -> 662.19891 | AG4: ='Yearly GHG (mCO2)'!I8 -> 3.0437585 | AH4: ='Yearly GHG (mCO2)'!J8 -> 1.0365256 | AJ4: 2016 | AK4: 52656 | AL4: 52656 | AN4: =AN3+AT8 -> 57733.971 | AS4: 0.4 | AT4: =0.6*AK2 -> 36739.8
A5: 2017/18 | B5: 221452.21 | C5: ='Yearly Towngas (TGU)'!I9 -> 5665933 | D5: 92966450 | E5: =SUM(B5:D5) -> 98853835 | F5: =E5/'Yearly GHG (mCO2)'!G9 -> 5515.3198 | G5: =E5/'Yearly GHG (mCO2)'!H9 -> 192.84038 | J5: 2017/18 | K5: 92966450 | L5: 0 | N5: 0 | AD5: 2017/18 | AE5: ='Yearly GHG (mCO2)'!E9 -> 48812.938 | AF5: ='Yearly GHG (mCO2)'!D9 -> 639.41977 | AG5: ='Yearly GHG (mCO2)'!I9 -> 2.7234044 | AH5: ='Yearly GHG (mCO2)'!J9 -> 0.95222461 | AJ5: 2017 | AK5: 48813 | AL5: 48813 | AN5: =AN4+AT8 -> 55984.457 | AS5: 0.5 | AT5: =0.5*AK2 -> 30616.5
A6: 2018/19 | B6: 205172.45 | C6: ='Yearly Towngas (TGU)'!I10 -> 6128182 | D6: 90186094 | E6: =SUM(B6:D6) -> 96519448 | F6: =E6/'Yearly GHG (mCO2)'!G10 -> 5214.8715 | G6: =E6/'Yearly GHG (mCO2)'!H10 -> 187.37815 | J6: 2018/19 | K6: 90186094 | L6: 0 | N6: 0 | AD6: 2018/19 | AE6: ='Yearly GHG (mCO2)'!E10 -> 47481.826 | AF6: ='Yearly GHG (mCO2)'!D10 -> 656.55334 | AG6: ='Yearly GHG (mCO2)'!I10 -> 2.5654065 | AH6: ='Yearly GHG (mCO2)'!J10 -> 0.92178901 | AJ6: 2018 | AK6: 47482 | AL6: 47482 | AN6: =AN5+AT8 -> 54234.943
A7: 2019/20 | B7: 181092.19 | C7: ='Yearly Towngas (TGU)'!I11 -> 4520415 | D7: 87353244 | E7: =SUM(B7:D7) -> 92054751 | F7: =E7/'Yearly GHG (mCO2)'!G11 -> 5207.0112 | G7: =E7/'Yearly GHG (mCO2)'!H11 -> 178.71061 | J7: 2019/20 | K7: 87353244 | L7: 2920 | M7: 0.51 | N7: =(L7*M7)/1000 -> 1.4892 | P7: =L7/K7 -> 3.3427494e-05 | AD7: 2019/20 | AE7: ='Yearly GHG (mCO2)'!E11 -> 44850.269 | AF7: ='Yearly GHG (mCO2)'!D11 -> 241.89826 | AG7: ='Yearly GHG (mCO2)'!I11 -> 2.5369234 | AH7: ='Yearly GHG (mCO2)'!J11 -> 0.87070126 | AJ7: 2019 | AK7: =44850-N7 -> 44848.511 | AL7: =44850 -> 44850 | AN7: =AN6+AT8 -> 52485.429 | AS7: Slopes
A8: 2020/21 | B8: 224833.4 | C8: ='Yearly Towngas (TGU)'!I12 -> 4701278 | D8: 88318175 | E8: =SUM(B8:D8) -> 93244286 | F8: =E8/'Yearly GHG (mCO2)'!G12 -> 4729.1315 | G8: =E8/'Yearly GHG (mCO2)'!H12 -> 165.44555 | J8: 2020/21 | K8: 88318175 | L8: 391443 | M8: 0.37 | N8: =(L8*M8)/1000 -> 144.83391 | P8: =L8/K8 -> 0.0044321908 | AD8: 2020/21 | AE8: ='Yearly GHG (mCO2)'!E12 -> 33904.269 | AF8: ='Yearly GHG (mCO2)'!D12 -> 124.75376 | AG8: ='Yearly GHG (mCO2)'!I12 -> 1.719545 | AH8: ='Yearly GHG (mCO2)'!J12 -> 0.6015715 | AJ8: 2020 | AK8: =33904-N8 -> 33759.166 | AL8: =33904 -> 33904 | AN8: =AN7+AT8 -> 50735.914 | AS8: 2028 Slope | AT8: =(AN16-AN2)/14 -> -1749.5143
A9: 2021/22 | B9: 234812 | C9: ='Yearly Towngas (TGU)'!I13 -> 5113008 | D9: 89692408 | E9: =SUM(B9:D9) -> 95040228 | F9: =E9/'Yearly GHG (mCO2)'!G13 -> 4626.4045 | G9: =E9/'Yearly GHG (mCO2)'!H13 -> 164.4274 | J9: 2021/22 | K9: 89692408 | L9: 1912724 | M9: 0.39 | N9: =(L9*M9)/1000 -> 745.96236 | P9: =L9/K9 -> 0.021325372 | AD9: 2021/22 | AE9: ='Yearly GHG (mCO2)'!E13 -> 36252.174 | AF9: ='Yearly GHG (mCO2)'!D13 -> 258.65209 | AG9: ='Yearly GHG (mCO2)'!I13 -> 1.7646972 | AH9: ='Yearly GHG (mCO2)'!J13 -> 0.62719237 | AJ9: 2021 | AK9: =36252-N9 -> 35506.038 | AL9: =36252 -> 36252 | AN9: =AN8+AT8 -> 48986.4 | AS9: 2035 Slope | AT9: =(AO23-AO16)/(22-15) -> -874.75714
A10: 2022/23 | B10: 292973.43 | C10: ='Yearly Towngas (TGU)'!I14 -> 5491373 | D10: 93932338 | E10: =SUM(B10:D10) -> 99716684 | F10: =E10/'Yearly GHG (mCO2)'!G14 -> 4638.6326 | G10: =E10/'Yearly GHG (mCO2)'!H14 -> 172.51813 | J10: 2022/23 | K10: 93932338 | L10: 2319773 | M10: 0.39 | N10: =(L10*M10)/1000 -> 904.71147 | O10: =(L10-L9)/L9 -> 0.21281115 | P10: =L10/K10 -> 0.024696213 | AD10: 2022/23 | AE10: ='Yearly GHG (mCO2)'!E14 -> 38013.728 | AF10: ='Yearly GHG (mCO2)'!D14 -> 555.67178 | AG10: ='Yearly GHG (mCO2)'!I14 -> 1.7683271 | AH10: ='Yearly GHG (mCO2)'!J14 -> 0.657669 | AJ10: 2022 | AK10: =38014-N10 -> 37109.289 | AL10: =38014 -> 38014 | AN10: =AN9+AT8 -> 47236.886 | AS10: 2045 Slope | AT10: =(AP33-AP23)/(32-22) -> -3061.65
A11: 2023/24 | B11: 243473.34 | C11: ='Yearly Towngas (TGU)'!I15 -> 5826263.4 | D11: 96709341 | E11: =SUM(B11:D11) -> 1.0277908e+08 | F11: =E11/'Yearly GHG (mCO2)'!G15 -> 4636.1621 | G11: =E11/'Yearly GHG (mCO2)'!H15 -> 175.00507 | J11: 2023/24 | K11: 96709341 | L11: 2334777 | M11: 0.39 | N11: =(L11*M11)/1000 -> 910.56303 | AD11: 2023/24 | AE11: ='Yearly GHG (mCO2)'!E15 -> 40466.06 | AF11: ='Yearly GHG (mCO2)'!D15 -> 425.79 | AG11: ='Yearly GHG (mCO2)'!I15 -> 1.8253444 | AH11: ='Yearly GHG (mCO2)'!J15 -> 0.68902795 | AJ11: 2023 | AK11: =AL11-N11 -> 39555.437 | AL11: 40466 | AM11: 38236.386 | AN11: =AN10+AT8 -> 45487.371 | AS11: 2050 Slope | AT11: =(AQ38-AQ23)/(37-22) -> -2041.1
A12: 2024/25 | B12: ='Yearly Fuel'!K16 -> 219309.77 | C12: ='Yearly Towngas (TGU)'!I16 -> 5633744.4 | D12: ='Yearly Electricity Reformatted'!Q13 -> 105238070 | E12: =SUM(B12:D12) -> 1.1109112e+08 | F12: =E12/'Yearly GHG (mCO2)'!G16 -> 4652.6416 | G12: =E12/'Yearly GHG (mCO2)'!H16 -> 189.15825 | J12: 2024/25 | K12: ='Yearly Electricity Reformatted'!Q13 -> 105238070 | L12: ='Yearly Renewable'!F11 -> 2728619 | M12: 0.39 | N12: =(L12*M12)/1000 -> 1064.1614 | AD12: 2024/25 | AE12: ='Yearly GHG (mCO2)'!E16 -> 41443.1 | AF12: ='Yearly GHG (mCO2)'!D16 -> 284.31867 | AG12: ='Yearly GHG (mCO2)'!I16 -> 1.7356912 | AH12: ='Yearly GHG (mCO2)'!J16 -> 0.7056643 | AJ12: 2024 | AL12: 41443 | AM12: 37131.515 | AN12: =AN11+AT8 -> 43737.857
A13: 2025/26 | B13: ='Yearly Fuel'!K17 -> 0 | C13: ='Yearly Towngas (TGU)'!I17 -> 4206293.7 | D13: ='Yearly Electricity Reformatted'!Q14 -> 65366173 | E13: =SUM(B13:D13) -> 69572467 | F13: =E13/'Yearly GHG (mCO2)'!G17 -> #DIV/0! | G13: =E13/'Yearly GHG (mCO2)'!H17 -> #DIV/0! | AE13: =AE12/AE2-1 -> -0.3231944 | AF13: =AF12/AF2-1 -> -0.64247708 | AG13: =AG12/AG2-1 -> -0.53683446 | AH13: =AH12/AH2-1 -> -0.45426038 | AJ13: 2025 | AM13: 37121.752 | AN13: =AN12+AT8 -> 41988.343 | AS13: 2022 | AT13: =(AK2-AK10)/AK2 -> 0.39396586
AE14: =AE12/AE11-1 -> 0.024144667 | AF14: =AF12/AF11-1 -> -0.33225611 | AG14: =AG12/AG11-1 -> -0.049115754 | AH14: =AH12/AH11-1 -> 0.024144667 | AJ14: 2026 | AM14: 43405.672 | AN14: =AN13+AT8 -> 40238.829 | AS14: 2021 | AT14: =(AK9-AK2)/AK2 -> -0.42014865
AJ15: 2027 | AM15: 41891.025 | AN15: =AN14+AT8 -> 38489.314 | AS15: 2023 | AT15: =(AL11-AK2)/AK2 -> -0.33914719
AJ16: 2028 | AM16: 47439.701 | AN16: =AT4 -> 36739.8 | AO16: =AN16 -> 36739.8 | AS16: 2024 | AT16: =(AL12-AK2)/AK2 -> -0.32319174
AJ17: 2029 | AM17: 45117.055 | AO17: =AO16+AT9 -> 35865.043
AJ18: 2030 | AM18: 49445.731 | AO18: =AO17+AT9 -> 34990.286 | AT18: =(AL10-AL2)/AL2*100 -> -37.919096
AJ19: 2031 | AM19: 47614.408 | AO19: =AO18+AT9 -> 34115.529 | AT19: =(AL11-AL2)/AL2*100 -> -33.914719
AJ20: 2032 | AM20: 44815.761 | AO20: =AO19+AT9 -> 33240.771
AJ21: 2033 | AM21: 42948.438 | AO21: =AO20+AT9 -> 32366.014
AJ22: 2034 | AM22: 41741.114 | AO22: =AO21+AT9 -> 31491.257
AJ23: 2035 | AM23: 39843.791 | AO23: =AT5 -> 30616.5 | AP23: =AO23 -> 30616.5 | AQ23: =AP23 -> 30616.5
AJ24: 2036 | AM24: 39066.468 | AP24: =AP23+AT10 -> 27554.85 | AQ24: =AQ23+AT11 -> 28575.4
AJ25: 2037 | AM25: 37113.144 | AP25: =AP24+AT10 -> 24493.2 | AQ25: =AQ24+AT11 -> 26534.3
AJ26: 2038 | AM26: 35699.821 | AP26: =AP25+AT10 -> 21431.55 | AQ26: =AQ25+AT11 -> 24493.2
AJ27: 2039 | AM27: 33716.497 | AP27: =AP26+AT10 -> 18369.9 | AQ27: =AQ26+AT11 -> 22452.1
AJ28: 2040 | AM28: 32613.174 | AP28: =AP27+AT10 -> 15308.25 | AQ28: =AQ27+AT11 -> 20411
AJ29: 2041 | AM29: 30574.851 | AP29: =AP28+AT10 -> 12246.6 | AQ29: =AQ28+AT11 -> 18369.9
AJ30: 2042 | AM30: 31114.851 | AP30: =AP29+AT10 -> 9184.95 | AQ30: =AQ29+AT11 -> 16328.8
AJ31: 2043 | AM31: 29040.527 | AP31: =AP30+AT10 -> 6123.3 | AQ31: =AQ30+AT11 -> 14287.7
AJ32: 2044 | AM32: 27434.204 | AP32: =AP31+AT10 -> 3061.65 | AQ32: =AQ31+AT11 -> 12246.6
AJ33: 2045 | AM33: 25323.881 | AP33: 0 | AQ33: =AQ32+AT11 -> 10205.5
AJ34: 2046 | AM34: 25983.881 | AQ34: =AQ33+AT11 -> 8164.4
AJ35: 2047 | AM35: 23818.557 | AQ35: =AQ34+AT11 -> 6123.3
AJ36: 2048 | AM36: 24214.557 | AQ36: =AQ35+AT11 -> 4082.2
AJ37: 2049 | AM37: 22013.234 | AQ37: =AQ36+AT11 -> 2041.1
AJ38: 2050 | AQ38: 0

Sheet Monthly Renewable
A1: Period | B1: LPT Bill | C1: SSQ Bill | D1: JSQ Bill | E1: VC & Guest Lodge | F1: Total | G1: 12-Month Rolling Sum
A2: 43891 | B2: 552 | F2: 552 | G2: =SUM(F2:F13) -> 48047
A3: 43922 | B3: 832 | F3: 832 | G3: =SUM(F3:F14) -> 97324
A4: 43952 | B4: 756 | F4: 756 | G4: =SUM(F4:F15) -> 152319
A5: 43983 | B5: 780 | F5: 780 | G5: =SUM(F5:F16) -> 281265
A6: 44013 | B6: 954 | F6: 954 | G6: =SUM(F6:F17) -> 391443
A7: 44044 | B7: 1462 | F7: 1462 | G7: =SUM(F7:F18) -> 550622
A8: 44075 | B8: 1419 | F8: 1419 | G8: =SUM(F8:F19) -> 708464
A9: 44105 | B9: 1699 | F9: 1699 | G9: =SUM(F9:F20) -> 922923
A10: 44136 | B10: 1498 | F10: 1498 | G10: =SUM(F10:F21) -> 1060438
A11: 44166 | B11: 7001 | F11: 7001 | G11: =SUM(F11:F22) -> 1229018
A12: 44197 | B12: 8076 | F12: 8076 | G12: =SUM(F12:F23) -> 1350990
A13: 44228 | B13: 23018 | F13: 23018 | G13: =SUM(F13:F24) -> 1446027
... A17: 44348 | B17: 110958 | F17: 110958 | G17: =SUM(F17:F28) -> 1838203
A18: 44378 | B18: 160133 | C18: 0 | F18: 160133 | G18: =SUM(F18:F29) -> 1912724
A19: 44409 | B19: 147598 | C19: 8279 | D19: 3427 | F19: 159304 | G19: =SUM(F19:F30) -> 2000570
A20: 44440 | B20: 180730 | C20: 23799 | D20: 11349 | F20: 215878 | G20: =SUM(F20:F31) -> 2062319
A21: 44470 | B21: 122185 | C21: 9107 | D21: 7922 | F21: 139214 | G21: =SUM(F21:F32) -> 2101115
A22: 44501 | B22: 144397 | C22: 13911 | D22: 11770 | F22: 170078 | G22: =SUM(F22:F33) -> 2181426
A23: 44531 | B23: 117181 | C23: 6562 | D23: 5230 | F23: 128973 | G23: =SUM(F23:F34) -> 2144254
A24: 44562 | B24: 94201 | C24: 4908 | D24: 4004 | F24: 103113 | G24: =SUM(F24:F35) -> 2180122
A25: 44594 | B25: 107196 | C25: 4891 | D25: 4180 | F25: 116267 | G25: =SUM(F25:F36) -> 2230217
A26: 44626 | B26: 145751 | C26: 7025 | D26: 6137 | F26: 158916 | G26: =SUM(F26:F37) -> 2296025
A27: 44652 | B27: 201510 | C27: 8833 | D27: 7666 | F27: 218009 | G27: =SUM(F27:F38) -> 2321129
A28: 44682 | B28: 144961 | C28: 6611 | D28: 5788 | F28: 157360 | G28: =SUM(F28:F39) -> 2231400
A29: 44713 | B29: 171373 | C29: 7469 | D29: 6637 | F29: 185479 | G29: =SUM(F29:F40) -> 2267492
A30: 44743 | B30: 230422 | C30: 9293 | D30: 8264 | F30: 247979 | G30: =SUM(F30:F41) -> 2325806
... A37: 44958 | B37: 166577 | C37: 6916 | D37: 8582 | F37: 182075 | G37: =SUM(F37:F48) -> 2466202
A38: 44986 | B38: 166701 | C38: 6502 | D38: 8075 | E38: 2742 | F38: 184020 | G38: =SUM(F38:F49) -> 2417364
A39: 45017 | B39: 117085 | C39: 4635 | D39: 5779 | E39: 781 | F39: 128280 | G39: =SUM(F39:F50) -> 2380465
A40: 45047 | B40: 177122 | C40: 6807 | D40: 8365 | E40: 1158 | F40: 193452 | G40: =SUM(F40:F51) -> 2424661
A41: 45078 | B41: 224897 | C41: 7772 | D41: 9772 | E41: 1352 | F41: 243793 | G41: =SUM(F41:F52) -> 2393764
A42: 45108 | B42: 255467 | C42: 9081 | D42: 12814 | E42: 1557 | F42: 278919 | G42: =SUM(F42:F53) -> 2334777
A43: 45139 | B43: 260667 | C43: 8733 | D43: 14748 | E43: 1494 | F43: 285642 | G43: =SUM(F43:F54) -> 2349779
A44: 45170 | B44: 193050 | C44: 6417 | D44: 10761 | E44: 1102 | F44: 211330 | G44: =SUM(F44:F55) -> 2333316
A45: 45200 | B45: 187049 | C45: 6214 | D45: 10597 | E45: 997 | F45: 204857 | G45: =SUM(F45:F56) -> 2372803
A46: 45231 | B46: 199647 | C46: 6841 | D46: 11363 | E46: 1007 | F46: 218858 | G46: =SUM(F46:F57) -> 2419222
A47: 45262 | B47: 129813 | C47: 4941 | D47: 7827 | E47: 697 | F47: 143278 | G47: =SUM(F47:F58) -> 2376275
A48: 45292 | B48: 174410 | C48: 6432 | D48: 9963 | E48: 893 | F48: 191698 | G48: =SUM(F48:F59) -> 2434966
A49: 45323 | B49: 121311 | C49: 4299 | D49: 6964 | E49: 663 | F49: 133237 | G49: =SUM(F49:F60) -> 2445237
...

Sheet Yearly Renewable
A1: Date | B1: LPT Bill | C1: SSQ Bill | D1: JSQ Bill | E1: VC & Guest Lodge | F1: Renewable energy generation | G1: % of total electricity
A2: 2015/16 | F2: 0
A3: 2016/17 | F3: 0
A4: 2017/18 | F4: 0
A5: 2018/19 | F5: 0
A6: 2019/20 | B6: =SUM('Monthly Renewable'!B2:B5) -> 2920 | C6: =SUM('Monthly Renewable'!C2:C5) -> 0 | D6: =SUM('Monthly Renewable'!D2:D5) -> 0 | E6: =SUM('Monthly Renewable'!E2:E5) -> 0 | F6: =SUM('Monthly Renewable'!B2:B5) -> 2920 | G6: =F6/'Yearly Electricity (Overview)'!C7 -> 3.3427494e-05
A7: 2020/21 | B7: =SUM('Monthly Renewable'!B6:B17) -> 391443 | C7: =SUM('Monthly Renewable'!C6:C17) -> 0 | D7: =SUM('Monthly Renewable'!D6:D17) -> 0 | E7: =SUM('Monthly Renewable'!E6:E17) -> 0 | F7: =SUM('Monthly Renewable'!B6:B17) -> 391443 | G7: =F7/'Yearly Electricity (Overview)'!C8 -> 0.0044321908
A8: 2021/22 | B8: =SUM('Monthly Renewable'!B18:B29) -> 1737216 | C8: =SUM('Monthly Renewable'!C18:C29) -> 101395 | D8: =SUM('Monthly Renewable'!D18:D29) -> 74110 | E8: =SUM('Monthly Renewable'!E18:E29) -> 0 | F8: =SUM('Monthly Renewable'!F18:F29) -> 1912724 | G8: =F8/'Yearly Electricity (Overview)'!C9 -> 0.021325372
A9: 2022/23 | B9: =SUM('Monthly Renewable'!B30:B41) -> 2130219 | C9: =SUM('Monthly Renewable'!C30:C41) -> 87168 | D9: =SUM('Monthly Renewable'!D30:D41) -> 102386 | E9: =SUM('Monthly Renewable'!E30:E41) -> 6033 | F9: =SUM('Monthly Renewable'!F30:F41) -> 2325806 | G9: =F9/'Yearly Electricity (Overview)'!C10 -> 0.02476044
A10: 2023/24 | B10: =SUM('Monthly Renewable'!B42:B53) -> 2132177 | C10: =SUM('Monthly Renewable'!C42:C53) -> 72563 | D10: =SUM('Monthly Renewable'!D42:D53) -> 118062 | E10: =SUM('Monthly Renewable'!E42:E53) -> 11975 | F10: =SUM('Monthly Renewable'!F42:F53) -> 2334777 | G10: =F10/'Yearly Electricity (Overview)'!C11 -> 0.024142208
A11: 2024/25 | B11: =SUM('Monthly Renewable'!B54:B65) -> 2488719 | C11: =SUM('Monthly Renewable'!C54:C65) -> 82931 | D11: =SUM('Monthly Renewable'!D54:D65) -> 143367 | E11: =SUM('Monthly Renewable'!E54:E65) -> 13602 | F11: =SUM('Monthly Renewable'!F54:F65) -> 2728619 | G11: =F11/'Yearly Electricity (Overview)'!C12 -> 0.02639305
A12: 2025/26 | B12: =SUM('Monthly Renewable'!B66:B77) -> 2058995 | C12: =SUM('Monthly Renewable'!C66:C77) -> 67909 | D12: =SUM('Monthly Renewable'!D66:D77) -> 118759 | E12: =SUM('Monthly Renewable'!E66:E77) -> 10846 | F12: =SUM('Monthly Renewable'!F66:F77) -> 2256509 | G12: =F12/'Yearly Electricity (Overview)'!C13 -> 0.034872334

Sheet Monthly Electricity (Overview)
A1: Period | B1: CLP Total | C1: Main Academic Buildings & Other Public Facilities | D1: EC | E1: CYT | F1: Shaw Auditorium | G1: APCF (R/F Zone L) | H1: New Data Centre (2/F Zone L) | I1: Main Chiller Plant | J1: LSKBB | K1: IAS | L1: Conference Lodge | M1: LSK Hostel | N1: LSK Chiller Plant | O1: WWT | P1: Water Sport Centre | Q1: SISC | R1: HPC5 | S1: RB2 | T1: IB | U1: SRD (UG10-13) | V1: TA-B | W1: GGT | X1: Student Housing UG1-UG9, PG1-PG2 | Y1: Staff Quarters & Commercial Outlets | Z1: Commercial Outlets | AA1: Staff Quarters | AB1: Combined Chiller Plants | AD1: TKO JC Hall | AE1: EC 3/F Data Centre (Elect) | AF1: EC 3/F Data Centre (Chiller kWhe) | AG1: SRD (Chiller kWhe) | AH1: IB (Chiller kWhe) | AI1: BMW EV Charger kWh (LG7 & WWT) | AJ1: Corner Stone EV Charger kWh
A2: 41640 | B2: 5938547 | C2: 3924710 | D2: 190811 | E2: 41274 | F2: 0 | G2: 0 | H2: 0 | I2: 500427 | J2: 205345 | K2: 44678 | L2: 0 | M2: 0 | N2: 48446 | O2: 59654 | P2: 0 | Q2: 0 | W2: 0 | X2: 361571 | Y2: 561631 | Z2: 229909 | AA2: 331722 | AB2: 548873 | AD2: 0 | AE2: 0 | AF2: 0 | AG2: 0 | AH2: 0
A3: 41671 | B3: 5888877 | C3: 3565612 | D3: 252064 | E3: 28315 | F3: 0 | G3: 0 | H3: 0 | I3: 502155 | J3: 290449 | K3: 56447 | L3: 0 | M3: 0 | N3: 47613 | O3: 47313 | P3: 0 | Q3: 0 | W3: 0 | X3: 504993 | Y3: 593916 | Z3: 220164 | AA3: 373752 | AB3: 549768 | AD3: 0 | AE3: 0 | AF3: 0 | AG3: 0 | AH3: 0
A4: 41699 | B4: 6018786 | C4: 3680694 | D4: 185065 | E4: 40257 | F4: 0 | G4: 0 | H4: 0 | I4: 754593 | J4: 182485 | K4: 34491 | L4: 0 | M4: 0 | N4: 46854 | O4: 43566 | P4: 0 | Q4: 0 | W4: 0 | X4: 511265 | Y4: 539516 | Z4: 247766 | AA4: 291750 | AB4: 801447 | AD4: 0 | AE4: 0 | AF4: 0 | AG4: 0 | AH4: 0
A5: 41730 | B5: 7488350 | C5: 4459315 | D5: 203049 | E5: 56946 | F5: 0 | G5: 0 | H5: 0 | I5: 1100944 | J5: 213938 | K5: 46284 | L5: 0 | M5: 0 | N5: 141417 | O5: 73814 | P5: 0 | Q5: 0 | W5: 0 | X5: 612777 | Y5: 579866 | Z5: 295835 | AA5: 284031 | AB5: 1242361 | AD5: 0 | AE5: 0 | AF5: 0 | AG5: 0 | AH5: 0
A6: 41760 | B6: 7986119 | C6: 3816523 | D6: 345876 | E6: 89452 | F6: 0 | G6: 0 | H6: 0 | I6: 1749797 | J6: 224043 | K6: 103456 | L6: 0 | M6: 0 | N6: 170062 | O6: 82044 | P6: 0 | Q6: 0 | W6: 0 | X6: 692230 | Y6: 712636 | Z6: 281303 | AA6: 431333 | AB6: 1919859 | AD6: 0 | AE6: 0 | AF6: 0 | AG6: 0 | AH6: 0
A7: 41791 | B7: 8876152 | C7: 4173507 | D7: 250379 | E7: 92936 | F7: 0 | G7: 0 | H7: 0 | I7: 2204099 | J7: 250703 | K7: 71494 | L7: 0 | M7: 0 | N7: 273139 | O7: 97780 | P7: 0 | Q7: 0 | W7: 0 | X7: 574711 | Y7: 887404 | Z7: 266840 | AA7: 620564 | AB7: 2477238 | AD7: 0 | AE7: 0 | AF7: 0 | AG7: 0 | AH7: 0
A8: 41821 | B8: 9340526 | C8: 4361073 | D8: 221804 | E8: 97729 | F8: 0 | G8: 0 | H8: 0 | I8: 2443732 | J8: 225313 | K8: 48903 | L8: 0 | M8: 0 | N8: 246402 | O8: 109439 | P8: 0 | Q8: 0 | W8: 0 | X8: 687729 | Y8: 898402 | Z8: 274134 | AA8: 624268 | AB8: 2690134 | AD8: 0 | AE8: 0 | AF8: 0 | AG8: 0 | AH8: 0
A9: 41852 | B9: 8583907 | C9: 3673176 | D9: 228122 | E9: 146934 | F9: 0 | G9: 0 | H9: 0 | I9: 2460070 | J9: 232978 | K9: 53454 | L9: 0 | M9: 0 | N9: 275655 | O9: 99316 | P9: 0 | Q9: 0 | W9: 0 | X9: 624042 | Y9: 790160 | Z9: 264880 | AA9: 525280 | AB9: 2735725 | AD9: 0 | AE9: 0 | AF9: 0 | AG9: 0 | AH9: 0
A10: 41883 | B10: 10023872 | C10: 4469625 | D10: 276014 | E10: 132812 | F10: 0 | G10: 0 | H10: 0 | I10: 2515785 | J10: 269881 | K10: 79871 | L10: 0 | M10: 0 | N10: 307475 | O10: 89352 | P10: 0 | Q10: 0 | W10: 0 | X10: 956639 | Y10: 926418 | Z10: 311968 | AA10: 614450 | AB10: 2823260 | AD10: 0 | AE10: 0 | AF10: 0 | AG10: 0 | AH10: 0
A11: 41913 | B11: 8035429 | C11: 4049333 | D11: 203926 | E11: 145929 | F11: 0 | G11: 0 | H11: 0 | I11: 1763222 | J11: 248622 | K11: 39903 | L11: 0 | M11: 0 | N11: 153059 | O11: 89097 | P11: 0 | Q11: 0 | W11: 0 | X11: 708839 | Y11: 633499 | Z11: 297097 | AA11: 336402 | AB11: 1916281 | AD11: 0 | AE11: 0 | AF11: 0 | AG11: 0 | AH11: 0
A12: 41944 | B12: 6858052 | C12: 3872340 | D12: 214292 | E12: 95091 | F12: 0 | G12: 0 | H12: 0 | I12: 1119362 | J12: 267023 | K12: 50426 | L12: 0 | M12: 0 | N12: 153510 | O12: 76299 | P12: 0 | Q12: 0 | W12: 0 | X12: 532301 | Y12: 477408 | Z12: 276436 | AA12: 200972 | AB12: 1272872 | AD12: 0 | AE12: 0 | AF12: 0 | AG12: 0 | AH12: 0
A13: 41974 | B13: 6405579 | C13: 3982954 | D13: 253212 | E13: 117318 | F13: 0 | G13: 0 | H13: 0 | I13: 548769 | J13: 246466 | K13: 71670 | L13: 0 | M13: 0 | N13: 67209 | O13: 55450 | P13: 0 | Q13: 0 | W13: 0 | X13: 483170 | Y13: 579361 | Z13: 281511 | AA13: 297850 | AB13: 615978 | AD13: 0 | AE13: 0 | AF13: 0 | AG13: 0 | AH13: 0
... A97: 44531 | B97: 6220963 | C97: 3182178.4 | D97: 188870 | E97: 372696 | F97: 51400 | G97: 104736 | H97: 229645.4 | I97: 572406.24 | J97: 233281 | K97: 41794 | L97: 67881 | M97: 0 | N97: 63246 | O97: 28037 | P97: 2677 | Q97: 46306 | W97: 104824 | X97: 405363 | Y97: 525622 | Z97: 304173 | AA97: 221449 | AB97: 635652.24 | AD97: 77426 | AE97: 0 | AF97: 0 | AG97: 0 | AH97: 0
A98: 44562 | B98: 5719630 | C98: 2842487.1 | D98: 185403 | E98: 344018 | F98: 42810 | G98: 92900 | H98: 217019.99 | I98: 502701.94 | J98: 215329 | K98: 38644 | L98: 60492 | M98: 0 | N98: 47723 | O98: 40907 | P98: 2661 | Q98: 23332 | W98: 111988 | X98: 439968 | Y98: 511246 | Z98: 258838 | AA98: 252408 | AB98: 550424.94 | AE98: 0 | AF98: 0 | AG98: 0 | AH98: 0
A99: 44593 | B99: 5973372 | C99: 3167490.8 | D99: 193713 | E99: 357227 | F99: 46410 | G99: 105333 | H99: 231947.37 | I99: 353482.87 | J99: 219454 | K99: 37755 | L99: 52974 | M99: 0 | N99: 40630 | O99: 25565 | P99: 1839 | Q99: 11847 | W99: 102478 | X99: 374586 | Y99: 650640 | Z99: 261658 | AA99: 388982 | AB99: 394112.87 | AE99: 0 | AF99: 0 | AG99: 0 | AH99: 0
A100: 44621 | B100: 6036375 | C100: 2996940.2 | D100: 176300 | E100: 355006 | F100: 47140 | G100: 109266 | H100: 215372.04 | I100: 778373.73 | J100: 211474 | K100: 40293 | L100: 58322 | M100: 0 | N100: 73854 | O100: 24678 | P100: 3000 | Q100: 11987 | W100: 111442 | X100: 352459 | Y100: 470468 | Z100: 242578 | AA100: 227890 | AB100: 852227.73 | AD100: 63508 | AE100: 0 | AF100: 0 | AG100: 0 | AH100: 0
A101: 44652 | B101: 6614469 | C101: 3105847.9 | D101: 173413 | E101: 338789 | F101: 49364 | G101: 123200 | H101: 267931.48 | I101: 1054668.6 | J101: 202690 | K101: 50830 | L101: 57767 | M101: 0 | N101: 115979 | O101: 22670 | P101: 3000 | Q101: 24522 | W101: 110156 | X101: 393679 | Y101: 519962 | Z101: 257203 | AA101: 262759 | AB101: 1170647.6 | AD101: 61090 | AE101: 0 | AF101: 0 | AG101: 0 | AH101: 0
A102: 44682 | B102: 7536144 | C102: 3332646.6 | D102: 186465 | E102: 381972 | F102: 66226 | G102: 134268 | H102: 257005.27 | I102: 1500945.1 | J102: 218112 | K102: 47282 | L102: 60742 | M102: 0 | N102: 128870 | O102: 23250 | P102: 9190 | Q102: 64674 | W102: 137154 | X102: 386561 | Y102: 600781 | Z102: 291975 | AA102: 308806 | AB102: 1629815.1 | AD102: 63499 | AE102: 0 | AF102: 0 | AG102: 0 | AH102: 0
A103: 44713 | B103: 8743056 | C103: 3343878.4 | D103: 191180 | E103: 373954 | F103: 64920 | G103: 135646 | H103: 226258.95 | I103: 2130901.6 | J103: 216767 | K103: 69729 | L103: 131317 | M103: 0 | N103: 226263 | O103: 47562 | P103: 4513 | Q103: 74042 | W103: 200798 | X103: 482838 | Y103: 822488 | Z103: 299799 | AA103: 522689 | AB103: 2357164.6 | AD103: 60911 | AE103: 0 | AF103: 0 | AG103: 0 | AH103: 0
A104: 44743 | B104: 8658648 | C104: 2985191.2 | D104: 180624 | E104: 335327 | F104: 66990 | G104: 125766 | H104: 239655.83 | I104: 2485643 | J104: 181196 | K104: 67366 | L104: 129521 | M104: 0 | N104: 222744 | O104: 46061 | P104: 6355 | Q104: 70476 | W104: 188600 | X104: 460050 | Y104: 867082 | Z104: 274978 | AA104: 592104 | AB104: 2708387 | AD104: 64945 | AE104: 0 | AF104: 0 | AG104: 0 | AH104: 0
A105: 44774 | B105: 9488278 | C105: 3657836.1 | D105: 238816 | E105: 389800 | F105: 69480 | G105: 141763 | H105: 279749.7 | I105: 2278104.2 | J105: 202462 | K105: 68389 | L105: 127143 | M105: 0 | N105: 238990 | O105: 58088 | P105: 6748 | Q105: 78711 | W105: 200020 | X105: 509485 | Y105: 942693 | Z105: 328477 | AA105: 614216 | AB105: 2517094.2 | AD105: 79973 | AE105: 0 | AF105: 0 | AG105: 0 | AH105: 0
A106: 44805 | B106: 9620380 | C106: 3972223.6 | D106: 182258 | E106: 370600 | F106: 70960 | G106: 129726 | H106: 279735.37 | I106: 1988413 | J106: 144397 | K106: 59150 | L106: 126966 | M106: 0 | N106: 209950 | O106: 49648 | P106: 14349 | Q106: 74107 | W106: 197340 | X106: 792745 | Y106: 957812 | Z106: 371840 | AA106: 585972 | AB106: 2198363 | AD106: 128837 | AE106: 0 | AF106: 0 | AG106: 0 | AH106: 0
A107: 44835 | B107: 7608376 | C107: 3026538 | D107: 201410 | E107: 352020 | F107: 62050 | G107: 145774 | H107: 275237.47 | I107: 1469216.3 | J107: 304172 | K107: 47679 | L107: 93814 | M107: 0 | N107: 143116 | O107: 29278 | P107: 7337.3 | Q107: 64072 | W107: 133610 | X107: 595968 | Y107: 657084 | Z107: 337505 | AA107: 319579 | AB107: 1612332.3 | AD107: 135269 | AE107: 0 | AF107: 0 | AG107: 0 | AH107: 0
A108: 44866 | B108: 8270405 | C108: 3955547.5 | D108: 261890 | E108: 399870 | F108: 73590 | G108: 160396 | H108: 274731.02 | I108: 1233452.5 | J108: 258047 | K108: 56060 | L108: 72060 | M108: 0 | N108: 130337 | O108: 42146 | P108: 6492 | Q108: 61394 | W108: 119820 | X108: 509994 | Y108: 654578 | Z108: 378554 | AA108: 276024 | AB108: 1363789.5 | AD108: 98952 | AE108: 0 | AF108: 0 | AG108: 0 | AH108: 0
A109: 44896 | B109: 6285639 | C109: 3000351.5 | D109: 189301 | E109: 364897 | F109: 66390 | G109: 207432 | H109: 284045.88 | I109: 556257.59 | J109: 229681 | K109: 44577 | L109: 91252 | M109: 0 | N109: 47314 | O109: 30935 | P109: 3918 | Q109: 49088 | W109: 105310 | X109: 408265 | Y109: 606624 | Z109: 330635 | AA109: 275989 | AB109: 603571.59 | AD109: 79105 | AE109: 0 | AF109: 0 | AG109: 0 | AH109: 0
A110: 44927 | B110: 6116888 | C110: 2907283 | D110: 203969 | E110: 366341 | F110: 64380 | G110: 206177 | H110: 274256 | I110: 556060 | J110: 217300 | K110: 39987 | L110: 69190 | M110: 0 | N110: 45634 | O110: 21361 | P110: 3960 | Q110: 46743 | T110: 0 | U110: 0 | V110: 120500 | W110: 95650 | X110: 318713 | Y110: 559384 | Z110: 291933 | AA110: 267451 | AB110: 601694 | AD110: 42482 | AE110: 0 | AF110: 0 | AG110: 0 | AH110: 0
A111: 44958 | B111: 6266442 | C111: 3003711 | D111: 199047 | E111: 344682 | F111: 59850 | G111: 180898 | H111: 266331 | I111: 601288 | J111: 228400 | K111: 42292 | L111: 66777 | M111: 0 | N111: 53805 | O111: 25635 | P111: 3751 | Q111: 32839 | T111: 0 | U111: 0 | V111: 111300 | W111: 97450 | X111: 401557 | Y111: 546828 | Z111: 330857 | AA111: 215971 | AB111: 655093 | AD111: 66007 | AE111: 0 | AF111: 0 | AG111: 0 | AH111: 0
A112: 44986 | B112: 6828592 | C112: 3087483 | D112: 208188 | E112: 371708 | F112: 62330 | G112: 161082 | H112: 290893 | I112: 869346 | J112: 244523 | K112: 53343 | L112: 77615 | N112: 87303 | O112: 29052 | P112: 4863 | Q112: 60432 | T112: 0 | U112: 0 | V112: 128500 | W112: 105840 | X112: 422423 | Y112: 563668 | Z112: 362033 | AA112: 201635 | AB112: 956649 | AD112: 65226 | AE112: 0 | AF112: 0 | AG112: 0 | AH112: 0
A113: 45017 | B113: 6998355 | C113: 2888262 | D113: 203002 | E113: 343942 | F113: 60020 | G113: 130668 | H113: 296464 | I113: 1134981 | J113: 221077 | K113: 51421 | L113: 84792 | N113: 105975 | O113: 33207 | P113: 5858 | Q113: 55411 | T113: 0 | U113: 0 | V113: 171500 | W113: 112930 | X113: 505398 | Y113: 593447 | Z113: 334481 | AA113: 258966 | AB113: 1240956 | AD113: 98989 | AE113: 0 | AF113: 0 | AG113: 0 | AH113: 0
A114: 45047 | B114: 8625441 | C114: 3325897 | D114: 217017 | E114: 395100 | F114: 70780 | G114: 134571 | H114: 333422 | I114: 1674901 | J114: 246200 | K114: 67214 | L114: 129786 | N114: 162347 | O114: 34087 | P114: 9007 | Q114: 69546 | T114: 0 | U114: 0 | V114: 241758 | W114: 158700 | X114: 580251 | Y114: 774857 | Z114: 378813 | AA114: 396044 | AB114: 1837248 | AD114: 100765 | AE114: 0 | AF114: 0 | AG114: 0 | AH114: 0
A115: 45078 | B115: 9164894 | C115: 3168628 | D115: 196368 | E115: 377740 | F115: 69220 | G115: 130018 | H115: 325721 | I115: 2088084 | J115: 221800 | K115: 56861 | L115: 153093 | N115: 185045 | O115: 35804 | P115: 11908 | Q115: 63058 | T115: 0 | U115: 0 | V115: 309600 | W115: 197740 | X115: 654247 | Y115: 919959 | Z115: 338399 | AA115: 581560 | AB115: 2273129 | AD115: 122163 | AE115: 0 | AF115: 0 | AG115: 0 | AH115: 0
A116: 45108 | B116: 8395978 | C116: 2247388 | D116: 231950 | E116: 401450 | F116: 66610 | G116: 124539 | H116: 366511 | I116: 2235244 | J116: 230400 | K116: 49612 | L116: 149108 | N116: 186865 | O116: 43768 | P116: 14113 | Q116: 67884 | T116: 0 | U116: 0 | V116: 355700 | W116: 191240 | X116: 578961 | Y116: 854635 | Z116: 301258 | AA116: 553377 | AB116: 2422109 | AD116: 101445 | AE116: 0 | AF116: 0 | AG116: 0 | AH116: 0
A117: 45139 | B117: 10021052 | C117: 3687850 | D117: 212471 | E117: 386230 | F117: 63030 | G117: 123688 | H117: 315255 | I117: 2261709 | J117: 220600 | K117: 63082 | L117: 196791 | N117: 245701 | O117: 33881 | P117: 12424 | Q117: 62895 | T117: 0 | U117: 0 | V117: 355100 | W117: 182220 | X117: 574170 | Y117: 1023955 | Z117: 353508 | AA117: 670447 | AB117: 2507410 | AD117: 132118 | AE117: 0 | AF117: 0 | AG117: 0 | AH117: 0
A118: 45170 | B118: 9234983 | C118: 3068198 | D118: 210702 | E118: 397330 | F118: 60020 | G118: 125072 | H118: 309832 | I118: 2087766 | J118: 228100 | K118: 48820 | L118: 133636 | N118: 172602 | O118: 57403 | P118: 8392 | Q118: 58131 | T118: 0 | U118: 37989 | V118: 332800 | W118: 174560 | X118: 798145 | Y118: 925485 | Z118: 370944 | AA118: 554541 | AB118: 2260368 | AD118: 123050 | AE118: 0 | AF118: 0 | AG118: 0 | AH118: 0
A119: 45200 | B119: 8906994 | C119: 3472720 | D119: 209344 | E119: 401070 | F119: 60560 | G119: 130293 | H119: 330878 | I119: 1682178 | J119: 234800 | K119: 54006 | L119: 129915 | N119: 161279 | O119: 30563 | P119: 6860 | Q119: 55225 | T119: 0 | U119: 37989 | V119: 273600 | W119: 141370 | X119: 695080 | Y119: 799264 | Z119: 377527 | AA119: 421737 | AB119: 1843457 | AD119: 129469 | AE119: 0 | AF119: 0 | AG119: 0 | AH119: 0
A120: 45231 | B120: 7592642 | C120: 3137873 | D120: 209208 | E120: 401387 | F120: 61030 | G120: 132665 | H120: 335333 | I120: 1145718 | J120: 240600 | K120: 52505 | L120: 114445 | N120: 110214 | O120: 45235 | P120: 6132 | Q120: 48733 | T120: 0 | U120: 37989 | V120: 188800 | W120: 116120 | X120: 542826 | Y120: 665829 | Z120: 389105 | AA120: 276724 | AB120: 1255932 | AD120: 81480 | AE120: 0 | AF120: 0 | AG120: 0 | AH120: 0
A121: 45261 | B121: 6470056 | C121: 2881577 | D121: 187500 | E121: 362093 | F121: 58940 | G121: 141268 | H121: 297075 | I121: 760035 | J121: 205900 | K121: 47269 | L121: 92079 | N121: 63014 | O121: 26483 | P121: 3860 | Q121: 40280 | T121: 0 | U121: 37989 | V121: 157500 | W121: 102910 | X121: 423456 | Y121: 580828 | Z121: 332453 | AA121: 248375 | AB121: 823049 | AD121: 61721 | AE121: 0 | AF121: 0 | AG121: 0 | AH121: 0
A122: 45292 | B122: 6692267 | C122: 3287729 | D122: 208974 | E122: 396860 | F122: 58410 | G122: 149803 | H122: 338199 | I122: 578170 | J122: 227300 | K122: 41306 | L122: 88012 | N122: 40751 | O122: 27266 | P122: 4854 | Q122: 43154 | T122: 0 | U122: 40620 | V122: 142000 | W122: 110960 | X122: 290247 | Y122: 617652 | Z122: 349422 | AA122: 268230 | AB122: 618921 | AD122: 41708 | AE122: 0 | AF122: 0 | AG122: 0 | AH122: 0
A123: 45323 | B123: 6654580 | C123: 3141372 | D123: 237623 | E123: 372509 | F123: 58160 | G123: 126061 | H123: 326079 | I123: 682091 | J123: 216300 | K123: 38954 | L123: 71168 | N123: 59396 | O123: 28310 | P123: 4703 | Q123: 39420 | S123: 1879 | T123: 0 | U123: 59861 | V123: 136800 | W123: 90700 | X123: 359002 | Y123: 604192 | Z123: 351548 | AA123: 252644 | AB123: 741487 | AD123: 58086 | AE123: 0 | AF123: 0 | AG123: 0 | AH123: 0
...

Sheet Monthly Electricity (Processed)
A1: Period | B1: On-Campus Buildings 12-Month Rolling Sum | C1: Total + TKOJCH | D1: On-Campus Buildings Monthly Total | E1: Monthly Total + TKOJCH
A2: 41640 | D2: 5938547 | E2: 5938547
A3: 41671 | D3: 5888877 | E3: 5888877
A4: 41699 | D4: 6018786 | E4: 6018786
A5: 41730 | D5: 7488350 | E5: 7488350
A6: 41760 | D6: 7986119 | E6: 7986119
A7: 41791 | D7: 8876152 | E7: 8876152
A8: 41821 | D8: 9340526 | E8: 9340526
A9: 41852 | D9: 8583907 | E9: 8583907
A10: 41883 | D10: 10023872 | E10: 10023872
A11: 41913 | D11: 8035429 | E11: 8035429
A12: 41944 | D12: 6858052 | E12: 6858052
A13: 41974 | D13: 6405579 | E13: 6405579
... A18: 42125 | D18: 8190535 | E18: 8190535
A19: 42156 | B19: 93067207 | C19: 93067207 | D19: 9712387 | E19: 9712387
A20: 42186 | B20: 92560708 | D20: 8834027 | E20: 8834027
A21: 42217 | B21: 92658683 | D21: 8681882 | E21: 8681882
A22: 42248 | B22: 92589207 | D22: 9954396 | E22: 9954396
A23: 42278 | B23: 92906500 | D23: 8352722 | E23: 8352722
A24: 42309 | B24: 94099443 | D24: 8050995 | E24: 8050995
A25: 42339 | B25: 94187317 | D25: 6493453 | E25: 6493453
A26: 42370 | B26: 94394903 | D26: 6245223 | E26: 6245223
A27: 42401 | B27: 95166272 | D27: 6466884 | E27: 6466884
A28: 42430 | B28: 94971369 | D28: 6613470 | E28: 6613470
A29: 42461 | B29: 95180695 | D29: 7584721 | E29: 7584721
A30: 42491 | B30: 95720512 | D30: 8730352 | E30: 8730352
A31: 42522 | B31: 95800070 | C31: 95800070 | D31: 9791945 | E31: 9791945
A32: 42552 | B32: 96134757 | D32: 9168714 | E32: 9168714
A33: 42583 | B33: 96947485 | D33: 9494610 | E33: 9494610
A34: 42614 | B34: 96474873 | D34: 9481784 | E34: 9481784
A35: 42644 | B35: 96161212 | D35: 8039061 | E35: 8039061
A36: 42675 | B36: 96368281 | D36: 8258064 | E36: 8258064
A37: 42705 | B37: 96342853 | D37: 6468025 | E37: 6468025
A38: 42736 | B38: 95623203 | D38: 5525573 | E38: 5525573
A39: 42767 | B39: 95982844 | D39: 6826525 | E39: 6826525
A40: 42795 | B40: 96253205 | D40: 6883831 | E40: 6883831
A41: 42826 | B41: 95356819 | D41: 6688335 | E41: 6688335
A42: 42856 | B42: 94764032 | D42: 8137565 | E42: 8137565
A43: 42887 | B43: 94486358 | C43: 94486358 | D43: 9514271 | E43: 9514271
A44: 42917 | B44: 93560730 | D44: 8243086 | E44: 8243086
...

Sheet Monthly Electricity Reformatted
A1: Period | B1: Main Academic Buildings and Others | C1: Main Chiller Plant | D1: LSK Chiller Plant | E1: Cheng Yu Tung Building | F1: LSK Building | G1: IAS Building | H1: HPC 6 | I1: Research Building 2 | J1: Innovation Building | K1: Conference Lodge | L1: Staff Quarter Common Area | M1: Student Housing | N1: Staff Quarters | O1: Commercial Outlets | P1: Staff Quarters & Commercial Outlet | Q1: Whole Campus (including staff quarter common area) | R1: Whole Campus (excluding staff quarter common area)
A2: 44013 | B2: =SUM('Monthly Electricity (Overview)'!C80:D80)+SUM('Monthly Electricity (Overview)'!F80:H80)+SUM('Monthly Electricity (Overview)'!O80:Q80) -> 4086378.4 | C2: ='Monthly Electricity (Overview)'!I80 -> 2154407.6 | D2: ='Monthly Electricity (Overview)'!N80 -> 242508 | E2: ='Monthly Electricity (Overview)'!E80 -> 404540 | F2: ='Monthly Electricity (Overview)'!J80 -> 231715 | G2: ='Monthly Electricity (Overview)'!K80 -> 83182 | K2: ='Monthly Electricity (Overview)'!L80 -> 140263 | L2: 99693 | M2: =SUM('Monthly Electricity (Overview)'!U80:X80)+'Monthly Electricity (Overview)'!AD80 -> 526454 | N2: ='Monthly Electricity (Overview)'!AA80 -> 760101 | O2: ='Monthly Electricity (Overview)'!Z80 -> 265659 | P2: ='Monthly Electricity (Overview)'!Y80 -> 1025760 | Q2: =SUM(B2:P2)-P2 -> 8994901 | R2: =SUM(B2:O2)-L2 -> 8895208
A3: 44044 | B3: =SUM('Monthly Electricity (Overview)'!C81:D81)+SUM('Monthly Electricity (Overview)'!F81:H81)+SUM('Monthly Electricity (Overview)'!O81:Q81) -> 3248295.5 | C3: ='Monthly Electricity (Overview)'!I81 -> 2394486.5 | D3: ='Monthly Electricity (Overview)'!N81 -> 229261 | E3: ='Monthly Electricity (Overview)'!E81 -> 348726 | F3: ='Monthly Electricity (Overview)'!J81 -> 200857 | G3: ='Monthly Electricity (Overview)'!K81 -> 76791 | K3: ='Monthly Electricity (Overview)'!L81 -> 121644 | L3: 111077 | M3: =SUM('Monthly Electricity (Overview)'!U81:X81)+'Monthly Electricity (Overview)'!AD81 -> 551691 | N3: ='Monthly Electricity (Overview)'!AA81 -> 598243 | O3: ='Monthly Electricity (Overview)'!Z81 -> 232096 | P3: ='Monthly Electricity (Overview)'!Y81 -> 830339 | Q3: =SUM(B3:P3)-P3 -> 8113168 | R3: =SUM(B3:O3)-L3 -> 8002091
A4: 44075 | B4: =SUM('Monthly Electricity (Overview)'!C82:D82)+SUM('Monthly Electricity (Overview)'!F82:H82)+SUM('Monthly Electricity (Overview)'!O82:Q82) -> 4666264.6 | C4: ='Monthly Electricity (Overview)'!I82 -> 2048304.4 | D4: ='Monthly Electricity (Overview)'!N82 -> 227888 | E4: ='Monthly Electricity (Overview)'!E82 -> 401301 | F4: ='Monthly Electricity (Overview)'!J82 -> 250434 | G4: ='Monthly Electricity (Overview)'!K82 -> 74921 | K4: ='Monthly Electricity (Overview)'!L82 -> 130572 | L4: 124553 | M4: =SUM('Monthly Electricity (Overview)'!U82:X82)+'Monthly Electricity (Overview)'!AD82 -> 974645 | N4: ='Monthly Electricity (Overview)'!AA82 -> 623207 | O4: ='Monthly Electricity (Overview)'!Z82 -> 303922 | P4: ='Monthly Electricity (Overview)'!Y82 -> 927129 | Q4: =SUM(B4:P4)-P4 -> 9826012 | R4: =SUM(B4:O4)-L4 -> 9701459
A5: 44105 | B5: =SUM('Monthly Electricity (Overview)'!C83:D83)+SUM('Monthly Electricity (Overview)'!F83:H83)+SUM('Monthly Electricity (Overview)'!O83:Q83) -> 3898002.6 | C5: ='Monthly Electricity (Overview)'!I83 -> 1335753.4 | D5: ='Monthly Electricity (Overview)'!N83 -> 152364 | E5: ='Monthly Electricity (Overview)'!E83 -> 373141 | F5: ='Monthly Electricity (Overview)'!J83 -> 232357 | G5: ='Monthly Electricity (Overview)'!K83 -> 54482 | K5: ='Monthly Electricity (Overview)'!L83 -> 100678 | L5: 81463 | M5: =SUM('Monthly Electricity (Overview)'!U83:X83)+'Monthly Electricity (Overview)'!AD83 -> 592456 | N5: ='Monthly Electricity (Overview)'!AA83 -> 320386 | O5: ='Monthly Electricity (Overview)'!Z83 -> 267278 | P5: ='Monthly Electricity (Overview)'!Y83 -> 587664 | Q5: =SUM(B5:P5)-P5 -> 7408361 | R5: =SUM(B5:O5)-L5 -> 7326898
A6: 44136 | B6: =SUM('Monthly Electricity (Overview)'!C84:D84)+SUM('Monthly Electricity (Overview)'!F84:H84)+SUM('Monthly Electricity (Overview)'!O84:Q84) -> 4027716.6 | C6: ='Monthly Electricity (Overview)'!I84 -> 915177.39 | D6: ='Monthly Electricity (Overview)'!N84 -> 98770 | E6: ='Monthly Electricity (Overview)'!E84 -> 396796 | F6: ='Monthly Electricity (Overview)'!J84 -> 234747 | G6: ='Monthly Electricity (Overview)'!K84 -> 51126 | K6: ='Monthly Electricity (Overview)'!L84 -> 81285 | L6: 59032 | M6: =SUM('Monthly Electricity (Overview)'!U84:X84)+'Monthly Electricity (Overview)'!AD84 -> 507861 | N6: ='Monthly Electricity (Overview)'!AA84 -> 232228 | O6: ='Monthly Electricity (Overview)'!Z84 -> 293224 | P6: ='Monthly Electricity (Overview)'!Y84 -> 525452 | Q6: =SUM(B6:P6)-P6 -> 6897963 | R6: =SUM(B6:O6)-L6 -> 6838931
A7: 44166 | B7: =SUM('Monthly Electricity (Overview)'!C85:D85)+SUM('Monthly Electricity (Overview)'!F85:H85)+SUM('Monthly Electricity (Overview)'!O85:Q85) -> 3623050.2 | C7: ='Monthly Electricity (Overview)'!I85 -> 506804.8 | D7: ='Monthly Electricity (Overview)'!N85 -> 50904 | E7: ='Monthly Electricity (Overview)'!E85 -> 380382 | F7: ='Monthly Electricity (Overview)'!J85 -> 232272 | G7: ='Monthly Electricity (Overview)'!K85 -> 47403 | K7: ='Monthly Electricity (Overview)'!L85 -> 48764 | L7: 53030 | M7: =SUM('Monthly Electricity (Overview)'!U85:X85)+'Monthly Electricity (Overview)'!AD85 -> 433833 | N7: ='Monthly Electricity (Overview)'!AA85 -> 250102 | O7: ='Monthly Electricity (Overview)'!Z85 -> 259382 | P7: ='Monthly Electricity (Overview)'!Y85 -> 509484 | Q7: =SUM(B7:P7)-P7 -> 5885927 | R7: =SUM(B7:O7)-L7 -> 5832897
A8: 44197 | B8: =SUM('Monthly Electricity (Overview)'!C86:D86)+SUM('Monthly Electricity (Overview)'!F86:H86)+SUM('Monthly Electricity (Overview)'!O86:Q86) -> 3569274.8 | C8: ='Monthly Electricity (Overview)'!I86 -> 393066.22 | D8: ='Monthly Electricity (Overview)'!N86 -> 47672 | E8: ='Monthly Electricity (Overview)'!E86 -> 382076 | F8: ='Monthly Electricity (Overview)'!J86 -> 223334 | G8: ='Monthly Electricity (Overview)'!K86 -> 44857 | K8: ='Monthly Electricity (Overview)'!L86 -> 48817 | L8: 48369 | M8: =SUM('Monthly Electricity (Overview)'!U86:X86)+'Monthly Electricity (Overview)'!AD86 -> 468058 | N8: ='Monthly Electricity (Overview)'!AA86 -> 337663 | O8: ='Monthly Electricity (Overview)'!Z86 -> 249052 | P8: ='Monthly Electricity (Overview)'!Y86 -> 586715 | Q8: =SUM(B8:P8)-P8 -> 5812239 | R8: =SUM(B8:O8)-L8 -> 5763870
A9: 44228 | B9: =SUM('Monthly Electricity (Overview)'!C87:D87)+SUM('Monthly Electricity (Overview)'!F87:H87)+SUM('Monthly Electricity (Overview)'!O87:Q87) -> 3434871 | C9: ='Monthly Electricity (Overview)'!I87 -> 528780.96 | D9: ='Monthly Electricity (Overview)'!N87 -> 52226 | E9: ='Monthly Electricity (Overview)'!E87 -> 321055 | F9: ='Monthly Electricity (Overview)'!J87 -> 197886 | G9: ='Monthly Electricity (Overview)'!K87 -> 40970 | K9: ='Monthly Electricity (Overview)'!L87 -> 42444 | L9: 45841 | M9: =SUM('Monthly Electricity (Overview)'!U87:X87)+'Monthly Electricity (Overview)'!AD87 -> 447420 | N9: ='Monthly Electricity (Overview)'!AA87 -> 185977 | O9: ='Monthly Electricity (Overview)'!Z87 -> 237507 | P9: ='Monthly Electricity (Overview)'!Y87 -> 423484 | Q9: =SUM(B9:P9)-P9 -> 5534978 | R9: =SUM(B9:O9)-L9 -> 5489137
A10: 44256 | B10: =SUM('Monthly Electricity (Overview)'!C88:D88)+SUM('Monthly Electricity (Overview)'!F88:H88)+SUM('Monthly Electricity (Overview)'!O88:Q88) -> 4228426.4 | C10: ='Monthly Electricity (Overview)'!I88 -> 785188.6 | D10: ='Monthly Electricity (Overview)'!N88 -> 77337 | E10: ='Monthly Electricity (Overview)'!E88 -> 392798 | F10: ='Monthly Electricity (Overview)'!J88 -> 242322 | G10: ='Monthly Electricity (Overview)'!K88 -> 52128 | K10: ='Monthly Electricity (Overview)'!L88 -> 54444 | L10: 55029 | M10: =SUM('Monthly Electricity (Overview)'!U88:X88)+'Monthly Electricity (Overview)'!AD88 -> 498639 | N10: ='Monthly Electricity (Overview)'!AA88 -> 236455 | O10: ='Monthly Electricity (Overview)'!Z88 -> 288377 | P10: ='Monthly Electricity (Overview)'!Y88 -> 524832 | Q10: =SUM(B10:P10)-P10 -> 6911144 | R10: =SUM(B10:O10)-L10 -> 6856115
A11: 44287 | B11: =SUM('Monthly Electricity (Overview)'!C89:D89)+SUM('Monthly Electricity (Overview)'!F89:H89)+SUM('Monthly Electricity (Overview)'!O89:Q89) -> 4095221.4 | C11: ='Monthly Electricity (Overview)'!I89 -> 1050938.6 | D11: ='Monthly Electricity (Overview)'!N89 -> 122683 | E11: ='Monthly Electricity (Overview)'!E89 -> 384122 | F11: ='Monthly Electricity (Overview)'!J89 -> 233551 | G11: ='Monthly Electricity (Overview)'!K89 -> 52762 | K11: ='Monthly Electricity (Overview)'!L89 -> 53047 | L11: 62537 | M11: =SUM('Monthly Electricity (Overview)'!U89:X89)+'Monthly Electricity (Overview)'!AD89 -> 625184 | N11: ='Monthly Electricity (Overview)'!AA89 -> 271666 | O11: ='Monthly Electricity (Overview)'!Z89 -> 282594 | P11: ='Monthly Electricity (Overview)'!Y89 -> 554260 | Q11: =SUM(B11:P11)-P11 -> 7234306 | R11: =SUM(B11:O11)-L11 -> 7171769
A12: 44317 | B12: =SUM('Monthly Electricity (Overview)'!C90:D90)+SUM('Monthly Electricity (Overview)'!F90:H90)+SUM('Monthly Electricity (Overview)'!O90:Q90) -> 4271235.1 | C12: ='Monthly Electricity (Overview)'!I90 -> 1964651.9 | D12: ='Monthly Electricity (Overview)'!N90 -> 200723 | E12: ='Monthly Electricity (Overview)'!E90 -> 367014 | F12: ='Monthly Electricity (Overview)'!J90 -> 209323 | G12: ='Monthly Electricity (Overview)'!K90 -> 63649 | K12: ='Monthly Electricity (Overview)'!L90 -> 77349 | L12: 84771 | M12: =SUM('Monthly Electricity (Overview)'!U90:X90)+'Monthly Electricity (Overview)'!AD90 -> 857498 | N12: ='Monthly Electricity (Overview)'!AA90 -> 579923 | O12: ='Monthly Electricity (Overview)'!Z90 -> 308231 | P12: ='Monthly Electricity (Overview)'!Y90 -> 888154 | Q12: =SUM(B12:P12)-P12 -> 8984368 | R12: =SUM(B12:O12)-L12 -> 8899597
A13: 44348 | B13: =SUM('Monthly Electricity (Overview)'!C91:D91)+SUM('Monthly Electricity (Overview)'!F91:H91)+SUM('Monthly Electricity (Overview)'!O91:Q91) -> 3979044.5 | C13: ='Monthly Electricity (Overview)'!I91 -> 2020738.5 | D13: ='Monthly Electricity (Overview)'!N91 -> 228931 | E13: ='Monthly Electricity (Overview)'!E91 -> 411370 | F13: ='Monthly Electricity (Overview)'!J91 -> 230711 | G13: ='Monthly Electricity (Overview)'!K91 -> 64191 | K13: ='Monthly Electricity (Overview)'!L91 -> 113132 | L13: 90161 | M13: =SUM('Monthly Electricity (Overview)'!U91:X91)+'Monthly Electricity (Overview)'!AD91 -> 752249 | N13: ='Monthly Electricity (Overview)'!AA91 -> 535380 | O13: ='Monthly Electricity (Overview)'!Z91 -> 275823 | P13: ='Monthly Electricity (Overview)'!Y91 -> 811203 | Q13: =SUM(B13:P13)-P13 -> 8701731 | R13: =SUM(B13:O13)-L13 -> 8611570
... A44: 45292 | B44: =SUM('Monthly Electricity (Overview)'!C122:D122)+SUM('Monthly Electricity (Overview)'!F122:H122)+SUM('Monthly Electricity (Overview)'!O122:Q122) -> 4118389 | C44: ='Monthly Electricity (Overview)'!I122 -> 578170 | D44: ='Monthly Electricity (Overview)'!N122 -> 40751 | E44: ='Monthly Electricity (Overview)'!E122 -> 396860 | F44: ='Monthly Electricity (Overview)'!J122 -> 227300 | G44: ='Monthly Electricity (Overview)'!K122 -> 41306 | K44: ='Monthly Electricity (Overview)'!L122 -> 88012 | L44: 50823 | M44: =SUM('Monthly Electricity (Overview)'!U122:X122)+'Monthly Electricity (Overview)'!AD122 -> 625535 | N44: ='Monthly Electricity (Overview)'!AA122 -> 268230 | O44: ='Monthly Electricity (Overview)'!Z122 -> 349422 | P44: ='Monthly Electricity (Overview)'!Y122 -> 617652 | Q44: =SUM(B44:P44)-P44 -> 6784798 | R44: =SUM(B44:O44)-L44 -> 6733975
A45: 45323 | B45: =SUM('Monthly Electricity (Overview)'!C123:D123)+SUM('Monthly Electricity (Overview)'!F123:H123)+SUM('Monthly Electricity (Overview)'!O123:Q123) -> 3961728 | C45: ='Monthly Electricity (Overview)'!I123 -> 682091 | D45: ='Monthly Electricity (Overview)'!N123 -> 59396 | E45: ='Monthly Electricity (Overview)'!E123 -> 372509 | F45: ='Monthly Electricity (Overview)'!J123 -> 216300 | G45: ='Monthly Electricity (Overview)'!K123 -> 38954 | I45: ='Monthly Electricity (Overview)'!S123 -> 1879 | K45: ='Monthly Electricity (Overview)'!L123 -> 71168 | L45: 54165 | M45: =SUM('Monthly Electricity (Overview)'!U123:X123)+'Monthly Electricity (Overview)'!AD123 -> 704449 | N45: ='Monthly Electricity (Overview)'!AA123 -> 252644 | O45: ='Monthly Electricity (Overview)'!Z123 -> 351548 | P45: ='Monthly Electricity (Overview)'!Y123 -> 604192 | Q45: =SUM(B45:P45)-P45 -> 6766831 | R45: =SUM(B45:O45)-L45 -> 6712666
A46: 45352 | B46: =SUM('Monthly Electricity (Overview)'!C124:D124)+SUM('Monthly Electricity (Overview)'!F124:H124)+SUM('Monthly Electricity (Overview)'!O124:Q124) -> 3490692 | C46: ='Monthly Electricity (Overview)'!I124 -> 921046 | D46: ='Monthly Electricity (Overview)'!N124 -> 72772 | E46: ='Monthly Electricity (Overview)'!E124 -> 367021 | F46: ='Monthly Electricity (Overview)'!J124 -> 217900 | G46: ='Monthly Electricity (Overview)'!K124 -> 42295 | I46: ='Monthly Electricity (Overview)'!S124 -> 5290 | K46: ='Monthly Electricity (Overview)'!L124 -> 88712 | L46: 46664 | M46: =SUM('Monthly Electricity (Overview)'!U124:X124)+'Monthly Electricity (Overview)'!AD124 -> 854152 | N46: ='Monthly Electricity (Overview)'!AA124 -> 269197 | O46: ='Monthly Electricity (Overview)'!Z124 -> 350051 | P46: ='Monthly Electricity (Overview)'!Y124 -> 619248 | Q46: =SUM(B46:P46)-P46 -> 6725792 | R46: =SUM(B46:O46)-L46 -> 6679128
A47: 45383 | B47: =SUM('Monthly Electricity (Overview)'!C125:D125)+SUM('Monthly Electricity (Overview)'!F125:H125)+SUM('Monthly Electricity (Overview)'!O125:Q125) -> 4423922 | C47: ='Monthly Electricity (Overview)'!I125 -> 1608077 | D47: ='Monthly Electricity (Overview)'!N125 -> 116582 | E47: ='Monthly Electricity (Overview)'!E125 -> 452750 | F47: ='Monthly Electricity (Overview)'!J125 -> 248500 | G47: ='Monthly Electricity (Overview)'!K125 -> 48452 | I47: ='Monthly Electricity (Overview)'!S125 -> 7974 | K47: ='Monthly Electricity (Overview)'!L125 -> 116672 | L47: 76596 | M47: =SUM('Monthly Electricity (Overview)'!U125:X125)+'Monthly Electricity (Overview)'!AD125 -> 1273246 | N47: ='Monthly Electricity (Overview)'!AA125 -> 440626 | O47: ='Monthly Electricity (Overview)'!Z125 -> 399926 | P47: ='Monthly Electricity (Overview)'!Y125 -> 840552 | Q47: =SUM(B47:P47)-P47 -> 9213323 | R47: =SUM(B47:O47)-L47 -> 9136727
A48: 45413 | B48: =SUM('Monthly Electricity (Overview)'!C126:D126)+SUM('Monthly Electricity (Overview)'!F126:H126)+SUM('Monthly Electricity (Overview)'!O126:Q126) -> 3913685 | C48: ='Monthly Electricity (Overview)'!I126 -> 1626912 | D48: ='Monthly Electricity (Overview)'!N126 -> 101590 | E48: ='Monthly Electricity (Overview)'!E126 -> 410970 | F48: ='Monthly Electricity (Overview)'!J126 -> 231500 | G48: ='Monthly Electricity (Overview)'!K126 -> 42471 | I48: ='Monthly Electricity (Overview)'!S126 -> 10102 | K48: ='Monthly Electricity (Overview)'!L126 -> 113551 | L48: 69174 | M48: =SUM('Monthly Electricity (Overview)'!U126:X126)+'Monthly Electricity (Overview)'!AD126 -> 1308291 | N48: ='Monthly Electricity (Overview)'!AA126 -> 389597 | O48: ='Monthly Electricity (Overview)'!Z126 -> 380344 | P48: ='Monthly Electricity (Overview)'!Y126 -> 769941 | Q48: =SUM(B48:P48)-P48 -> 8598187 | R48: =SUM(B48:O48)-L48 -> 8529013
A49: 45444 | B49: =SUM('Monthly Electricity (Overview)'!C127:D127)+SUM('Monthly Electricity (Overview)'!F127:H127)+SUM('Monthly Electricity (Overview)'!O127:Q127) -> 3562315 | C49: ='Monthly Electricity (Overview)'!I127 -> 2083326 | D49: ='Monthly Electricity (Overview)'!N127 -> 166930 | E49: ='Monthly Electricity (Overview)'!E127 -> 396960 | F49: ='Monthly Electricity (Overview)'!J127 -> 211700 | G49: ='Monthly Electricity (Overview)'!K127 -> 59734 | I49: ='Monthly Electricity (Overview)'!S127 -> 10738 | K49: ='Monthly Electricity (Overview)'!L127 -> 167321 | L49: 89300 | M49: =SUM('Monthly Electricity (Overview)'!U127:X127)+'Monthly Electricity (Overview)'!AD127 -> 1222168 | N49: ='Monthly Electricity (Overview)'!AA127 -> 545833 | O49: ='Monthly Electricity (Overview)'!Z127 -> 335002 | P49: ='Monthly Electricity (Overview)'!Y127 -> 880835 | Q49: =SUM(B49:P49)-P49 -> 8851327 | R49: =SUM(B49:O49)-L49 -> 8762027
A50: 45474 | B50: =SUM('Monthly Electricity (Overview)'!C128:D128)+SUM('Monthly Electricity (Overview)'!F128:H128)+SUM('Monthly Electricity (Overview)'!O128:Q128) -> 4315786 | C50: ='Monthly Electricity (Overview)'!I128 -> 2536101 | D50: ='Monthly Electricity (Overview)'!N128 -> 146460 | E50: ='Monthly Electricity (Overview)'!E128 -> 452350 | F50: ='Monthly Electricity (Overview)'!J128 -> 242000 | G50: ='Monthly Electricity (Overview)'!K128 -> 49635 | I50: ='Monthly Electricity (Overview)'!S128 -> 12602 | J50: ='Monthly Electricity (Overview)'!T128 -> 0 | K50: ='Monthly Electricity (Overview)'!L128 -> 148622 | L50: 96675 | M50: =SUM('Monthly Electricity (Overview)'!U128:X128)+'Monthly Electricity (Overview)'!AD128 -> 1489580 | N50: ='Monthly Electricity (Overview)'!AA128 -> 698723 | O50: ='Monthly Electricity (Overview)'!Z128 -> 365544 | P50: ='Monthly Electricity (Overview)'!Y128 -> 1064267 | Q50: =SUM(B50:P50)-P50 -> 10554078 | R50: =SUM(B50:O50)-L50 -> 10457403
A51: 45505 | B51: =SUM('Monthly Electricity (Overview)'!C129:D129)+SUM('Monthly Electricity (Overview)'!F129:H129)+SUM('Monthly Electricity (Overview)'!O129:Q129) -> 4038667 | C51: ='Monthly Electricity (Overview)'!I129 -> 2339192 | D51: ='Monthly Electricity (Overview)'!N129 -> 171979 | E51: ='Monthly Electricity (Overview)'!E129 -> 430560 | F51: ='Monthly Electricity (Overview)'!J129 -> 245100 | G51: ='Monthly Electricity (Overview)'!K129 -> 56920 | I51: ='Monthly Electricity (Overview)'!S129 -> 12862 | J51: ='Monthly Electricity (Overview)'!T129 -> 0 | K51: ='Monthly Electricity (Overview)'!L129 -> 181289 | L51: 102262 | M51: =SUM('Monthly Electricity (Overview)'!U129:X129)+'Monthly Electricity (Overview)'!AD129 -> 1382991 | N51: ='Monthly Electricity (Overview)'!AA129 -> 655351 | O51: ='Monthly Electricity (Overview)'!Z129 -> 369772 | P51: ='Monthly Electricity (Overview)'!Y129 -> 1025123 | Q51: =SUM(B51:P51)-P51 -> 9986945 | R51: =SUM(B51:O51)-L51 -> 9884683
A52: 45536 | B52: =SUM('Monthly Electricity (Overview)'!C130:D130)+SUM('Monthly Electricity (Overview)'!F130:H130)+SUM('Monthly Electricity (Overview)'!O130:Q130) -> 4312478 | C52: ='Monthly Electricity (Overview)'!I130 -> 2259366 | D52: ='Monthly Electricity (Overview)'!N130 -> 166126 | E52: ='Monthly Electricity (Overview)'!E130 -> 411230 | F52: ='Monthly Electricity (Overview)'!J130 -> 247100 | G52: ='Monthly Electricity (Overview)'!K130 -> 52628 | I52: ='Monthly Electricity (Overview)'!S130 -> 15342 | J52: ='Monthly Electricity (Overview)'!T130 -> 0 | K52: ='Monthly Electricity (Overview)'!L130 -> 163882 | L52: 94188 | M52: =SUM('Monthly Electricity (Overview)'!U130:X130)+'Monthly Electricity (Overview)'!AD130 -> 1637729 | N52: ='Monthly Electricity (Overview)'!AA130 -> 638681 | O52: ='Monthly Electricity (Overview)'!Z130 -> 418704 | P52: ='Monthly Electricity (Overview)'!Y130 -> 1057385 | Q52: =SUM(B52:P52)-P52 -> 10417454 | R52: =SUM(B52:O52)-L52 -> 10323266
A53: 45566 | B53: =SUM('Monthly Electricity (Overview)'!C131:D131)+SUM('Monthly Electricity (Overview)'!F131:H131)+SUM('Monthly Electricity (Overview)'!O131:Q131) -> 4180749 | C53: ='Monthly Electricity (Overview)'!I131 -> 1681166 | D53: ='Monthly Electricity (Overview)'!N131 -> 120288 | E53: ='Monthly Electricity (Overview)'!E131 -> 410000 | F53: ='Monthly Electricity (Overview)'!J131 -> 251900 | G53: ='Monthly Electricity (Overview)'!K131 -> 45340 | I53: ='Monthly Electricity (Overview)'!S131 -> 12002 | J53: ='Monthly Electricity (Overview)'!T131 -> 0 | K53: ='Monthly Electricity (Overview)'!L131 -> 117930 | L53: 74174 | M53: =SUM('Monthly Electricity (Overview)'!U131:X131)+'Monthly Electricity (Overview)'!AD131 -> 1326153 | N53: ='Monthly Electricity (Overview)'!AA131 -> 422468 | O53: ='Monthly Electricity (Overview)'!Z131 -> 413057 | P53: ='Monthly Electricity (Overview)'!Y131 -> 835525 | Q53: =SUM(B53:P53)-P53 -> 9055227 | R53: =SUM(B53:O53)-L53 -> 8981053
A54: 45597 | B54: =SUM('Monthly Electricity (Overview)'!C132:D132)+SUM('Monthly Electricity (Overview)'!F132:H132)+SUM('Monthly Electricity (Overview)'!O132:Q132) -> 4486491 | C54: ='Monthly Electricity (Overview)'!I132 -> 1208974 | D54: ='Monthly Electricity (Overview)'!N132 -> 108966 | E54: ='Monthly Electricity (Overview)'!E132 -> 386500 | F54: ='Monthly Electricity (Overview)'!J132 -> 241600 | G54: ='Monthly Electricity (Overview)'!K132 -> 54146 | I54: ='Monthly Electricity (Overview)'!S132 -> 5447 | J54: ='Monthly Electricity (Overview)'!T132 -> 0 | K54: ='Monthly Electricity (Overview)'!L132 -> 116907 | L54: 69509 | M54: =SUM('Monthly Electricity (Overview)'!U132:X132)+'Monthly Electricity (Overview)'!AD132 -> 1050654 | N54: ='Monthly Electricity (Overview)'!AA132 -> 294258 | O54: ='Monthly Electricity (Overview)'!Z132 -> 402470 | P54: ='Monthly Electricity (Overview)'!Y132 -> 696728 | Q54: =SUM(B54:P54)-P54 -> 8425922 | R54: =SUM(B54:O54)-L54 -> 8356413
A55: 45627 | B55: =SUM('Monthly Electricity (Overview)'!C133:D133)+SUM('Monthly Electricity (Overview)'!F133:H133)+SUM('Monthly Electricity (Overview)'!O133:Q133) -> 4283226 | C55: ='Monthly Electricity (Overview)'!I133 -> 668561 | D55: ='Monthly Electricity (Overview)'!N133 -> 47641 | E55: ='Monthly Electricity (Overview)'!E133 -> 439800 | F55: ='Monthly Electricity (Overview)'!J133 -> 261300 | G55: ='Monthly Electricity (Overview)'!K133 -> 39693 | I55: ='Monthly Electricity (Overview)'!S133 -> 9029 | J55: ='Monthly Electricity (Overview)'!T133 -> 37973 | K55: ='Monthly Electricity (Overview)'!L133 -> 75231 | L55: 42277 | M55: =SUM('Monthly Electricity (Overview)'!U133:X133)+'Monthly Electricity (Overview)'!AD133 -> 807015 | N55: ='Monthly Electricity (Overview)'!AA133 -> 248724 | O55: ='Monthly Electricity (Overview)'!Z133 -> 386220 | P55: ='Monthly Electricity (Overview)'!Y133 -> 634944 | Q55: =SUM(B55:P55)-P55 -> 7346690 | R55: =SUM(B55:O55)-L55 -> 7304413
A56: 45658 | B56: =SUM('Monthly Electricity (Overview)'!C134:D134)+SUM('Monthly Electricity (Overview)'!F134:H134)+SUM('Monthly Electricity (Overview)'!O134:Q134) -> 3980431 | C56: ='Monthly Electricity (Overview)'!I134 -> 529555 | D56: ='Monthly Electricity (Overview)'!N134 -> 51613 | E56: ='Monthly Electricity (Overview)'!E134 -> 373437 | F56: ='Monthly Electricity (Overview)'!J134 -> 214600 | G56: ='Monthly Electricity (Overview)'!K134 -> 47528 | I56: ='Monthly Electricity (Overview)'!S134 -> 10237 | J56: ='Monthly Electricity (Overview)'!T134 -> 28831 | K56: ='Monthly Electricity (Overview)'!L134 -> 83004 | L56: 42652 | M56: =SUM('Monthly Electricity (Overview)'!U134:X134)+'Monthly Electricity (Overview)'!AD134 -> 612893 | N56: ='Monthly Electricity (Overview)'!AA134 -> 211046 | O56: ='Monthly Electricity (Overview)'!Z134 -> 369287 | P56: ='Monthly Electricity (Overview)'!Y134 -> 580333 | Q56: =SUM(B56:P56)-P56 -> 6555114 | R56: =SUM(B56:O56)-L56 -> 6512462
A57: 45689 | B57: =SUM('Monthly Electricity (Overview)'!C135:D135)+SUM('Monthly Electricity (Overview)'!F135:H135)+SUM('Monthly Electricity (Overview)'!O135:Q135) -> 4304728 | C57: ='Monthly Electricity (Overview)'!I135 -> 522670 | D57: ='Monthly Electricity (Overview)'!N135 -> 48514 | E57: ='Monthly Electricity (Overview)'!E135 -> 416863 | F57: ='Monthly Electricity (Overview)'!J135 -> 253800 | G57: ='Monthly Electricity (Overview)'!K135 -> 46126 | I57: ='Monthly Electricity (Overview)'!S135 -> 10191 | J57: ='Monthly Electricity (Overview)'!T135 -> 37593 | K57: ='Monthly Electricity (Overview)'!L135 -> 79071 | L57: 46317 | M57: =SUM('Monthly Electricity (Overview)'!U135:X135)+'Monthly Electricity (Overview)'!AD135 -> 792669 | N57: ='Monthly Electricity (Overview)'!AA135 -> 290822 | O57: ='Monthly Electricity (Overview)'!Z135 -> 387630 | P57: ='Monthly Electricity (Overview)'!Y135 -> 678452 | Q57: =SUM(B57:P57)-P57 -> 7236994 | R57: =SUM(B57:O57)-L57 -> 7190677
