Workbook

Sheet JUL-19
C2: HKUST - Campus and Student Hostel
C3: General Wastes Statistics | K3: Month/Year: Jul-2019 | AI3: Submission Date: 9-AUG-2019
C4: Waste Types | D4: Date of General Wastes Collection Details (Tonne) | AI4: Total Weight
D5: 43647 | E5: 43648 | F5: 43649 | G5: 43650 | H5: 43651 | I5: 43652 | J5: 43653 | K5: 43654 | L5: 43655 | M5: 43656 | N5: 43657 | O5: 43658 | P5: 43659 | Q5: 43660 | R5: 43661 | S5: 43662 | T5: 43663 | U5: 43664 | V5: 43665 | W5: 43666 | X5: 43667 | Y5: 43668 | Z5: 43669 | AA5: 43670 | AB5: 43671 | AC5: 43672 | AD5: 43673 | AE5: 43674 | AF5: 43675 | AG5: 43676 | AH5: 43677
C6: General Wastes | D6: 2.91 | E6: 2.91 | F6: 2.91 | G6: 2.91 | H6: 2.91 | I6: 2.91 | J6: 2.91 | K6: 2.91 | L6: 3.06 | M6: 2.4 | N6: 3.3 | O6: 2.99 | P6: 2.56 | Q6: 2.31 | R6: 2.91 | S6: 2.91 | T6: 3.45 | U6: 2.96 | V6: 3.14 | W6: 2.58 | X6: 2.12 | Y6: 2.78 | Z6: 2.56 | AA6: 2.84 | AB6: 2.85 | AC6: 4.06 | AD6: 3.93 | AE6: 2.21 | AF6: 2.78 | AG6: 3.35 | AH6: 2.91 | AI6: =SUM(D6:AH6) -> 90.24
C7: Yellow skip | E7: 3.1 | G7: 1.6 | H7: 2 | I7: 1.6 | K7: 2.2 | L7: 1.1 | M7: 1.3 | N7: 1 | O7: 1.2 | P7: 1 | Q7: 1 | S7: 1.6 | T7: 2 | V7: 1.5 | W7: 1.1 | Y7: 2.1 | Z7: 1 | AA7: 1.4 | AB7: 2.2 | AC7: 3.2 | AD7: 1.9 | AF7: 1.7 | AG7: 1 | AH7: 1.2 | AI7: =SUM(D7:AH7) -> 39
C8: Total Weight (Tonne) | D8: =SUM(D6:D7) -> 2.91 | E8: =SUM(E6:E7) -> 6.01 | F8: =SUM(F6:F7) -> 2.91 | G8: =SUM(G6:G7) -> 4.51 | H8: =SUM(H6:H7) -> 4.91 | I8: =SUM(I6:I7) -> 4.51 | J8: =SUM(J6:J7) -> 2.91 | K8: =SUM(K6:K7) -> 5.11 | ... AI8: =SUM(AI6:AI7) -> 129.24
C9: Recyclable Wastes Statistics
C10: Recycled Types | D10: Date of Recycling Wastes Collection Details (kg) | AI10: Total Weight
D11: 43647 | E11: 43648 | F11: 43649 | G11: 43650 | H11: 43652 | I11: 43654 | J11: 43656 | K11: 43657 | L11: 43659 | M11: 43662 | N11: 43663 | O11: 43664 | P11: 43665 | Q11: 43668 | R11: 43669 | S11: 43671 | T11: 43673 | U11: 43675 | V11: 43676
C12: Old Corrugated Containers | D12: 309 | E12: 403 | F12: 850 | G12: 280 | H12: 140 | I12: 214 | J12: 490 | K12: 150 | L12: 323 | M12: 280 | N12: 245 | O12: 102 | P12: 305 | Q12: 108 | R12: 150 | S12: 710 | T12: 105 | U12: 200 | V12: 332 | AI12: =SUM(D12:AH12) -> 5696
C13: Office Paper / Newspapers | E13: 280 | F13: 350 | G13: 365 | H13: 175 | J13: 1010 | K13: 350 | L13: 425 | M13: 350 | N13: 316 | O13: 258 | P13: 150 | R13: 473 | S13: 382 | T13: 600 | U13: 192 | V13: 780 | AI13: =SUM(D13:AH13) -> 6456
C14: Waste Plastic Bottles | E14: 20 | G14: 95 | H14: 68 | K14: 35 | O14: 60 | Q14: 42 | S14: 29 | U14: 41 | AI14: =SUM(D14:AH14) -> 390
C15: Aluminum Cans | F15: 10 | G15: 16 | I15: 14 | K15: 14 | M15: 10 | O15: 11 | S15: 16 | U15: 9 | AI15: =SUM(D15:AH15) -> 100
C16: Metal | H16: 350 | Q16: 35 | V16: 38 | AI16: =SUM(D16:AH16) -> 423
C17: Other:(pls specify) | AI17: =SUM(D17:AH17) -> 0
C18: Total Weight (kg) | D18: =SUM(D12:D17) -> 309 | E18: =SUM(E12:E17) -> 703 | F18: =SUM(F12:F17) -> 1210 | G18: =SUM(G12:G17) -> 756 | H18: =SUM(H12:H17) -> 733 | I18: =SUM(I12:I17) -> 228 | J18: =SUM(J12:J17) -> 1500 | K18: =SUM(K12:K17) -> 549 | ... AI18: =SUM(AI12:AI17) -> 13065
C20: (A) Total Weight of General Waste of this Month : | H20: =AI8*1000 -> 129240 | J20: kg | M20: (C) Total Recycling Ratio Percentage of this Month : | T20: =(H21/(H20+H21))*100 -> 9.1809845 | AA20: % < i.e.= B/(A+B) >
C21: (B) Total Weight of Recycled Waste of this Month : | H21: =AI18 -> 13065 | J21: kg | M21: (D) Total Recycling Ratio of Y-T-D Average : | T21: =SUM(D25:AI25)/COUNTA(D25:AI25)*100 -> 9.1809845 | AA21: %
C23: Yearly Summary of Recycling Ratio Percentage
C24: Month | D24: 43647 | F24: 43678 | H24: 43709 | J24: 43739 | L24: 43770 | N24: 43800 | P24: 43831 | R24: 43862 | T24: 43891 | V24: 43922 | X24: 43952 | Z24: 43983 | AB24: 44013 | AD24: 44044 | AF24: 44075 | AH24: 44105
C25: Recycling Ratio Percentage | D25: =T20/100 -> 0.091809845

Sheet AUG-19
C2: HKUST - Campus and Student Hostel
C3: General Wastes Statistics | K3: Month/Year: Aug-2019 | AI3: Submission Date: 2-Sep-2019
C4: Waste Types | D4: Date of General Wastes Collection Details (Tonne) | AI4: Total Weight
D5: 43678 | E5: 43679 | F5: 43680 | G5: 43681 | H5: 43682 | I5: 43683 | J5: 43684 | K5: 43685 | L5: 43686 | M5: 43687 | N5: 43688 | O5: 43689 | P5: 43690 | Q5: 43691 | R5: 43692 | S5: 43693 | T5: 43694 | U5: 43695 | V5: 43696 | W5: 43697 | X5: 43698 | Y5: 43699 | Z5: 43700 | AA5: 43701 | AB5: 43702 | AC5: 43703 | AD5: 43704 | AE5: 43705 | AF5: 43706 | AG5: 43707 | AH5: 43708
C6: General Wastes | D6: 2.7 | E6: 2.7 | F6: 2.97 | G6: 2.4 | H6: 3.73 | I6: 2.53 | J6: 3.68 | K6: 3.35 | L6: 3.84 | M6: 3.51 | N6: 3.54 | O6: 3.82 | P6: 3.56 | Q6: 4.2 | R6: 4.03 | S6: 4.04 | T6: 3.61 | U6: 2.92 | V6: 3.01 | W6: 4.37 | X6: 4.21 | Y6: 3.73 | Z6: 3.9 | AA6: 3.44 | AB6: 3.01 | AC6: 3.92 | AD6: 4.84 | AE6: 4.39 | AF6: 4.25 | AG6: 4.45 | AH6: 3.54 | AI6: =SUM(D6:AH6) -> 112.19
C7: Yellow skip | D7: 2.94 | E7: 2.76 | F7: 2.08 | G7: 0 | H7: 1.21 | I7: 2.92 | J7: 2.31 | K7: 1.27 | L7: 3.78 | M7: 1.42 | N7: 0 | O7: 4.04 | P7: 2.29 | Q7: 1.08 | R7: 1.05 | S7: 1.03 | T7: 1.02 | U7: 0 | V7: 1.32 | W7: 0.69 | X7: 1.64 | Y7: 1.66 | Z7: 2.7 | AA7: 2.52 | AB7: 0 | AC7: 1.09 | AD7: 1.15 | AE7: 1.07 | AF7: 2.68 | AG7: 1.55 | AH7: 2.48 | AI7: =SUM(D7:AH7) -> 51.75
C8: Total Weight (Tonne) | D8: =SUM(D6:D7) -> 5.64 | E8: =SUM(E6:E7) -> 5.46 | F8: =SUM(F6:F7) -> 5.05 | G8: =SUM(G6:G7) -> 2.4 | H8: =SUM(H6:H7) -> 4.94 | I8: =SUM(I6:I7) -> 5.45 | J8: =SUM(J6:J7) -> 5.99 | K8: =SUM(K6:K7) -> 4.62 | ... AI8: =SUM(AI6:AI7) -> 163.94
C9: Recyclable Wastes Statistics
C10: Recycled Types | D10: Date of Recycling Wastes Collection Details (kg) | AI10: Total Weight
D11: 43678 | E11: 43680 | F11: 43683 | G11: 43684 | H11: 43685 | I11: 43687 | J11: 43690 | K11: 43691 | L11: 43693 | M11: 43696 | N11: 43698 | O11: 43700 | P11: 43703 | Q11: 43705 | R11: 43707
C12: Old Corrugated Containers | D12: 370 | E12: 230 | F12: 203 | G12: 180 | I12: 382 | J12: 237 | K12: 595 | L12: 645 | M12: 434 | N12: 477 | O12: 495 | P12: 515 | Q12: 724 | R12: 772 | AI12: =SUM(D12:AH12) -> 6259
C13: Office Paper / Newspapers | D13: 360 | E13: 432 | F13: 410 | G13: 345 | I13: 300 | J13: 456 | L13: 490 | M13: 388 | N13: 301 | O13: 428 | P13: 632 | Q13: 400 | R13: 704 | AI13: =SUM(D13:AH13) -> 5646
C14: Waste Plastic Bottles | E14: 41 | I14: 65 | J14: 30 | L14: 43 | N14: 32 | P14: 40 | R14: 51 | AI14: =SUM(D14:AH14) -> 302
C15: Aluminum Cans | E15: 12 | I15: 10 | J15: 11 | R15: 18 | AI15: =SUM(D15:AH15) -> 51
C16: Metal | H16: 118 | L16: 66 | P16: 83 | AI16: =SUM(D16:AH16) -> 267
C17: Other:(pls specify) | AI17: =SUM(D17:AH17) -> 0
C18: Total Weight (kg) | D18: =SUM(D12:D17) -> 730 | E18: =SUM(E12:E17) -> 715 | F18: =SUM(F12:F17) -> 613 | G18: =SUM(G12:G17) -> 525 | H18: =SUM(H12:H17) -> 118 | I18: =SUM(I12:I17) -> 757 | J18: =SUM(J12:J17) -> 734 | K18: =SUM(K12:K17) -> 595 | ... AI18: =SUM(AI12:AI17) -> 12525
C20: (A) Total Weight of General Waste of this Month : | H20: =AI8*1000 -> 163940 | J20: kg | M20: (C) Total Recycling Ratio Percentage of this Month : | T20: =(H21/(H20+H21))*100 -> 7.0977248 | AA20: % < i.e.= B/(A+B) >
C21: (B) Total Weight of Recycled Waste of this Month : | H21: =AI18 -> 12525 | J21: kg | M21: (D) Total Recycling Ratio of Y-T-D Average : | T21: =SUM(D25:AI25)/COUNTA(D25:AI25)*100 -> 8.1393546 | AA21: %
C23: Yearly Summary of Recycling Ratio Percentage
C24: Month | D24: 43647 | F24: 43678 | H24: 43709 | J24: 43739 | L24: 43770 | N24: 43800 | P24: 43831 | R24: 43862 | T24: 43891 | V24: 43922 | X24: 43952 | Z24: 43983 | AB24: 44013 | AD24: 44044 | AF24: 44075 | AH24: 44105
C25: Recycling Ratio Percentage | D25: ='JUL-19'!D25:E25 -> 0.091809845 | F25: =T20/100 -> 0.070977248

Sheet SEP-19 
C2: HKUST - Campus and Student Hostel
C3: General Wastes Statistics | K3: Month/Year: SEP-2019 | AI3: Submission Date: 9-Sep-2019
C4: Waste Types | D4: Date of General Wastes Collection Details (Tonne) | AI4: Total Weight
D5: 43709 | E5: 43710 | F5: 43711 | G5: 43712 | H5: 43713 | I5: 43714 | J5: 43715 | K5: 43716 | L5: 43717 | M5: 43718 | N5: 43719 | O5: 43720 | P5: 43721 | Q5: 43722 | R5: 43723 | S5: 43724 | T5: 43725 | U5: 43726 | V5: 43727 | W5: 43728 | X5: 43729 | Y5: 43730 | Z5: 43731 | AA5: 43732 | AB5: 43733 | AC5: 43734 | AD5: 43735 | AE5: 43736 | AF5: 43737 | AG5: 43738
C6: General Wastes | D6: 3.17 | E6: 5.16 | F6: 5.17 | G6: 5.03 | H6: 5.42 | I6: 5.15 | J6: 4.82 | K6: 3.67 | L6: 5.87 | M6: 5.18 | N6: 5.02 | O6: 5.23 | P6: 4.88 | Q6: 3.42 | R6: 3.5 | S6: 4.4 | T6: 5.28 | U6: 4.93 | V6: 4.95 | W6: 5.14 | X6: 4.31 | Y6: 3.45 | Z6: 4.22 | AA6: 4.92 | AB6: 4.93 | AC6: 4.83 | AD6: 4.73 | AE6: 4.16 | AF6: 3.59 | AG6: 3.9 | AI6: =SUM(D6:AH6) -> 138.43
C7: Yellow skip | D7: 0 | E7: 3.39 | F7: 3.11 | G7: 1.13 | H7: 1.78 | I7: 2.03 | J7: 0.66 | K7: 0 | L7: 3.63 | M7: 2.93 | N7: 1.73 | O7: 2.95 | P7: 2.4 | Q7: 0 | R7: 0.99 | S7: 3.7 | T7: 2.39 | U7: 3.25 | V7: 2.41 | W7: 3.84 | X7: 0.91 | Y7: 0 | Z7: 2.89 | AA7: 4.13 | AB7: 4.02 | AC7: 2.69 | AD7: 2.41 | AE7: 0.9 | AF7: 0 | AG7: 2.72 | AI7: =SUM(D7:AH7) -> 62.99
C8: Total Weight (Tonne) | D8: =SUM(D6:D7) -> 3.17 | E8: =SUM(E6:E7) -> 8.55 | F8: =SUM(F6:F7) -> 8.28 | G8: =SUM(G6:G7) -> 6.16 | H8: =SUM(H6:H7) -> 7.2 | I8: =SUM(I6:I7) -> 7.18 | J8: =SUM(J6:J7) -> 5.48 | K8: =SUM(K6:K7) -> 3.67 | ... AG8: =SUM(AG6:AG7) -> 6.62 | AH8: =SUM(AH6:AH6) -> 0 | AI8: =SUM(AI6:AI7) -> 201.42
C9: Recyclable Wastes Statistics
C10: Recycled Types | D10: Date of Recycling Wastes Collection Details (kg) | AI10: Total Weight
D11: 43710 | E11: 43712 | F11: 43713 | G11: 43714 | H11: 43717 | I11: 43719 | J11: 43721 | K11: 43724 | L11: 43726 | M11: 43727 | N11: 43728 | O11: 43731 | P11: 43733 | Q11: 43734 | R11: 43736 | S11: 43738
C12: Old Corrugated Containers | D12: 413 | E12: 385 | F12: 603 | G12: 400 | H12: 509 | I12: 412 | J12: 650 | K12: 357 | L12: 252 | M12: 531 | N12: 392 | O12: 383 | P12: 315 | Q12: 342 | R12: 500 | S12: 311 | AI12: =SUM(D12:AH12) -> 6755
C13: Office Paper / Newspapers | E13: 400 | G13: 280 | H13: 335 | I13: 700 | J13: 365 | K13: 283 | L13: 200 | O13: 275 | P13: 600 | Q13: 362 | S13: 250 | AI13: =SUM(D13:AH13) -> 4050
C14: Waste Plastic Bottles | D14: 45 | F14: 32 | H14: 48 | J14: 50 | L14: 53 | N14: 46 | P14: 55 | S14: 51 | AI14: =SUM(D14:AH14) -> 380
C15: Aluminum Cans | D15: 12 | F15: 14 | H15: 11 | J15: 13 | N15: 10 | P15: 12 | S15: 11 | AI15: =SUM(D15:AH15) -> 83
C16: Metal | G16: 56 | K16: 28 | O16: 45 | R16: 40 | AI16: =SUM(D16:AH16) -> 169
C17: Other:(pls specify) | AI17: =SUM(D17:AH17) -> 0
C18: Total Weight (kg) | D18: =SUM(D12:D17) -> 470 | E18: =SUM(E12:E17) -> 785 | F18: =SUM(F12:F17) -> 649 | G18: =SUM(G12:G17) -> 736 | H18: =SUM(H12:H17) -> 903 | I18: =SUM(I12:I17) -> 1112 | J18: =SUM(J12:J17) -> 1078 | K18: =SUM(K12:K17) -> 668 | ... AI18: =SUM(AI12:AI17) -> 11437
C20: (A) Total Weight of General Waste of this Month : | H20: =AI8*1000-6854 -> 194566 | J20: kg | M20: (C) Total Recycling Ratio Percentage of this Month : | T20: =(H21/(H20+H21))*100 -> 5.5518609 | AA20: % < i.e.= B/(A+B) >
C21: (B) Total Weight of Recycled Waste of this Month : | H21: =AI18 -> 11437 | J21: kg | M21: (D) Total Recycling Ratio of Y-T-D Average : | T21: =SUM(D25:AI25)/COUNTA(D25:AI25)*100 -> 7.2768567 | AA21: %
C23: Yearly Summary of Recycling Ratio Percentage
C24: Month | D24: 43647 | F24: 43678 | H24: 43709 | J24: 43739 | L24: 43770 | N24: 43800 | P24: 43831 | R24: 43862 | T24: 43891 | V24: 43922 | X24: 43952 | Z24: 43983 | AB24: 44013 | AD24: 44044 | AF24: 44075 | AH24: 44105
C25: Recycling Ratio Percentage | D25: ='JUL-19'!D25:E25 -> 0.091809845 | F25: ='AUG-19'!F25:G25 -> 0.070977248 | H25: =T20/100 -> 0.055518609

Sheet OCT-19 
C2: HKUST - Campus and Student Hostel
C3: General Wastes Statistics | K3: Month/Year: OCT-2019 | AI3: Submission Date: 29-Oct-2019
C4: Waste Types | D4: Date of General Wastes Collection Details (Tonne) | AI4: Total Weight
D5: 43739 | E5: 43740 | F5: 43741 | G5: 43742 | H5: 43743 | I5: 43744 | J5: 43745 | K5: 43746 | L5: 43747 | M5: 43748 | N5: 43749 | O5: 43750 | P5: 43751 | Q5: 43752 | R5: 43753 | S5: 43754 | T5: 43755 | U5: 43756 | V5: 43757 | W5: 43758 | X5: 43759 | Y5: 43760 | Z5: 43761 | AA5: 43762 | AB5: 43763 | AC5: 43764 | AD5: 43765 | AE5: 43766 | AF5: 43767 | AG5: 43768 | AH5: 43769
C6: General Wastes | D6: 3.32 | E6: 4.42 | F6: 4.89 | G6: 4.92 | H6: 3.37 | I6: 3.98 | J6: 2.55 | K6: 4.61 | L6: 4.66 | M6: 5.16 | N6: 3.47 | O6: 3.65 | P6: 3.46 | Q6: 4.66 | R6: 4.94 | S6: 4.35 | T6: 4.8 | U6: 4.25 | V6: 4.27 | W6: 3.26 | X6: 4.42 | Y6: 4.64 | Z6: 4.53 | AA6: 4.74 | AB6: 4.73 | AC6: 4.01 | AD6: 3.25 | AE6: 5.01 | AF6: 4.92 | AG6: 4.73 | AH6: 5.6 | AI6: =SUM(D6:AH6) -> 133.57
C7: Yellow skip | D7: 0 | E7: 1.65 | F7: 2.02 | G7: 1.61 | H7: 1.2 | I7: 0.66 | J7: 2.22 | K7: 2.67 | L7: 1.13 | M7: 2.48 | N7: 1.13 | O7: 1.34 | P7: 0 | Q7: 3.09 | R7: 1.95 | S7: 2.21 | T7: 3 | U7: 3.78 | V7: 1.87 | W7: 0 | X7: 3.92 | Y7: 2.21 | Z7: 1.49 | AA7: 2.14 | AB7: 0.74 | AC7: 3.18 | AD7: 0 | AE7: 2.9 | AF7: 4.22 | AG7: 2 | AH7: 2.67 | AI7: =SUM(D7:AH7) -> 59.48
C8: Total Weight (Tonne) | D8: =SUM(D6:D7) -> 3.32 | E8: =SUM(E6:E7) -> 6.07 | F8: =SUM(F6:F7) -> 6.91 | G8: =SUM(G6:G7) -> 6.53 | H8: =SUM(H6:H7) -> 4.57 | I8: =SUM(I6:I7) -> 4.64 | J8: =SUM(J6:J7) -> 4.77 | K8: =SUM(K6:K7) -> 7.28 | ... AG8: =SUM(AG6:AG7) -> 6.73 | AH8: =SUM(AH6:AH6) -> 5.6 | AI8: =SUM(AI6:AI7) -> 193.05
C9: Recyclable Wastes Statistics
C10: Recycled Types | D10: Date of Recycling Wastes Collection Details (kg) | AI10: Total Weight
D11: 43740 | E11: 43742 | F11: 43745 | G11: 43474 | H11: 43748 | I11: 43749 | J11: 43752 | K11: 43754 | L11: 43756 | M11: 43757 | N11: 43760 | O11: 43761 | P11: 43763 | Q11: 43766 | R11: 43768
C12: Old Corrugated Containers | D12: 385 | E12: 426 | F12: 538 | G12: 400 | H12: 433 | I12: 298 | J12: 456 | K12: 312 | L12: 607 | M12: 515 | N12: 410 | O12: 465 | P12: 540 | Q12: 500 | R12: 492 | AI12: =SUM(D12:AH12) -> 6777
C13: Office Paper / Newspapers | D13: 250 | E13: 241 | F13: 250 | G13: 455 | H13: 263 | I13: 300 | J13: 562 | L13: 240 | N13: 683 | O13: 235 | Q13: 354 | R13: 451 | AI13: =SUM(D13:AH13) -> 4284
C14: Waste Plastic Bottles | E14: 56 | G14: 43 | I14: 33 | K14: 54 | M14: 50 | N14: 48 | P14: 51 | R14: 32 | AI14: =SUM(D14:AH14) -> 367
C15: Aluminum Cans | E15: 13 | G15: 11 | I15: 12 | K15: 10 | M15: 11 | P15: 14 | R15: 10 | AI15: =SUM(D15:AH15) -> 81
C16: Metal | F16: 48 | J16: 46 | N16: 55 | Q16: 30 | AI16: =SUM(D16:AH16) -> 179
C17: Other:(pls specify) | AI17: =SUM(D17:AH17) -> 0
C18: Total Weight (kg) | D18: =SUM(D12:D17) -> 635 | E18: =SUM(E12:E17) -> 736 | F18: =SUM(F12:F17) -> 836 | G18: =SUM(G12:G17) -> 909 | H18: =SUM(H12:H17) -> 696 | I18: =SUM(I12:I17) -> 643 | J18: =SUM(J12:J17) -> 1064 | K18: =SUM(K12:K17) -> 376 | ... AI18: =SUM(AI12:AI17) -> 11688
C20: (A) Total Weight of General Waste of this Month : | H20: =AI8*1000-9816 -> 183234 | J20: kg | M20: (C) Total Recycling Ratio Percentage of this Month : | T20: =(H21/(H20+H21))*100 -> 5.9962447 | AA20: % < i.e.= B/(A+B) >
C21: (B) Total Weight of Recycled Waste of this Month : | H21: =AI18 -> 11688 | J21: kg | M21: (D) Total Recycling Ratio of Y-T-D Average : | T21: =SUM(D25:AI25)/COUNTA(D25:AI25)*100 -> 6.9567037 | AA21: %
C23: Yearly Summary of Recycling Ratio Percentage
C24: Month | D24: 43647 | F24: 43678 | H24: 43709 | J24: 43739 | L24: 43770 | N24: 43800 | P24: 43831 | R24: 43862 | T24: 43891 | V24: 43922 | X24: 43952 | Z24: 43983 | AB24: 44013 | AD24: 44044 | AF24: 44075 | AH24: 44105
C25: Recycling Ratio Percentage | D25: ='JUL-19'!D25:E25 -> 0.091809845 | F25: ='AUG-19'!F25:G25 -> 0.070977248 | H25: =('SEP-19 '!T20)/100 -> 0.055518609 | J25: =T20/100 -> 0.059962447

Sheet NOV-19
C2: HKUST - Campus and Student Hostel
C3: General Wastes Statistics | K3: Month/Year: NOV-2019 | AI3: Submission Date: 30-Nov-2019
C4: Waste Types | D4: Date of General Wastes Collection Details (Tonne) | AI4: Total Weight
D5: 43770 | E5: 43771 | F5: 43772 | G5: 43773 | H5: 43774 | I5: 43775 | J5: 43776 | K5: 43777 | L5: 43778 | M5: 43779 | N5: 43780 | O5: 43781 | P5: 43782 | Q5: 43783 | R5: 43784 | S5: 43785 | T5: 43786 | U5: 43787 | V5: 43788 | W5: 43789 | X5: 43790 | Y5: 43791 | Z5: 43792 | AA5: 43793 | AB5: 43794 | AC5: 43795 | AD5: 43796 | AE5: 43797 | AF5: 43798 | AG5: 43799
C6: General Wastes | D6: 5.13 | E6: 4.18 | F6: 3.43 | G6: 5.08 | H6: 4.56 | I6: 5.53 | J6: 5.2 | K6: 5.19 | L6: 3.8 | M6: 4.02 | N6: 4.06 | O6: 2.61 | P6: 3.51 | Q6: 3.1 | R6: 2.66 | S6: 2.45 | T6: 2.68 | U6: 3.34 | V6: 3.21 | W6: 3.02 | X6: 2.89 | Y6: 2.66 | Z6: 2.46 | AA6: 1.99 | AB6: 3.36 | AC6: 3.54 | AD6: 3.59 | AE6: 3.43 | AF6: 3.05 | AG6: 2.94 | AI6: =SUM(D6:AH6) -> 106.67
C7: Yellow skip | D7: =0.62+0.85 -> 1.47 | E7: =0.59+0.68 -> 1.27 | F7: 0 | G7: =0.74+0.81+1.3 -> 2.85 | H7: =0.69+0.86 -> 1.55 | I7: =0.98+1.23 -> 2.21 | J7: =1.33+0.54+0.73 -> 2.6 | K7: =0.86+0.65 -> 1.51 | L7: 0.85 | M7: 0 | N7: =0.75+0.99 -> 1.74 | O7: =0.98 -> 0.98 | P7: =0.59+0.41 -> 1 | Q7: =0.45+0.97 -> 1.42 | R7: =1.59 -> 1.59 | S7: =0.65 -> 0.65 | T7: 0 | U7: =0.39+0.56+1.77 -> 2.72 | V7: =1.29 -> 1.29 | W7: =0.98+1.07 -> 2.05 | X7: =0.59+1.36 -> 1.95 | Y7: =1.07+1.02 -> 2.09 | Z7: =0.68+1.56 -> 2.24 | AA7: 0 | AB7: =0.82+1.02+1.28+0.79 -> 3.91 | AC7: =1.16+0.72 -> 1.88 | AD7: =0.89+1.13 -> 2.02 | AE7: =1+1.16+0.91 -> 3.07 | AF7: =1.45+1.27 -> 2.72 | AG7: =1.41 -> 1.41 | AI7: =SUM(D7:AH7) -> 49.04
C8: Total Weight (Tonne) | D8: =SUM(D6:D7) -> 6.6 | E8: =SUM(E6:E7) -> 5.45 | F8: =SUM(F6:F7) -> 3.43 | G8: =SUM(G6:G7) -> 7.93 | H8: =SUM(H6:H7) -> 6.11 | I8: =SUM(I6:I7) -> 7.74 | J8: =SUM(J6:J7) -> 7.8 | K8: =SUM(K6:K7) -> 6.7 | ... AG8: =SUM(AG6:AG7) -> 4.35 | AH8: =SUM(AH6:AH6) -> 0 | AI8: =SUM(AI6:AI7) -> 155.71
C9: Recyclable Wastes Statistics
C10: Recycled Types | D10: Date of Recycling Wastes Collection Details (kg) | AI10: Total Weight
D11: 43770 | E11: 43771 | F11: 43773 | G11: 43774 | H11: 43775 | I11: 43776 | J11: 43778 | K11: 43781 | L11: 43783 | M11: 43785 | N11: 43788 | O11: 43791 | P11: 43794 | Q11: 43796 | R11: 43798
C12: Old Corrugated Containers | D12: 608 | E12: 612 | F12: 300 | G12: 367 | H12: 610 | I12: 235 | J12: 500 | K12: 205 | L12: 116 | M12: 110 | N12: 282 | O12: 473 | P12: 304 | Q12: 385 | R12: 630 | AI12: =SUM(D12:AH12) -> 5737
C13: Office Paper / Newspapers | D13: 350 | E13: 523 | G13: 302 | I13: 350 | J13: 206 | N13: 365 | O13: 300 | P13: 621 | Q13: 320 | R13: 215 | AI13: =SUM(D13:AH13) -> 3552
C14: Waste Plastic Bottles | D14: 46 | H14: 40 | J14: 42 | L14: 33 | M14: 28 | O14: 41 | P14: 30 | R14: 53 | AI14: =SUM(D14:AH14) -> 313
C15: Aluminum Cans | D15: 11 | H15: 12 | J15: 10 | L15: 8 | M15: 6 | O15: 10 | P15: 9 | R15: 13 | AI15: =SUM(D15:AH15) -> 79
C16: Metal | E16: 68 | I16: 52 | N16: 44 | Q16: 56 | AI16: =SUM(D16:AH16) -> 220
C17: Other:(pls specify) | AI17: =SUM(D17:AH17) -> 0
C18: Total Weight (kg) | D18: =SUM(D12:D17) -> 1015 | E18: =SUM(E12:E17) -> 1203 | F18: =SUM(F12:F17) -> 300 | G18: =SUM(G12:G17) -> 669 | H18: =SUM(H12:H17) -> 662 | I18: =SUM(I12:I17) -> 637 | J18: =SUM(J12:J17) -> 758 | K18: =SUM(K12:K17) -> 205 | ... AI18: =SUM(AI12:AI17) -> 9901
C20: (A) Total Weight of General Waste of this Month : | H20: =AI8*1000-5250 -> 150460 | J20: kg | M20: (C) Total Recycling Ratio Percentage of this Month : | T20: =(H21/(H20+H21))*100 -> 6.1741945 | AA20: % < i.e.= B/(A+B) >
C21: (B) Total Weight of Recycled Waste of this Month : | H21: =AI18 -> 9901 | J21: kg | M21: (D) Total Recycling Ratio of Y-T-D Average : | T21: =SUM(D25:AI25)/COUNTA(D25:AI25)*100 -> 6.8002019 | AA21: %
C23: Yearly Summary of Recycling Ratio Percentage
C24: Month | D24: 43647 | F24: 43678 | H24: 43709 | J24: 43739 | L24: 43770 | N24: 43800 | P24: 43831 | R24: 43862 | T24: 43891 | V24: 43922 | X24: 43952 | Z24: 43983 | AB24: 44013 | AD24: 44044 | AF24: 44075 | AH24: 44105
C25: Recycling Ratio Percentage | D25: ='JUL-19'!D25:E25 -> 0.091809845 | F25: ='AUG-19'!F25:G25 -> 0.070977248 | H25: =('SEP-19 '!T20)/100 -> 0.055518609 | J25: ='OCT-19 '!J25:K25 -> 0.059962447 | L25: =T20/100 -> 0.061741945

Sheet DEC-19 
C2: HKUST - Campus and Student Hostel
C3: General Wastes Statistics | K3: Month/Year: DEC-2019 | AI3: Submission Date: 9-DEC-2019
C4: Waste Types | D4: Date of General Wastes Collection Details (Tonne) | AI4: Total Weight
D5: 43800 | E5: 43801 | F5: 43802 | G5: 43803 | H5: 43804 | I5: 43805 | J5: 43806 | K5: 43807 | L5: 43808 | M5: 43809 | N5: 43810 | O5: 43811 | P5: 43812 | Q5: 43813 | R5: 43814 | S5: 43815 | T5: 43816 | U5: 43817 | V5: 43818 | W5: 43819 | X5: 43820 | Y5: 43821 | Z5: 43822 | AA5: 43823 | AB5: 43824 | AC5: 43825 | AD5: 43826 | AE5: 43827 | AF5: 43828 | AG5: 43829 | AH5: 43830
C6: General Wastes | D6: 1.87 | E6: 4.95 | F6: 4.48 | G6: 4.51 | H6: 4.76 | I6: 4.43 | J6: 3.85 | K6: 3.13 | L6: 3.75 | M6: 4.1 | N6: 4.75 | O6: 4.73 | P6: 3.97 | Q6: 4.12 | R6: 3.26 | S6: 4.23 | T6: 4.12 | U6: 4.37 | V6: 4.22 | W6: 4.67 | X6: 5.71 | Y6: 2.37 | Z6: 3.26 | AA6: 3.31 | AB6: 2.09 | AC6: 2.44 | AD6: 3.29 | AE6: 2.28 | AF6: 1.7 | AG6: 3.06 | AH6: 2.75 | AI6: =SUM(D6:AH6) -> 114.53
C7: Yellow skip | D7: 0 | E7: 3.09 | F7: 2.77 | G7: 1.23 | H7: 1.85 | I7: 4.2 | J7: 1.58 | K7: 0 | L7: 3.92 | M7: 2.57 | N7: 2.82 | O7: 1.76 | P7: 2.58 | Q7: 2.08 | R7: 0 | S7: 2.49 | T7: 2.66 | U7: 1.91 | V7: 2.42 | W7: 1.12 | X7: 2.1 | Y7: 0 | Z7: 2.78 | AA7: 1.62 | AB7: 3.84 | AC7: 0 | AD7: 2.26 | AE7: 0 | AF7: 0 | AG7: 1.65 | AH7: 1.08 | AI7: =SUM(D7:AH7) -> 56.38
C8: Total Weight (Tonne) | D8: =SUM(D6:D7) -> 1.87 | E8: =SUM(E6:E7) -> 8.04 | F8: =SUM(F6:F7) -> 7.25 | G8: =SUM(G6:G7) -> 5.74 | H8: =SUM(H6:H7) -> 6.61 | I8: =SUM(I6:I7) -> 8.63 | J8: =SUM(J6:J7) -> 5.43 | K8: =SUM(K6:K7) -> 3.13 | ... AG8: =SUM(AG6:AG7) -> 4.71 | AH8: =SUM(AH6:AH6) -> 2.75 | AI8: =SUM(AI6:AI7) -> 170.91
C9: Recyclable Wastes Statistics
C10: Recycled Types | D10: Date of Recycling Wastes Collection Details (kg) | AI10: Total Weight
D11: 43801 | E11: 44170 | F11: 44171 | G11: 44174 | H11: 44176 | I11: 44178 | J11: 44182 | K11: 44184 | L11: 44186 | M11: 44189 | N11: 44193 | O11: 44196
C12: Old Corrugated Containers | D12: 446 | E12: 538 | F12: 502 | G12: 400 | H12: 638 | I12: 453 | J12: 596 | K12: 633 | L12: 504 | M12: 645 | N12: 612 | O12: 580 | AI12: =SUM(D12:AH12) -> 6547
C13: Office Paper / Newspapers | D13: 155 | E13: 140 | F13: 268 | G13: 410 | H13: 272 | I13: 480 | J13: 800 | K13: 156 | L13: 188 | M13: 403 | N13: 210 | O13: 465 | AI13: =SUM(D13:AH13) -> 3947
C14: Waste Plastic Bottles | E14: 38 | G14: 40 | I14: 45 | K14: 50 | M14: 36 | O14: 51 | AI14: =SUM(D14:AH14) -> 260
C15: Aluminum Cans | D15: 9 | F15: 11 | H15: 18 | J15: 12 | L15: 9 | N15: 16 | AI15: =SUM(D15:AH15) -> 75
C16: Metal | E16: 50 | I16: 45 | K16: 40 | O16: 62 | AI16: =SUM(D16:AH16) -> 197
C17: Other:(pls specify) | AI17: =SUM(D17:AH17) -> 0
C18: Total Weight (kg) | D18: =SUM(D12:D17) -> 610 | E18: =SUM(E12:E17) -> 766 | F18: =SUM(F12:F17) -> 781 | G18: =SUM(G12:G17) -> 850 | H18: =SUM(H12:H17) -> 928 | I18: =SUM(I12:I17) -> 1023 | J18: =SUM(J12:J17) -> 1408 | K18: =SUM(K12:K17) -> 879 | ... AI18: =SUM(AI12:AI17) -> 11026
C20: (A) Total Weight of General Waste of this Month : | H20: =AI8*1000 -> 170910 | J20: kg | M20: (C) Total Recycling Ratio Percentage of this Month : | T20: =(H21/(H20+H21))*100 -> 6.0603729 | AA20: % < i.e.= B/(A+B) >
C21: (B) Total Weight of Recycled Waste of this Month : | H21: =AI18 -> 11026 | J21: kg | M21: (D) Total Recycling Ratio of Y-T-D Average : | T21: =SUM(D25:AI25)/COUNTA(D25:AI25)*100 -> 6.676897 | AA21: %
C23: Yearly Summary of Recycling Ratio Percentage
C24: Month | D24: 43647 | F24: 43678 | H24: 43709 | J24: 43739 | L24: 43770 | N24: 43800 | P24: 43831 | R24: 43862 | T24: 43891 | V24: 43922 | X24: 43952 | Z24: 43983 | AB24: 44013 | AD24: 44044 | AF24: 44075 | AH24: 44105
C25: Recycling Ratio Percentage | D25: ='JUL-19'!D25:E25 -> 0.091809845 | F25: ='AUG-19'!F25:G25 -> 0.070977248 | H25: =('SEP-19 '!T20)/100 -> 0.055518609 | J25: ='OCT-19 '!J25:K25 -> 0.059962447 | L25: ='NOV-19'!L25:M25 -> 0.061741945 | N25: =T20/100 -> 0.060603729

Sheet JAN-20
C2: HKUST - Campus and Student Hostel
C3: General Wastes Statistics | K3: Month/Year: JAN-2020 | AI3: Submission Date: 01-Feb-2020
C4: Waste Types | D4: Date of General Wastes Collection Details (Tonne) | AI4: Total Weight
D5: 43831 | E5: 43832 | F5: 43833 | G5: 43834 | H5: 43835 | I5: 43836 | J5: 43837 | K5: 43838 | L5: 43839 | M5: 43840 | N5: 43841 | O5: 43842 | P5: 43843 | Q5: 43844 | R5: 43845 | S5: 43846 | T5: 43847 | U5: 43848 | V5: 43849 | W5: 43850 | X5: 43851 | Y5: 43852 | Z5: 43853 | AA5: 43854 | AB5: 43855 | AC5: 43856 | AD5: 43857 | AE5: 43858 | AF5: 43859 | AG5: 43860 | AH5: 43861
C6: General Wastes | D6: 1.041 | E6: 2.9778 | F6: 2.7342 | G6: 2.7122 | H6: 1.5662 | I6: 3.7648 | J6: 3.308 | K6: 3.4654 | L6: 3.6578 | M6: 3.4236 | N6: 2.8306 | O6: 1.8106 | P6: 3.8872 | Q6: 3.9012 | R6: 3.5898 | S6: 3.9894 | T6: 3.8816 | U6: 2.7368 | V6: 1.6028 | W6: 3.2058 | X6: 3.802 | Y6: 3.569 | Z6: 3.0418 | AA6: 3.4682 | AB6: 1.9766 | AC6: 1.4714 | AD6: 1.4386 | AE6: 0.8994 | AF6: 2.863 | AG6: 2.3372 | AH6: 1.8254 | AI6: =SUM(D6:AH6) -> 86.7794
C7: Yellow skip | D7: 0 | E7: 2.16 | F7: 0.71 | G7: 0 | H7: 0 | I7: 1.55 | J7: 2.13 | K7: 1.91 | L7: 1.08 | M7: 0.7 | N7: 0.7 | O7: 0 | P7: 1.07 | Q7: 1.23 | R7: 0 | S7: 1.35 | T7: 0.42 | U7: 1.45 | V7: 0 | W7: 1.78 | X7: 0 | Y7: 3.4 | Z7: 3.03 | AA7: 0 | AB7: 0 | AC7: 0 | AD7: 0 | AE7: 0 | AF7: 0 | AG7: 2.04 | AH7: 1.08 | AI7: =SUM(D7:AH7) -> 27.79
C8: Total Weight (Tonne) | D8: =SUM(D6:D7) -> 1.041 | E8: =SUM(E6:E7) -> 5.1378 | F8: =SUM(F6:F7) -> 3.4442 | G8: =SUM(G6:G7) -> 2.7122 | H8: =SUM(H6:H7) -> 1.5662 | I8: =SUM(I6:I7) -> 5.3148 | J8: =SUM(J6:J7) -> 5.438 | K8: =SUM(K6:K7) -> 5.3754 | ... AG8: =SUM(AG6:AG7) -> 4.3772 | AH8: =SUM(AH6:AH6) -> 1.8254 | AI8: =SUM(AI6:AI7) -> 114.5694
C9: Recyclable Wastes Statistics
C10: Recycled Types | D10: Date of Recycling Wastes Collection Details (kg) | AI10: Total Weight
D11: 43832 | E11: 43834 | F11: 43837 | G11: 43839 | H11: 43841 | I11: 43844 | J11: 43845 | K11: 43847 | L11: 43848 | M11: 43851 | N11: 43852 | O11: 43853 | P11: 43860
C12: Old Corrugated Containers | D12: 404 | E12: 686 | F12: 512 | G12: 390 | H12: 483 | I12: 301 | J12: 700 | K12: 318 | L12: 208 | M12: 450 | N12: 756 | O12: 735 | P12: 210 | AI12: =SUM(D12:AH12) -> 6153
C13: Office Paper / Newspapers | D13: 250 | E13: 312 | F13: 320 | H13: 480 | I13: 206 | J13: 312 | M13: 385 | N13: 402 | O13: 283 | P13: 500 | AI13: =SUM(D13:AH13) -> 3450
C14: Waste Plastic Bottles | E14: 40 | H14: 32 | J14: 49 | M14: 30 | O14: 51 | AI14: =SUM(D14:AH14) -> 202
C15: Aluminum Cans | D15: 10 | F15: 8 | G15: 15 | I15: 16 | N15: 13 | AI15: =SUM(D15:AH15) -> 62
C16: Metal | E16: 62 | H16: 58 | M16: 44 | P16: 50 | AI16: =SUM(D16:AH16) -> 214
C17: Other:(pls specify) | AI17: =SUM(D17:AH17) -> 0
C18: Total Weight (kg) | D18: =SUM(D12:D17) -> 664 | E18: =SUM(E12:E17) -> 1100 | F18: =SUM(F12:F17) -> 840 | G18: =SUM(G12:G17) -> 405 | H18: =SUM(H12:H17) -> 1053 | I18: =SUM(I12:I17) -> 523 | J18: =SUM(J12:J17) -> 1061 | K18: =SUM(K12:K17) -> 318 | ... AI18: =SUM(AI12:AI17) -> 10081
C20: (A) Total Weight of General Waste of this Month : | H20: =AI8*1000 -> 114569.4 | J20: kg | M20: (C) Total Recycling Ratio Percentage of this Month : | T20: =(H21/(H20+H21))*100 -> 8.0874189 | AA20: % < i.e.= B/(A+B) >
C21: (B) Total Weight of Recycled Waste of this Month : | H21: =AI18 -> 10081 | J21: kg | M21: (D) Total Recycling Ratio of Y-T-D Average : | T21: =SUM(D25:AI25)/COUNTA(D25:AI25)*100 -> 6.8784002 | AA21: %
C23: Yearly Summary of Recycling Ratio Percentage
C24: Month | D24: 43647 | F24: 43678 | H24: 43709 | J24: 43739 | L24: 43770 | N24: 43800 | P24: 43831 | R24: 43862 | T24: 43891 | V24: 43922 | X24: 43952 | Z24: 43983 | AB24: 44013 | AD24: 44044 | AF24: 44075 | AH24: 44105
C25: Recycling Ratio Percentage | D25: ='JUL-19'!D25:E25 -> 0.091809845 | F25: ='AUG-19'!F25:G25 -> 0.070977248 | H25: =('SEP-19 '!T20)/100 -> 0.055518609 | J25: ='OCT-19 '!J25:K25 -> 0.059962447 | L25: ='NOV-19'!L25:M25 -> 0.061741945 | N25: ='DEC-19 '!N25:O25 -> 0.060603729 | P25: =T20/100 -> 0.080874189

Sheet FEB-20
C2: HKUST - Campus and Student Hostel
C3: General Wastes Statistics | K3: Month/Year: FEB-2020 | AI3: Submission Date: 2-Mar-2020
C4: Waste Types | D4: Date of General Wastes Collection Details (Tonne) | AI4: Total Weight
D5: 43862 | E5: 43863 | F5: 43864 | G5: 43865 | H5: 43866 | I5: 43867 | J5: 43868 | K5: 43869 | L5: 43870 | M5: 43871 | N5: 43872 | O5: 43873 | P5: 43874 | Q5: 43875 | R5: 43876 | S5: 43877 | T5: 43878 | U5: 43879 | V5: 43880 | W5: 43881 | X5: 43882 | Y5: 43883 | Z5: 43884 | AA5: 43885 | AB5: 43886 | AC5: 43887 | AD5: 43888 | AE5: 43889 | AF5: 43890
C6: General Wastes | D6: 2.0574 | E6: 1.388 | F6: 1.9974 | G6: 2.557 | H6: 2.6558 | I6: 2.5074 | J6: 2.3048 | K6: 2.5336 | L6: 2.1096 | M6: 2.434 | N6: 2.809 | O6: 2.6622 | P6: 2.5914 | Q6: 2.5158 | R6: 2.357 | S6: 2.1266 | T6: 3.072 | U6: 2.796 | V6: 2.2586 | W6: 2.5166 | X6: 2.4752 | Y6: 1.732 | Z6: 1.3724 | AA6: 2.2782 | AB6: 2.2468 | AC6: 2.4028 | AD6: 2.675 | AE6: 2.7206 | AF6: 2.1634 | AI6: =SUM(D6:AH6) -> 68.3166
C7: Yellow skip | D7: 0 | E7: 0 | F7: 0.99 | G7: 0 | H7: 0.63 | I7: 0.99 | J7: 1.25 | K7: 0 | L7: 0 | M7: 1.99 | N7: 0 | O7: 0 | P7: 0.56 | Q7: 1.58 | R7: 0 | S7: 0 | T7: 0.91 | U7: 0 | V7: 0.68 | W7: 0.65 | X7: 1.07 | Y7: 0 | Z7: 0 | AA7: 1.61 | AB7: 0 | AC7: 1.3 | AD7: 1.07 | AE7: 0 | AF7: 1.32 | AI7: =SUM(D7:AH7) -> 16.6
C8: Total Weight (Tonne) | D8: =SUM(D6:D7) -> 2.0574 | E8: =SUM(E6:E7) -> 1.388 | F8: =SUM(F6:F7) -> 2.9874 | G8: =SUM(G6:G7) -> 2.557 | H8: =SUM(H6:H7) -> 3.2858 | I8: =SUM(I6:I7) -> 3.4974 | J8: =SUM(J6:J7) -> 3.5548 | K8: =SUM(K6:K7) -> 2.5336 | ... AF8: =SUM(AF6:AF7) -> 3.4834 | AI8: =SUM(AI6:AI7) -> 84.9166
C9: Recyclable Wastes Statistics
C10: Recycled Types | D10: Date of Recycling Wastes Collection Details (kg) | AI10: Total Weight
D11: 43866 | E11: 43871 | F11: 43873 | G11: 43876 | H11: 43879 | I11: 43882 | J11: 24 | K11: 43888 | L11: 43890
C12: Old Corrugated Containers | D12: 352 | E12: 590 | F12: 110 | G12: 445 | H12: 430 | I12: 628 | J12: 276 | K12: 708 | L12: 520 | AI12: =SUM(D12:AH12) -> 4059
C13: Office Paper / Newspapers | D13: 400 | G13: 265 | I13: 956 | J13: 310 | K13: 182 | L13: 220 | AI13: =SUM(D13:AH13) -> 2333
C14: Waste Plastic Bottles | D14: 45 | F14: 50 | H14: 48 | J14: 42 | L14: 27 | AI14: =SUM(D14:AH14) -> 212
C15: Aluminum Cans | D15: 9 | F15: 12 | H15: 10 | J15: 8 | L15: 8 | AI15: =SUM(D15:AH15) -> 47
C16: Metal | E16: 40 | G16: 37 | I16: 42 | K16: 45 | AI16: =SUM(D16:AH16) -> 164
C17: Other:(pls specify) | AI17: =SUM(D17:AH17) -> 0
C18: Total Weight (kg) | D18: =SUM(D12:D17) -> 806 | E18: =SUM(E12:E17) -> 630 | F18: =SUM(F12:F17) -> 172 | G18: =SUM(G12:G17) -> 747 | H18: =SUM(H12:H17) -> 488 | I18: =SUM(I12:I17) -> 1626 | J18: =SUM(J12:J17) -> 636 | K18: =SUM(K12:K17) -> 935 | ... AI18: =SUM(AI12:AI17) -> 6815
C20: (A) Total Weight of General Waste of this Month : | H20: =AI8*1000 -> 84916.6 | J20: kg | M20: (C) Total Recycling Ratio Percentage of this Month : | T20: =(H21/(H20+H21))*100 -> 7.4292828 | AA20: % < i.e.= B/(A+B) >
C21: (B) Total Weight of Recycled Waste of this Month : | H21: =AI18 -> 6815 | J21: kg | M21: (D) Total Recycling Ratio of Y-T-D Average : | T21: =SUM(D25:AI25)/COUNTA(D25:AI25)*100 -> 6.9472605 | AA21: %
C23: Yearly Summary of Recycling Ratio Percentage
C24: Month | D24: 43647 | F24: 43678 | H24: 43709 | J24: 43739 | L24: 43770 | N24: 43800 | P24: 43831 | R24: 43862 | T24: 43891 | V24: 43922 | X24: 43952 | Z24: 43983 | AB24: 44013 | AD24: 44044 | AF24: 44075 | AH24: 44105
C25: Recycling Ratio Percentage | D25: 0.091809845 | F25: 0.070977248 | H25: 0.055518609 | J25: 0.059962447 | L25: 0.061741945 | N25: 0.060603729 | P25: 0.080874189 | R25: =T20/100 -> 0.074292828

Sheet MAR-20
C2: HKUST - Campus and Student Hostel
C3: General Wastes Statistics | K3: Month/Year: MAR-2020 | AI3: Submission Date: 30-Mar-2020
C4: Waste Types | D4: Date of General Wastes Collection Details (Tonne) | AI4: Total Weight
D5: 43891 | E5: 43892 | F5: 43893 | G5: 43894 | H5: 43895 | I5: 43896 | J5: 43897 | K5: 43898 | L5: 43899 | M5: 43900 | N5: 43901 | O5: 43902 | P5: 43903 | Q5: 43904 | R5: 43905 | S5: 43906 | T5: 43907 | U5: 43908 | V5: 43909 | W5: 43910 | X5: 43911 | Y5: 43912 | Z5: 43913 | AA5: 43914 | AB5: 43915 | AC5: 43916 | AD5: 43917 | AE5: 43918 | AF5: 43919 | AG5: 43920 | AH5: 43921
C6: General Wastes | D6: 1.3742 | E6: 2.6198 | F6: 1.8468 | G6: 2.3042 | H6: 1.931 | I6: 2.833 | J6: 2.266 | K6: 1.6904 | L6: 2.7418 | M6: 2.7524 | N6: 2.814 | O6: 3.052 | P6: 3.0894 | Q6: 2.4956 | R6: 1.603 | S6: 2.5772 | T6: 3.084 | U6: 2.69 | V6: 2.749 | W6: 2.605 | X6: 2.225 | Y6: 1.3308 | Z6: 2.9254 | AA6: 2.5 | AB6: 2.4818 | AC6: 2.1288 | AD6: 2.588 | AE6: 1.8514 | AF6: 1.16 | AG6: 2.6352 | AH6: 3.055 | AI6: =SUM(D6:AH6) -> 74.0002
C7: Yellow skip | D7: 0 | E7: 0.55 | F7: 1.58 | G7: 0 | H7: 1.78 | I7: 0 | J7: 2.5 | K7: 0 | L7: 0.57 | M7: 0.65 | N7: 0.76 | O7: 1.68 | P7: 1.38 | Q7: 0 | R7: 0 | S7: 1.67 | T7: 0 | U7: 1.54 | V7: 1.25 | W7: 1.41 | X7: 0 | Y7: 0 | Z7: 2.09 | AA7: 0 | AB7: 1.02 | AC7: 0.96 | AD7: 0.83 | AE7: 0 | AF7: 0 | AG7: 1.87 | AH7: 0 | AI7: =SUM(D7:AH7) -> 24.09
C8: Total Weight (Tonne) | D8: =SUM(D6:D7) -> 1.3742 | E8: =SUM(E6:E7) -> 3.1698 | F8: =SUM(F6:F7) -> 3.4268 | G8: =SUM(G6:G7) -> 2.3042 | H8: =SUM(H6:H7) -> 3.711 | I8: =SUM(I6:I7) -> 2.833 | J8: =SUM(J6:J7) -> 4.766 | K8: =SUM(K6:K7) -> 1.6904 | ... AI8: =SUM(AI6:AI7) -> 98.0902
C9: Recyclable Wastes Statistics
C10: Recycled Types | D10: Date of Recycling Wastes Collection Details (kg) | AI10: Total Weight
D11: 43893 | E11: 43896 | F11: 43897 | G11: 43900 | H11: 43902 | I11: 43903 | J11: 43907 | K11: 43910 | L11: 43911 | M11: 43913 | N11: 43916 | O11: 43918 | P11: 43921
C12: Old Corrugated Containers | D12: 500 | E12: 445 | F12: 110 | G12: 468 | H12: 700 | I12: 352 | J12: 650 | K12: 543 | L12: 360 | M12: 218 | N12: 350 | O12: 400 | P12: 189 | AI12: =SUM(D12:AH12) -> 5285
C13: Office Paper / Newspapers | D13: 255 | E13: 200 | G13: 286 | H13: 212 | I13: 334 | K13: 600 | L13: 285 | N13: 406 | P13: 410 | AI13: =SUM(D13:AH13) -> 2988
C14: Waste Plastic Bottles | D14: 52 | F14: 48 | H14: 56 | J14: 39 | L14: 40 | N14: 42 | P14: 28 | AI14: =SUM(D14:AH14) -> 305
C15: Aluminum Cans | D15: 10 | F15: 11 | H15: 10 | J15: 8 | L15: 9 | N15: 8 | P15: 10 | AI15: =SUM(D15:AH15) -> 66
C16: Metal | E16: 47 | I16: 58 | K16: 56 | O16: 50 | AI16: =SUM(D16:AH16) -> 211
C17: Other:(pls specify) | AI17: =SUM(D17:AH17) -> 0
C18: Total Weight (kg) | D18: =SUM(D12:D17) -> 817 | E18: =SUM(E12:E17) -> 692 | F18: =SUM(F12:F17) -> 169 | G18: =SUM(G12:G17) -> 754 | H18: =SUM(H12:H17) -> 978 | I18: =SUM(I12:I17) -> 744 | J18: =SUM(J12:J17) -> 697 | K18: =SUM(K12:K17) -> 1199 | ... AI18: =SUM(AI12:AI17) -> 8855
C20: (A) Total Weight of General Waste of this Month : | H20: =AI8*1000 -> 98090.2 | J20: kg | M20: (C) Total Recycling Ratio Percentage of this Month : | T20: =(H21/(H20+H21))*100 -> 8.2799415 | AA20: % < i.e.= B/(A+B) >
C21: (B) Total Weight of Recycled Waste of this Month : | H21: =AI18 -> 8855 | J21: kg | M21: (D) Total Recycling Ratio of Y-T-D Average : | T21: =SUM(D25:AI25)/COUNTA(D25:AI25)*100 -> 7.0953362 | AA21: %
C23: Yearly Summary of Recycling Ratio Percentage
C24: Month | D24: 43647 | F24: 43678 | H24: 43709 | J24: 43739 | L24: 43770 | N24: 43800 | P24: 43831 | R24: 43862 | T24: 43891 | V24: 43922 | X24: 43952 | Z24: 43983 | AB24: 44013 | AD24: 44044 | AF24: 44075 | AH24: 44105
C25: Recycling Ratio Percentage | D25: 0.091809845 | F25: 0.070977248 | H25: 0.055518609 | J25: 0.059962447 | L25: 0.061741945 | N25: 0.060603729 | P25: 0.080874189 | R25: 0.074292828 | T25: =T20/100 -> 0.082799415

Sheet APR-20
C2: HKUST - Campus and Student Hostel
C3: General Wastes Statistics | K3: Month/Year: APR-2020 | AI3: Submission Date: 4-MAY-2020
C4: Waste Types | D4: Date of General Wastes Collection Details (Tonne) | AI4: Total Weight
D5: 43922 | E5: 43923 | F5: 43924 | G5: 43925 | H5: 43926 | I5: 43927 | J5: 43928 | K5: 43929 | L5: 43930 | M5: 43931 | N5: 43932 | O5: 43933 | P5: 43934 | Q5: 43935 | R5: 43936 | S5: 43937 | T5: 43938 | U5: 43939 | V5: 43940 | W5: 43941 | X5: 43942 | Y5: 43943 | Z5: 43944 | AA5: 43945 | AB5: 43946 | AC5: 43947 | AD5: 43948 | AE5: 43949 | AF5: 43950 | AG5: 43951
C6: General Wastes | D6: 3.138 | E6: 2.7242 | F6: 2.7912 | G6: 1.77 | H6: 1.6902 | I6: 3.2502 | J6: 3.0054 | K6: 2.9708 | L6: 3.1758 | M6: 2.0096 | N6: 1.6438 | O6: 1.5266 | P6: 2.1878 | Q6: 3.943 | R6: 2.8714 | S6: 2.9392 | T6: 2.9236 | U6: 2.6458 | V6: 1.57 | W6: 2.7152 | X6: 3.013 | Y6: 2.963 | Z6: 3.1916 | AA6: 2.761 | AB6: 2.505 | AC6: 1.4504 | AD6: 2.8134 | AE6: 3.1264 | AF6: 2.807 | AG6: 1.6808 | AI6: =SUM(D6:AH6) -> 77.8034
C7: Yellow skip | D7: 0.58 | E7: 1.27 | F7: 0.63 | G7: 0 | H7: 0 | I7: 1.72 | J7: 0 | K7: 1.19 | L7: 1.68 | M7: 0 | N7: 0.57 | O7: 0 | P7: 0.62 | Q7: 0.68 | R7: 0 | S7: 1.69 | T7: 0 | U7: 0.75 | V7: 0 | W7: 1.92 | X7: 1.67 | Y7: 0 | Z7: 1.93 | AA7: 1.85 | AB7: 0 | AC7: 0 | AD7: 3.11 | AE7: 0 | AF7: 1.92 | AG7: 1 | AI7: =SUM(D7:AH7) -> 24.78
C8: Total Weight (Tonne) | D8: =SUM(D6:D7) -> 3.718 | E8: =SUM(E6:E7) -> 3.9942 | F8: =SUM(F6:F7) -> 3.4212 | G8: =SUM(G6:G7) -> 1.77 | H8: =SUM(H6:H7) -> 1.6902 | I8: =SUM(I6:I7) -> 4.9702 | J8: =SUM(J6:J7) -> 3.0054 | K8: =SUM(K6:K7) -> 4.1608 | ... AI8: =SUM(AI6:AI7) -> 102.5834
C9: Recyclable Wastes Statistics
C10: Recycled Types | D10: Date of Recycling Wastes Collection Details (kg) | AI10: Total Weight
D11: 43924 | E11: 43928 | F11: 43930 | G11: 43935 | H11: 43938 | I11: 43939 | J11: 43942 | K11: 43944 | L11: 43946 | M11: 43949
C12: Old Corrugated Containers | D12: 566 | E12: 440 | F12: 508 | G12: 650 | H12: 556 | I12: 453 | J12: 400 | K12: 420 | L12: 592 | M12: 365 | AI12: =SUM(D12:AH12) -> 4950
C13: Office Paper / Newspapers | D13: 300 | E13: 526 | F13: 213 | G13: 305 | H13: 440 | K13: 582 | M13: 384 | AI13: =SUM(D13:AH13) -> 2750
C14: Waste Plastic Bottles | D14: 43 | F14: 29 | H14: 50 | J14: 46 | L14: 32 | M14: 38 | AI14: =SUM(D14:AH14) -> 238
C15: Aluminum Cans | D15: 10 | F15: 13 | H15: 14 | J15: 12 | L15: 9 | AI15: =SUM(D15:AH15) -> 58
C16: Metal | E16: 55 | G16: 40 | I16: 36 | K16: 43 | M16: 40 | AI16: =SUM(D16:AH16) -> 214
C17: Other:(pls specify) | AI17: =SUM(D17:AH17) -> 0
C18: Total Weight (kg) | D18: =SUM(D12:D17) -> 919 | E18: =SUM(E12:E17) -> 1021 | F18: =SUM(F12:F17) -> 763 | G18: =SUM(G12:G17) -> 995 | H18: =SUM(H12:H17) -> 1060 | I18: =SUM(I12:I17) -> 489 | J18: =SUM(J12:J17) -> 458 | K18: =SUM(K12:K17) -> 1045 | ... AI18: =SUM(AI12:AI17) -> 8210
C20: (A) Total Weight of General Waste of this Month : | H20: =AI8*1000 -> 102583.4 | J20: kg | M20: (C) Total Recycling Ratio Percentage of this Month : | T20: =(H21/(H20+H21))*100 -> 7.4101887 | AA20: % < i.e.= B/(A+B) >
C21: (B) Total Weight of Recycled Waste of this Month : | H21: =AI18 -> 8210 | J21: kg | M21: (D) Total Recycling Ratio of Y-T-D Average : | T21: =SUM(D25:AI25)/COUNTA(D25:AI25)*100 -> 7.1268214 | AA21: %
C23: Yearly Summary of Recycling Ratio Percentage
C24: Month | D24: 43647 | F24: 43678 | H24: 43709 | J24: 43739 | L24: 43770 | N24: 43800 | P24: 43831 | R24: 43862 | T24: 43891 | V24: 43922 | X24: 43952 | Z24: 43983 | AB24: 44013 | AD24: 44044 | AF24: 44075 | AH24: 44105
C25: Recycling Ratio Percentage | D25: 0.091809845 | F25: 0.070977248 | H25: 0.055518609 | J25: 0.059962447 | L25: 0.061741945 | N25: 0.060603729 | P25: 0.080874189 | R25: 0.074292828 | T25: ='MAR-20'!T25:U25 -> 0.082799415 | V25: =T20/100 -> 0.074101887

Sheet MAY-20
C2: HKUST - Campus and Student Hostel
C3: General Wastes Statistics | K3: Month/Year: MAY-2020 | AI3: Submission Date: 2-June-2020
C4: Waste Types | D4: Date of General Wastes Collection Details (Tonne) | AI4: Total Weight
D5: 43952 | E5: 43953 | F5: 43954 | G5: 43955 | H5: 43956 | I5: 43957 | J5: 43958 | K5: 43959 | L5: 43960 | M5: 43961 | N5: 43962 | O5: 43963 | P5: 43964 | Q5: 43965 | R5: 43966 | S5: 43967 | T5: 43968 | U5: 43969 | V5: 43970 | W5: 43971 | X5: 43972 | Y5: 43973 | Z5: 43974 | AA5: 43975 | AB5: 43976 | AC5: 43977 | AD5: 43978 | AE5: 43979 | AF5: 43980 | AG5: 43981 | AH5: 43982
C6: General Wastes | D6: 1.8118 | E6: 3.0736 | F6: 1.7554 | G6: 3.151 | H6: 3.822 | I6: 3.2516 | J6: 3.1054 | K6: 2.9348 | L6: 2.8834 | M6: 1.837 | N6: 3.2164 | O6: 3.6968 | P6: 3.2256 | Q6: 3.6098 | R6: 3.279 | S6: 2.7084 | T6: 1.6956 | U6: 3.4376 | V6: 3.833 | W6: 3.3048 | X6: 3.788 | Y6: 3.7588 | Z6: 3.2478 | AA6: 1.7078 | AB6: 3.1764 | AC6: 4.1106 | AD6: 3.3968 | AE6: 3.6338 | AF6: 3.7682 | AG6: 3.462 | AH6: 2.0058 | AI6: =SUM(D6:AH6) -> 95.689
C7: Yellow skip | D7: 0 | E7: 1.68 | F7: 0 | G7: 2.33 | H7: 0.51 | I7: 1.45 | J7: 2.46 | K7: 0.93 | L7: 1.32 | M7: 0 | N7: 1.27 | O7: 3.4 | P7: 1.8 | Q7: 2.04 | R7: 1.31 | S7: 0.73 | T7: 0 | U7: 1.51 | V7: 2.09 | W7: 0.79 | X7: 2.65 | Y7: 1.52 | Z7: 1.53 | AA7: 0 | AB7: 3.47 | AC7: 2.33 | AD7: 3.82 | AE7: 2.17 | AF7: 2.77 | AG7: 0.75 | AH7: 0 | AI7: =SUM(D7:AH7) -> 46.63
C8: Total Weight (Tonne) | D8: =SUM(D6:D7) -> 1.8118 | E8: =SUM(E6:E7) -> 4.7536 | F8: =SUM(F6:F7) -> 1.7554 | G8: =SUM(G6:G7) -> 5.481 | H8: =SUM(H6:H7) -> 4.332 | I8: =SUM(I6:I7) -> 4.7016 | J8: =SUM(J6:J7) -> 5.5654 | K8: =SUM(K6:K7) -> 3.8648 | ... AI8: =SUM(AI6:AI7) -> 142.319
C9: Recyclable Wastes Statistics
C10: Recycled Types | D10: Date of Recycling Wastes Collection Details (kg) | AI10: Total Weight
D11: 43952 | E11: 43956 | F11: 43959 | G11: 43960 | H11: 43963 | I11: 43966 | J11: 43967 | K11: 43970 | L11: 43972 | M11: 43973 | N11: 43977 | O11: 43979 | P11: 43980 | Q11: 43981
C12: Old Corrugated Containers | D12: 580 | E12: 602 | F12: 315 | G12: 210 | H12: 445 | I12: 560 | J12: 386 | K12: 208 | L12: 490 | M12: 223 | N12: 675 | O12: 433 | P12: 310 | AI12: =SUM(D12:AH12) -> 5437
C13: Office Paper / Newspapers | F13: 270 | H13: 406 | I13: 488 | J13: 300 | K13: 215 | L13: 220 | M13: 212 | N13: 450 | O13: 437 | P13: 190 | AI13: =SUM(D13:AH13) -> 3188
C14: Waste Plastic Bottles | D14: 30 | F14: 25 | H14: 28 | J14: 45 | L14: 42 | N14: 46 | P14: 29 | AI14: =SUM(D14:AH14) -> 245
C15: Aluminum Cans | D15: 11 | F15: 12 | H15: 10 | J15: 11 | L15: 8 | N15: 6 | P15: 9 | AI15: =SUM(D15:AH15) -> 67
C16: Metal | E16: 42 | G16: 36 | I16: 39 | K16: 35 | M16: 40 | O16: 51 | Q16: 1500 | AI16: =SUM(D16:AH16) -> 1743
C17: Other:(pls specify) | AI17: =SUM(D17:AH17) -> 0
C18: Total Weight (kg) | D18: =SUM(D12:D17) -> 621 | E18: =SUM(E12:E17) -> 644 | F18: =SUM(F12:F17) -> 622 | G18: =SUM(G12:G17) -> 246 | H18: =SUM(H12:H17) -> 889 | I18: =SUM(I12:I17) -> 1087 | J18: =SUM(J12:J17) -> 742 | K18: =SUM(K12:K17) -> 458 | ... AI18: =SUM(AI12:AI17) -> 10680
C20: (A) Total Weight of General Waste of this Month : | H20: =AI8*1000 -> 142319 | J20: kg | M20: (C) Total Recycling Ratio Percentage of this Month : | T20: =(H21/(H20+H21))*100 -> 6.9804378 | AA20: % < i.e.= B/(A+B) >
C21: (B) Total Weight of Recycled Waste of this Month : | H21: =AI18 -> 10680 | J21: kg | M21: (D) Total Recycling Ratio of Y-T-D Average : | T21: =SUM(D25:AI25)/COUNTA(D25:AI25)*100 -> 7.1135138 | AA21: %
C23: Yearly Summary of Recycling Ratio Percentage
C24: Month | D24: 43647 | F24: 43678 | H24: 43709 | J24: 43739 | L24: 43770 | N24: 43800 | P24: 43831 | R24: 43862 | T24: 43891 | V24: 43922 | X24: 43952 | Z24: 43983 | AB24: 44013 | AD24: 44044 | AF24: 44075 | AH24: 44105
C25: Recycling Ratio Percentage | D25: 0.091809845 | F25: 0.070977248 | H25: 0.055518609 | J25: 0.059962447 | L25: 0.061741945 | N25: 0.060603729 | P25: 0.080874189 | R25: 0.074292828 | T25: ='MAR-20'!T25:U25 -> 0.082799415 | V25: ='APR-20'!V25:W25 -> 0.074101887 | X25: =T20/100 -> 0.069804378

Sheet June-20
C2: HKUST - Campus and Student Hostel
C3: General Wastes Statistics | K3: Month/Year: JUNE-2020 | AI3: Submission Date: 2-July-2020
C4: Waste Types | D4: Date of General Wastes Collection Details (Tonne) | AI4: Total Weight
D5: 43983 | E5: 43984 | F5: 43985 | G5: 43986 | H5: 43987 | I5: 43988 | J5: 43989 | K5: 43990 | L5: 43991 | M5: 43992 | N5: 43993 | O5: 43994 | P5: 43995 | Q5: 43996 | R5: 43997 | S5: 43998 | T5: 43999 | U5: 44000 | V5: 44001 | W5: 44002 | X5: 44003 | Y5: 44004 | Z5: 44005 | AA5: 44006 | AB5: 44007 | AC5: 44008 | AD5: 44009 | AE5: 44010 | AF5: 44011 | AG5: 44012
C6: General Wastes | D6: 3.8348 | E6: 4.1274 | F6: 4.5218 | G6: 5.1492 | H6: 3.5408 | I6: 3.0762 | J6: 1.6636 | K6: 3.867 | L6: 3.926 | M6: 3.283 | N6: 3.3804 | O6: 3.6042 | P6: 2.9702 | Q6: 2.1228 | R6: 3.9434 | S6: 4.1016 | T6: 3.7158 | U6: 3.8002 | V6: 3.693 | W6: 2.8008 | X6: 1.5762 | Y6: 3.6854 | Z6: 3.52 | AA6: 3.4834 | AB6: 2.0082 | AC6: 3.82 | AD6: 2.783 | AE6: 1.8228 | AF6: 3.3458 | AG6: 3.7266 | AI6: =SUM(D6:AH6) -> 100.8936
C7: Yellow skip | D7: 3.6 | E7: 0.92 | F7: 1 | G7: 0 | H7: 1.49 | I7: 2.32 | J7: 0 | K7: 2.14 | L7: 3.08 | M7: 0 | N7: 0.92 | O7: 3.8 | P7: 0.73 | Q7: 0 | R7: 2.45 | S7: 2.95 | T7: 0.67 | U7: 1.39 | V7: 1.78 | W7: 1.64 | X7: 0 | Y7: 1.58 | Z7: 2.07 | AA7: 1.25 | AB7: 0 | AC7: 2.77 | AD7: 1.01 | AE7: 0 | AF7: 1.43 | AG7: 2.25 | AI7: =SUM(D7:AH7) -> 43.24
C8: Total Weight (Tonne) | D8: =SUM(D6:D7) -> 7.4348 | E8: =SUM(E6:E7) -> 5.0474 | F8: =SUM(F6:F7) -> 5.5218 | G8: =SUM(G6:G7) -> 5.1492 | H8: =SUM(H6:H7) -> 5.0308 | I8: =SUM(I6:I7) -> 5.3962 | J8: =SUM(J6:J7) -> 1.6636 | K8: =SUM(K6:K7) -> 6.007 | ... AI8: =SUM(AI6:AI7) -> 144.1336
C9: Recyclable Wastes Statistics
C10: Recycled Types | D10: Date of Recycling Wastes Collection Details (kg) | AI10: Total Weight
D11: 43984 | E11: 43986 | F11: 43987 | G11: 43990 | H11: 43991 | I11: 43994 | J11: 43995 | K11: 43998 | L11: 44000 | M11: 44001 | N11: 44002 | O11: 44004 | P11: 44005 | Q11: 44008 | R11: 44009 | S11: 44012
C12: Old Corrugated Containers | D12: 386 | E12: 490 | F12: 360 | G12: 388 | H12: 264 | I12: 523 | J12: 450 | K12: 246 | L12: 312 | M12: 584 | N12: 210 | O12: 238 | P12: 365 | Q12: 345 | R12: 934 | S12: 300 | AI12: =SUM(D12:AH12) -> 6395
C13: Office Paper / Newspapers | D13: 766 | F13: 585 | H13: 668 | J13: 785 | K13: 640 | N13: 312 | P13: 186 | Q13: 300 | AI13: =SUM(D13:AH13) -> 4242
C14: Waste Plastic Bottles | D14: 33 | G14: 45 | I14: 43 | K14: 46 | N14: 50 | P14: 30 | S14: 32 | AI14: =SUM(D14:AH14) -> 279
C15: Aluminum Cans | D15: 12 | G15: 13 | I15: 11 | K15: 11 | N15: 9 | P15: 11 | S15: 10 | AI15: =SUM(D15:AH15) -> 77
C16: Metal | E16: 50 | H16: 48 | J16: 42 | L16: 39 | O16: 45 | R16: 2040 | AI16: =SUM(D16:AH16) -> 2264
C17: Other:(pls specify) | AI17: =SUM(D17:AH17) -> 0
C18: Total Weight (kg) | D18: =SUM(D12:D17) -> 1197 | E18: =SUM(E12:E17) -> 540 | F18: =SUM(F12:F17) -> 945 | G18: =SUM(G12:G17) -> 446 | H18: =SUM(H12:H17) -> 980 | I18: =SUM(I12:I17) -> 577 | J18: =SUM(J12:J17) -> 1277 | K18: =SUM(K12:K17) -> 943 | ... AI18: =SUM(AI12:AI17) -> 13257
C20: (A) Total Weight of General Waste of this Month : | H20: =AI8*1000 -> 144133.6 | J20: kg | M20: (C) Total Recycling Ratio Percentage of this Month : | T20: =(H21/(H20+H21))*100 -> 8.4229935 | AA20: % < i.e.= B/(A+B) >
C21: (B) Total Weight of Recycled Waste of this Month : | H21: =AI18 -> 13257 | J21: kg | M21: (D) Total Recycling Ratio of Y-T-D Average : | T21: =SUM(D25:AI25)/COUNTA(D25:AI25)*100 -> 7.2226371 | AA21: %
C23: Yearly Summary of Recycling Ratio Percentage
C24: Month | D24: 43647 | F24: 43678 | H24: 43709 | J24: 43739 | L24: 43770 | N24: 43800 | P24: 43831 | R24: 43862 | T24: 43891 | V24: 43922 | X24: 43952 | Z24: 43983 | AB24: 44013 | AD24: 44044 | AF24: 44075 | AH24: 44105
C25: Recycling Ratio Percentage | D25: 0.091809845 | F25: 0.070977248 | H25: 0.055518609 | J25: 0.059962447 | L25: 0.061741945 | N25: 0.060603729 | P25: 0.080874189 | R25: 0.074292828 | T25: ='MAR-20'!T25:U25 -> 0.082799415 | V25: ='APR-20'!V25:W25 -> 0.074101887 | X25: ='MAY-20'!X25:Y25 -> 0.069804378 | Z25: =T20/100 -> 0.084229935

Sheet Jul-20
C2: HKUST - Campus and Student Hostel
C3: General Wastes Statistics | K3: Month/Year: JULY-2020 | AI3: Submission Date: 3-Aug-2020
C4: Waste Types | D4: Date of General Wastes Collection Details (Tonne) | AI4: Total Weight
D5: 44013 | E5: 44014 | F5: 44015 | G5: 44016 | H5: 44017 | I5: 44018 | J5: 44019 | K5: 44020 | L5: 44021 | M5: 44022 | N5: 44023 | O5: 44024 | P5: 44025 | Q5: 44026 | R5: 44027 | S5: 44028 | T5: 44029 | U5: 44030 | V5: 44031 | W5: 44032 | X5: 44033 | Y5: 44034 | Z5: 44035 | AA5: 44036 | AB5: 44037 | AC5: 44038 | AD5: 44039 | AE5: 44040 | AF5: 44041 | AG5: 44042 | AH5: 44043
C6: General Wastes | D6: 1.7272 | E6: 3.812 | F6: 3.668 | G6: 2.766 | H6: 1.5088 | I6: 3.6488 | J6: 3.8102 | K6: 3.386 | L6: 3.664 | M6: 3.5886 | N6: 2.761 | O6: 1.6598 | P6: 3.8236 | Q6: 3.4364 | R6: 3.2686 | S6: 3.0632 | T6: 3.6722 | U6: 2.9546 | V6: 1.581 | W6: 3.8528 | X6: 3.4898 | Y6: 3.2704 | Z6: 3.5022 | AA6: 3.3696 | AB6: 2.9114 | AC6: 1.8146 | AD6: 3.6798 | AE6: 3.8504 | AF6: 3.7742 | AG6: 4.285 | AH6: 3.9408 | AI6: =SUM(D6:AH6) -> 99.541
C7: Yellow skip | D7: 0 | E7: 1.53 | F7: 0.74 | G7: 0.38 | H7: 0 | I7: 1.14 | J7: 1.59 | K7: 1.81 | L7: 1.5 | M7: 0 | N7: 0.8 | O7: 0 | P7: 1.1 | Q7: 1.48 | R7: 0 | S7: 0.24 | T7: 2.68 | U7: 0 | V7: 0 | W7: 1.27 | X7: 0 | Y7: 0 | Z7: 2.27 | AA7: 0 | AB7: 1.18 | AC7: 0 | AD7: 0.44 | AE7: 1.11 | AF7: 1.2 | AG7: 2.99 | AH7: 0 | AI7: =SUM(D7:AH7) -> 25.45
C8: Total Weight (Tonne) | D8: =SUM(D6:D7) -> 1.7272 | E8: =SUM(E6:E7) -> 5.342 | F8: =SUM(F6:F7) -> 4.408 | G8: =SUM(G6:G7) -> 3.146 | H8: =SUM(H6:H7) -> 1.5088 | I8: =SUM(I6:I7) -> 4.7888 | J8: =SUM(J6:J7) -> 5.4002 | K8: =SUM(K6:K7) -> 5.196 | ... AI8: =SUM(AI6:AI7) -> 124.991
C9: Recyclable Wastes Statistics
C10: Recycled Types | D10: Date of Recycling Wastes Collection Details (kg) | AI10: Total Weight
D11: 44015 | E11: 44019 | F11: 44021 | G11: 44022 | H11: 44023 | I11: 44025 | J11: 44026 | K11: 44028 | L11: 44029 | M11: 44030 | N11: 44033 | O11: 44035 | P11: 44037 | Q11: 44040 | R11: 44042 | S11: 44043
C12: Old Corrugated Containers | D12: 506 | E12: 580 | F12: 424 | G12: 503 | H12: 316 | I12: 285 | K12: 620 | L12: 548 | M12: 305 | N12: 224 | O12: 560 | P12: 606 | Q12: 322 | R12: 421 | S12: 200 | AI12: =SUM(D12:AH12) -> 6420
C13: Office Paper / Newspapers | D13: 1020 | F13: 596 | H13: 230 | K13: 582 | L13: 225 | M13: 568 | N13: 452 | R13: 552 | AI13: =SUM(D13:AH13) -> 4225
C14: Waste Plastic Bottles | D14: 36 | F14: 39 | H14: 42 | K14: 40 | M14: 43 | O14: 45 | Q14: 30 | S14: 16 | AI14: =SUM(D14:AH14) -> 291
C15: Aluminum Cans | D15: 13 | F15: 10 | H15: 9 | K15: 12 | M15: 13 | O15: 13 | Q15: 11 | S15: 12 | AI15: =SUM(D15:AH15) -> 93
C16: Metal | E16: 40 | G16: 33 | I16: 45 | J16: 1200 | L16: 42 | N16: 30 | P16: 31 | R16: 38 | AI16: =SUM(D16:AH16) -> 1459
C17: Other:(pls specify) | AI17: =SUM(D17:AH17) -> 0
C18: Total Weight (kg) | D18: =SUM(D12:D17) -> 1575 | E18: =SUM(E12:E17) -> 620 | F18: =SUM(F12:F17) -> 1069 | G18: =SUM(G12:G17) -> 536 | H18: =SUM(H12:H17) -> 597 | I18: =SUM(I12:I17) -> 330 | J18: =SUM(J12:J17) -> 1200 | K18: =SUM(K12:K17) -> 1254 | ... AI18: =SUM(AI12:AI17) -> 12488
C20: (A) Total Weight of General Waste of this Month : | H20: =AI8*1000 -> 124991 | J20: kg | M20: (C) Total Recycling Ratio Percentage of this Month : | T20: =(H21/(H20+H21))*100 -> 9.0835691 | AA20: % < i.e.= B/(A+B) >
C21: (B) Total Weight of Recycled Waste of this Month : | H21: =AI18 -> 12488 | J21: kg | M21: (D) Total Recycling Ratio of Y-T-D Average : | T21: =SUM(D25:AI25)/COUNTA(D25:AI25)*100 -> 7.3657857 | AA21: %
C23: Yearly Summary of Recycling Ratio Percentage
C24: Month | D24: 43647 | F24: 43678 | H24: 43709 | J24: 43739 | L24: 43770 | N24: 43800 | P24: 43831 | R24: 43862 | T24: 43891 | V24: 43922 | X24: 43952 | Z24: 43983 | AB24: 44013 | AD24: 44044 | AF24: 44075 | AH24: 44105
C25: Recycling Ratio Percentage | D25: 0.091809845 | F25: 0.070977248 | H25: 0.055518609 | J25: 0.059962447 | L25: 0.061741945 | N25: 0.060603729 | P25: 0.080874189 | R25: 0.074292828 | T25: ='MAR-20'!T25:U25 -> 0.082799415 | V25: ='APR-20'!V25:W25 -> 0.074101887 | X25: ='MAY-20'!X25:Y25 -> 0.069804378 | Z25: ='June-20'!Z25:AA25 -> 0.084229935 | AB25: =T20/100 -> 0.090835691

Sheet Aug-20
C2: HKUST - Campus and Student Hostel
C3: General Wastes Statistics | K3: Month/Year: AUGUST-2020 | AI3: Submission Date: 1-Sep-2020
C4: Waste Types | D4: Date of General Wastes Collection Details (Tonne) | AI4: Total Weight
D5: 44044 | E5: 44045 | F5: 44046 | G5: 44047 | H5: 44048 | I5: 44049 | J5: 44050 | K5: 44051 | L5: 44052 | M5: 44053 | N5: 44054 | O5: 44055 | P5: 44056 | Q5: 44057 | R5: 44058 | S5: 44059 | T5: 44060 | U5: 44061 | V5: 44062 | W5: 44063 | X5: 44064 | Y5: 44065 | Z5: 44066 | AA5: 44067 | AB5: 44068 | AC5: 44069 | AD5: 44070 | AE5: 44071 | AF5: 44072 | AG5: 44073 | AH5: 44074
C6: General Wastes | D6: 3.8746 | E6: 2.3986 | F6: 4.062 | G6: 3.8344 | H6: 3.2214 | I6: 3.268 | J6: 3.3728 | K6: 2.748 | L6: 1.6944 | M6: 3.7052 | N6: 3.4948 | O6: 3.5704 | P6: 3.3392 | Q6: 3.4976 | R6: 3.4582 | S6: 2.0484 | T6: 3.9644 | U6: 3.3766 | V6: 2.6144 | W6: 3.619 | X6: 3.195 | Y6: 3.0858 | Z6: 1.862 | AA6: 3.5974 | AB6: 3.4994 | AC6: 3.3846 | AD6: 3.579 | AE6: 3.0848 | AF6: 2.7964 | AG6: 1.713 | AH6: 3.2278 | AI6: =SUM(D6:AH6) -> 98.1876
C7: Yellow skip | D7: 1.31 | E7: 0 | F7: 0.68 | G7: 1.39 | H7: 0 | I7: 0.7 | J7: 0.93 | K7: 0 | L7: 0 | M7: 2.38 | N7: 0 | O7: 2.13 | P7: 1.3 | Q7: 0.87 | R7: 0 | S7: 0 | T7: 3.29 | U7: 0 | V7: 0 | W7: 3.19 | X7: 0 | Y7: 1.06 | Z7: 0 | AA7: 0.84 | AB7: 0.88 | AC7: 0 | AD7: 2.01 | AE7: 0.89 | AF7: 0 | AG7: 0 | AH7: 1.25 | AI7: =SUM(D7:AH7) -> 25.1
C8: Total Weight (Tonne) | D8: =SUM(D6:D7) -> 5.1846 | E8: =SUM(E6:E7) -> 2.3986 | F8: =SUM(F6:F7) -> 4.742 | G8: =SUM(G6:G7) -> 5.2244 | H8: =SUM(H6:H7) -> 3.2214 | I8: =SUM(I6:I7) -> 3.968 | J8: =SUM(J6:J7) -> 4.3028 | K8: =SUM(K6:K7) -> 2.748 | ... AI8: =SUM(AI6:AI7) -> 123.2876
C9: Recyclable Wastes Statistics
C10: Recycled Types | D10: Date of Recycling Wastes Collection Details (kg) | AI10: Total Weight
D11: 44047 | E11: 44049 | F11: 44050 | G11: 44051 | H11: 44054 | I11: 44056 | J11: 44058 | K11: 44060 | L11: 44061 | M11: 44063 | N11: 44064 | O11: 44065 | P11: 44067 | Q11: 44069 | R11: 44070 | S11: 44071
C12: Old Corrugated Containers | D12: 556 | E12: 426 | F12: 445 | G12: 382 | H12: 433 | I12: 345 | J12: 468 | K12: 428 | L12: 455 | M12: 448 | N12: 609 | P12: 526 | Q12: 360 | R12: 361 | S12: 485 | AI12: =SUM(D12:AH12) -> 6727
C13: Office Paper / Newspapers | D13: 243 | E13: 480 | F13: 269 | H13: 339 | J13: 267 | K13: 508 | N13: 467 | P13: 288 | Q13: 321 | S13: 276 | AI13: =SUM(D13:AH13) -> 3458
C14: Waste Plastic Bottles | D14: 40 | F14: 42 | H14: 34 | J14: 33 | L14: 36 | N14: 37 | Q14: 42 | S14: 30 | AI14: =SUM(D14:AH14) -> 294
C15: Aluminum Cans | D15: 11 | F15: 12 | H15: 10 | J15: 11 | L15: 14 | N15: 12 | Q15: 10 | S15: 13 | AI15: =SUM(D15:AH15) -> 93
C16: Metal | E16: 46 | G16: 35 | I16: 30 | K16: 43 | M16: 41 | O16: 1600 | P16: 39 | R16: 40 | AI16: =SUM(D16:AH16) -> 1874
C17: Other:(pls specify) | AI17: =SUM(D17:AH17) -> 0
C18: Total Weight (kg) | D18: =SUM(D12:D17) -> 850 | E18: =SUM(E12:E17) -> 952 | F18: =SUM(F12:F17) -> 768 | G18: =SUM(G12:G17) -> 417 | H18: =SUM(H12:H17) -> 816 | I18: =SUM(I12:I17) -> 375 | J18: =SUM(J12:J17) -> 779 | K18: =SUM(K12:K17) -> 979 | ... AI18: =SUM(AI12:AI17) -> 12446
C20: (A) Total Weight of General Waste of this Month : | H20: =AI8*1000 -> 123287.6 | J20: kg | M20: (C) Total Recycling Ratio Percentage of this Month : | T20: =(H21/(H20+H21))*100 -> 9.1694319 | AA20: % < i.e.= B/(A+B) >
C21: (B) Total Weight of Recycled Waste of this Month : | H21: =AI18 -> 12446 | J21: kg | M21: (D) Total Recycling Ratio of Y-T-D Average : | T21: =SUM(D25:AI25)/COUNTA(D25:AI25)*100 -> 7.4946176 | AA21: %
C23: Yearly Summary of Recycling Ratio Percentage
C24: Month | D24: 43647 | F24: 43678 | H24: 43709 | J24: 43739 | L24: 43770 | N24: 43800 | P24: 43831 | R24: 43862 | T24: 43891 | V24: 43922 | X24: 43952 | Z24: 43983 | AB24: 44013 | AD24: 44044 | AF24: 44075 | AH24: 44105
C25: Recycling Ratio Percentage | D25: 0.091809845 | F25: 0.070977248 | H25: 0.055518609 | J25: 0.059962447 | L25: 0.061741945 | N25: 0.060603729 | P25: 0.080874189 | R25: 0.074292828 | T25: ='MAR-20'!T25:U25 -> 0.082799415 | V25: ='APR-20'!V25:W25 -> 0.074101887 | X25: ='MAY-20'!X25:Y25 -> 0.069804378 | Z25: ='June-20'!Z25:AA25 -> 0.084229935 | AB25: ='Jul-20'!AB25:AC25 -> 0.090835691 | AD25: =T20/100 -> 0.091694319

Sheet SEP-20
C2: HKUST - Campus and Student Hostel
C3: General Wastes Statistics | K3: Month/Year: SEPEMBER-2020 | AI3: Submission Date: 6-Oct-2020
C4: Waste Types | D4: Date of General Wastes Collection Details (Tonne) | AI4: Total Weight
D5: 44075 | E5: 44076 | F5: 44077 | G5: 44078 | H5: 44079 | I5: 44080 | J5: 44081 | K5: 44082 | L5: 44083 | M5: 44084 | N5: 44085 | O5: 44086 | P5: 44087 | Q5: 44088 | R5: 44089 | S5: 44090 | T5: 44091 | U5: 44092 | V5: 44093 | W5: 44094 | X5: 44095 | Y5: 44096 | Z5: 44097 | AA5: 44098 | AB5: 44099 | AC5: 44100 | AD5: 44101 | AE5: 44102 | AF5: 44103 | AG5: 44104
C6: General Wastes | D6: 3.8022 | E6: 3.2734 | F6: 3.1942 | G6: 3.5766 | H6: 3.0716 | I6: 2.0634 | J6: 4.0176 | K6: 4.1406 | L6: 3.977 | M6: 3.6244 | N6: 3.7312 | O6: 2.8826 | P6: 1.6356 | Q6: 3.8698 | R6: 4.0998 | S6: 3.8702 | T6: 3.9056 | U6: 3.6026 | V6: 3.459 | W6: 1.7164 | X6: 3.889 | Y6: 4.486 | Z6: 3.6614 | AA6: 3.5702 | AB6: 3.7168 | AC6: 3.0912 | AD6: 1.8604 | AE6: 3.7618 | AF6: 3.8456 | AG6: 4.0834 | AI6: =SUM(D6:AH6) -> 103.4796
C7: Yellow skip | D7: 1.4 | E7: 0 | F7: 1.88 | G7: 0.92 | H7: 0 | I7: 0 | J7: 2.46 | K7: 0.44 | L7: 0 | M7: 2.81 | N7: 0 | O7: 1.25 | P7: 0 | Q7: 1.69 | R7: 1.05 | S7: 0 | T7: 1.08 | U7: 1.84 | V7: 0 | W7: 0 | X7: 1.36 | Y7: 0 | Z7: 1.22 | AA7: 1.61 | AB7: 0.74 | AC7: 0 | AD7: 0 | AE7: 1.93 | AF7: 0 | AG7: 2.77 | AI7: =SUM(D7:AH7) -> 26.45
C8: Total Weight (Tonne) | D8: =SUM(D6:D7) -> 5.2022 | E8: =SUM(E6:E7) -> 3.2734 | F8: =SUM(F6:F7) -> 5.0742 | G8: =SUM(G6:G7) -> 4.4966 | H8: =SUM(H6:H7) -> 3.0716 | I8: =SUM(I6:I7) -> 2.0634 | J8: =SUM(J6:J7) -> 6.4776 | K8: =SUM(K6:K7) -> 4.5806 | ... AI8: =SUM(AI6:AI7) -> 129.9296
C9: Recyclable Wastes Statistics
C10: Recycled Types | D10: Date of Recycling Wastes Collection Details (kg) | AI10: Total Weight
D11: 44075 | E11: 44076 | F11: 44077 | G11: 44078 | H11: 44081 | I11: 44083 | J11: 44085 | K11: 44089 | L11: 44091 | M11: 44092 | N11: 44096 | O11: 44098 | P11: 44100 | Q11: 44103 | R11: 44104
C12: Old Corrugated Containers | D12: 512 | E12: 340 | F12: 348 | G12: 410 | H12: 425 | I12: 426 | J12: 504 | K12: 382 | L12: 426 | M12: 500 | N12: 675 | O12: 619 | P12: 528 | Q12: 538 | R12: 365 | AI12: =SUM(D12:AH12) -> 6998
C13: Office Paper / Newspapers | D13: 342 | F13: 390 | G13: 362 | I13: 359 | K13: 375 | L13: 450 | N13: 384 | O13: 117 | Q13: 332 | R13: 700 | AI13: =SUM(D13:AH13) -> 3811
C14: Waste Plastic Bottles | D14: 36 | F14: 38 | H14: 41 | J14: 39 | L14: 32 | N14: 35 | P14: 52 | R14: 28 | AI14: =SUM(D14:AH14) -> 301
C15: Aluminum Cans | D15: 10 | F15: 12 | H15: 8 | J15: 14 | L15: 11 | N15: 10 | P15: 14 | R15: 13 | AI15: =SUM(D15:AH15) -> 92
C16: Metal | E16: 37 | G16: 42 | I16: 33 | K16: 38 | M16: 44 | O16: 32 | Q16: 40 | AI16: =SUM(D16:AH16) -> 266
C17: Other:(pls specify) | AI17: =SUM(D17:AH17) -> 0
C18: Total Weight (kg) | D18: =SUM(D12:D17) -> 900 | E18: =SUM(E12:E17) -> 377 | F18: =SUM(F12:F17) -> 788 | G18: =SUM(G12:G17) -> 814 | H18: =SUM(H12:H17) -> 474 | I18: =SUM(I12:I17) -> 818 | J18: =SUM(J12:J17) -> 557 | K18: =SUM(K12:K17) -> 795 | ... AI18: =SUM(AI12:AI17) -> 11468
C20: (A) Total Weight of General Waste of this Month : | H20: =AI8*1000 -> 129929.6 | J20: kg | M20: (C) Total Recycling Ratio Percentage of this Month : | T20: =(H21/(H20+H21))*100 -> 8.110463 | AA20: % < i.e.= B/(A+B) >
C21: (B) Total Weight of Recycled Waste of this Month : | H21: =AI18 -> 11468 | J21: kg | M21: (D) Total Recycling Ratio of Y-T-D Average : | T21: =SUM(D25:AI25)/COUNTA(D25:AI25)*100 -> 7.535674 | AA21: %
C23: Yearly Summary of Recycling Ratio Percentage
